Workbook
Name ATWACC: 'Q5'!$D$3
Name Beta_E: 'Q4'!$D$10
Name Equity: 'Q4'!$D$9
Name Net_Debt: 'Q4'!$D$8
Name PTWACC: 'Q5'!$D$2
Name RAAPL: 'Q1'!$C$2:$C$1259
Name Rd: 'Q4'!$D$6
Name Rf: 'Q4'!$D$4
Name Rm: 'Q4'!$D$5
Name RSPX: 'Q1'!$F$2:$F$1259
Name Tax: 'Q4'!$D$7

Sheet Q1
A1: Date | B1: Adj Close** AAPL | C1: Return AAPL | E1: Adj Close** SPX | F1: Return SPX
A2: 45198 | B2: 170.77 | C2: =(B2-B3)/B3 -> 0.0030543319 | E2: 4288.05 | F2: =(E2-E3)/E3 -> -0.0027094914
A3: 45197 | B3: 170.25 | C3: =(B3-B4)/B4 -> 0.0015295017 | E3: 4299.7 | F3: =(E3-E4)/E4 -> 0.0058930731
A4: 45196 | B4: 169.99 | C4: =(B4-B5)/B5 -> -0.008862457 | E4: 4274.51 | F4: =(E4-E5)/E5 -> 0.00022931862
A5: 45195 | B5: 171.51 | C5: =(B5-B6)/B6 -> -0.023402802 | E5: 4273.53 | F5: =(E5-E6)/E6 -> -0.014734498
A6: 45194 | B6: 175.62 | C6: =(B6-B7)/B7 -> 0.0073419755 | E6: 4337.44 | F6: =(E6-E7)/E7 -> 0.0040230923 | I6: Results
A7: 45191 | B7: 174.34 | C7: =(B7-B8)/B8 -> 0.0049573438 | E7: 4320.06 | F7: =(E7-E8)/E8 -> -0.002295612
A8: 45190 | B8: 173.48 | C8: =(B8-B9)/B9 -> -0.0089122486 | E8: 4330 | F8: =(E8-E9)/E9 -> -0.01640089 | I8: Equity Beta of Apple = | K8: =_xlfn.COVARIANCE.S(RAAPL,RSPX)/_xlfn.VAR.S(RSPX) -> 1.2358442
A9: 45189 | B9: 175.04 | C9: =(B9-B10)/B10 -> -0.019987683 | E9: 4402.2 | F9: =(E9-E10)/E10 -> -0.0093947952
A10: 45188 | B10: 178.61 | C10: =(B10-B11)/B11 -> 0.006196834 | E10: 4443.95 | F10: =(E10-E11)/E11 -> -0.0021511026 | I10: Formula(s)
A11: 45187 | B11: 177.51 | C11: =(B11-B12)/B12 -> 0.016899633 | E11: 4453.53 | F11: =(E11-E12)/E12 -> 0.00072129645 | I11: β = | J11: COVARIANCE.S(RAAPL,RSPX)/VAR.S(RSPX)
A12: 45184 | B12: 174.56 | C12: =(B12-B13)/B13 -> -0.0041645274 | E12: 4450.32 | F12: =(E12-E13)/E13 -> -0.012159553
A13: 45183 | B13: 175.29 | C13: =(B13-B14)/B14 -> 0.0088052486 | E13: 4505.1 | F13: =(E13-E14)/E14 -> 0.0084298838
A14: 45182 | B14: 173.76 | C14: =(B14-B15)/B15 -> -0.011828935 | E14: 4467.44 | F14: =(E14-E15)/E15 -> 0.0012416235
A15: 45181 | B15: 175.84 | C15: =(B15-B16)/B16 -> -0.017104528 | E15: 4461.9 | F15: =(E15-E16)/E16 -> -0.0056958725
A16: 45180 | B16: 178.9 | C16: =(B16-B17)/B17 -> 0.0066396579 | E16: 4487.46 | F16: =(E16-E17)/E17 -> 0.0067235148
A17: 45177 | B17: 177.72 | C17: =(B17-B18)/B18 -> 0.003500847 | E17: 4457.49 | F17: =(E17-E18)/E18 -> 0.0014266008
A18: 45176 | B18: 177.1 | C18: =(B18-B19)/B19 -> -0.029269897 | E18: 4451.14 | F18: =(E18-E19)/E19 -> -0.0032113009
A19: 45175 | B19: 182.44 | C19: =(B19-B20)/B20 -> -0.03578035 | E19: 4465.48 | F19: =(E19-E20)/E20 -> -0.0069715778 | O19: =_xlfn.COVARIANCE.S(RAAPL,RSPX)/_xlfn.VAR.S(RSPX) -> 1.2358442
A20: 45174 | B20: 189.21 | C20: =(B20-B21)/B21 -> 0.0012700429 | E20: 4496.83 | F20: =(E20-E21)/E21 -> -0.0041941906
A21: 45170 | B21: 188.97 | C21: =(B21-B22)/B22 -> 0.0084854307 | E21: 4515.77 | F21: =(E21-E22)/E22 -> 0.0017991597
A22: 45169 | B22: 187.38 | C22: =(B22-B23)/B23 -> 0.0011754648 | E22: 4507.66 | F22: =(E22-E23)/E23 -> -0.0015969452
A23: 45168 | B23: 187.16 | C23: =(B23-B24)/B24 -> 0.019167937 | E23: 4514.87 | F23: =(E23-E24)/E24 -> 0.0038331299
A24: 45167 | B24: 183.64 | C24: =(B24-B25)/B25 -> 0.021811707 | E24: 4497.63 | F24: =(E24-E25)/E25 -> 0.014508347
A25: 45166 | B25: 179.72 | C25: =(B25-B26)/B26 -> 0.0088127982 | E25: 4433.31 | F25: =(E25-E26)/E26 -> 0.0062645975
A26: 45163 | B26: 178.15 | C26: =(B26-B27)/B27 -> 0.012676216 | E26: 4405.71 | F26: =(E26-E27)/E27 -> 0.0067179884
A27: 45162 | B27: 175.92 | C27: =(B27-B28)/B28 -> -0.026183227 | E27: 4376.31 | F27: =(E27-E28)/E28 -> -0.01345804
A28: 45161 | B28: 180.65 | C28: =(B28-B29)/B29 -> 0.021949426 | E28: 4436.01 | F28: =(E28-E29)/E29 -> 0.011044888
A29: 45160 | B29: 176.77 | C29: =(B29-B30)/B30 -> 0.0079256472 | E29: 4387.55 | F29: =(E29-E30)/E30 -> -0.0027774179
A30: 45159 | B30: 175.38 | C30: =(B30-B31)/B31 -> 0.0076993795 | E30: 4399.77 | F30: =(E30-E31)/E31 -> 0.006879175
A31: 45156 | B31: 174.04 | C31: =(B31-B32)/B32 -> 0.0028233938 | E31: 4369.71 | F31: =(E31-E32)/E32 -> -0.00014872917
... A1259: 43374 | B1259: 54.27 | C1259: =(B1259-B1260)/B1260 -> 0.0066777963 | E1259: 2924.59 | F1259: =(E1259-E1260)/E1260 -> 0.0036410682
A1260: 43371 | B1260: 53.91 | E1260: 2913.98

Sheet Q2
C2: Assumptions, Values & Formulas
C3: Assumptions & Values: | F3: Formulas
C4: Market value of equity | D4: =D5*D6 -> 2700308651190 | F4: = share price * Shares Outstanding
C5: $/Shr | D5: ='Q1'!B2 -> 170.77 | F5: as of close 29/09/2023 Yahoo Finance
C6: Shares outstanding | D6: 15812547000 | F6: as of 30/09/2023 - Apple Annual Report
C7: Net Debt | D7: =(D8+D9)-D10 -> 75138000000 | F7: = (Term debt short term + Term debt long term) - Cash and cash equivalents
C8: Term debt short term | D8: 9822000000 | F8: as of 30/09/2023 - Apple Annual Report
C9: Term debt long term | D9: 95281000000 | F9: as of 30/09/2023 - Apple Annual Report
C10: Cash and cash equivalents | D10: 29965000000 | F10: as of 30/09/2023 - Apple Annual Report
C11: Beta of Equity | D11: ='Q1'!K8 -> 1.2358442 | F11: Unlevered beta without taxes:
C12: Beta of Debt | D12: 0
C14: Assumptions and 10K Values
C16: Beta of Assets | D16: =(D4/(D4+D7))*D11+(D7/(D4+D7))*D12 -> 1.202387
C18: Calculations

Sheet Q3
C2: Assumptions & Values
C4: Term debt long term | D4: 95281000000 | F4: as of 12/30/2023 - Apple Annual Report
C5: YTM | D5: 0.06
C6: Recovery Rate | D6: 0.55
C7: Expected loss rate | D7: =(1+D5)*(1-D6) -> 0.477
C8: Probabilty default AA-rated bonds | D8: 0.001
C12: Formula | F12: Result
F14: Cost of debt | H14: =(1-D8)*D5+D8*(D5-D7) -> 0.059523
C17: Calculations

Sheet Q4
C2: Assumptions & Values | I2: Formulas
C4: Risk-free rate | D4: 0.035
C5: Market return | D5: =D4+5% -> 0.085
C6: Cost of Debt | D6: ='Q3'!H14 -> 0.059523
C7: Tax-rate | D7: 0.15
C8: Net Debt | D8: ='Q2'!D7 -> 75138000000
C9: Equity | D9: ='Q2'!D4 -> 2700308651190
C10: Beta of Equity | D10: ='Q1'!K8 -> 1.2358442
C13: Results
C15: Cost of equity | E15: =D4+D10*(D5-D4) -> 0.096792212
C17: Pre-Tax WACC | E17: =(D9/(D9+D8))*E15+(D8/(D9+D8))*D6 -> 0.095783245
C19: After-Tax WACC | E19: =(D9/(D9+D8))*E15+(D8/(D9+D8))*D6*(1-D7) -> 0.09554153
C22: Calculations

Sheet Q5
C2: pre-tax WACC | D2: 0.0905
C3: after-tax WACC | D3: 0.09
C5: In millions $ | D5: 0 | E5: =D5+1 -> 1 | F5: =E5+1 -> 2 | G5: =F5+1 -> 3 | H5: =G5+1 -> 4 | I5: =H5+1 -> 5 | J5: =I5+1 -> 6 | M5: Depreciation Schedule
C6: Income Statement | D6: 45200 | E6: 45566 | F6: 45931 | G6: 46296 | H6: 46661 | I6: 47027 | J6: 47392 | M6: Asset | N6: Price | O6: Period | P6: Life | Q6: Salvage | R6: t=0 | S6: t=1 | T6: t=2 | U6: t=3 | V6: t=4 | W6: t=5 | X6: t=6
C7: Sales | D7: 0 | E7: 385 | F7: =E7*(1+F8) -> 396.55 | G7: =F7*(1+G8) -> 408.4465 | H7: =G7*(1+H8) -> 437.03776 | I7: =H7*(1+I8) -> 467.6304 | J7: =I7*(1+J8) -> 467.6304 | M7: Investment 1 | N7: =D27 -> 128 | O7: 0 | P7: 5 | Q7: 0 | R7: 0 | S7: =$N$7/$P$7 -> 25.6 | T7: =$N$7/$P$7 -> 25.6 | U7: =$N$7/$P$7 -> 25.6 | V7: =$N$7/$P$7 -> 25.6 | W7: =$N$7/$P$7 -> 25.6 | X7: 0
C8: % growth | F8: 0.03 | G8: 0.03 | H8: 0.07 | I8: 0.07 | J8: 0 | M8: Investment 2 | N8: =E27 -> 162 | O8: 1 | P8: 5 | Q8: 0 | R8: 0 | S8: 0 | T8: =$N$8/$P$8 -> 32.4 | U8: =$N$8/$P$8 -> 32.4 | V8: =$N$8/$P$8 -> 32.4 | W8: =$N$8/$P$8 -> 32.4 | X8: =$N$8/$P$8 -> 32.4
Q9: Total: | R9: =SUM(R7:R8) -> 0 | S9: =SUM(S7:S8) -> 25.6 | T9: =SUM(T7:T8) -> 58 | U9: =SUM(U7:U8) -> 58 | V9: =SUM(V7:V8) -> 58 | W9: =SUM(W7:W8) -> 58 | X9: =SUM(X7:X8) -> 32.4
C10: COGS | D10: =D11*D7 -> 0 | E10: =E11*E7 -> 142.45 | F10: =F11*F7 -> 146.7235 | G10: =G11*G7 -> 151.1252 | H10: =H11*H7 -> 161.70397 | I10: =I11*I7 -> 173.02325 | J10: =J11*J7 -> 173.02325
C11: % of sales | D11: 0.37 | E11: 0.37 | F11: 0.37 | G11: 0.37 | H11: 0.37 | I11: 0.37 | J11: 0.37 | M11: Formulas
M12: EBIT = | N12: Sales - COGS - R&D - G&A - D&A
C13: R&D | D13: 389 | E13: 0 | F13: 0 | G13: 0 | H13: 0 | I13: 0 | J13: 0 | M13: EBIAT = | N13: EBIT - Taxes
M14: Change in NWC = | N14: Current(CA + Inv - CL) - Previous(CA + Inv -CL)
C15: G&A | D15: 0 | E15: 79 | F15: 79 | G15: 79 | H15: 79 | I15: 79 | J15: 79 | M15: Unlevered FCF = | N15: EBIAT + D&A - CapEx - Change in NWC
M16: Present Value of FCF = | N16: FCF/(1+WACC)^t
C17: EBIT | D17: =D7-D10-D13-D15-D25 -> -389 | E17: =E7-E10-E13-E15-E25 -> 137.95 | F17: =F7-F10-F13-F15-F25 -> 112.8265 | G17: =G7-G10-G13-G15-G25 -> 120.3213 | H17: =H7-H10-H13-H15-H25 -> 138.33379 | I17: =I7-I10-I13-I15-I25 -> 157.60715 | J17: =J7-J10-J13-J15-J25 -> 183.20715 | M17: NPV = | N17: SUM( PV(FCF); t=0 to t=6)
C19: Taxes | D19: =D17*D20 -> -58.35 | E19: =E17*E20 -> 20.6925 | F19: =F17*F20 -> 16.923975 | G19: =G17*G20 -> 18.048194 | H19: =H17*H20 -> 20.750068 | I19: =I17*I20 -> 23.641073 | J19: =J17*J20 -> 27.481073
C20: % of EBIT | D20: 0.15 | E20: 0.15 | F20: 0.15 | G20: 0.15 | H20: 0.15 | I20: 0.15 | J20: 0.15
C22: EBIAT | D22: =D17-D19 -> -330.65 | E22: =E17-E19 -> 117.2575 | F22: =F17-F19 -> 95.902525 | G22: =G17-G19 -> 102.2731 | H22: =H17-H19 -> 117.58372 | I22: =I17-I19 -> 133.96608 | J22: =J17-J19 -> 155.72608
C24: Cashflow Items | D24: 45200 | E24: 45566 | F24: 45931 | G24: 46296 | H24: 46661 | I24: 47027 | J24: 47392
C25: D&A | D25: =R9 -> 0 | E25: =S9 -> 25.6 | F25: =T9 -> 58 | G25: =U9 -> 58 | H25: =V9 -> 58 | I25: =W9 -> 58 | J25: =X9 -> 32.4
C27: CapEx | D27: 128 | E27: 162 | F27: 0 | G27: 0 | H27: 0 | I27: 0 | J27: 0
C29: CA | D29: =D30*D7 -> 0 | E29: =E30*E7 -> 57.75 | F29: =F30*F7 -> 59.4825 | G29: =G30*G7 -> 61.266975 | H29: =H30*H7 -> 65.555663 | I29: =I30*I7 -> 70.14456 | J29: =J30*J7 -> 70.14456
C30: % of sales | D30: 0.15 | E30: 0.15 | F30: 0.15 | G30: 0.15 | H30: 0.15 | I30: 0.15 | J30: 0.15
C32: Inventory | D32: =D33*D10 -> 0 | E32: =E33*E10 -> 11.396 | F32: =F33*F10 -> 11.73788 | G32: =G33*G10 -> 12.090016 | H32: =H33*H10 -> 12.936318 | I32: =I33*I10 -> 13.84186 | J32: =J33*J10 -> 13.84186
C33: % of COGS | D33: 0.08 | E33: 0.08 | F33: 0.08 | G33: 0.08 | H33: 0.08 | I33: 0.08 | J33: 0.08
C35: CL | D35: =D36*D10 -> 0 | E35: =E36*E10 -> 15.6695 | F35: =F36*F10 -> 16.139585 | G35: =G36*G10 -> 16.623773 | H35: =H36*H10 -> 17.787437 | I35: =I36*I10 -> 19.032557 | J35: =J36*J10 -> 19.032557
C36: % of COGS | D36: 0.11 | E36: 0.11 | F36: 0.11 | G36: 0.11 | H36: 0.11 | I36: 0.11 | J36: 0.11
C38: Change in NWC | D38: 0 | E38: =(E29+E32-E35)-(D29+D32-D35) -> 53.4765 | F38: =(F29+F32-F35)-(E29+E32-E35) -> 1.604295 | G38: =(G29+G32-G35)-(F29+F32-F35) -> 1.6524238 | H38: =(H29+H32-H35)-(G29+G32-G35) -> 3.9713253 | I38: =(I29+I32-I35)-(H29+H32-H35) -> 4.2493181 | J38: =(J29+J32-J35)-(I29+I32-I35) -> 0
C40: Free Cash Flows | D40: 45200 | E40: 45566 | F40: 45931 | G40: 46296 | H40: 46661 | I40: 47027 | J40: 47392
C42: Unlevered FCF | D42: =D22+D25-D27-D38 -> -458.65 | E42: =E22+E25-E27-E38 -> -72.619 | F42: =F22+F25-F27-F38 -> 152.29823 | G42: =G22+G25-G27-G38 -> 158.62068 | H42: =H22+H25-H27-H38 -> 171.61239 | I42: =I22+I25-I27-I38 -> 187.71676 | J42: =J22+J25-J27-J38 -> 188.12608
C43: Present Value of FCF | D43: =D42/(1+ATWACC)^D5 -> -458.65 | E43: =E42/(1+ATWACC)^E5 -> -66.622936 | F43: =F42/(1+ATWACC)^F5 -> 128.18637 | G43: =G42/(1+ATWACC)^G5 -> 122.48427 | H43: =H42/(1+ATWACC)^H5 -> 121.57455 | I43: =I42/(1+ATWACC)^I5 -> 122.00301 | J43: =J42/(1+ATWACC)^J5 -> 112.17343
C45: NPV | D45: =ROUND(SUM(D43:J43),2) -> 81.15
M77: Calculations Based on Book
M78: t= | N78: 0 | O78: 1 | P78: 2 | Q78: 3 | R78: 4 | S78: 5 | T78: 6
L79: Incremental Earnings Forcast ($ million)
L80: 1 | M80: Sales | N80: {=D7:J7} -> 0 | O80: 385 | P80: 396.55 | Q80: 408.4465 | R80: 437.03776 | S80: 467.6304 | T80: 467.6304
L81: 2 | M81: COGS | N81: {=D10:J10} -> 0 | O81: 142.45 | P81: 146.7235 | Q81: 151.1252 | R81: 161.70397 | S81: 173.02325 | T81: 173.02325
L82: 3 | M82: Gross Profit | N82: =N80-N81 -> 0 | O82: =O80-O81 -> 242.55 | P82: =P80-P81 -> 249.8265 | Q82: =Q80-Q81 -> 257.3213 | R82: =R80-R81 -> 275.33379 | S82: =S80-S81 -> 294.60715 | T82: =T80-T81 -> 294.60715
L83: 4 | M83: OpEx | N83: {=-D15:J15-D13:J13} -> -389 | O83: -79 | P83: -79 | Q83: -79 | R83: -79 | S83: -79 | T83: -79
L84: 5 | M84: Depreciation | N84: {=-D25:J25} -> 0 | O84: -25.6 | P84: -58 | Q84: -58 | R84: -58 | S84: -58 | T84: -32.4
...

Sheet Q6
B3: FCF Discounted at Pre-Tax WACC
B5: pre-tax WACC | C5: 0.0905
B7: Unlevered FCF | C7: -458.65 | D7: -72.619 | E7: 152.29823 | F7: 158.62068 | G7: 171.61239 | H7: 187.71676 | I7: 188.12608
B8: PV FCF PretaxWACC | C8: ='Q5'!D42/(1+PTWACC)^'Q5'!D5 -> -458.65 | D8: ='Q5'!E42/(1+PTWACC)^'Q5'!E5 -> -66.592389 | E8: ='Q5'!F42/(1+PTWACC)^'Q5'!F5 -> 128.06885 | F8: ='Q5'!G42/(1+PTWACC)^'Q5'!G5 -> 122.31586 | G8: ='Q5'!H42/(1+PTWACC)^'Q5'!H5 -> 121.35173 | H8: ='Q5'!I42/(1+PTWACC)^'Q5'!I5 -> 121.72358 | I8: ='Q5'!J42/(1+PTWACC)^'Q5'!J5 -> 111.86519
B10: NPV | C10: =SUM(C8:I8) -> 80.082826
B12: Interest Tax Shield Assumptions
B13: In millions $
B14: Constant Debt Level | C14: 400 | E14: Cost of Debt | F14: 0.06
B15: Tax Rate | C15: 0.15 | E15: Interest Exp | F15: =C14*F14 -> 24
B17: Interest Tax Shield | C17: 45200 | D17: 45566 | E17: 45931 | F17: 46296 | G17: 46661 | H17: 47027 | I17: 47392
B18: Interest Expense | C18: 0 | D18: =$F$15 -> 24 | E18: =$F$15 -> 24 | F18: =$F$15 -> 24 | G18: =$F$15 -> 24 | H18: =$F$15 -> 24 | I18: =$F$15 -> 24
B19: Tax Shield | C19: =$C$15*C18 -> 0 | D19: =$C$15*D18 -> 3.6 | E19: =$C$15*E18 -> 3.6 | F19: =$C$15*F18 -> 3.6 | G19: =$C$15*G18 -> 3.6 | H19: =$C$15*H18 -> 3.6 | I19: =$C$15*I18 -> 3.6
B20: PV(Tax Shields) | C20: =C19/(1+PTWACC)^'Q5'!D5 -> 0 | D20: =D19/(1+$F$14)^'Q5'!E5 -> 3.3962264 | E20: =E19/(1+$F$14)^'Q5'!F5 -> 3.2039872 | F20: =F19/(1+$F$14)^'Q5'!G5 -> 3.0226294 | G20: =G19/(1+$F$14)^'Q5'!H5 -> 2.8515372 | H20: =H19/(1+$F$14)^'Q5'!I5 -> 2.6901294 | I20: =I19/(1+$F$14)^'Q5'!J5 -> 2.5378579
B22: PV(Total Tax Shield) | C22: =ROUND(SUM(C20:I20),2) -> 17.7
B24: NPV of Project Using the APV method
B26: NPV | C26: =C22+'Q6'!C10 -> 97.782826
