Workbook

Sheet Market Data Sheet
E1: Decision Support - Hedging 2 Case
E2: version 1.0
A4: Options Markets | B4: Last | C4: Position | D4: Cost | E4: Bid | F4: Ask
A5: Jan16C | B5: =RTD("rit2.rtd",,$A5,B$4) -> JAN16C|LAST | C5: =RTD("rit2.rtd",,$A5,C$4) -> JAN16C|POSITION | D5: =RTD("rit2.rtd",,$A5,D$4) -> JAN16C|COST | E5: =RTD("rit2.rtd",,$A5,E$4) -> JAN16C|BID | F5: =RTD("rit2.rtd",,$A5,F$4) -> JAN16C|ASK
A6: Jan16P | B6: =RTD("rit2.rtd",,$A6,B$4) -> JAN16P|LAST | C6: =RTD("rit2.rtd",,$A6,C$4) -> JAN16P|POSITION | D6: =RTD("rit2.rtd",,$A6,D$4) -> JAN16P|COST | E6: =RTD("rit2.rtd",,$A6,E$4) -> JAN16P|BID | F6: =RTD("rit2.rtd",,$A6,F$4) -> JAN16P|ASK
A7: Jan17C | B7: =RTD("rit2.rtd",,$A7,B$4) -> JAN17C|LAST | C7: =RTD("rit2.rtd",,$A7,C$4) -> JAN17C|POSITION | D7: =RTD("rit2.rtd",,$A7,D$4) -> JAN17C|COST | E7: =RTD("rit2.rtd",,$A7,E$4) -> JAN17C|BID | F7: =RTD("rit2.rtd",,$A7,F$4) -> JAN17C|ASK
A8: Jan17P | B8: =RTD("rit2.rtd",,$A8,B$4) -> JAN17P|LAST | C8: =RTD("rit2.rtd",,$A8,C$4) -> JAN17P|POSITION | D8: =RTD("rit2.rtd",,$A8,D$4) -> JAN17P|COST | E8: =RTD("rit2.rtd",,$A8,E$4) -> JAN17P|BID | F8: =RTD("rit2.rtd",,$A8,F$4) -> JAN17P|ASK
A9: Jan18C | B9: =RTD("rit2.rtd",,$A9,B$4) -> JAN18C|LAST | C9: =RTD("rit2.rtd",,$A9,C$4) -> JAN18C|POSITION | D9: =RTD("rit2.rtd",,$A9,D$4) -> JAN18C|COST | E9: =RTD("rit2.rtd",,$A9,E$4) -> JAN18C|BID | F9: =RTD("rit2.rtd",,$A9,F$4) -> JAN18C|ASK
A10: Jan18P | B10: =RTD("rit2.rtd",,$A10,B$4) -> JAN18P|LAST | C10: =RTD("rit2.rtd",,$A10,C$4) -> JAN18P|POSITION | D10: =RTD("rit2.rtd",,$A10,D$4) -> JAN18P|COST | E10: =RTD("rit2.rtd",,$A10,E$4) -> JAN18P|BID | F10: =RTD("rit2.rtd",,$A10,F$4) -> JAN18P|ASK
A11: Jan19C | B11: =RTD("rit2.rtd",,$A11,B$4) -> JAN19C|LAST | C11: =RTD("rit2.rtd",,$A11,C$4) -> JAN19C|POSITION | D11: =RTD("rit2.rtd",,$A11,D$4) -> JAN19C|COST | E11: =RTD("rit2.rtd",,$A11,E$4) -> JAN19C|BID | F11: =RTD("rit2.rtd",,$A11,F$4) -> JAN19C|ASK
A12: Jan19P | B12: =RTD("rit2.rtd",,$A12,B$4) -> JAN19P|LAST | C12: =RTD("rit2.rtd",,$A12,C$4) -> JAN19P|POSITION | D12: =RTD("rit2.rtd",,$A12,D$4) -> JAN19P|COST | E12: =RTD("rit2.rtd",,$A12,E$4) -> JAN19P|BID | F12: =RTD("rit2.rtd",,$A12,F$4) -> JAN19P|ASK
A13: Jan20C | B13: =RTD("rit2.rtd",,$A13,B$4) -> JAN20C|LAST | C13: =RTD("rit2.rtd",,$A13,C$4) -> JAN20C|POSITION | D13: =RTD("rit2.rtd",,$A13,D$4) -> JAN20C|COST | E13: =RTD("rit2.rtd",,$A13,E$4) -> JAN20C|BID | F13: =RTD("rit2.rtd",,$A13,F$4) -> JAN20C|ASK
A14: Jan20P | B14: =RTD("rit2.rtd",,$A14,B$4) -> JAN20P|LAST | C14: =RTD("rit2.rtd",,$A14,C$4) -> JAN20P|POSITION | D14: =RTD("rit2.rtd",,$A14,D$4) -> JAN20P|COST | E14: =RTD("rit2.rtd",,$A14,E$4) -> JAN20P|BID | F14: =RTD("rit2.rtd",,$A14,F$4) -> JAN20P|ASK
A15: Jan21C | B15: =RTD("rit2.rtd",,$A15,B$4) -> JAN21C|LAST | C15: =RTD("rit2.rtd",,$A15,C$4) -> JAN21C|POSITION | D15: =RTD("rit2.rtd",,$A15,D$4) -> JAN21C|COST | E15: =RTD("rit2.rtd",,$A15,E$4) -> JAN21C|BID | F15: =RTD("rit2.rtd",,$A15,F$4) -> JAN21C|ASK
A16: Jan21P | B16: =RTD("rit2.rtd",,$A16,B$4) -> JAN21P|LAST | C16: =RTD("rit2.rtd",,$A16,C$4) -> JAN21P|POSITION | D16: =RTD("rit2.rtd",,$A16,D$4) -> JAN21P|COST | E16: =RTD("rit2.rtd",,$A16,E$4) -> JAN21P|BID | F16: =RTD("rit2.rtd",,$A16,F$4) -> JAN21P|ASK
... A22: Jan24P | B22: =RTD("rit2.rtd",,$A22,B$4) -> JAN24P|LAST | C22: =RTD("rit2.rtd",,$A22,C$4) -> JAN24P|POSITION | D22: =RTD("rit2.rtd",,$A22,D$4) -> JAN24P|COST | E22: =RTD("rit2.rtd",,$A22,E$4) -> JAN24P|BID | F22: =RTD("rit2.rtd",,$A22,F$4) -> JAN24P|ASK
A23: February
A24: Feb16C | B24: =RTD("rit2.rtd",,$A24,B$4) -> FEB16C|LAST | C24: =RTD("rit2.rtd",,$A24,C$4) -> FEB16C|POSITION | D24: =RTD("rit2.rtd",,$A24,D$4) -> FEB16C|COST | E24: =RTD("rit2.rtd",,$A24,E$4) -> FEB16C|BID | F24: =RTD("rit2.rtd",,$A24,F$4) -> FEB16C|ASK
A25: Feb16P | B25: =RTD("rit2.rtd",,$A25,B$4) -> FEB16P|LAST | C25: =RTD("rit2.rtd",,$A25,C$4) -> FEB16P|POSITION | D25: =RTD("rit2.rtd",,$A25,D$4) -> FEB16P|COST | E25: =RTD("rit2.rtd",,$A25,E$4) -> FEB16P|BID | F25: =RTD("rit2.rtd",,$A25,F$4) -> FEB16P|ASK
A26: Feb17C | B26: =RTD("rit2.rtd",,$A26,B$4) -> FEB17C|LAST | C26: =RTD("rit2.rtd",,$A26,C$4) -> FEB17C|POSITION | D26: =RTD("rit2.rtd",,$A26,D$4) -> FEB17C|COST | E26: =RTD("rit2.rtd",,$A26,E$4) -> FEB17C|BID | F26: =RTD("rit2.rtd",,$A26,F$4) -> FEB17C|ASK
A27: Feb17P | B27: =RTD("rit2.rtd",,$A27,B$4) -> FEB17P|LAST | C27: =RTD("rit2.rtd",,$A27,C$4) -> FEB17P|POSITION | D27: =RTD("rit2.rtd",,$A27,D$4) -> FEB17P|COST | E27: =RTD("rit2.rtd",,$A27,E$4) -> FEB17P|BID | F27: =RTD("rit2.rtd",,$A27,F$4) -> FEB17P|ASK
A28: Feb18C | B28: =RTD("rit2.rtd",,$A28,B$4) -> FEB18C|LAST | C28: =RTD("rit2.rtd",,$A28,C$4) -> FEB18C|POSITION | D28: =RTD("rit2.rtd",,$A28,D$4) -> FEB18C|COST | E28: =RTD("rit2.rtd",,$A28,E$4) -> FEB18C|BID | F28: =RTD("rit2.rtd",,$A28,F$4) -> FEB18C|ASK
A29: Feb18P | B29: =RTD("rit2.rtd",,$A29,B$4) -> FEB18P|LAST | C29: =RTD("rit2.rtd",,$A29,C$4) -> FEB18P|POSITION | D29: =RTD("rit2.rtd",,$A29,D$4) -> FEB18P|COST | E29: =RTD("rit2.rtd",,$A29,E$4) -> FEB18P|BID | F29: =RTD("rit2.rtd",,$A29,F$4) -> FEB18P|ASK
A30: Feb19C | B30: =RTD("rit2.rtd",,$A30,B$4) -> FEB19C|LAST | C30: =RTD("rit2.rtd",,$A30,C$4) -> FEB19C|POSITION | D30: =RTD("rit2.rtd",,$A30,D$4) -> FEB19C|COST | E30: =RTD("rit2.rtd",,$A30,E$4) -> FEB19C|BID | F30: =RTD("rit2.rtd",,$A30,F$4) -> FEB19C|ASK
A31: Feb19P | B31: =RTD("rit2.rtd",,$A31,B$4) -> FEB19P|LAST | C31: =RTD("rit2.rtd",,$A31,C$4) -> FEB19P|POSITION | D31: =RTD("rit2.rtd",,$A31,D$4) -> FEB19P|COST | E31: =RTD("rit2.rtd",,$A31,E$4) -> FEB19P|BID | F31: =RTD("rit2.rtd",,$A31,F$4) -> FEB19P|ASK
A32: Feb20C | B32: =RTD("rit2.rtd",,$A32,B$4) -> FEB20C|LAST | C32: =RTD("rit2.rtd",,$A32,C$4) -> FEB20C|POSITION | D32: =RTD("rit2.rtd",,$A32,D$4) -> FEB20C|COST | E32: =RTD("rit2.rtd",,$A32,E$4) -> FEB20C|BID | F32: =RTD("rit2.rtd",,$A32,F$4) -> FEB20C|ASK
A33: Feb20P | B33: =RTD("rit2.rtd",,$A33,B$4) -> FEB20P|LAST | C33: =RTD("rit2.rtd",,$A33,C$4) -> FEB20P|POSITION | D33: =RTD("rit2.rtd",,$A33,D$4) -> FEB20P|COST | E33: =RTD("rit2.rtd",,$A33,E$4) -> FEB20P|BID | F33: =RTD("rit2.rtd",,$A33,F$4) -> FEB20P|ASK
A34: Feb21C | B34: =RTD("rit2.rtd",,$A34,B$4) -> FEB21C|LAST | C34: =RTD("rit2.rtd",,$A34,C$4) -> FEB21C|POSITION | D34: =RTD("rit2.rtd",,$A34,D$4) -> FEB21C|COST | E34: =RTD("rit2.rtd",,$A34,E$4) -> FEB21C|BID | F34: =RTD("rit2.rtd",,$A34,F$4) -> FEB21C|ASK
A35: Feb21P | B35: =RTD("rit2.rtd",,$A35,B$4) -> FEB21P|LAST | C35: =RTD("rit2.rtd",,$A35,C$4) -> FEB21P|POSITION | D35: =RTD("rit2.rtd",,$A35,D$4) -> FEB21P|COST | E35: =RTD("rit2.rtd",,$A35,E$4) -> FEB21P|BID | F35: =RTD("rit2.rtd",,$A35,F$4) -> FEB21P|ASK
... A41: Feb24P | B41: =RTD("rit2.rtd",,$A41,B$4) -> FEB24P|LAST | C41: =RTD("rit2.rtd",,$A41,C$4) -> FEB24P|POSITION | D41: =RTD("rit2.rtd",,$A41,D$4) -> FEB24P|COST | E41: =RTD("rit2.rtd",,$A41,E$4) -> FEB24P|BID | F41: =RTD("rit2.rtd",,$A41,F$4) -> FEB24P|ASK
A42: March
A43: Mar16C | B43: =RTD("rit2.rtd",,$A43,B$4) -> MAR16C|LAST | C43: =RTD("rit2.rtd",,$A43,C$4) -> MAR16C|POSITION | D43: =RTD("rit2.rtd",,$A43,D$4) -> MAR16C|COST | E43: =RTD("rit2.rtd",,$A43,E$4) -> MAR16C|BID | F43: =RTD("rit2.rtd",,$A43,F$4) -> MAR16C|ASK
A44: Mar16P | B44: =RTD("rit2.rtd",,$A44,B$4) -> MAR16P|LAST | C44: =RTD("rit2.rtd",,$A44,C$4) -> MAR16P|POSITION | D44: =RTD("rit2.rtd",,$A44,D$4) -> MAR16P|COST | E44: =RTD("rit2.rtd",,$A44,E$4) -> MAR16P|BID | F44: =RTD("rit2.rtd",,$A44,F$4) -> MAR16P|ASK
A45: Mar17C | B45: =RTD("rit2.rtd",,$A45,B$4) -> MAR17C|LAST | C45: =RTD("rit2.rtd",,$A45,C$4) -> MAR17C|POSITION | D45: =RTD("rit2.rtd",,$A45,D$4) -> MAR17C|COST | E45: =RTD("rit2.rtd",,$A45,E$4) -> MAR17C|BID | F45: =RTD("rit2.rtd",,$A45,F$4) -> MAR17C|ASK
A46: Mar17P | B46: =RTD("rit2.rtd",,$A46,B$4) -> MAR17P|LAST | C46: =RTD("rit2.rtd",,$A46,C$4) -> MAR17P|POSITION | D46: =RTD("rit2.rtd",,$A46,D$4) -> MAR17P|COST | E46: =RTD("rit2.rtd",,$A46,E$4) -> MAR17P|BID | F46: =RTD("rit2.rtd",,$A46,F$4) -> MAR17P|ASK
A47: Mar18C | B47: =RTD("rit2.rtd",,$A47,B$4) -> MAR18C|LAST | C47: =RTD("rit2.rtd",,$A47,C$4) -> MAR18C|POSITION | D47: =RTD("rit2.rtd",,$A47,D$4) -> MAR18C|COST | E47: =RTD("rit2.rtd",,$A47,E$4) -> MAR18C|BID | F47: =RTD("rit2.rtd",,$A47,F$4) -> MAR18C|ASK
A48: Mar18P | B48: =RTD("rit2.rtd",,$A48,B$4) -> MAR18P|LAST | C48: =RTD("rit2.rtd",,$A48,C$4) -> MAR18P|POSITION | D48: =RTD("rit2.rtd",,$A48,D$4) -> MAR18P|COST | E48: =RTD("rit2.rtd",,$A48,E$4) -> MAR18P|BID | F48: =RTD("rit2.rtd",,$A48,F$4) -> MAR18P|ASK
A49: Mar19C | B49: =RTD("rit2.rtd",,$A49,B$4) -> MAR19C|LAST | C49: =RTD("rit2.rtd",,$A49,C$4) -> MAR19C|POSITION | D49: =RTD("rit2.rtd",,$A49,D$4) -> MAR19C|COST | E49: =RTD("rit2.rtd",,$A49,E$4) -> MAR19C|BID | F49: =RTD("rit2.rtd",,$A49,F$4) -> MAR19C|ASK
A50: Mar19P | B50: =RTD("rit2.rtd",,$A50,B$4) -> MAR19P|LAST | C50: =RTD("rit2.rtd",,$A50,C$4) -> MAR19P|POSITION | D50: =RTD("rit2.rtd",,$A50,D$4) -> MAR19P|COST | E50: =RTD("rit2.rtd",,$A50,E$4) -> MAR19P|BID | F50: =RTD("rit2.rtd",,$A50,F$4) -> MAR19P|ASK
A51: Mar20C | B51: =RTD("rit2.rtd",,$A51,B$4) -> MAR20C|LAST | C51: =RTD("rit2.rtd",,$A51,C$4) -> MAR20C|POSITION | D51: =RTD("rit2.rtd",,$A51,D$4) -> MAR20C|COST | E51: =RTD("rit2.rtd",,$A51,E$4) -> MAR20C|BID | F51: =RTD("rit2.rtd",,$A51,F$4) -> MAR20C|ASK
...

Sheet Summary Table
A2: Period | B2: =RTD("rit2.rtd",,"PERIOD") -> PERIOD | F2: Type | G2: C | H2: P | I2: C | J2: P | K2: C | L2: P | M2: C | N2: P | O2: C | P2: P | Q2: C | R2: P | S2: C | T2: P | U2: C | V2: P | W2: C | X2: P | Y2: C | Z2: P | AA2: C | AB2: P | AC2: C | AD2: P | AE2: C | AF2: P | AG2: C | AH2: P | AI2: C | AJ2: P | AK2: C | AL2: P | AM2: C | AN2: P | AO2: C | AP2: P | AQ2: C | AR2: P | AS2: C | AT2: P | AU2: C | AV2: P | AW2: C | AX2: P | AY2: C | AZ2: P | BA2: C | BB2: P | BC2: C | BD2: P | BE2: C | BF2: P | BG2: C | BH2: P
F3: Strike | G3: 16 | H3: 16 | I3: 17 | J3: 17 | K3: 18 | L3: 18 | M3: 19 | N3: 19 | O3: 20 | P3: 20 | Q3: 21 | R3: 21 | S3: 22 | T3: 22 | U3: 23 | V3: 23 | W3: 24 | X3: 24 | Y3: 16 | Z3: 16 | AA3: 17 | AB3: 17 | AC3: 18 | AD3: 18 | AE3: 19 | AF3: 19 | AG3: 20 | AH3: 20 | AI3: 21 | AJ3: 21 | AK3: 22 | AL3: 22 | AM3: 23 | AN3: 23 | AO3: 24 | AP3: 24 | AQ3: 16 | AR3: 16 | AS3: 17 | AT3: 17 | AU3: 18 | AV3: 18 | AW3: 19 | AX3: 19 | AY3: 20 | AZ3: 20 | BA3: 21 | BB3: 21 | BC3: 22 | BD3: 22 | BE3: 23 | BF3: 23 | BG3: 24 | BH3: 24
F4: Position | G4: {=TRANSPOSE('Market Data Sheet'!C5:C22)} -> JAN16C|POSITION | H4: JAN16P|POSITION | I4: JAN17C|POSITION | J4: JAN17P|POSITION | K4: JAN18C|POSITION | L4: JAN18P|POSITION | M4: JAN19C|POSITION | N4: JAN19P|POSITION | O4: JAN20C|POSITION | P4: JAN20P|POSITION | Q4: JAN21C|POSITION | R4: JAN21P|POSITION | S4: JAN22C|POSITION | T4: JAN22P|POSITION | U4: JAN23C|POSITION | V4: JAN23P|POSITION | W4: JAN24C|POSITION | X4: JAN24P|POSITION | Y4: {=TRANSPOSE('Market Data Sheet'!C24:C41)} -> FEB16C|POSITION | Z4: FEB16P|POSITION | AA4: FEB17C|POSITION | AB4: FEB17P|POSITION | AC4: FEB18C|POSITION | AD4: FEB18P|POSITION | AE4: FEB19C|POSITION | AF4: FEB19P|POSITION | AG4: FEB20C|POSITION | AH4: FEB20P|POSITION | AI4: FEB21C|POSITION | AJ4: FEB21P|POSITION | AK4: FEB22C|POSITION | AL4: FEB22P|POSITION | AM4: FEB23C|POSITION | AN4: FEB23P|POSITION | AO4: FEB24C|POSITION | AP4: FEB24P|POSITION | AQ4: {=TRANSPOSE('Market Data Sheet'!C43:C60)} -> MAR16C|POSITION | AR4: MAR16P|POSITION | AS4: MAR17C|POSITION | AT4: MAR17P|POSITION | AU4: MAR18C|POSITION | AV4: MAR18P|POSITION | AW4: MAR19C|POSITION | AX4: MAR19P|POSITION | AY4: MAR20C|POSITION | AZ4: MAR20P|POSITION | BA4: MAR21C|POSITION | BB4: MAR21P|POSITION | BC4: MAR22C|POSITION | BD4: MAR22P|POSITION | BE4: MAR23C|POSITION | BF4: MAR23P|POSITION | BG4: MAR24C|POSITION | BH4: MAR24P|POSITION
F5: Cost | G5: {=TRANSPOSE('Market Data Sheet'!D5:D22)} -> JAN16C|COST | H5: JAN16P|COST | I5: JAN17C|COST | J5: JAN17P|COST | K5: JAN18C|COST | L5: JAN18P|COST | M5: JAN19C|COST | N5: JAN19P|COST | O5: JAN20C|COST | P5: JAN20P|COST | Q5: JAN21C|COST | R5: JAN21P|COST | S5: JAN22C|COST | T5: JAN22P|COST | U5: JAN23C|COST | V5: JAN23P|COST | W5: JAN24C|COST | X5: JAN24P|COST | Y5: {=TRANSPOSE('Market Data Sheet'!D24:D41)} -> FEB16C|COST | Z5: FEB16P|COST | AA5: FEB17C|COST | AB5: FEB17P|COST | AC5: FEB18C|COST | AD5: FEB18P|COST | AE5: FEB19C|COST | AF5: FEB19P|COST | AG5: FEB20C|COST | AH5: FEB20P|COST | AI5: FEB21C|COST | AJ5: FEB21P|COST | AK5: FEB22C|COST | AL5: FEB22P|COST | AM5: FEB23C|COST | AN5: FEB23P|COST | AO5: FEB24C|COST | AP5: FEB24P|COST | AQ5: {=TRANSPOSE('Market Data Sheet'!D43:D60)} -> MAR16C|COST | AR5: MAR16P|COST | AS5: MAR17C|COST | AT5: MAR17P|COST | AU5: MAR18C|COST | AV5: MAR18P|COST | AW5: MAR19C|COST | AX5: MAR19P|COST | AY5: MAR20C|COST | AZ5: MAR20P|COST | BA5: MAR21C|COST | BB5: MAR21P|COST | BC5: MAR22C|COST | BD5: MAR22P|COST | BE5: MAR23C|COST | BF5: MAR23P|COST | BG5: MAR24C|COST | BH5: MAR24P|COST
F6: Ticker | G6: Jan16C | H6: Jan16P | I6: Jan17C | J6: Jan17P | K6: Jan18C | L6: Jan18P | M6: Jan19C | N6: Jan19P | O6: Jan20C | P6: Jan20P | Q6: Jan21C | R6: Jan21P | S6: Jan22C | T6: Jan22P | U6: Jan23C | V6: Jan23P | W6: Jan24C | X6: Jan24P | Y6: Feb16C | Z6: Feb16P | AA6: Feb17C | AB6: Feb17P | AC6: Feb18C | AD6: Feb18P | AE6: Feb19C | AF6: Feb19P | AG6: Feb20C | AH6: Feb20P | AI6: Feb21C | AJ6: Feb21P | AK6: Feb22C | AL6: Feb22P | AM6: Feb23C | AN6: Feb23P | AO6: Feb24C | AP6: Feb24P | AQ6: Mar16C | AR6: Mar16P | AS6: Mar17C | AT6: Mar17P | AU6: Mar18C | AV6: Mar18P | AW6: Mar19C | AX6: Mar19P | AY6: Mar20C | AZ6: Mar20P | BA6: Mar21C | BB6: Mar21P | BC6: Mar22C | BD6: Mar22P | BE6: Mar23C | BF6: Mar23P | BG6: Mar24C | BH6: Mar24P
F8: Values at Settlement
A9: Unhedged | B9: Jan Opts | C9: Feb Opts | D9: Mar Opts | E9: Stock Price | F9: Underlying
A10: =F10 -> 1400000 | B10: =IF($B$2=1,SUM(G10:X10),0) -> 0 | C10: =SUM(Y10:AP10) -> #VALUE! | D10: =SUM(AQ10:BH10) -> #VALUE! | E10: 14 | F10: =E10*100000 -> 1400000 | G10: =100*G$4*IF(G$2="C",MAX($E10-G$3,0),IF(G$2="P",MAX(G$3-$E10,0))) -> #VALUE! | H10: =100*H$4*IF(H$2="C",MAX($E10-H$3,0),IF(H$2="P",MAX(H$3-$E10,0))) -> #VALUE! | I10: =100*I$4*IF(I$2="C",MAX($E10-I$3,0),IF(I$2="P",MAX(I$3-$E10,0))) -> #VALUE! | J10: =100*J$4*IF(J$2="C",MAX($E10-J$3,0),IF(J$2="P",MAX(J$3-$E10,0))) -> #VALUE! | K10: =100*K$4*IF(K$2="C",MAX($E10-K$3,0),IF(K$2="P",MAX(K$3-$E10,0))) -> #VALUE! | L10: =100*L$4*IF(L$2="C",MAX($E10-L$3,0),IF(L$2="P",MAX(L$3-$E10,0))) -> #VALUE! | M10: =100*M$4*IF(M$2="C",MAX($E10-M$3,0),IF(M$2="P",MAX(M$3-$E10,0))) -> #VALUE! | N10: =100*N$4*IF(N$2="C",MAX($E10-N$3,0),IF(N$2="P",MAX(N$3-$E10,0))) -> #VALUE! | ... BH10: =100*BH$4*IF(BH$2="C",MAX($E10-BH$3,0),IF(BH$2="P",MAX(BH$3-$E10,0))) -> #VALUE!
A11: =F11 -> 1500000 | B11: =IF($B$2=1,SUM(G11:X11),0) -> 0 | C11: =SUM(Y11:AP11) -> #VALUE! | D11: =SUM(AQ11:BH11) -> #VALUE! | E11: 15 | F11: =E11*100000 -> 1500000 | G11: =100*G$4*IF(G$2="C",MAX($E11-G$3,0),IF(G$2="P",MAX(G$3-$E11,0))) -> #VALUE! | H11: =100*H$4*IF(H$2="C",MAX($E11-H$3,0),IF(H$2="P",MAX(H$3-$E11,0))) -> #VALUE! | I11: =100*I$4*IF(I$2="C",MAX($E11-I$3,0),IF(I$2="P",MAX(I$3-$E11,0))) -> #VALUE! | J11: =100*J$4*IF(J$2="C",MAX($E11-J$3,0),IF(J$2="P",MAX(J$3-$E11,0))) -> #VALUE! | K11: =100*K$4*IF(K$2="C",MAX($E11-K$3,0),IF(K$2="P",MAX(K$3-$E11,0))) -> #VALUE! | L11: =100*L$4*IF(L$2="C",MAX($E11-L$3,0),IF(L$2="P",MAX(L$3-$E11,0))) -> #VALUE! | M11: =100*M$4*IF(M$2="C",MAX($E11-M$3,0),IF(M$2="P",MAX(M$3-$E11,0))) -> #VALUE! | N11: =100*N$4*IF(N$2="C",MAX($E11-N$3,0),IF(N$2="P",MAX(N$3-$E11,0))) -> #VALUE! | ... BH11: =100*BH$4*IF(BH$2="C",MAX($E11-BH$3,0),IF(BH$2="P",MAX(BH$3-$E11,0))) -> #VALUE!
A12: =F12 -> 1600000 | B12: =IF($B$2=1,SUM(G12:X12),0) -> 0 | C12: =SUM(Y12:AP12) -> #VALUE! | D12: =SUM(AQ12:BH12) -> #VALUE! | E12: 16 | F12: =E12*100000 -> 1600000 | G12: =100*G$4*IF(G$2="C",MAX($E12-G$3,0),IF(G$2="P",MAX(G$3-$E12,0))) -> #VALUE! | H12: =100*H$4*IF(H$2="C",MAX($E12-H$3,0),IF(H$2="P",MAX(H$3-$E12,0))) -> #VALUE! | I12: =100*I$4*IF(I$2="C",MAX($E12-I$3,0),IF(I$2="P",MAX(I$3-$E12,0))) -> #VALUE! | J12: =100*J$4*IF(J$2="C",MAX($E12-J$3,0),IF(J$2="P",MAX(J$3-$E12,0))) -> #VALUE! | K12: =100*K$4*IF(K$2="C",MAX($E12-K$3,0),IF(K$2="P",MAX(K$3-$E12,0))) -> #VALUE! | L12: =100*L$4*IF(L$2="C",MAX($E12-L$3,0),IF(L$2="P",MAX(L$3-$E12,0))) -> #VALUE! | M12: =100*M$4*IF(M$2="C",MAX($E12-M$3,0),IF(M$2="P",MAX(M$3-$E12,0))) -> #VALUE! | N12: =100*N$4*IF(N$2="C",MAX($E12-N$3,0),IF(N$2="P",MAX(N$3-$E12,0))) -> #VALUE! | ... BH12: =100*BH$4*IF(BH$2="C",MAX($E12-BH$3,0),IF(BH$2="P",MAX(BH$3-$E12,0))) -> #VALUE!
A13: =F13 -> 1700000 | B13: =IF($B$2=1,SUM(G13:X13),0) -> 0 | C13: =SUM(Y13:AP13) -> #VALUE! | D13: =SUM(AQ13:BH13) -> #VALUE! | E13: 17 | F13: =E13*100000 -> 1700000 | G13: =100*G$4*IF(G$2="C",MAX($E13-G$3,0),IF(G$2="P",MAX(G$3-$E13,0))) -> #VALUE! | H13: =100*H$4*IF(H$2="C",MAX($E13-H$3,0),IF(H$2="P",MAX(H$3-$E13,0))) -> #VALUE! | I13: =100*I$4*IF(I$2="C",MAX($E13-I$3,0),IF(I$2="P",MAX(I$3-$E13,0))) -> #VALUE! | J13: =100*J$4*IF(J$2="C",MAX($E13-J$3,0),IF(J$2="P",MAX(J$3-$E13,0))) -> #VALUE! | K13: =100*K$4*IF(K$2="C",MAX($E13-K$3,0),IF(K$2="P",MAX(K$3-$E13,0))) -> #VALUE! | L13: =100*L$4*IF(L$2="C",MAX($E13-L$3,0),IF(L$2="P",MAX(L$3-$E13,0))) -> #VALUE! | M13: =100*M$4*IF(M$2="C",MAX($E13-M$3,0),IF(M$2="P",MAX(M$3-$E13,0))) -> #VALUE! | N13: =100*N$4*IF(N$2="C",MAX($E13-N$3,0),IF(N$2="P",MAX(N$3-$E13,0))) -> #VALUE! | ... BH13: =100*BH$4*IF(BH$2="C",MAX($E13-BH$3,0),IF(BH$2="P",MAX(BH$3-$E13,0))) -> #VALUE!
A14: =F14 -> 1800000 | B14: =IF($B$2=1,SUM(G14:X14),0) -> 0 | C14: =SUM(Y14:AP14) -> #VALUE! | D14: =SUM(AQ14:BH14) -> #VALUE! | E14: 18 | F14: =E14*100000 -> 1800000 | G14: =100*G$4*IF(G$2="C",MAX($E14-G$3,0),IF(G$2="P",MAX(G$3-$E14,0))) -> #VALUE! | H14: =100*H$4*IF(H$2="C",MAX($E14-H$3,0),IF(H$2="P",MAX(H$3-$E14,0))) -> #VALUE! | I14: =100*I$4*IF(I$2="C",MAX($E14-I$3,0),IF(I$2="P",MAX(I$3-$E14,0))) -> #VALUE! | J14: =100*J$4*IF(J$2="C",MAX($E14-J$3,0),IF(J$2="P",MAX(J$3-$E14,0))) -> #VALUE! | K14: =100*K$4*IF(K$2="C",MAX($E14-K$3,0),IF(K$2="P",MAX(K$3-$E14,0))) -> #VALUE! | L14: =100*L$4*IF(L$2="C",MAX($E14-L$3,0),IF(L$2="P",MAX(L$3-$E14,0))) -> #VALUE! | M14: =100*M$4*IF(M$2="C",MAX($E14-M$3,0),IF(M$2="P",MAX(M$3-$E14,0))) -> #VALUE! | N14: =100*N$4*IF(N$2="C",MAX($E14-N$3,0),IF(N$2="P",MAX(N$3-$E14,0))) -> #VALUE! | ... BH14: =100*BH$4*IF(BH$2="C",MAX($E14-BH$3,0),IF(BH$2="P",MAX(BH$3-$E14,0))) -> #VALUE!
A15: =F15 -> 1900000 | B15: =IF($B$2=1,SUM(G15:X15),0) -> 0 | C15: =SUM(Y15:AP15) -> #VALUE! | D15: =SUM(AQ15:BH15) -> #VALUE! | E15: 19 | F15: =E15*100000 -> 1900000 | G15: =100*G$4*IF(G$2="C",MAX($E15-G$3,0),IF(G$2="P",MAX(G$3-$E15,0))) -> #VALUE! | H15: =100*H$4*IF(H$2="C",MAX($E15-H$3,0),IF(H$2="P",MAX(H$3-$E15,0))) -> #VALUE! | I15: =100*I$4*IF(I$2="C",MAX($E15-I$3,0),IF(I$2="P",MAX(I$3-$E15,0))) -> #VALUE! | J15: =100*J$4*IF(J$2="C",MAX($E15-J$3,0),IF(J$2="P",MAX(J$3-$E15,0))) -> #VALUE! | K15: =100*K$4*IF(K$2="C",MAX($E15-K$3,0),IF(K$2="P",MAX(K$3-$E15,0))) -> #VALUE! | L15: =100*L$4*IF(L$2="C",MAX($E15-L$3,0),IF(L$2="P",MAX(L$3-$E15,0))) -> #VALUE! | M15: =100*M$4*IF(M$2="C",MAX($E15-M$3,0),IF(M$2="P",MAX(M$3-$E15,0))) -> #VALUE! | N15: =100*N$4*IF(N$2="C",MAX($E15-N$3,0),IF(N$2="P",MAX(N$3-$E15,0))) -> #VALUE! | ... BH15: =100*BH$4*IF(BH$2="C",MAX($E15-BH$3,0),IF(BH$2="P",MAX(BH$3-$E15,0))) -> #VALUE!
A16: =F16 -> 2000000 | B16: =IF($B$2=1,SUM(G16:X16),0) -> 0 | C16: =SUM(Y16:AP16) -> #VALUE! | D16: =SUM(AQ16:BH16) -> #VALUE! | E16: 20 | F16: =E16*100000 -> 2000000 | G16: =100*G$4*IF(G$2="C",MAX($E16-G$3,0),IF(G$2="P",MAX(G$3-$E16,0))) -> #VALUE! | H16: =100*H$4*IF(H$2="C",MAX($E16-H$3,0),IF(H$2="P",MAX(H$3-$E16,0))) -> #VALUE! | I16: =100*I$4*IF(I$2="C",MAX($E16-I$3,0),IF(I$2="P",MAX(I$3-$E16,0))) -> #VALUE! | J16: =100*J$4*IF(J$2="C",MAX($E16-J$3,0),IF(J$2="P",MAX(J$3-$E16,0))) -> #VALUE! | K16: =100*K$4*IF(K$2="C",MAX($E16-K$3,0),IF(K$2="P",MAX(K$3-$E16,0))) -> #VALUE! | L16: =100*L$4*IF(L$2="C",MAX($E16-L$3,0),IF(L$2="P",MAX(L$3-$E16,0))) -> #VALUE! | M16: =100*M$4*IF(M$2="C",MAX($E16-M$3,0),IF(M$2="P",MAX(M$3-$E16,0))) -> #VALUE! | N16: =100*N$4*IF(N$2="C",MAX($E16-N$3,0),IF(N$2="P",MAX(N$3-$E16,0))) -> #VALUE! | ... BH16: =100*BH$4*IF(BH$2="C",MAX($E16-BH$3,0),IF(BH$2="P",MAX(BH$3-$E16,0))) -> #VALUE!
A17: =F17 -> 2100000 | B17: =IF($B$2=1,SUM(G17:X17),0) -> 0 | C17: =SUM(Y17:AP17) -> #VALUE! | D17: =SUM(AQ17:BH17) -> #VALUE! | E17: 21 | F17: =E17*100000 -> 2100000 | G17: =100*G$4*IF(G$2="C",MAX($E17-G$3,0),IF(G$2="P",MAX(G$3-$E17,0))) -> #VALUE! | H17: =100*H$4*IF(H$2="C",MAX($E17-H$3,0),IF(H$2="P",MAX(H$3-$E17,0))) -> #VALUE! | I17: =100*I$4*IF(I$2="C",MAX($E17-I$3,0),IF(I$2="P",MAX(I$3-$E17,0))) -> #VALUE! | J17: =100*J$4*IF(J$2="C",MAX($E17-J$3,0),IF(J$2="P",MAX(J$3-$E17,0))) -> #VALUE! | K17: =100*K$4*IF(K$2="C",MAX($E17-K$3,0),IF(K$2="P",MAX(K$3-$E17,0))) -> #VALUE! | L17: =100*L$4*IF(L$2="C",MAX($E17-L$3,0),IF(L$2="P",MAX(L$3-$E17,0))) -> #VALUE! | M17: =100*M$4*IF(M$2="C",MAX($E17-M$3,0),IF(M$2="P",MAX(M$3-$E17,0))) -> #VALUE! | N17: =100*N$4*IF(N$2="C",MAX($E17-N$3,0),IF(N$2="P",MAX(N$3-$E17,0))) -> #VALUE! | ... BH17: =100*BH$4*IF(BH$2="C",MAX($E17-BH$3,0),IF(BH$2="P",MAX(BH$3-$E17,0))) -> #VALUE!
A18: =F18 -> 2200000 | B18: =IF($B$2=1,SUM(G18:X18),0) -> 0 | C18: =SUM(Y18:AP18) -> #VALUE! | D18: =SUM(AQ18:BH18) -> #VALUE! | E18: 22 | F18: =E18*100000 -> 2200000 | G18: =100*G$4*IF(G$2="C",MAX($E18-G$3,0),IF(G$2="P",MAX(G$3-$E18,0))) -> #VALUE! | H18: =100*H$4*IF(H$2="C",MAX($E18-H$3,0),IF(H$2="P",MAX(H$3-$E18,0))) -> #VALUE! | I18: =100*I$4*IF(I$2="C",MAX($E18-I$3,0),IF(I$2="P",MAX(I$3-$E18,0))) -> #VALUE! | J18: =100*J$4*IF(J$2="C",MAX($E18-J$3,0),IF(J$2="P",MAX(J$3-$E18,0))) -> #VALUE! | K18: =100*K$4*IF(K$2="C",MAX($E18-K$3,0),IF(K$2="P",MAX(K$3-$E18,0))) -> #VALUE! | L18: =100*L$4*IF(L$2="C",MAX($E18-L$3,0),IF(L$2="P",MAX(L$3-$E18,0))) -> #VALUE! | M18: =100*M$4*IF(M$2="C",MAX($E18-M$3,0),IF(M$2="P",MAX(M$3-$E18,0))) -> #VALUE! | N18: =100*N$4*IF(N$2="C",MAX($E18-N$3,0),IF(N$2="P",MAX(N$3-$E18,0))) -> #VALUE! | ... BH18: =100*BH$4*IF(BH$2="C",MAX($E18-BH$3,0),IF(BH$2="P",MAX(BH$3-$E18,0))) -> #VALUE!
A19: =F19 -> 2300000 | B19: =IF($B$2=1,SUM(G19:X19),0) -> 0 | C19: =SUM(Y19:AP19) -> #VALUE! | D19: =SUM(AQ19:BH19) -> #VALUE! | E19: 23 | F19: =E19*100000 -> 2300000 | G19: =100*G$4*IF(G$2="C",MAX($E19-G$3,0),IF(G$2="P",MAX(G$3-$E19,0))) -> #VALUE! | H19: =100*H$4*IF(H$2="C",MAX($E19-H$3,0),IF(H$2="P",MAX(H$3-$E19,0))) -> #VALUE! | I19: =100*I$4*IF(I$2="C",MAX($E19-I$3,0),IF(I$2="P",MAX(I$3-$E19,0))) -> #VALUE! | J19: =100*J$4*IF(J$2="C",MAX($E19-J$3,0),IF(J$2="P",MAX(J$3-$E19,0))) -> #VALUE! | K19: =100*K$4*IF(K$2="C",MAX($E19-K$3,0),IF(K$2="P",MAX(K$3-$E19,0))) -> #VALUE! | L19: =100*L$4*IF(L$2="C",MAX($E19-L$3,0),IF(L$2="P",MAX(L$3-$E19,0))) -> #VALUE! | M19: =100*M$4*IF(M$2="C",MAX($E19-M$3,0),IF(M$2="P",MAX(M$3-$E19,0))) -> #VALUE! | N19: =100*N$4*IF(N$2="C",MAX($E19-N$3,0),IF(N$2="P",MAX(N$3-$E19,0))) -> #VALUE! | ... BH19: =100*BH$4*IF(BH$2="C",MAX($E19-BH$3,0),IF(BH$2="P",MAX(BH$3-$E19,0))) -> #VALUE!
A20: =F20 -> 2400000 | B20: =IF($B$2=1,SUM(G20:X20),0) -> 0 | C20: =SUM(Y20:AP20) -> #VALUE! | D20: =SUM(AQ20:BH20) -> #VALUE! | E20: 24 | F20: =E20*100000 -> 2400000 | G20: =100*G$4*IF(G$2="C",MAX($E20-G$3,0),IF(G$2="P",MAX(G$3-$E20,0))) -> #VALUE! | H20: =100*H$4*IF(H$2="C",MAX($E20-H$3,0),IF(H$2="P",MAX(H$3-$E20,0))) -> #VALUE! | I20: =100*I$4*IF(I$2="C",MAX($E20-I$3,0),IF(I$2="P",MAX(I$3-$E20,0))) -> #VALUE! | J20: =100*J$4*IF(J$2="C",MAX($E20-J$3,0),IF(J$2="P",MAX(J$3-$E20,0))) -> #VALUE! | K20: =100*K$4*IF(K$2="C",MAX($E20-K$3,0),IF(K$2="P",MAX(K$3-$E20,0))) -> #VALUE! | L20: =100*L$4*IF(L$2="C",MAX($E20-L$3,0),IF(L$2="P",MAX(L$3-$E20,0))) -> #VALUE! | M20: =100*M$4*IF(M$2="C",MAX($E20-M$3,0),IF(M$2="P",MAX(M$3-$E20,0))) -> #VALUE! | N20: =100*N$4*IF(N$2="C",MAX($E20-N$3,0),IF(N$2="P",MAX(N$3-$E20,0))) -> #VALUE! | ... BH20: =100*BH$4*IF(BH$2="C",MAX($E20-BH$3,0),IF(BH$2="P",MAX(BH$3-$E20,0))) -> #VALUE!
A21: =F21 -> 2500000 | B21: =IF($B$2=1,SUM(G21:X21),0) -> 0 | C21: =SUM(Y21:AP21) -> #VALUE! | D21: =SUM(AQ21:BH21) -> #VALUE! | E21: 25 | F21: =E21*100000 -> 2500000 | G21: =100*G$4*IF(G$2="C",MAX($E21-G$3,0),IF(G$2="P",MAX(G$3-$E21,0))) -> #VALUE! | H21: =100*H$4*IF(H$2="C",MAX($E21-H$3,0),IF(H$2="P",MAX(H$3-$E21,0))) -> #VALUE! | I21: =100*I$4*IF(I$2="C",MAX($E21-I$3,0),IF(I$2="P",MAX(I$3-$E21,0))) -> #VALUE! | J21: =100*J$4*IF(J$2="C",MAX($E21-J$3,0),IF(J$2="P",MAX(J$3-$E21,0))) -> #VALUE! | K21: =100*K$4*IF(K$2="C",MAX($E21-K$3,0),IF(K$2="P",MAX(K$3-$E21,0))) -> #VALUE! | L21: =100*L$4*IF(L$2="C",MAX($E21-L$3,0),IF(L$2="P",MAX(L$3-$E21,0))) -> #VALUE! | M21: =100*M$4*IF(M$2="C",MAX($E21-M$3,0),IF(M$2="P",MAX(M$3-$E21,0))) -> #VALUE! | N21: =100*N$4*IF(N$2="C",MAX($E21-N$3,0),IF(N$2="P",MAX(N$3-$E21,0))) -> #VALUE! | ... BH21: =100*BH$4*IF(BH$2="C",MAX($E21-BH$3,0),IF(BH$2="P",MAX(BH$3-$E21,0))) -> #VALUE!
A22: =F22 -> 2600000 | B22: =IF($B$2=1,SUM(G22:X22),0) -> 0 | C22: =SUM(Y22:AP22) -> #VALUE! | D22: =SUM(AQ22:BH22) -> #VALUE! | E22: 26 | F22: =E22*100000 -> 2600000 | G22: =100*G$4*IF(G$2="C",MAX($E22-G$3,0),IF(G$2="P",MAX(G$3-$E22,0))) -> #VALUE! | H22: =100*H$4*IF(H$2="C",MAX($E22-H$3,0),IF(H$2="P",MAX(H$3-$E22,0))) -> #VALUE! | I22: =100*I$4*IF(I$2="C",MAX($E22-I$3,0),IF(I$2="P",MAX(I$3-$E22,0))) -> #VALUE! | J22: =100*J$4*IF(J$2="C",MAX($E22-J$3,0),IF(J$2="P",MAX(J$3-$E22,0))) -> #VALUE! | K22: =100*K$4*IF(K$2="C",MAX($E22-K$3,0),IF(K$2="P",MAX(K$3-$E22,0))) -> #VALUE! | L22: =100*L$4*IF(L$2="C",MAX($E22-L$3,0),IF(L$2="P",MAX(L$3-$E22,0))) -> #VALUE! | M22: =100*M$4*IF(M$2="C",MAX($E22-M$3,0),IF(M$2="P",MAX(M$3-$E22,0))) -> #VALUE! | N22: =100*N$4*IF(N$2="C",MAX($E22-N$3,0),IF(N$2="P",MAX(N$3-$E22,0))) -> #VALUE! | ... BH22: =100*BH$4*IF(BH$2="C",MAX($E22-BH$3,0),IF(BH$2="P",MAX(BH$3-$E22,0))) -> #VALUE!
A23: Opt Cost | B23: =-IF($B$2<=1,SUMPRODUCT(G4:X4,G5:X5),0)*100 -> 0 | C23: =-IF($B$2<=2,SUMPRODUCT(Y4:AP4,Y5:AP5),0)*100 -> 0 | D23: =-IF($B$2<=3,SUMPRODUCT(AQ4:BH4,AQ5:BH5),0)*100 -> 0
A25: All Graph | B25: Jan Graph | C25: Feb Graph | D25: Mar Graph
A26: =A10+SUM(B10:D10)+SUM($B$23:$D$23) -> #VALUE! | B26: =A10+B10+B$23 -> 1400000 | C26: =A10+C10+C$23 -> #VALUE! | D26: =A10+D10+D$23 -> #VALUE!
A27: =A11+SUM(B11:D11)+SUM($B$23:$D$23) -> #VALUE! | B27: =A11+B11+B$23 -> 1500000 | C27: =A11+C11+C$23 -> #VALUE! | D27: =A11+D11+D$23 -> #VALUE!
A28: =A12+SUM(B12:D12)+SUM($B$23:$D$23) -> #VALUE! | B28: =A12+B12+B$23 -> 1600000 | C28: =A12+C12+C$23 -> #VALUE! | D28: =A12+D12+D$23 -> #VALUE!
A29: =A13+SUM(B13:D13)+SUM($B$23:$D$23) -> #VALUE! | B29: =A13+B13+B$23 -> 1700000 | C29: =A13+C13+C$23 -> #VALUE! | D29: =A13+D13+D$23 -> #VALUE!
A30: =A14+SUM(B14:D14)+SUM($B$23:$D$23) -> #VALUE! | B30: =A14+B14+B$23 -> 1800000 | C30: =A14+C14+C$23 -> #VALUE! | D30: =A14+D14+D$23 -> #VALUE!
A31: =A15+SUM(B15:D15)+SUM($B$23:$D$23) -> #VALUE! | B31: =A15+B15+B$23 -> 1900000 | C31: =A15+C15+C$23 -> #VALUE! | D31: =A15+D15+D$23 -> #VALUE!
A32: =A16+SUM(B16:D16)+SUM($B$23:$D$23) -> #VALUE! | B32: =A16+B16+B$23 -> 2000000 | C32: =A16+C16+C$23 -> #VALUE! | D32: =A16+D16+D$23 -> #VALUE!
A33: =A17+SUM(B17:D17)+SUM($B$23:$D$23) -> #VALUE! | B33: =A17+B17+B$23 -> 2100000 | C33: =A17+C17+C$23 -> #VALUE! | D33: =A17+D17+D$23 -> #VALUE!
A34: =A18+SUM(B18:D18)+SUM($B$23:$D$23) -> #VALUE! | B34: =A18+B18+B$23 -> 2200000 | C34: =A18+C18+C$23 -> #VALUE! | D34: =A18+D18+D$23 -> #VALUE!
A35: =A19+SUM(B19:D19)+SUM($B$23:$D$23) -> #VALUE! | B35: =A19+B19+B$23 -> 2300000 | C35: =A19+C19+C$23 -> #VALUE! | D35: =A19+D19+D$23 -> #VALUE!
A36: =A20+SUM(B20:D20)+SUM($B$23:$D$23) -> #VALUE! | B36: =A20+B20+B$23 -> 2400000 | C36: =A20+C20+C$23 -> #VALUE! | D36: =A20+D20+D$23 -> #VALUE!
A37: =A21+SUM(B21:D21)+SUM($B$23:$D$23) -> #VALUE! | B37: =A21+B21+B$23 -> 2500000 | C37: =A21+C21+C$23 -> #VALUE! | D37: =A21+D21+D$23 -> #VALUE!
A38: =A22+SUM(B22:D22)+SUM($B$23:$D$23) -> #VALUE! | B38: =A22+B22+B$23 -> 2600000 | C38: =A22+C22+C$23 -> #VALUE! | D38: =A22+D22+D$23 -> #VALUE!
B40: Graph

Sheet Notes
B2: POGO | F2: OPTIONS | G2: JAN | H2: FEB | I2: MAR
B4: Holding | D4: 100000 | F4: Call | G4: 10 | H4: 10 | I4: 10
B5: $/Shr | D5: 20 | F5: Put | G5: 10 | H5: 10 | I5: 10
B6: Annualized Volatility | D6: 0.3 | Q6: Time | R6: JAN | S6: FEB | T6: MAR
B7: Quaretly Volatility | D7: =D6*SQRT(60/252) -> 0.14638501 | Q7: Frozen Period | R7: =18*10 -> 180 | S7: =18*10 -> 180 | T7: =18*10 -> 180
B8: Monthly Volatlity | D8: =D6*SQRT(20/252) -> 0.084515425 | Q8: Trading | R8: =20*10-18 -> 182 | S8: =20*10-18 -> 182 | T8: =20*10-18 -> 182
B9: Daily Volatility | D9: =D6/SQRT(252) -> 0.018898224 | Q9: Total | R9: =SUM(R7:R8) -> 362 | S9: =SUM(S7:S8) -> 362 | T9: =SUM(T7:T8) -> 362 | U9: =SUM(R9:T9) -> 1086
B10: Tick Volatility | D10: =D9/SQRT(10) -> 0.005976143 | Q10: in min. | R10: =R9/60 -> 6.0333333 | S10: =S9/60 -> 6.0333333 | T10: =T9/60 -> 6.0333333 | U10: =U9/60 -> 18.1
B12: TRADING
B14: Cost per Contract, $ | D14: 0.02
B17: SIMULATION 1: COLLAR STRATEGY DEBIT
C18: JANUARY | F18: FEBURARY | I18: MARCH
C19: Expiry | D19: Strike | E19: Contract | F19: Expiry | G19: Strike | H19: Contract | I19: Expiry | J19: Strike | K19: Contracts
B20: Calls
B21: Buy | C21: x10
B22: Sell | C22: Mar | D22: 23 | E22: 0.29 | L22: Credit | M22: =E22*1000*100-$D$14*1000 -> 28980
B23: Puts | L23: Debit | M23: =E24*100*1000+1000*$D$14 -> 41020
B24: Buy | C24: Mar | D24: 18 | E24: 0.41 | L24: Net Cost | M24: =M22-M23 -> -12040
B25: Sell | C25: x10
B28: SIMULATION 2: Bear Spread CREDIT
C29: JANUARY | F29: FEBURARY | I29: MARCH
C30: Expiry | D30: Strike | E30: Contract | F30: Expiry | G30: Strike | H30: Contract | I30: Expiry | J30: Strike | K30: Contracts
B31: Calls
B32: Buy | L32: First Spread | O32: Second Spread
B33: Sell | L33: Credit | M33: =E36*500*100-$D$14*1000 -> 3480 | O33: Credit | P33: =H36*300*100-$D$14*1000 -> 4780
B34: Puts | C34: x3 | F34: x7 | L34: Debit | M34: =E35*100*300+1000*$D$14 -> 12020 | O34: Debit | P34: =H35*100*700+1000*$D$14 -> 48320
B35: Buy | C35: Mar | D35: 19 | E35: 0.4 | F35: Mar | G35: 21 | H35: 0.69 | L35: Net Cost | M35: =M33-M34 -> -8540 | O35: Net Cost | P35: =P33-P34 -> -43540
B36: Sell | C36: Mar | D36: 16 | E36: 0.07 | F36: Mar | G36: 18 | H36: 0.16
C37: x5 | F37: x3
B40: SIMULATION 3: PROTECTIVE PUT CREDIT
C41: JANUARY | F41: FEBURARY | I41: MARCH
C42: Expiry | D42: Strike | E42: Contract | F42: Expiry | G42: Strike | H42: Contract | I42: Expiry | J42: Strike | K42: Contracts
B43: Calls
B44: Buy
B45: Sell
B46: Puts | C46: x10
B47: Buy | C47: Mar | D47: 18 | E47: 0.63 ish
B48: Sell
