Workbook
Name Copy: LBO!$B$21:$N$78
Name EBITDAgrowth: 'Exhibit 6'!$C$8
Name Exitm: 'Exhibit 6'!$C$11
Name LTgrowth: 'Exhibit 6'!$C$10
Name STgrowth: 'Exhibit 6'!$C$9

Sheet Copyright
A3: Product Number: | B3: W30170
A4: Title: | B4: Elon Musk’s Twitter Deal: Valuation and Financing of the Leveraged Buyout - Student Spreadsheet
B5: This spreadsheet supports the product "Elon Musk’s Twitter Deal: Valuation and Financing of the Leveraged Buyout " (W30166)
A6: Prepared by: | B6: Atif Ikram, Frank Li
A8: Last Revised: | B8: 44971
A10: No part of this file may be reproduced, stored in a retrieval system, posted to the Internet, or transmitted in any form or by any means without the permission of Ivey Business School Foundation. To order copies or request permission to reproduce materials, contact Ivey Publishing, Ivey Business School, Western University, London, Ontario, Canada, N6G 0N1; (t) 519.661.3208; (e) cases@ivey.ca; www.iveypublishing.ca. Our goal is to publish materials of the highest quality; submit any errata to publishcases@ivey.ca.
A12: © 2022 Ivey Business School Foundation

Sheet Exhibit 1
A1: EXHIBIT 1: STOCK PERFORMANCE OF TESLA INC. AND TWITTER INC.
A3: Date | B3: Tesla Adj Close | C3: Tesla Cum. Return | D3: Twitter Adj Close | E3: Twitter Cum. Return | F3: S&P 500 (VOO) Adj. Close | G3: S&P 500 (VOO) Cum. Return
A4: 44593 | B4: 931.25 | C4: =B4/$B$4 -> 1 | D4: 38.119999 | E4: =D4/$D$4 -> 1 | F4: 414.99231 | G4: =F4/$F$4 -> 1
A5: 44594 | B5: 905.65997 | C5: =B5/$B$4 -> 0.97252078 | D5: 36.509998 | E5: =D5/$D$4 -> 0.95776493 | F5: 418.94898 | G5: =F5/$F$4 -> 1.0095343
A6: 44595 | B6: 891.14001 | C6: =B6/$B$4 -> 0.95692888 | D6: 34.48 | E6: =D6/$D$4 -> 0.90451209 | F6: 409.21176 | G6: =F6/$F$4 -> 0.98607071
A7: 44596 | B7: 923.32001 | C7: =B7/$B$4 -> 0.99148457 | D7: 36.939999 | E7: =D7/$D$4 -> 0.96904512 | F7: 411.13528 | G7: =F7/$F$4 -> 0.99070579
A8: 44599 | B8: 907.34003 | C8: =B8/$B$4 -> 0.97432486 | D8: 36.040001 | E8: =D8/$D$4 -> 0.94543552 | F8: 409.77988 | G8: =F8/$F$4 -> 0.98743969
A9: 44600 | B9: 922 | C9: =B9/$B$4 -> 0.99006711 | D9: 35.98 | E9: =D9/$D$4 -> 0.94386151 | F9: 413.09866 | G9: =F9/$F$4 -> 0.99543691
A10: 44601 | B10: 932 | C10: =B10/$B$4 -> 1.0008054 | D10: 37.830002 | E10: =D10/$D$4 -> 0.99239252 | F10: 419.1583 | G10: =F10/$F$4 -> 1.0100387
A11: 44602 | B11: 904.54999 | C11: =B11/$B$4 -> 0.97132885 | D11: 37.080002 | E11: =D11/$D$4 -> 0.97271781 | F11: 411.79306
A12: 44603 | B12: 860 | C12: =B12/$B$4 -> 0.92348993 | D12: 35.84 | E12: =D12/$D$4 -> 0.9401889 | F12: 403.58075 | G12: =F12/$F$4 -> 0.97250176
A13: 44606 | B13: 875.76001 | C13: =B13/$B$4 -> 0.94041343 | D13: 35.689999 | E13: =D13/$D$4 -> 0.93625393 | F13: 402.26517 | G13: =F13/$F$4 -> 0.96933162
A14: 44607 | B14: 922.42999 | C14: =B14/$B$4 -> 0.99052885 | D14: 36.98 | E14: =D14/$D$4 -> 0.97009446 | F14: 408.72342 | G14: =F14/$F$4 -> 0.98489396
A15: 44608 | B15: 923.39001 | C15: =B15/$B$4 -> 0.99155975 | D15: 36.240002 | E15: =D15/$D$4 -> 0.95068213 | F15: 409.21176 | G15: =F15/$F$4 -> 0.98607071
A16: 44609 | B16: 876.34998 | C16: =B16/$B$4 -> 0.94104695 | D16: 35.43 | E16: =D16/$D$4 -> 0.92943339 | F16: 400.51108 | G16: =F16/$F$4 -> 0.96510482
A17: 44610 | B17: 856.97998 | C17: =B17/$B$4 -> 0.92024696 | D17: 34.32 | E17: =D17/$D$4 -> 0.90031482 | F17: 397.94971 | G17: =F17/$F$4 -> 0.95893273
A18: 44614 | B18: 821.53003 | C18: =B18/$B$4 -> 0.8821799 | D18: 32.93 | E18: =D18/$D$4 -> 0.86385102 | F18: 393.59439 | G18: =F18/$F$4 -> 0.94843779
A19: 44615 | B19: 764.03998 | C19: =B19/$B$4 -> 0.82044561 | D19: 32.759998 | E19: =D19/$D$4 -> 0.85939137 | F19: 386.50824 | G19: =F19/$F$4 -> 0.93136241
A20: 44616 | B20: 800.77002 | C20: =B20/$B$4 -> 0.85988727 | D20: 34.98 | E20: =D20/$D$4 -> 0.91762857 | F20: 392.44821 | G20: =F20/$F$4 -> 0.94567587
A21: 44617 | B21: 809.87 | C21: =B21/$B$4 -> 0.86965906 | D21: 35.290001 | E21: =D21/$D$4 -> 0.92576081 | F21: 401.01935 | G21: =F21/$F$4 -> 0.96632959
A22: 44620 | B22: 870.42999 | C22: =B22/$B$4 -> 0.93468993 | D22: 35.549999 | E22: =D22/$D$4 -> 0.93258132 | F22: 400.01276 | G22: =F22/$F$4 -> 0.96390402
A23: 44621 | B23: 864.37 | C23: =B23/$B$4 -> 0.92818254 | D23: 35.560001 | E23: =D23/$D$4 -> 0.9328437 | F23: 394.01297 | G23: =F23/$F$4 -> 0.94944644
... A119: 44761 | B119: 736.59003 | C119: =B119/$B$4 -> 0.79096916 | D119: 39.490002 | E119: =D119/$D$4 -> 1.0359392 | F119: 360.60998 | G119: =F119/$F$4 -> 0.86895582

Sheet Exhibit 2
A1: EXHIBIT 2: TWITTER INC. MONTHLY ACTIVE USER GROWTH AND FINANCIAL PERFORMANCE
B3: Monthly Active Users (in Million) | E3: US$ Million
A4: Year | B4: Total | C4: 0.05 | D4: 0.2 | E4: Revenue | F4: Operating Income | G4: Net Income | H4: Free Cash Flows
A5: 2010 | B5: 54 | C5: =B5*0.05 -> 2.7 | D5: =B5*0.2 -> 10.8 | E5: 28 | F5: -67 | G5: -67 | H5: -54
A6: 2011 | B6: 117 | C6: =B6*0.05 -> 5.85 | D6: =B6*0.2 -> 23.4 | E6: 106 | F6: -127 | G6: -164 | H6: -82
A7: 2012 | B7: 185 | C7: =B7*0.05 -> 9.25 | D7: =B7*0.2 -> 37 | E7: 317 | F7: -77 | G7: -79 | H7: -78
A8: 2013 | B8: 241 | C8: =B8*0.05 -> 12.05 | D8: =B8*0.2 -> 48.2 | E8: 665 | F8: -636 | G8: -645 | H8: -74
A9: 2014 | B9: 288 | C9: =B9*0.05 -> 14.4 | D9: =B9*0.2 -> 57.6 | E9: 1403 | F9: -539 | G9: -578 | H9: -120
A10: 2015 | B10: 305 | C10: =B10*0.05 -> 15.25 | D10: =B10*0.2 -> 61 | E10: 2218 | F10: -450 | G10: -521 | H10: 36
A11: 2016 | B11: 318 | C11: =B11*0.05 -> 15.9 | D11: =B11*0.2 -> 63.6 | E11: 2530 | F11: -367 | G11: -457 | H11: 544
A12: 2017 | B12: 330 | C12: =B12*0.05 -> 16.5 | D12: =B12*0.2 -> 66 | E12: 2443 | F12: 39 | G12: -108 | H12: 708
A13: 2018 | B13: 321 | C13: =B13*0.05 -> 16.05 | D13: =B13*0.2 -> 64.2 | E13: 3042 | F13: 453 | G13: 1206 | H13: 869
A14: 2019 | B14: 330 | C14: =B14*0.05 -> 16.5 | D14: =B14*0.2 -> 66 | E14: 3459 | F14: 366 | G14: 1466 | H14: 769
A15: 2020 | B15: 353 | C15: =B15*0.05 -> 17.65 | D15: =B15*0.2 -> 70.6 | E15: 3716 | F15: 27 | G15: -1136 | H15: 129
A16: 2021 | B16: 396.5 | C16: =B16*0.05 -> 19.825 | D16: =B16*0.2 -> 79.3 | E16: 5077 | F16: -493 | G16: 221 | H16: -370
A17: CAGR | B17: =(B16/B5)^(1/($A$16-$A$5))-1 -> 0.1987085 | E17: =(E16/E5)^(1/($A$16-$A$5))-1 -> 0.60440334
E18: =E16/B16 -> 12.80454
A21: Note: MAU = monthly active users
A22: Source: Adapted by the case authors from Brian Dean, “How Many People Use Twitter in 2022? [New Twitter Stats],” Backlinko, January 5, 2022, https://backlinko.com/twitter-users; “Twitter Revenue 2011–2022 | TWTR,” Macrotrends, accessed September 13, 2022, https://www.macrotrends.net/stocks/charts/TWTR/twitter/revenue.

Sheet Exhibit 3
A1: EXHIBIT 3: FINANCIAL STATEMENTS OF TWITTER INC. (US$ MILLION)
B3: 2019 | C3: 2020 | D3: 2021
A4: Income Statement
A5: Revenue | B5: 3459.329 | C5: 3716.349 | D5: 5077.482
A6: Growth | C6: =(C5-B5)/B5 -> 0.074297646 | D6: =(D5-C5)/C5 -> 0.36625543
A7: Recurring Operating Expenses (including D&A) | B7: -3092.956 | C7: -3689.691 | D7: -4804.52
A8: Non-Recurring Operating Expenses | B8: 0 | C8: 0 | D8: -765.701
A9: Operating Income / (Loss) | B9: =B5+B7+B8 -> 366.373 | C9: =C5+C7+C8 -> 26.658 | D9: =D5+D7+D8 -> -492.739
A10: Operating Margin | B10: =B9/B5 -> 0.10590869 | C10: =C9/C5 -> 0.0071731692 | D10: =D9/D5 -> -0.097043968
A11: Depreciation and Amortization | B11: 465.5 | C11: 495.177 | D11: 544.848
A12: EBITDA | B12: =B9+B11-B8 -> 831.873 | C12: =C9+C11-C8 -> 521.835 | D12: =D9+D11-D8 -> 817.81
A13: EBITDA Margin | B13: =B12/B5 -> 0.24047236 | C13: =C12/C5 -> 0.14041604 | D13: =D12/D5 -> 0.16106606
A15: Interest Expense | B15: -138.18 | C15: -152.878 | D15: -51.186
A16: Interest Income | B16: 157.703 | C16: 88.178 | D16: 35.683
A17: Other Income / (Expense) | B17: 4.243 | C17: -12.897 | D17: 97.129
A18: Net Interest Income / (Expense) | B18: =B15+B16+B17 -> 23.766 | C18: =C15+C16+C17 -> -77.597 | D18: =D15+D16+D17 -> 81.626
A20: Taxable Income | B20: =B9+B18 -> 390.139 | C20: =C9+C18 -> -50.939 | D20: =D9+D18 -> -411.113
A21: Provision / (Benefit) For Income Taxes | B21: 1075.52 | C21: -1084.687 | D21: 189.704
A22: Net Income / (Loss) | B22: =B20+B21 -> 1465.659 | C22: =C20+C21 -> -1135.626 | D22: =D20+D21 -> -221.409
A24: Balance Sheet
A26: Cash and cash equivalents | B26: 1799.08 | C26: 1988.43 | D26: 2186.55
A27: Short-term investments | B27: 4839.97 | C27: 5483.87 | D27: 4207.13
A28: Total Current Assets | B28: 7620.08 | C28: 8637.11 | D28: 7918.37
A30: Property and Equipment, Net | B30: 1031.78 | C30: 1493.79 | D30: 2082.16
A31: Intangible Assets, Net | B31: 55.11 | C31: 58.338 | D31: 69.324
A32: Goodwill | B32: 1256.7 | C32: 1312.346 | D32: 1301.52
A33: Total Assets | B33: 12703.39 | C33: 13379.09 | D33: 14059.52
A35: Convertible Notes, Short-Term | B35: 0 | C35: 917.866 | D35: 0
A36: Total Current Liabilities | B36: 832.48 | C36: 1952.826 | D36: 1343.867
A37: Convertible Notes, Long-Term | B37: 1816.83 | C37: 1875.878 | D37: 3559.023
A38: Senior Notes, Long-Term | B38: 691.97 | C38: 692.994 | D38: 693.996
A39: Total Liabilities | B39: 3999 | C39: 5409.008 | D39: 6752.317
A40: Total Stockholders' Equity | B40: 8704.386 | C40: 7970.08 | D40: 7307.199
A42: Note: D&A = depreciation and amortization; EBITDA = earnings before interest, taxes, depreciation, and amortization
A43: Source: United States Securities and Exchange Commission, Twitter, Inc: Fiscal Year 2019 Annual Report, accessed September 13, 2022, https://s22.q4cdn.com/826641620/files/doc_financials/2019/FiscalYR2019_Twitter_Annual_-Report-(3).pdf; United States Securities and Exchange Commission, Twitter, Inc: Fiscal Year 2020 Annual Report, accessed September 13, 2022, https://www.sec.gov/Archives/edgar/data/1418091/000141809121000031/twtr-20201231.htm; United States Securities and Exchange Commission, Twitter, Inc: Fiscal Year 2021 Annual Report, accessed September 13, 2022, https://www.sec.gov/Archives/edgar/data/1418091/000141809122000029/twtr-20211231.htm.

Sheet Exhibit 4
A1: EXHIBIT 4: TRANSACTION SUMMARY
A3: Transaction Summary (All Amounts in Million, Except per Share Data) | E3: Sources and Uses Table
A4: Public shares | B4: 727.5 | C4: =B4/B6 -> 0.90869348 | E4: Sources (US$ Million) | K4: Uses (US$ Million)
A5: Elon Musk's shares | B5: 73.1 | C5: =B5/B6 -> 0.09130652 | E5: New debt*** | I5: 25000 | J5: =I5/I10 -> 0.47715679 | K5: Purchase of public equity | O5: =B8*B4 -> 39430.5 | P5: =O5/O10 -> 0.75258353
A6: Total shares outstanding | B6: =SUM(B4:B5) -> 800.6 | C6: 1 | E6: Existing Twitter cash | I6: =B12*-1 -> 6393.68 | J6: =I6/I10 -> 0.12203151 | K6: Musk's equity rollover at buyout price | O6: =B8*B5 -> 3962.02 | P6: =O6/O10 -> 0.07562042
E7: Equity | I7: 21000 | J7: =I7/I10 -> 0.4008117 | K7: Refinancing of existing debt | O7: 4476 | P7: =O7/O10 -> 0.085430412
A8: Musk's bid price | B8: 54.2 | E8: Musk's equity roll-over | H8: =B8*B5 -> 3962.02 | J8: =H8/I10 -> 0.075620189 | K8: Minimum cash**** | O8: 4025 | P8: =O8/O10 -> 0.076822477
A9: Implied equity value | B9: =B8*B6 -> 43392.52 | E9: Sponsor equity | H9: =I7-H8 -> 17037.98 | J9: =H9/I10 -> 0.32519151 | K9: Fees | O9: 500 | P9: =O9/O10 -> 0.0095431649
E10: Total | I10: =SUM(I5:I7) -> 52393.68 | J10: =SUM(J5:J5:J7) -> 1 | K10: Total | O10: =SUM(O5:O9) -> 52393.52 | P10: =SUM(P5:P9) -> 1
A11: Total debt (excludes operating leases)* | B11: =SUM('[1]Twitter Historical Data'!D34+'[1]Twitter Historical Data'!D36+'[1]Twitter Historical Data'!D37) -> 4253.019
A12: Cash** | B12: =-('[1]Twitter Historical Data'!D25+'[1]Twitter Historical Data'!D26) -> -6393.68
A13: Implied transaction value | B13: =B9+B11+B12 -> 41251.859
A15: Note: *Total debt calculated as sum of short-term and long-term interest-bearing debt; **Cash and cash equivalents calculated as sum of cash and short-term investments; ***Estimate based on details provided in the financing documents, indicating Term Loan of $6.5 billion, secured bridge loan of $3 Billion, unsecured bridge loan of $3 billion, (Elon Musk's) margin loan of $12.5 billion and aggregate equity commitment of $21 Billion; ****Minimum cash expected to be maintained at the time of acquisition to support the high level of debt
A16: Source: Adapted by the case authors from FT Alphaville, “Alphaville's Twitter LBO Model,” Financial Times, April 17, 2022, https://www.ft.com/cont ent/c52aea67-9e6a-4e04-adc2-744bc4e0b738; United States Securities and Exchange Commission, Twitter Inc.: Amendment No. 4 to Schedule 13d, April 25, 2022, https://www.sec.gov/Archives/edgar/data/1418091/000110465922049844/tm2213189d8_sc13da.htm.

Sheet Exhibit 5
A1: EXHIBIT 5: COMPARABLE COMPANY FINANCIAL BENCHMARKS
B3: Market Cap (US$ Billion) | E3: Gross Profit Margin | H3: Adjusted EBITDA Margin | K3: Equity Beta | L3: Equity Value (US$ Billions)
B4: 2021 | C4: 2020 | D4: 2019 | E4: 2021 | F4: 2020 | G4: 2019 | H4: 2021 | I4: 2020 | J4: 2019 | K4: 2021 | L4: 2021
A5: Twitter Inc. (TWTR) | B5: 34.55 | C5: 42.96 | D5: 24.83 | E5: 0.6459 | F5: 0.6323 | G5: 0.6713 | H5: 0.1872 | I5: 0.1607 | J5: 0.2873 | K5: 0.59 | L5: 34.55
A6: Meta Platforms Inc. (FB) | B6: 935.65 | C6: 778.04 | D6: 585.37 | E6: 0.8034 | F6: 0.8058 | G6: 0.8194 | H6: 0.4652 | I6: 0.4614 | J6: 0.4339 | K6: 1.37 | L6: 935.65
A7: Pinterest Inc. (PINS) | B7: 23.71 | C7: 40.73 | D7: 10.41 | E7: 0.7947 | F7: 0.7345 | G7: 0.6859 | H7: 0.1388 | I7: - | J7: - | K7: 1.24 | L7: 23.71
A8: Snap Inc. (SNAP) | B8: 76.15 | C8: 75.27 | D8: 23.12 | E8: 0.5749 | F8: 0.5282 | G8: 0.4778 | H8: - | I8: - | J8: - | K8: 1.18 | L8: 76.15
A9: Weibo Corporation (WB) | B9: 6.93 | C9: 8.68 | D9: 10.75 | E9: 0.8211 | F9: 0.8212 | G9: 0.8139 | H9: 0.3807 | I9: 0.3812 | J9: 0.3983 | K9: 0.88 | L9: 6.93
A10: Match Group, Inc. (MTCH) | B10: 36.37 | C10: 40.28 | D10: 13.28 | E10: 0.7186 | F10: 0.7341 | G10: 0.763 | K10: 1.24 | L10: 36.37
A11: Bumble Inc. (BMBL) | B11: 4.11 | C11: - | D11: - | E11: 0.7258 | F11: - | G11: - | H11: 0.1531 | I11: - | J11: - | K11: - | L11: 4.11
B13: Debt Value (US$ Billion) | C13: Stock Price (December 31) | E13: Shares (in Million) | F13: Revenue (US$ Million) | H13: MAU (in Million) | I13: PE Ratio | J13: EV/Revenue | K13: EV/EBITDA | L13: EV/MAU
B14: 2021 | C14: 2021 | E14: 2021 | F14: 2021 | H14: 2021 | I14: 2021 | J14: 2021 | K14: 2021 | L14: 2021
A15: Twitter Inc. (TWTR) | B15: 4.253 | C15: 43.22 | E15: 798 | F15: 5077.48 | H15: 353 | I15: -94.29 | J15: 6.8 | K15: 41.9 | L15: 92.17
A16: Meta Platforms Inc. (FB) | B16: 0.581 | C16: 336.35 | E16: 2859 | F16: 117929 | H16: 2900 | I16: 24.06 | J16: 8.6 | K16: 16.1 | L16: 302.24
A17: Pinterest Inc. (PINS) | B17: 0.25 | C17: 36.35 | E17: 692 | F17: 2578.03 | H17: 431 | I17: 66.09 | J17: 8.9 | K17: 56.8 | L17: 50.49
A18: Snap Inc. (SNAP) | B18: 2.25 | C18: 47.03 | E18: 1559 | F18: 4117.05 | H18: 428 | I18: -32.13 | J18: 20.1 | K18: - | L18: 175.86
A19: Weibo Corporation (WB) | B19: 1.538 | C19: 30.98 | E19: 230 | F19: 2257.08 | H19: 573 | I19: 20.79 | J19: 2.6 | K19: 7.4 | L19: 9.6
A20: Match Group, Inc. (MTCH) | B20: 3.829 | C20: 132.25 | E20: 305 | F20: 2983.28 | H20: 16.33 | I20: 70.72 | J20: 14.5 | K20: 46 | L20: 2516.78
A21: Bumble Inc. (BMBL) | B21: 0.68 | C21: 33.86 | E21: 193 | F21: 765.67 | H21: 12.33 | I21: 57.2 | J21: 7.7 | K21: 105.4 | L21: 452.64
A23: Note: EBITDA = earnings before interest, taxes, depreciation, and amortization; equity value = market value of equity; debt value = market value of debt estimated using book value; adjusted EBITDA accounts for irregular or one-time line items; equity betas use five-year periods and monthly returns; MAU = monthly active users; PE = price-to-earnings; EV = enterprise value
A24: Source:Adapted by the case authors from Yahoo! Finance, accessed April 26, 2022, https://finance.yahoo.com/; Macrotrends, accessed April 26, 2022, https://www.macrotrends.net/; Finbox, accessed April 27, 2022, https://finbox.com/.

Sheet Exhibit 6
A1: EXHIBIT 6: PROJECTED NET INCOME GIVEN EBITDA GROWTH (BEST-CASE SCENARIO)
B3: Pprice | C3: 21000
B4: Equity RR | C4: 0.25
B6: Chooser | C6: 2 | D6: <---CHANGE THIS BETWEEN 1,2 & 3 to get the different scenarios
B7: Input | E7: Bear | H7: Base | K7: Bull
B8: =E8 -> EBITDA % | C8: =CHOOSE($C$6,F8,I8,L8) -> 0.225 | E8: EBITDA % | F8: 0.2 | H8: EBITDA % | I8: 0.225 | K8: EBITDA % | L8: 0.25
B9: =E9 -> ST Growth | C9: =CHOOSE($C$6,F9,I9,L9) -> 0.125 | E9: ST Growth | F9: 0.1 | H9: ST Growth | I9: 0.125 | K9: ST Growth | L9: 0.15
B10: =E10 -> LT Growth | C10: =CHOOSE($C$6,F10,I10,L10) -> 0.1 | E10: LT Growth | F10: 0.08 | H10: LT Growth | I10: 0.1 | K10: LT Growth | L10: 0.1
B11: =E11 -> Exit | C11: =CHOOSE($C$6,F11,I11,L11) -> 22.5 | E11: Exit | F11: 20 | H11: Exit | I11: 22.5 | K11: Exit | L11: 25
A13: Twitter Inc.
A14: Metric | C14: Closing (2022 E)
B15: 2021 A | D15: 2023 E | E15: 2024 E | F15: 2025 E | G15: 2026 E | H15: 2027 E | I15: 2028 E
A16: Revenue Growth | B16: 0.36625543 | C16: 0.25 | D16: =STgrowth -> 0.125 | E16: =STgrowth -> 0.125 | F16: =STgrowth -> 0.125 | G16: =STgrowth -> 0.125 | H16: =STgrowth -> 0.125 | I16: =LTgrowth -> 0.1
A17: Depreciation and Amortization | D17: 0.095 | E17: 0.09 | F17: 0.085 | G17: 0.08 | H17: 0.075
A18: EBITDA Margin (Pre-Tax) | B18: 0.16106606 | D18: 0.25 | E18: 0.25 | F18: 0.25 | G18: 0.25 | H18: 0.25
A20: Capital Expenditures (% Revenue) | D20: 0.1 | E20: 0.1 | F20: 0.1 | G20: 0.1 | H20: 0.1
A21: Change in NWC (% Change in Revenue) | D21: 0.01 | E21: 0.01 | F21: 0.01 | G21: 0.01 | H21: 0.01
A23: Terminal EBITDA Multiple (x) | C23: =Exitm -> 22.5 | H23: =Exitm -> 22.5
A24: Debt | C24: 25000 | D24: =C24-D46 -> 25635.457 | E24: =D24-E46 -> 26233.167 | F24: =E24-F46 -> 26783.794 | G24: =F24-G46 -> 27276.777 | H24: =G24-H46 -> 27700.199
A25: Min. Cash Balance | C25: 4025
A26: Blended Interest Rate on Debt** | C26: 0.07
A27: Tax Rate | C27: 0.28
A28: Elon Musk's Required Return | C28: 0.25
A29: Sponsors' Required Return | C29: 0.25
A32: Flow to Equity Valuation Analysis
B33: 2021 | C33: 2022 E | D33: 2023 E | E33: 2024 E | F33: 2025 E | G33: 2026 E | H33: 2027 E
A34: Revenue | B34: 5077.482 | C34: =B34*(1+C16) -> 6346.8525 | D34: =C34*(1+D16) -> 7140.2091 | E34: =D34*(1+E16) -> 8032.7352 | F34: =E34*(1+F16) -> 9036.8271 | G34: =F34*(1+G16) -> 10166.43 | H34: =G34*(1+H16) -> 11437.234
A35: EBITDA | D35: =D34*EBITDAgrowth -> 1606.547 | E35: =E34*EBITDAgrowth -> 1807.3654 | F35: =F34*EBITDAgrowth -> 2033.2861 | G35: =G34*EBITDAgrowth -> 2287.4469 | H35: =H34*EBITDAgrowth -> 2573.3777
A36: Depreciation and Amortization | D36: =D34*-D17 -> -678.31986 | E36: =E34*-E17 -> -722.94617 | F36: =F34*-F17 -> -768.1303 | G36: =G34*-G17 -> -813.31444 | H36: =H34*-H17 -> -857.79257
A37: EBIT | D37: =D35+D36 -> 928.22718 | E37: =E35+E36 -> 1084.4193 | F37: =F35+F36 -> 1265.1558 | G37: =G35+G36 -> 1474.1324 | H37: =H35+H36 -> 1715.5851
A38: Interest Expense | D38: =$C$26*AVERAGE(C24,D24) -> 1772.241 | E38: =$C$26*AVERAGE(D24,E24) -> 1815.4019 | F38: =$C$26*AVERAGE(E24,F24) -> 1855.5936 | G38: =$C$26*AVERAGE(F24,G24) -> 1892.12 | H38: =$C$26*AVERAGE(G24,H24) -> 1924.1942
A39: Earnings Before Taxes | D39: =D37-D38 -> -844.01383 | E39: =E37-E38 -> -730.9826 | F39: =F37-F38 -> -590.43783 | G39: =G37-G38 -> -417.98757 | H39: =H37-H38 -> -208.60902
A40: Taxes | D40: =D39*-$C$27 -> 236.32387 | E40: =E39*-$C$27 -> 204.67513 | F40: =F39*-$C$27 -> 165.32259 | G40: =G39*-$C$27 -> 117.03652 | H40: =H39*-$C$27 -> 58.410525
A41: Net Income | D41: =D39+D40 -> -607.68996 | E41: =E39+E40 -> -526.30747 | F41: =F39+F40 -> -425.11524 | G41: =G39+G40 -> -300.95105 | H41: =H39+H40 -> -150.19849
A42: Capital Expenditures | D42: =D34*-D20 -> -714.02091 | E42: =E34*-E20 -> -803.27352 | F42: =F34*-F20 -> -903.68271 | G42: =G34*-G20 -> -1016.643 | H42: =H34*-H20 -> -1143.7234
A43: Change in NWC | D43: =D21*(D34-C34) -> 7.9335656 | E43: =E21*(E34-D34) -> 8.9252613 | F43: =F21*(F34-E34) -> 10.040919 | G43: =G21*(G34-F34) -> 11.296034 | H43: =H21*(H34-G34) -> 12.708038
A45: Cash Flow Available to Repay Debt | D45: =D41-D36+D43+D42 -> -635.45744 | E45: =E41-E36+E43+E42 -> -597.70957 | F45: =F41-F36+F43+F42 -> -550.62673 | G45: =G41-G36+G43+G42 -> -492.98362 | H45: =H41-H36+H43+H42 -> -423.42131
A46: Debt Draw Down / Repayment | D46: =IF(C63 <3, 0, D45) -> -635.45744 | E46: =IF(D63 <3, 0, E45) -> -597.70957 | F46: =IF(E63 <3, 0, F45) -> -550.62673 | G46: =IF(F63 <3, 0, G45) -> -492.98362 | H46: =IF(G63 <3, 0, H45) -> -423.42131
A47: Cash Flow to Equity | D47: =0 -> 0 | E47: =0 -> 0 | F47: =0 -> 0 | G47: =0 -> 0 | H47: =0 -> 0
A49: FCFE | C49: =-C3 -> -21000 | D49: =D47 -> 0 | E49: =E47 -> 0 | F49: =F47 -> 0 | G49: =G47 -> 0 | H49: =H47+B52 -> 34225.8
...

Sheet Exhibit 7
A1: EXHIBIT 7: ELON MUSK’S PROSPECTIVE EQUITY PARTNERS
A3: Equity Investor | C3: Amount (in US$ Million)
A4: Lawrence J. Ellison Revocable Trust | C4: 1000
A5: Sequoia Capital Fund LP | C5: 800
A6: Vy Capital | C6: 700
A7: Binance | C7: 500
A8: AH Capital Management LLC | C8: 400
A9: Qatar Holidng LLC | C9: 375
A10: Aliya Capital Partners LLC | C10: 360
A11: Fidelity Management & Research Company LLC | C11: 316
A12: Brookfield | C12: 250
A13: Strauss Capital LLC | C13: 150
A14: BAMCO Inc. (Baron) | C14: 100
A15: DFJ Growth IV Partners LLC | C15: 100
... A21: Honeycomb Asset Management LP | C21: 5
A23: Source: "Elon Musk Secures $7.1 Billion in New Financing for Twitter," Bloomberg, May 5, 2022, https://www.bloomberglinea.com/2022/05/05/elon-musk-secures-71-billion-in-new-financing-for-twitter.

Sheet LBO
B1: LBO TWITTER
A3: x | B3: Assumptions | Q3: For Document
B5: Input | Q5: Summary | R5: Bull | S5: Base | T5: Bear
B6: Input Selector | E6: 3 | G6: Bear | J6: Base | M6: Bull | Q6: EBITDA '27 | R6: 3191.4468 | S6: 2573.3777 | T6: 2044.3339
B7: EBITDA Margin | E7: =CHOOSE($E$6,H7,K7,N7) -> 0.25 | G7: EBITDA % | H7: 0.2 | J7: EBITDA % | K7: 0.225 | M7: EBITDA % | N7: 0.25 | Q7: Multiple | R7: =N10 -> 25 | S7: =K10 -> 22.5 | T7: =H10 -> 20
B8: Near-Term Growth Rate | E8: =CHOOSE($E$6,H8,K8,N8) -> 0.15 | G8: ST Growth | H8: 0.1 | J8: ST Growth | K8: 0.125 | M8: ST Growth | N8: 0.15 | Q8: Exit EV | R8: 79786.171 | S8: 57900.999 | T8: 40886.678
B9: Perpetual Growth Rate | E9: =CHOOSE($E$6,H9,K9,N9) -> 0.1 | G9: LT Growth | H9: 0.08 | J9: LT Growth | K9: 0.1 | M9: LT Growth | N9: 0.1 | Q9: Exit MC | R9: 57432.748 | S9: 34225.8 | T9: 16038.667
B10: Terminal EBITDA Multiple (x) | E10: =CHOOSE($E$6,H10,K10,N10) -> 25 | G10: Exit | H10: 20 | J10: Exit | K10: 22.5 | M10: Exit | N10: 25 | Q10: PV Equity | R10: -2180.4371 | S10: -9784.8899 | T10: -15744.45
Q11: IRR | R11: 0.22289188 | S11: 0.10262253 | T11: -0.052476922
B12: Financial Assumptions
B13: Debt | E13: ='Exhibit 6'!C24 -> 25000 | J13: For Refference | S13: Valuation (x)
B14: Min. Cash Balance | E14: ='Exhibit 6'!C25 -> 4025 | J14: Investors IRR | L14: =H70 -> 0.22289188 | Q14: Company | T14: EV/ | U14: EV/ | V14: EV/
B15: Blended Interest Rate on Debt | E15: ='Exhibit 6'!C26 -> 0.07 | J15: Exit EBITDA | L15: =N45 -> 3191.4468 | Q15: Name | S15: P/E | T15: Revenue | U15: EBITDA | V15: MAU
B16: Tax Rate | E16: ='Exhibit 6'!C27 -> 0.28 | J16: EV | L16: =N61 -> 79786.171 | Q16: Meta Platforms Inc. | S16: 24.06 | T16: 8,60x | U16: 16,10x | V16: 302,24x
B17: Required Return on Equity | E17: 0.25 | J17: PV of Equity | L17: =F78 -> -2180.4371 | Q17: Pinterest Inc. | S17: 66.09 | T17: 8,90x | U17: 56,80x | V17: 50,49x
B18: Initial Equity Investment | E18: 21000 | Q18: Snap Inc. | S18: -32.13 | T18: 20,10x | U18: - | V18: 175,86x
Q19: Weibo Corporation | S19: 20.79 | T19: 2,60x | U19: 7,40x | V19: 9,60x
Q20: Twitter Inc. (TWTR) | S20: -94.29 | T20: 6,80x | U20: 41,90x | V20: 92,17x
A21: x | B21: Operating Assumptions | Q21: Average | S21: -3.1 | T21: 9,40x | U21: 30,55x | V21: 126,07x
Q22: Median | S22: 20.79 | T22: 8,60x | U22: 29,00x | V22: 92,17x
B23: Metrics | F23: 2019 | G23: =+F23+1 -> 2020 | H23: =+G23+1 -> 2021 | I23: =+H23+1 -> 2022 | J23: =+I23+1 -> 2023 | K23: =+J23+1 -> 2024 | L23: =+K23+1 -> 2025 | M23: =+L23+1 -> 2026 | N23: =+M23+1 -> 2027 | O23: =+N23+1 -> 2028 | Q23: ST. Dev. | S23: 61.75 | T23: 6,49x | U23: 22,82x | V23: 116,13x
B24: Revenue Growth | G24: =G44/F44-1 -> 0.074297646 | H24: =H44/G44-1 -> 0.36625543 | I24: ='Exhibit 6'!C16 -> 0.25 | J24: =$E$8 -> 0.15 | K24: =$E$8 -> 0.15 | L24: =$E$8 -> 0.15 | M24: =$E$8 -> 0.15 | N24: =$E$8 -> 0.15 | O24: =$E$9 -> 0.1
B25: D&A % of Rev | J25: ='Exhibit 6'!D17 -> 0.095 | K25: ='Exhibit 6'!E17 -> 0.09 | L25: ='Exhibit 6'!F17 -> 0.085 | M25: ='Exhibit 6'!G17 -> 0.08 | N25: ='Exhibit 6'!H17 -> 0.075 | Q25: Compareables | T25: EV/ | U25: EV/ | V25: EV/
Q26: Valuation Twitter | T26: Revenue | U26: EBITDA | V26: MAU
B27: EBITDA Margin (Pre-Tax) | J27: =$E$7 -> 0.25 | K27: =$E$7 -> 0.25 | L27: =$E$7 -> 0.25 | M27: =$E$7 -> 0.25 | N27: =$E$7 -> 0.25 | Q27: Implied Share Price Avg | T27: 57.03 | U27: 28.63 | V27: 53.01
Q28: Implied Share Price Median | T28: 51.96 | U28: 27.04 | V28: 38.06
B29: Capital Expenditures (% Revenue) | J29: ='Exhibit 6'!D20 -> 0.1 | K29: ='Exhibit 6'!E20 -> 0.1 | L29: ='Exhibit 6'!F20 -> 0.1 | M29: ='Exhibit 6'!G20 -> 0.1 | N29: ='Exhibit 6'!H20 -> 0.1 | Q29: Average Implied Share Price | T29: 54.5 | U29: 27.83 | V29: 45.53
B30: Change in NWC (% Change in Revenue) | J30: ='Exhibit 6'!D21 -> 0.01 | K30: ='Exhibit 6'!E21 -> 0.01 | L30: ='Exhibit 6'!F21 -> 0.01 | M30: ='Exhibit 6'!G21 -> 0.01 | N30: ='Exhibit 6'!H21 -> 0.01
A32: x | B32: Financials
I33: Entry
B34: Debt & Cash Model | I34: 2022 | J34: =+I34+1 -> 2023 | K34: =+J34+1 -> 2024 | L34: =+K34+1 -> 2025 | M34: =+L34+1 -> 2026 | N34: =+M34+1 -> 2027 | O34: =+N34+1 -> 2028
B35: Starting Cash | J35: =I37 -> 4025 | K35: =J37 -> 4025 | L35: =K37 -> 4025 | M35: =L37 -> 4025 | N35: =M37 -> 4025
B36: (+/-) Cash | J36: =J55-J56 -> 0 | K36: 0 | L36: 0 | M36: 0 | N36: 0
B37: Ending Cash | I37: =E14 -> 4025 | J37: =SUM(J35:J36) -> 4025 | K37: =SUM(K35:K36) -> 4025 | L37: =SUM(L35:L36) -> 4025 | M37: =SUM(M35:M36) -> 4025 | N37: =SUM(N35:N36) -> 4025
B39: Starting Debt | J39: =I41 -> 25000 | K39: =J41 -> 25484.632 | L39: =K41 -> 25885.184 | M39: =L41 -> 26182.748 | N39: =M41 -> 26355.523
B40: Debt Draw Down/ Repayment | J40: =J36-J55 -> 484.63179 | K40: =K36-K55 -> 400.5525 | L40: =L36-L55 -> 297.56388 | M40: =M36-M55 -> 172.77518 | N40: =N36-N55 -> 22.8999
B41: Ending Debt | I41: ='Exhibit 6'!C24 -> 25000 | J41: =SUM(J39:J40) -> 25484.632 | K41: =SUM(K39:K40) -> 25885.184 | L41: =SUM(L39:L40) -> 26182.748 | M41: =SUM(M39:M40) -> 26355.523 | N41: =SUM(N39:N40) -> 26378.423
B43: Operating Model | F43: 2019 | G43: =+F43+1 -> 2020 | H43: =+G43+1 -> 2021 | I43: =+H43+1 -> 2022 | J43: =+I43+1 -> 2023 | K43: =+J43+1 -> 2024 | L43: =+K43+1 -> 2025 | M43: =+L43+1 -> 2026 | N43: =+M43+1 -> 2027 | O43: =+N43+1 -> 2028
B44: Revenue | F44: ='Exhibit 3'!B5 -> 3459.329 | G44: ='Exhibit 3'!C5 -> 3716.349 | H44: ='Exhibit 3'!D5 -> 5077.482 | I44: =H44*(1+I24) -> 6346.8525 | J44: =I44*(1+J24) -> 7298.8804 | K44: =J44*(1+K24) -> 8393.7124 | L44: =K44*(1+L24) -> 9652.7693 | M44: =L44*(1+M24) -> 11100.685 | N44: =M44*(1+N24) -> 12765.787
B45: EBITDA | F45: ='Exhibit 3'!B12 -> 831.873 | G45: ='Exhibit 3'!C12 -> 521.835 | H45: ='Exhibit 3'!D12 -> 817.81 | J45: =J44*J27 -> 1824.7201 | K45: =K44*K27 -> 2098.4281 | L45: =L44*L27 -> 2413.1923 | M45: =M44*M27 -> 2775.1712 | N45: =N44*N27 -> 3191.4468
...

Sheet Comps
B1: Trading Multiples
B2: 2021 | E2: Market Data ($) | J2: Financial (€) | N2: Valuation (x)
B3: Company | H3: Shares Out | O3: EV/ | P3: EV/ | Q3: EV/
B4: Name | E4: Price | F4: Mkt Cap (B) | G4: EV (B) | H4: Diluted (M) | J4: Revenue (M) | K4: MAU (M) | L4: Last Debt (B) | N4: P/E | O4: Revenue | P4: EBITDA | Q4: MAU
B5: Meta Platforms Inc. (FB) | E5: 336.35 | F5: 935.65 | G5: 1014.19 | H5: 2859 | J5: 117929 | K5: 2900 | L5: 0.58 | N5: 24.06 | O5: 8,60x | P5: 16,10x | Q5: 302,24x
B6: Pinterest Inc. (PINS) | E6: 36.35 | F6: 23.71 | G6: 22.94 | H6: 692 | J6: 2578.03 | K6: 431 | L6: 0.25 | N6: 66.09 | O6: 8,90x | P6: 56,80x | Q6: 50,49x
B7: Snap Inc. (SNAP) | E7: 47.03 | F7: 76.15 | G7: 82.75 | H7: 1559 | J7: 4117.05 | K7: 428 | L7: 2.25 | N7: -32.13 | O7: 20,10x | P7: - | Q7: 175,86x
B8: Weibo Corporation (WB) | E8: 30.98 | F8: 6.93 | G8: 5.87 | H8: 230 | J8: 2257.08 | K8: 573 | L8: 1.54 | N8: 20.79 | O8: 2,60x | P8: 7,40x | Q8: 9,60x
B9: Twitter Inc. (TWTR) | E9: 43.22 | F9: 34.55 | G9: 34.53 | H9: 798 | J9: 5077.48 | K9: 353 | L9: 4.25 | N9: -94.29 | O9: 6,80x | P9: 41,90x | Q9: 92,17x
B10: Average | N10: -3.1 | O10: 9,40x | P10: 30,55x | Q10: 126,07x
B11: Median | N11: 20.79 | O11: 8,60x | P11: 29,00x | Q11: 92,17x
B12: ST. Dev. | N12: 61.75 | O12: 6,49x | P12: 22,82x | Q12: 116,13x
B14: Company | F14: EV/ | G14: EV/ | H14: EV/
B15: Name | E15: P/E | F15: Revenue | G15: EBITDA | H15: MAU
B16: Twitter Inc. (TWTR) | E16: -94.29 | F16: 6,80x | G16: 41,90x | H16: 92,17x
B17: Average | E17: -3.1 | F17: 9,40x | G17: 30,55x | H17: 126,07x
B18: Median | E18: 20.79 | F18: 8,60x | G18: 29,00x | H18: 92,17x
F20: 5077.48 | G20: 817.81 | H20: 353
F22: EV/ | G22: EV/ | H22: EV/
B23: Twitter | D23: In Millions | E23: Ratio | F23: Revenue | G23: EBITDA | H23: MAU
B24: Debt | D24: 4253 | E24: Implied EV Avg | F24: 47728.33 | G24: 24984.1 | H24: 44503.42
B25: Cash | D25: 2186.55 | E25: Implied EV Median | F25: 43666.35 | G25: 23716.49 | H25: 32536.01
B26: Revenue | D26: 5077.48
B27: EBITDA | D27: 817.81 | E27: Implied MC Avg | F27: 45661.88 | G27: 22917.65 | H27: 42436.97
B28: MAU | D28: 353 | E28: Implied MC Median | F28: 41599.9 | G28: 21650.04 | H28: 30469.56
E30: Implied Share Price Avg | F30: 57.03 | G30: 28.63 | H30: 53.01
E31: Implied Share Price Median | F31: 51.96 | G31: 27.04 | H31: 38.06
E32: Average Implied Share Price | F32: 54.5 | G32: 27.83 | H32: 45.53
F35: =AVERAGE(F32:H32) -> 42.62 | H35: =F35*798 -> 34010.76
