Workbook
Name WACC: Main!$Q$93

Sheet Main
B2: Income Statement | H2: 2019 | I2: =H2+1 -> 2020 | J2: =I2+1 -> 2021 | K2: =J2+1 -> 2022 | L2: =K2+1 -> 2023 | M2: =L2+1 -> 2024 | N2: =M2+1 -> 2025 | O2: =N2+1 -> 2026 | P2: =O2+1 -> 2027 | Q2: =P2+1 -> 2028
B3: Revenue | G3: =Model!Q15 -> 70848 | H3: =Model!R15 -> 71965 | I3: =Model!S15 -> 77867 | J3: =Model!T15 -> 79024 | K3: =Model!U15 -> 63054 | L3: =Model!V15 -> 54228 | M3: =L3*(M21+1) -> 57481.68 | N3: =M3*(N21+1) -> 60930.581 | O3: =N3*(O21+1) -> 63977.11 | P3: =O3*(P21+1) -> 67175.965 | Q3: =P3*(Q21+1) -> 69863.004
B4: Cost of Sales | H4: =Model!R16 -> 29825 | I4: =Model!S16 -> 34255 | J4: =Model!T16 -> 35209 | K4: =Model!U16 -> 36188 | L4: =Model!V16 -> 32517 | M4: =M3*M22 -> 34489.008 | N4: =N3*N22 -> 33511.819 | O4: =O3*O22 -> 31988.555 | P4: =P3*P22 -> 30229.184 | Q4: =Q3*Q22 -> 27945.202
B5: Gross Profit | H5: =H3-H4 -> 42140 | I5: =I3-I4 -> 43612 | J5: =J3-J4 -> 43815 | K5: =K3-K4 -> 26866 | L5: =L3-L4 -> 21711 | M5: =M3-M4 -> 22992.672 | N5: =N3-N4 -> 27418.761 | O5: =O3-O4 -> 31988.555 | ... Q5: =Q3-Q4 -> 41917.802
B7: Research and Development | H7: =Model!R18 -> 13362 | I7: =Model!S18 -> 13556 | J7: =Model!T18 -> 15190 | K7: =Model!U18 -> 17528 | L7: =Model!V18 -> 16046 | M7: =M3*M23 -> 14678.959 | N7: =N3*N23 -> 15232.645 | O7: =O3*O23 -> 14394.85 | P7: =P3*P23 -> 13435.193 | Q7: =Q3*Q23 -> 13972.601
B8: Selling, General & Administrative | H8: =Model!R19 -> 6150 | I8: =Model!S19 -> 6180 | J8: =Model!T19 -> 6543 | K8: =Model!U19 -> 7002 | L8: =Model!V19 -> 5634 | M8: =M24*M3 -> 5704.8646 | N8: =N24*N3 -> 5788.4052 | O8: =O24*O3 -> 6077.8254 | P8: =P24*P3 -> 6045.8369 | Q8: =Q24*Q3 -> 5938.3553
B9: Operating Income | H9: =H5-H7-H8 -> 22628 | I9: =I5-I7-I8 -> 23876 | J9: =J5-J7-J8 -> 22082 | K9: =K5-K7-K8 -> 2336 | L9: =L5-L7-L8 -> 31 | M9: =M5-M7-M8 -> 2608.8481 | N9: =N5-N7-N8 -> 6397.711 | O9: =O5-O7-O8 -> 11515.88 | ... Q9: =Q5-Q7-Q8 -> 22006.846
B11: Interest NET | H11: =Model!R22 -> 484 | I11: =Model!S22 -> -504 | J11: =Model!T22 -> -482 | K11: =Model!U22 -> 1166 | L11: =Model!V22 -> 629 | M11: =M27*M46 -> 1174.45 | N11: =N27*N46 -> 1106.2088 | O11: =O27*O46 -> 1037.9675 | P11: =P27*P46 -> 969.72625 | Q11: =Q27*Q46 -> 901.485
B12: Pretax Income | H12: =H9-H11 -> 22144 | I12: =I9-I11 -> 24380 | J12: =J9-J11 -> 22564 | K12: =K9-K11 -> 1170 | L12: =L9-L11 -> -598 | M12: =M9-M11 -> 1434.3981 | N12: =N9-N11 -> 5291.5022 | O12: =O9-O11 -> 10477.912 | ... Q12: =Q9-Q11 -> 21105.361
B13: – Tax Provision | H13: =Model!R24 -> 3010 | I13: =Model!S24 -> 4179 | J13: =Model!T24 -> 1835 | K13: =Model!U24 -> -249 | L13: =Model!V24 -> -913 | M13: =M12*M28 -> 301.2236 | N13: =N12*N28 -> 1111.2155 | O13: =O12*O28 -> 2200.3616 | P13: =P12*P28 -> 3464.1652 | Q13: =Q12*Q28 -> 4432.1259
B14: Net Income | H14: =H12-H13 -> 19134 | I14: =I12-I13 -> 20201 | J14: =J12-J13 -> 20729 | K14: =K12-K13 -> 1419 | L14: =L12-L13 -> 315 | M14: =M12-M13 -> 1133.1745 | N14: =N12-N13 -> 4180.2868 | O14: =O12-O13 -> 8277.5507 | ... Q14: =Q12-Q13 -> 16673.235
B16: EBIT | H16: =H9 -> 22628 | I16: =I9 -> 23876 | J16: =J9 -> 22082 | K16: =K9 -> 2336 | L16: =L9 -> 31 | M16: =M9 -> 2608.8481 | N16: =N9 -> 6397.711 | O16: =O9 -> 11515.88 | ... Q16: =Q9 -> 22006.846
B17: Depreciation & Amortization | H17: =Model!R35+Model!R38 -> 10826 | I17: =Model!S35+Model!S38 -> 12239 | J17: =Model!T35+Model!T38 -> 11792 | K17: =Model!U35+Model!U38 -> 13035 | L17: =Model!V35+Model!V38 -> 12883 | M17: =M25*M3 -> 11496.336 | N17: =N25*N3 -> 12186.116 | O17: =O25*O3 -> 12795.422 | P17: =P25*P3 -> 12091.674 | Q17: =Q25*Q3 -> 11876.711
B18: EBITDA | H18: =H16+H17 -> 33454 | I18: =I16+I17 -> 36115 | J18: =J16+J17 -> 33874 | K18: =K16+K17 -> 15371 | L18: =L16+L17 -> 12914 | M18: =M16+M17 -> 14105.184 | N18: =N16+N17 -> 18583.827 | O18: =O16+O17 -> 24311.302 | ... Q18: =Q16+Q17 -> 33883.557
B20: Income Statement Drivers
B21: Revenue Growth | H21: =H3/G3-1 -> 0.015766147 | I21: =I3/H3-1 -> 0.082012089 | J21: =J3/I3-1 -> 0.014858669 | K21: =K3/J3-1 -> -0.2020905 | L21: =L3/K3-1 -> -0.13997526 | M21: 0.06 | N21: 0.06 | O21: 0.05 | P21: 0.05 | Q21: 0.04
B22: Cost of Sales % Revenues | H22: =H4/H3 -> 0.41443757 | I22: =I4/I3 -> 0.43991678 | J22: =J4/J3 -> 0.44554819 | K22: =K4/K3 -> 0.57392077 | L22: =L4/L3 -> 0.59963487 | M22: 0.6 | N22: 0.55 | O22: 0.5 | P22: 0.45 | Q22: 0.4
B23: Research and Development as % Revenues | H23: =H7/H3 -> 0.18567359 | I23: =I7/I3 -> 0.17409172 | J23: =J7/J3 -> 0.19222009 | K23: =K7/K3 -> 0.27798395 | L23: =L7/L3 -> 0.2958988 | M23: =AVERAGE(J23:L23) -> 0.25536761 | N23: 0.25 | O23: 0.225 | P23: 0.2 | Q23: 0.2
B24: Selling, General and Administrative Expenses % Revenues | H24: =H8/H3 -> 0.085458209 | I24: =I8/I3 -> 0.079366099 | J24: =J8/J3 -> 0.082797631 | K24: =K8/K3 -> 0.11104767 | L24: =L8/L3 -> 0.10389467 | M24: =AVERAGE(J24:L24) -> 0.099246657 | N24: 0.095 | O24: 0.095 | P24: 0.09 | Q24: 0.085
B25: D&A as a % of Revenue | H25: =H17/H3 -> 0.15043424 | I25: =I17/I3 -> 0.15717827 | J25: =J17/J3 -> 0.14922049 | K25: =K17/K3 -> 0.20672757 | L25: =L17/L3 -> 0.237571 | M25: 0.2 | N25: 0.2 | O25: 0.2 | P25: 0.18 | Q25: 0.17
B26: D&A as a % Capital Expenditures | H26: =H17/H58 -> 0.66773577 | I26: =I17/I58 -> 0.85833509 | J26: =J17/J58 -> 0.62947739 | K26: =K17/K58 -> 0.52467397 | L26: =L17/L58 -> 0.50031068
B27: Interest Expense as a % of LT Debt | H27: =H11/H46 -> 0.01814365 | I27: =I11/I46 -> -0.014292196 | J27: =J11/J46 -> -0.014304793 | K27: =K11/K46 -> 0.030941514 | L27: =L11/L46 -> 0.013389246 | M27: 0.025 | N27: 0.025 | O27: 0.025 | P27: 0.025 | Q27: 0.025
B28: Taxes % of Profit Before Tax | H28: =H13/H12 -> 0.13592847 | I28: =I13/I12 -> 0.17141099 | J28: =J13/J12 -> 0.081324233 | K28: =K13/K12 -> -0.21282051 | L28: =L13/L12 -> 1.5267559 | M28: 0.21 | N28: =M28 -> 0.21 | O28: =N28 -> 0.21 | P28: =O28 -> 0.21 | Q28: =P28 -> 0.21
B30: Balance Sheet | H30: 2019 | I30: =H30+1 -> 2020 | J30: =I30+1 -> 2021 | K30: =J30+1 -> 2022 | L30: =K30+1 -> 2023 | M30: =L30+1 -> 2024 | N30: =M30+1 -> 2025 | O30: =N30+1 -> 2026 | P30: =O30+1 -> 2027 | Q30: =P30+1 -> 2028
B31: Total Cash | H31: =Model!R47 -> 13123 | I31: =Model!S47 -> 23895 | J31: =Model!T47 -> 28413 | K31: =Model!U47 -> 28338 | L31: =Model!V47 -> 25034 | M31: =L31/1.2 -> 20861.667 | N31: =M31/1.2 -> 17384.722 | O31: =N31/1.2 -> 14487.269 | P31: =O31/1.2 -> 12072.724 | Q31: =P31/1.2 -> 10060.603
B32: Accounts Receivable | H32: =Model!R48 -> 7659 | I32: =Model!S48 -> 6782 | J32: =Model!T48 -> 9457 | K32: =Model!U48 -> 4133 | L32: =Model!V48 -> 3402 | M32: =M55*M3 -> 4023.7176 | N32: =N55*N3 -> 4874.4465 | O32: =O55*O3 -> 5757.9399 | P32: =P55*P3 -> 6717.5965 | Q32: =Q55*Q3 -> 6986.3004
B33: Inventory | H33: =Model!R49 -> 8744 | I33: =Model!S49 -> 8427 | J33: =Model!T49 -> 10776 | K33: =Model!U49 -> 13224 | L33: =Model!V49 -> 11127 | M33: =M56*M4 -> 10346.702 | N33: =N56*N4 -> 10053.546 | O33: =O56*O4 -> 9596.5665 | P33: =P56*P4 -> 9068.7553 | Q33: =Q56*Q4 -> 8383.5605
B34: Other Current Assets | H34: =Model!R50 -> 1713 | I34: =Model!S50 -> 8145 | J34: =Model!T50 -> 9072 | K34: =Model!U50 -> 4712 | L34: =Model!V50 -> 3706 | M34: =M57*M3 -> 4440.7577 | N34: =N57*N3 -> 4707.2032 | O34: =O57*O3 -> 4942.5633 | P34: =P57*P3 -> 5189.6915 | Q34: =Q57*Q3 -> 5397.2792
B35: Total Current Assets | H35: =H31+H32+H33+H34 -> 31239 | I35: =I31+I32+I33+I34 -> 47249 | J35: =J31+J32+J33+J34 -> 57718 | K35: =K31+K32+K33+K34 -> 50407 | L35: =L31+L32+L33+L34 -> 43269 | M35: =M31+M32+M33+M34 -> 39672.844 | N35: =N31+N32+N33+N34 -> 37019.918 | O35: =O31+O32+O33+O34 -> 34784.338 | ... Q35: =Q31+Q32+Q33+Q34 -> 30827.743
B37: Net Property, Plant & Equipment (PPE) | H37: =Model!R52 -> 55386 | I37: =Model!S52 -> 56584 | J37: =Model!T52 -> 63245 | K37: =Model!U52 -> 80860 | L37: =Model!V52 -> 96647 | M37: =L37+M58-M17 -> 106340.58 | N37: =M37+N58-N17 -> 115480.16 | O37: =N37+O58-O17 -> 121877.87 | P37: =O37+P58-P17 -> 126580.19 | Q37: =P37+Q58-Q17 -> 128676.08
B38: Intangibles | H38: =Model!R54 -> 37103 | I38: =Model!S54 -> 35997 | J38: =Model!T54 -> 34233 | K38: =Model!U54 -> 33609 | L38: =Model!V54 -> 32180 | M38: =L38 -> 32180 | N38: =M38 -> 32180 | O38: =N38 -> 32180 | P38: =O38 -> 32180 | Q38: =P38 -> 32180
B39: Other Non-Current Assets | H39: =Model!R55+Model!R53 -> 12796 | I39: =Model!S55+Model!S53 -> 13261 | J39: =Model!T55+Model!T53 -> 13210 | K39: =Model!U55+Model!U53 -> 17227 | L39: =Model!V55+Model!V53 -> 19476 | M39: =AVERAGE(J39:L39) -> 16637.667 | N39: =AVERAGE(K39:M39) -> 17780.222 | O39: =AVERAGE(L39:N39) -> 17964.63 | P39: =AVERAGE(M39:O39) -> 17460.84 | Q39: =AVERAGE(N39:P39) -> 17735.23
B40: Total Assets | H40: =H37+H38+H39+H35 -> 136524 | I40: =I37+I38+I39+I35 -> 153091 | J40: =J37+J38+J39+J35 -> 168406 | K40: =K37+K38+K39+K35 -> 182103 | L40: =L37+L38+L39+L35 -> 191572 | M40: =M37+M38+M39+M35 -> 194831.09 | N40: =N37+N38+N39+N35 -> 202460.3 | O40: =O37+O38+O39+O35 -> 206806.84 | ... Q40: =Q37+Q38+Q39+Q35 -> 209419.06
B42: Accounts Payable | H42: =Model!R59 -> 4128 | I42: =Model!S59 -> 5581 | J42: =Model!T59 -> 5747 | K42: =Model!U59 -> 9595 | L42: =Model!V59 -> 8578 | M42: =M60*M4 -> 5603.6295 | N42: =N60*N4 -> 6032.1275 | O42: =O60*O4 -> 6397.711 | P42: =P60*P4 -> 6650.4206 | Q42: =Q60*Q4 -> 6706.8484
B43: Other Current Liabilities | H43: =Model!R58+Model!R60+Model!R61 -> 18182 | I43: =Model!S58+Model!S60+Model!S61 -> 19173 | J43: =Model!T58+Model!T60+Model!T61 -> 21715 | K43: =Model!U58+Model!U60+Model!U61 -> 22560 | L43: =Model!V58+Model!V60+Model!V61 -> 19475 | M43: =M61*M3 -> 19001.725 | N43: =N61*N3 -> 18279.174 | O43: =O61*O3 -> 17593.705 | P43: =P61*P3 -> 16793.991 | Q43: =Q61*Q3 -> 17465.751
B44: Total Current Liabilities | H44: =H42+H43 -> 22310 | I44: =I42+I43 -> 24754 | J44: =J42+J43 -> 27462 | K44: =K42+K43 -> 32155 | L44: =L42+L43 -> 28053 | M44: =M42+M43 -> 24605.354 | N44: =N42+N43 -> 24311.302 | O44: =O42+O43 -> 23991.416 | ... Q44: =Q42+Q43 -> 24172.599
B46: Long Term Debt | H46: =Model!R63+Model!R64 -> 26676 | I46: =Model!S63+Model!S64 -> 35264 | J46: =Model!T63+Model!T64 -> 33695 | K46: =Model!U63+Model!U64 -> 37684 | L46: =Model!V63+Model!V64 -> 46978 | M46: =L46 -> 46978 | N46: =M46-N62 -> 44248.35 | O46: =N46-O62 -> 41518.7 | P46: =O46-P62 -> 38789.05 | Q46: =AVERAGE(H46:L46) -> 36059.4
B47: Deferred Tax Liabilities | H47: =Model!R65+Model!R66 -> 9879 | I47: =Model!S65+Model!S66 -> 12035 | J47: =Model!T65+Model!T66 -> 11858 | K47: =Model!U65+Model!U66 -> 8978 | L47: =Model!V65+Model!V66 -> 6576 | M47: =L47 -> 6576 | N47: =M47 -> 6576 | O47: =N47 -> 6576 | P47: =O47 -> 6576 | Q47: =P47 -> 6576
B48: Total Liabilities | H48: =H46+H47+H44 -> 58865 | I48: =I46+I47+I44 -> 72053 | J48: =J46+J47+J44 -> 73015 | K48: =K46+K47+K44 -> 78817 | L48: =L46+L47+L44 -> 81607 | M48: =M46+M47+M44 -> 78159.354 | N48: =N46+N47+N44 -> 75135.652 | O48: =O46+O47+O44 -> 72086.116 | ... Q48: =Q46+Q47+Q44 -> 66807.999
B50: Total Equity | H50: =Model!R68 -> 77659 | I50: =Model!S68 -> 81038 | J50: =Model!T68 -> 95391 | K50: =Model!U68 -> 103286 | L50: =Model!V68 -> 109965 | M50: =M40-M48 -> 116671.73 | N50: =N40-N48 -> 127324.65 | O50: =O40-O48 -> 134720.73 | P50: =P40-P48 -> 140460.34 | Q50: =Q40-Q48 -> 142611.06
...

Sheet Comp
A1: Intel Corporation (INTC)
A2: $35.69
A5: Comps Tables - Semiconductors
A6: Selected Financials
D7: Sales ($) | F7: EBITDA | J7: EBIT | N7: FCF
C8: Fiscal | G8: Margin | I8: Margin | K8: Margin | M8: Margin
A9: Company | B9: Ticker | C9: Period | D9: FY1 | E9: FY2 | F9: FY1 | G9: FY1 (%) | H9: FY2 | I9: FY2 (%) | J9: FY1 | K9: FY1 (%) | L9: FY2 | M9: FY2 (%) | N9: FY1 | O9: FY2
A10: Intel | B10: INTC-US | C10: 12/2023 | D10: 57453.879 | E10: 63988.641 | F10: 16401.496 | G10: 28.547239 | H10: 21461.039 | I10: 33.538826 | J10: 6737.5 | K10: 11.726797 | L10: 11046.438 | M10: 17.263124 | N10: -8549.0459 | O10: -1525.0211
A11: Texas Instruments | B11: TXN-US | C11: 12/2023 | D11: 15590.835 | E11: 17856.934 | F11: 7006.6377 | G11: 44.940746 | H11: 9201.7549 | I11: 51.530434 | J11: 5349.2681 | K11: 34.310337 | L11: 6835.6147 | M11: 38.279892 | N11: 1884.0786 | O11: 4076.9668
A12: QUALCOMM | B12: QCOM-US | C12: 12/24/2023 | D12: 38270.449 | E12: 41940.223 | F12: 14391.915 | G12: 37.605816 | H12: 15302.745 | I12: 36.487038 | J12: 12854.854 | K12: 33.589504 | L12: 14504.983 | M12: 34.584896 | N12: 10029.102 | O12: 11900.254
A13: Analog Devices | B13: ADI-US | C13: 02/03/2024 | D13: 9196.8223 | E13: 10352.638 | F13: 4019.9521 | G13: 43.710228 | H13: 4971.5117 | I13: 48.02169 | J13: 3629.3462 | K13: 39.463047 | L13: 4358.3345 | M13: 42.098782 | N13: 3079.1265 | O13: 3704.8669
A14: AMD | B14: AMD-US | C14: 12/2023 | D14: 25957.836 | E14: 32520.49 | F14: 8064.3765 | G14: 31.067213 | H14: 10861.549 | I14: 33.399094 | J14: 6725.125 | K14: 25.907881 | L14: 10016.578 | M14: 30.800823 | N14: 5287.7754 | O14: 6941.1646
A15: Marvell Tech | B15: MRVL-US | C15: 01/2024 | D15: 5332.6948 | E15: 6987.1938 | F15: 1640.3723 | G15: 30.760664 | H15: 2824.8684 | I15: 40.429226 | J15: 1533.1997 | K15: 28.750935 | L15: 2541.0623 | M15: 36.367424 | N15: 1395.9972 | O15: 2021.1117
A16: Microchip Technology | B16: MCHP-US | C16: 12/31/2023 | D16: 7638.4414 | E16: 5954.2739 | F16: 3501.217 | G16: 45.8368 | H16: 2348.8821 | I16: 39.448673 | J16: 3330.1177 | K16: 43.596821 | L16: 2118.3484 | M16: 35.576939 | N16: 2913.4771 | O16: 1564.9359
A17: Broadcom | B17: AVGO-US | C17: 02/04/2024 | D17: 50415.617 | E17: 57164.223 | F17: 30244.43 | G17: 59.990196 | H17: 36498.742 | I17: 63.848923 | J17: 29333.119 | K17: 58.182602 | L17: 35025.699 | M17: 61.272068 | N17: 22602.697 | O17: 27944.725
A18: Average | G18: 40.307363 | I18: 43.337988 | K18: 34.44099 | M18: 37.030494 | N18: 4830.401 | O18: 7078.6254
A19: Median | G19: 40.658022 | I19: 39.938949 | K19: 33.94992 | M19: 35.972182 | N19: 2996.3018 | O19: 3890.9169
A21: Valuation | E21: Market Data ($) | I21: Valuation (x) | K21: EV/EBITDA (x) | M21: P/E (x) | O21: P/FCF (x)
C22: Fiscal | E22: Price | F22: Enterprise | G22: Market | H22: Net | I22: Price/ | J22: EV/ | Q22: FCF | R22: Div
A23: Company | B23: Ticker | C23: Period | D23: Price | E23: Target | F23: Value | G23: Value | H23: Debt | I23: Sales | J23: Sales | K23: FY1 | L23: FY2 | M23: FY1 | N23: FY2 | O23: FY1 | P23: FY2 | Q23: Yield (%) | R23: Yield (%)
A24: Intel | B24: INTC-US | C24: 12/2023 | D24: 35.689999 | E24: 45.554722 | F24: 186283.12 | G24: 157068.12 | H24: 24663 | I24: 2.772116 | J24: 3.435183 | K24: 11.357691 | L24: 8.68006 | M24: 26.162418 | N24: 15.976723 | O24: - | P24: - | Q24: -6.74642 | R24: 1.400953
A26: Texas Instruments | B26: TXN-US | C26: 12/2023 | D26: 166.33 | E26: 169.45422 | F26: 155919.45 | G26: 153288.45 | H26: 3214 | I26: 8.696745 | J26: 8.90002 | K26: 22.253106 | L26: 16.944534 | M26: 33.183834 | N26: 25.997227 | O26: 94.955284 | P26: 44.197521 | Q26: 0.863961 | R26: 3.126315
A27: QUALCOMM | B27: QCOM-US | C27: 12/24/2023 | D27: 171.28999 | E27: 174.985 | F27: 200580.79 | G27: 197154.79 | H27: 3426 | I27: 5.319184 | J27: 5.52686 | K27: 13.937047 | L27: 13.107504 | M27: 17.318808 | N27: 15.372305 | O27: 18.487856 | P27: 14.28905 | Q27: 8.123042 | R27: 1.868177
A28: Analog Devices | B28: ADI-US | C28: 02/03/2024 | D28: 192.27 | E28: 211.89731 | F28: 102312.88 | G28: 96545.737 | H28: 5686.879 | I28: 8.28906 | J28: 8.844006 | K28: 25.451268 | L28: 20.579832 | M28: 32.106102 | N28: 25.331469 | O28: 31.727724 | P28: 27.75794 | Q28: 4.377265 | R28: 1.913975
A29: AMD | B29: AMD-US | C29: 12/2023 | D29: 163.28 | E29: 200.23215 | F29: 266258.05 | G29: 269662.05 | H29: -2770 | I29: 11.698854 | J29: 11.739773 | K29: 33.016569 | L29: 24.513819 | M29: 44.136044 | N29: 29.67338 | O29: 52.066326 | P29: 37.761333 | Q29: 0.467978 | R29: 0
A30: Marvell Tech | B30: MRVL-US | C30: 01/2024 | D30: 70.160004 | E30: 88.810997 | F30: 65472.3 | G30: 62257.2 | H30: 3752.7 | I30: 10.971696 | J30: 11.887412 | K30: 39.913073 | L30: 23.177115 | M30: 49.428516 | N30: 28.593857 | O30: 39.920341 | P30: 30.704596 | Q30: 1.778088 | R30: 0.342075
A31: Microchip Technology | B31: MCHP-US | C31: 12/31/2023 | D31: 85.639999 | E31: 92.989128 | F31: 52570.304 | G31: 47146.704 | H31: 5446.6 | I31: 5.479524 | J31: 6.154836 | K31: 15.014866 | L31: 22.38099 | M31: 17.379768 | N31: 28.319265 | O31: 15.866605 | P31: 30.55843 | Q31: 6.713986 | R31: 2.101822
A32: Broadcom | B32: AVGO-US | C32: 02/04/2024 | D32: 1344.0699 | E32: 1529.9056 | F32: 724541.54 | G32: 660504.54 | H32: 64037 | I32: 16.150281 | J32: 18.64252 | K32: 23.956198 | L32: 19.851137 | M32: 28.537937 | N32: 23.410473 | O32: 28.318565 | P32: 23.068222 | Q32: 4.925698 | R32: 1.562419
A33: Average | I33: 8.672182 | J33: 9.391326 | K33: 23.112477 | L33: 18.654374 | M33: 31.031678 | N33: 24.084337 | O33: 40.191814 | P33: 29.762442 | Q33: 2.56295 | R33: 1.539467
A34: Median | I34: 8.492902 | J34: 8.872013 | K34: 23.104652 | L34: 20.215485 | M34: 30.322019 | N34: 25.664348 | O34: 31.727724 | P34: 30.55843 | Q34: 3.077676 | R34: 1.715298
A36: Margins | C36: Fiscal | D36: Gross Margin (%) | F36: EBITDA Margin (%) | H36: EBIT Margin (%) | J36: Pretax Margin (%) | L36: Net Margin (%)
A37: Company | B37: Ticker | C37: Period | D37: Actual | E37: NTM | F37: Actual | G37: NTM | H37: Actual | I37: NTM | J37: Actual | K37: NTM | L37: Actual | M37: NTM
A38: Intel | B38: INTC-US | C38: 12/2023 | D38: 39.719333 | E38: 46.326939 | F38: 17.763886 | G38: 30.052948 | H38: 0.057166 | I38: 13.396825 | J38: 1.405178 | K38: 13.794189 | L38: 3.114627 | M38: 11.87332
A40: Texas Instruments | B40: TXN-US | C40: 12/2023 | D40: 62.897426 | E40: 59.050823 | F40: 48.912609 | G40: 46.967583 | H40: 41.845996 | I40: 35.531281 | J40: 42.342599 | K40: 35.454922 | L40: 36.96558 | M40: 30.770966
A41: QUALCOMM | B41: QCOM-US | C41: 12/24/2023 | D41: 55.535655 | E41: 56.5252 | F41: 29.904662 | G41: 36.98576 | H41: 24.812631 | I41: 34.141178 | J41: 22.13711 | K41: 33.581711 | L41: 21.704508 | M41: 29.135183
A42: Analog Devices | B42: ADI-US | C42: 02/03/2024 | D42: 54.727485 | E42: 68.128998 | F42: 49.148044 | G42: 45.762417 | H42: 29.864349 | I42: 40.717613 | J42: 26.346702 | K42: 38.028294 | L42: 24.340273 | M42: 33.131901
A43: AMD | B43: AMD-US | C43: 12/2023 | D43: 37.879189 | E43: 53.782242 | F43: 18.412698 | G43: 31.829739 | H43: 2.755732 | I43: 27.507872 | J43: 2.169312 | K43: 27.431498 | L43: 3.765432 | M43: 24.679964
A44: Marvell Tech | B44: MRVL-US | C44: 01/2024 | D44: 41.643517 | E44: 63.77507 | F44: 17.450115 | G44: 33.084652 | H44: -7.927084 | I44: 30.581675 | J44: -13.77526 | K44: 26.621857 | L44: -16.947183 | M44: 24.947155
A45: Microchip Technology | B45: MCHP-US | C45: 12/31/2023 | D45: 59.547142 | E45: 62.971653 | F45: 47.738635 | G45: 39.779552 | H45: 37.148912 | I45: 35.827446 | J45: 34.748809 | K45: 30.350075 | L45: 27.585965 | M45: 27.474489
A46: Broadcom | B46: AVGO-US | C46: 02/04/2024 | D46: 62.567863 | E46: 75.905518 | F46: 52.365882 | G46: 61.83387 | H46: 39.120031 | I46: 59.658726 | J46: 32.417342 | K46: 54.342239 | L46: 29.800592 | M46: 47.369823
...

Sheet Model
C2: Q421 | D2: Q122 | E2: Q222 | F2: Q322 | G2: Q422 | H2: Q123 | I2: Q223 | J2: Q323 | K2: Q423 | L2: Q124 | M2: Q224 | N2: YoY | P2: =Q2-1 -> 2017 | Q2: =R2-1 -> 2018 | R2: =S2-1 -> 2019 | S2: 2020 | T2: =S2+1 -> 2021 | U2: =T2+1 -> 2022 | V2: =U2+1 -> 2023 | W2: =V2+1 -> 2024 | X2: =W2+1 -> 2025 | Y2: =X2+1 -> 2026 | Z2: =Y2+1 -> 2027 | AA2: =Z2+1 -> 2028 | ... AK2: =AJ2+1 -> 2038
B3: Intel Corp.
B4: CCG
B5: Desktop | I5: 2370 | M5: 2527 | N5: =M5/I5-1 -> 0.066244726
B6: Notebook | I6: 3896 | M6: 4480 | N6: =M6/I6-1 -> 0.14989733
B7: Other | I7: 514 | M7: 403 | N7: =M7/I7-1 -> -0.21595331
B8: DCAI | I8: 3155 | M8: 3045 | N8: =M8/I8-1 -> -0.034865293
B9: NEX | I9: 1364 | M9: 1344 | N9: =M9/I9-1 -> -0.014662757
B10: Intel Foundy | I10: 4172 | M10: 4320 | N10: =M10/I10-1 -> 0.035474593
B11: All Other | I11: 1419 | M11: 968 | N11: =M11/I11-1 -> -0.31782946
B12: Total | I12: =I11+I10+I9+I8+I7+I6+I5 -> 16890 | M12: =M11+M10+M9+M8+M7+M6+M5 -> 17087 | N12: =M12/I12-1 -> 0.011663706
B13: Less Transaction Costs | I13: -3941 | M13: -4254 | N13: =M13/I13-1 -> 0.079421467
B15: Revenue | D15: 18383 | E15: 15321 | F15: 15338 | G15: 14042 | H15: 11715 | I15: =I13+I12 -> 12949 | J15: 14158 | K15: 15406 | L15: 12724 | M15: 12833 | P15: 62761 | Q15: 70848 | R15: 71965 | S15: 77867 | T15: 79024 | U15: 63054 | V15: 54228
B16: COGS | D16: 9109 | E16: 9734 | F16: 8803 | G16: 8542 | H16: 7707 | I16: 8311 | J16: 8140 | K16: 8359 | L16: 7507 | M16: 8286 | P16: 23663 | Q16: 27111 | R16: 29825 | S16: 34255 | T16: 35209 | U16: 36188 | V16: 32517
B17: Gross Margin | D17: =D15-D16 -> 9274 | E17: =E15-E16 -> 5587 | F17: =F15-F16 -> 6535 | G17: =G15-G16 -> 5500 | H17: =H15-H16 -> 4008 | I17: =I15-I16 -> 4638 | J17: =J15-J16 -> 6018 | K17: =K15-K16 -> 7047 | ... M17: =M15-M16 -> 4547 | P17: =P15-P16 -> 39098 | Q17: =Q15-Q16 -> 43737 | R17: =R15-R16 -> 42140 | S17: =S15-S16 -> 43612 | T17: =T15-T16 -> 43815 | U17: =U15-U16 -> 26866 | V17: =V15-V16 -> 21711
B18: R&D | D18: 4362 | E18: 4400 | F18: 4302 | G18: 4464 | H18: 4109 | I18: 4080 | J18: 3870 | K18: 3987 | L18: 4382 | M18: 4239 | P18: 13035 | Q18: 13543 | R18: 13362 | S18: 13556 | T18: 15190 | U18: 17528 | V18: 16046
B19: MG&A | D19: 1752 | E19: 1800 | F19: 1744 | G19: 1706 | H19: 1303 | I19: 1374 | J19: 1340 | K19: 1617 | L19: 1556 | M19: 1329 | P19: 7452 | Q19: 6750 | R19: 6150 | S19: 6180 | T19: 6543 | U19: 7002 | V19: =5634 -> 5634
B20: Operating Expenditures | D20: =D18+D19 -> 6114 | E20: =E18+E19 -> 6200 | F20: =F18+F19 -> 6046 | G20: =G18+G19 -> 6170 | H20: =H18+H19 -> 5412 | I20: =I18+I19 -> 5454 | J20: =J18+J19 -> 5210 | K20: =K18+K19 -> 5604 | ... M20: =M18+M19 -> 5568 | P20: =P18+P19 -> 20487 | Q20: =Q18+Q19 -> 20293 | R20: =R18+R19 -> 19512 | S20: =S18+S19 -> 19736 | T20: =T18+T19 -> 21733 | U20: =U18+U19 -> 24530 | V20: =V18+V19 -> 21680
B21: Operating Income | D21: =D17-D20 -> 3160 | E21: =E17-E20 -> -613 | F21: =F17-F20 -> 489 | G21: =G17-G20 -> -670 | H21: =H17-H20 -> -1404 | I21: =I17-I20 -> -816 | J21: =J17-J20 -> 808 | K21: =K17-K20 -> 1443 | ... M21: =M17-M20 -> -1021 | P21: =P17-P20 -> 18611 | Q21: =Q17-Q20 -> 23444 | R21: =R17-R20 -> 22628 | S21: =S17-S20 -> 23876 | T21: =T17-T20 -> 22082 | U21: =U17-U20 -> 2336 | V21: =V17-V20 -> 31
B22: Interest | D22: 997 | E22: -119 | F22: 138 | G22: 150 | H22: 141 | I22: 224 | J22: 147 | K22: 117 | L22: 145 | M22: 80 | P22: -349 | Q22: 126 | R22: 484 | S22: -504 | T22: -482 | U22: 1166 | V22: 629
B23: Pretax | D23: =D21+D22 -> 4157 | E23: =E21+E22 -> -732 | F23: =F21+F22 -> 627 | G23: =G21+G22 -> -520 | H23: =H21+H22 -> -1263 | I23: =I21+I22 -> -592 | J23: =J21+J22 -> 955 | K23: =K21+K22 -> 1560 | ... M23: =M21+M22 -> -941 | P23: =P21+P22 -> 18262 | Q23: =Q21+Q22 -> 23570 | R23: =R21+R22 -> 23112 | S23: =S21+S22 -> 23372 | T23: =T21+T22 -> 21600 | U23: =U21+U22 -> 3502 | V23: =V21+V22 -> 660
B24: Taxes | D24: 1548 | E24: -455 | F24: -1207 | G24: -135 | H24: 1610 | I24: -2289 | J24: -365 | K24: 128 | L24: -282 | M24: -350 | P24: 10751 | Q24: 2264 | R24: 3010 | S24: 4179 | T24: 1835 | U24: -249 | V24: -913
B25: Net Income | D25: =D23-D24 -> 2609 | E25: =E23-E24 -> -277 | F25: =F23-F24 -> 1834 | G25: =G23-G24 -> -385 | H25: =H23-H24 -> -2873 | I25: =I23-I24 -> 1697 | J25: =J23-J24 -> 1320 | K25: =K23-K24 -> 1432 | ... M25: =M23-M24 -> -591 | P25: =P23-P24 -> 7511 | Q25: =Q23-Q24 -> 21306 | R25: =R23-R24 -> 20102 | S25: =S23-S24 -> 19193 | T25: =T23-T24 -> 19765 | U25: =U23-U24 -> 3751 | V25: =V23-V24 -> 1573
B26: EPS | D26: =D25/D27 -> 0.63525688 | E26: =E25/E27 -> -0.067560976 | F26: =F25/F27 -> 0.44460606 | G26: =G25/G27 -> -0.093152674 | H26: =H25/H27 -> -0.69162253 | I26: =I25/I27 -> 0.40443279 | J26: =J25/J27 -> 0.31213053 | K26: =K25/K27 -> 0.33615023 | ... M26: =M25/M27 -> -0.13821328 | P26: =P25/P27 -> 1.5534643 | Q26: =Q25/Q27 -> 4.5322272 | R26: =R25/R27 -> 4.4940756 | S26: =S25/S27 -> 4.5352079 | T26: =T25/T27 -> 4.8325183 | U26: =U25/U27 -> 0.90977444 | V26: =V25/V27 -> 0.37345679
B27: Shares | D27: 4107 | E27: 4100 | F27: 4125 | G27: 4133 | H27: 4154 | I27: 4196 | J27: 4229 | K27: 4260 | L27: 4242 | M27: 4276 | P27: 4835 | Q27: 4701 | R27: 4473 | S27: 4232 | T27: 4090 | U27: 4123 | V27: 4212
B29: Revenue y/y | D29: =C15/D15-1 -> -1 | E29: =D15/E15-1 -> 0.19985641 | F29: =E15/F15-1 -> -0.0011083583 | G29: =F15/G15-1 -> 0.092294545 | H29: =G15/H15-1 -> 0.19863423 | I29: =H15/I15-1 -> -0.095296934 | J29: =I15/J15-1 -> -0.085393417 | K29: =J15/K15-1 -> -0.0810074 | ... M29: =L15/M15-1 -> -0.0084937271 | Q29: =P15/Q15-1 -> -0.11414578 | R29: =Q15/R15-1 -> -0.015521434 | S29: =R15/S15-1 -> -0.075795908 | T29: =S15/T15-1 -> -0.014641122 | U29: =T15/U15-1 -> 0.25327497 | V29: =U15/V15-1 -> 0.16275725
B30: GDP y/y
B31: Gross Margin % | D31: =D17/D15 -> 0.50448784 | E31: =E17/E15 -> 0.36466288 | F31: =F17/F15 -> 0.42606598 | G31: =G17/G15 -> 0.3916821 | H31: =H17/H15 -> 0.34212548 | I31: =I17/I15 -> 0.35817438 | J31: =J17/J15 -> 0.42506004 | K31: =K17/K15 -> 0.45741919 | ... M31: =M17/M15 -> 0.35432089
B33: Model NI | D33: =D25 -> 2609 | E33: =E25 -> -277 | F33: =F25 -> 1834 | G33: =G25 -> -385 | H33: =H25 -> -2873 | I33: =I25 -> 1697 | J33: =J25 -> 1320 | K33: =K25 -> 1432 | ... M33: =M25 -> -591 | P33: =P25 -> 7511 | Q33: =Q25 -> 21306 | R33: =R25 -> 20102 | S33: =S25 -> 19193 | T33: =T25 -> 19765 | U33: =U25 -> 3751 | V33: =V25 -> 1573
B34: Reported NI | D34: 8113 | E34: -454 | F34: 1019 | G34: -661 | H34: -2768 | I34: 1473 | J34: 310 | K34: 2660 | L34: -437 | M34: -1610 | P34: 9601 | Q34: 21053 | R34: 21048 | S34: 20899 | T34: 19868 | U34: 8017 | V34: 1675
B35: Depreciation | D35: 2847 | H35: 1901 | I35: =3733-H35 -> 1832 | L35: 2200 | P35: 6752 | Q35: 7520 | R35: 9204 | S35: 10482 | T35: 9953 | U35: 11128 | V35: 11128
B36: SBC | D36: 707 | H36: 739 | I36: =1661-H36 -> 922 | L36: 1179 | P36: 1358 | Q36: 1546 | R36: 1705 | S36: 1854 | T36: 2036 | U36: 3128 | V36: 3229
B37: Restructuring | D37: 17 | H37: 55 | I37: =255-H37 -> 200 | L37: 348 | P37: 0 | Q37: 0 | R37: 0 | S37: 198 | T37: 2626 | U37: 1074 | V37: -424
B38: Amortization | D38: 501 | H38: 465 | I38: =909-H38 -> 444 | L38: 351 | P38: 1377 | Q38: 1565 | R38: 1622 | S38: 1757 | T38: 1839 | U38: 1907 | V38: 1755
B39: Equity Investments | D39: -4325 | H39: -167 | L39: -208 | P39: -2583 | Q39: 155 | R39: -892 | S39: -1757 | T39: -1458 | U39: -4254 | V39: -42
B40: Divestures | D40: 1121 | H40: 0 | L40: 0 | P40: -387 | Q40: -497 | R40: -690 | S40: -30 | T40: 0 | U40: -1059 | V40: 0
B41: WC | D41: =2384-1147-128-1884+1219-1292 -> -848 | H41: =286+231-771-1560+1344-1540 -> -2010 | L41: =80-366-386-1289-591-2104 -> -4656 | P41: =-781-1300+191+311+1105+6778-312 -> 5992 | Q41: =-1714-214+211+1367-1601+301-260 -> -1910 | R41: =-935-1481+696+91-782+885+2674 -> 1148 | S41: =883-687+405+348-181+1620+73 -> 2461 | T41: =-2674-2339+1190+515-1583-441-76 -> -5408 | U41: =5327-2436-29-1533-24-4535-1278 -> -4508 | V41: =731+2097-801-614-3531-451 -> -2569
B42: CFFO | D42: =SUM(D34:D41) -> 8133 | H42: =SUM(H34:H41) -> -1785 | L42: =SUM(L34:L41) -> -1223 | P42: =SUM(P34:P41) -> 22110 | Q42: =SUM(Q34:Q41) -> 29432 | R42: =SUM(R34:R41) -> 33145 | S42: =SUM(S34:S41) -> 35864 | T42: =SUM(T34:T41) -> 29456 | U42: =SUM(U34:U41) -> 15433 | V42: =SUM(V34:V41) -> 14752
B44: CapEx | D44: -4604 | H44: -7413 | L44: -5970 | P44: -11778 | Q44: -15181 | R44: -16213 | S44: -14259 | T44: -18733 | U44: -24844 | V44: -25750
B45: FCF | D45: =D42+D44 -> 3529 | H45: =H42+H44 -> -9198 | L45: =L42+L44 -> -7193 | P45: =P42+P44 -> 10332 | Q45: =Q42+Q44 -> 14251 | R45: =R42+R44 -> 16932 | S45: =S42+S44 -> 21605 | T45: =T42+T44 -> 10723 | U45: =U42+U44 -> -9411 | V45: =V42+V44 -> -10998
...

Sheet Stock Price

Sheet Old_DCF
B2: Intel DCF
A4: x | B4: Ticker | C4: INTC
B5: Date | C5: 45348
B7: Assumptions
B8: Valuation Assumptions
B9: WACC | D9: 0.0939
B10: TGR | D10: 0.03
L12: 1 | M12: =L12+1 -> 2 | N12: =M12+1 -> 3 | O12: =N12+1 -> 4 | P12: =O12+1 -> 5
B13: Income Statement | E13: 2017 | F13: =E13+1 -> 2018 | G13: =F13+1 -> 2019 | H13: =G13+1 -> 2020 | I13: =H13+1 -> 2021 | J13: =I13+1 -> 2022 | K13: =J13+1 -> 2023 | L13: =K13+1 -> 2024 | M13: =L13+1 -> 2025 | ... P13: =O13+1 -> 2028
B14: Revenue | E14: =Model!P15 -> 62761 | F14: =Model!Q15 -> 70848 | G14: =Model!R15 -> 71965 | H14: =Model!S15 -> 77867 | I14: =Model!T15 -> 79024 | J14: =Model!U15 -> 63054 | K14: =Model!V15 -> 54228
B15: % growth | F15: =F14/E14-1 -> 0.12885391 | G15: =G14/F14-1 -> 0.015766147 | H15: =H14/G14-1 -> 0.082012089 | I15: =I14/H14-1 -> 0.014858669 | J15: =J14/I14-1 -> -0.2020905 | K15: =K14/J14-1 -> -0.13997526
B17: EBIT | E17: =Model!P21 -> 18611 | F17: =Model!Q21 -> 23444 | G17: =Model!R21 -> 22628 | H17: =Model!S21 -> 23876 | I17: =Model!T21 -> 22082 | J17: =Model!U21 -> 2336 | K17: =Model!V21 -> 31
B18: % of sales | E18: =E17/E14 -> 0.29653766 | F18: =F17/F14 -> 0.3309056 | G18: =G17/G14 -> 0.31443063 | H18: =H17/H14 -> 0.3066254 | I18: =I17/I14 -> 0.2794341 | J18: =J17/J14 -> 0.03704761 | K18: =K17/K14 -> 0.0005716604
B20: Taxes | E20: =Model!P24 -> 10751 | F20: =Model!Q24 -> 2264 | G20: =Model!R24 -> 3010 | H20: =Model!S24 -> 4179 | I20: =Model!T24 -> 1835 | J20: =Model!U24 -> -249 | K20: =Model!V24 -> -913
B21: % of EBIT | E21: =E20/E17 -> 0.57766912 | F21: =F20/F17 -> 0.096570551 | G21: =G20/G17 -> 0.13302104 | H21: =H20/H17 -> 0.17502932 | I21: =I20/I17 -> 0.083099357 | J21: =J20/J17 -> -0.10659247
B23: Cash Flow Items | E23: 2017 | F23: =E23+1 -> 2018 | G23: =F23+1 -> 2019 | H23: =G23+1 -> 2020 | I23: =H23+1 -> 2021 | J23: =I23+1 -> 2022 | K23: =J23+1 -> 2023 | L23: =K23+1 -> 2024 | M23: =L23+1 -> 2025 | ... P23: =O23+1 -> 2028
B24: D&A | E24: =Model!P35+Model!P38 -> 8129 | F24: =Model!Q35+Model!Q38 -> 9085 | G24: =Model!R35+Model!R38 -> 10826 | H24: =Model!S35+Model!S38 -> 12239 | I24: =Model!T35+Model!T38 -> 11792 | J24: =Model!U35+Model!U38 -> 13035 | K24: =Model!V35+Model!V38 -> 12883
B25: % of sales | E25: =E24/E14 -> 0.12952311 | F25: =F24/F14 -> 0.12823227 | G25: =G24/G14 -> 0.15043424 | H25: =H24/H14 -> 0.15717827 | I25: =I24/I14 -> 0.14922049 | J25: =J24/J14 -> 0.20672757 | K25: =K24/K14 -> 0.237571
B27: CapEx | E27: =-Model!P44 -> 11778 | F27: =-Model!Q44 -> 15181 | G27: =-Model!R44 -> 16213 | H27: =-Model!S44 -> 14259 | I27: =-Model!T44 -> 18733 | J27: =-Model!U44 -> 24844 | K27: =-Model!V44 -> 25750
B28: % of sales | E28: =E27/E14 -> 0.18766431 | F28: =F27/F14 -> 0.21427563 | G28: =G27/G14 -> 0.22529007 | H28: =H27/H14 -> 0.18311994 | I28: =I27/I14 -> 0.23705457 | J28: =J27/J14 -> 0.39401148 | K28: =K27/K14 -> 0.47484694
B30: Change in NWC | E30: =Model!P41 -> 5992 | F30: =Model!Q41 -> -1910 | G30: =Model!R41 -> 1148 | H30: =Model!S41 -> 2461 | I30: =Model!T41 -> -5408 | J30: =Model!U41 -> -4508 | K30: =Model!V41 -> -2569
B31: % of sales | E31: =E30/E14 -> 0.095473303 | F31: =F30/F14 -> -0.026959124 | G31: =G30/G14 -> 0.015952199 | H31: =H30/H14 -> 0.031605173 | I31: =I30/I14 -> -0.068434906 | J31: =J30/J14 -> -0.071494275 | K31: =K30/K14 -> -0.04737405
B33: DCF | E33: 2017 | F33: =E33+1 -> 2018 | G33: =F33+1 -> 2019 | H33: =G33+1 -> 2020 | I33: =H33+1 -> 2021 | J33: =I33+1 -> 2022 | K33: =J33+1 -> 2023 | L33: =K33+1 -> 2024 | M33: =L33+1 -> 2025 | ... P33: =O33+1 -> 2028
B34: Revenue | E34: =E14 -> 62761 | F34: =F14 -> 70848 | G34: =G14 -> 71965 | H34: =H14 -> 77867 | I34: =I14 -> 79024 | J34: =J14 -> 63054 | K34: =K14 -> 54228 | L34: 57290 | M34: 63920 | N34: 69970 | O34: 72610 | P34: 85780
B35: % growth | F35: =F34/E34-1 -> 0.12885391 | G35: =G34/F34-1 -> 0.015766147 | H35: =H34/G34-1 -> 0.082012089 | I35: =I34/H34-1 -> 0.014858669 | J35: =J34/I34-1 -> -0.2020905 | K35: =K34/J34-1 -> -0.13997526 | L35: =L34/K34-1 -> 0.056465295 | M35: =M34/L34-1 -> 0.115727 | ... P35: =P34/O34-1 -> 0.18137998
B37: EBIT | E37: =E17 -> 18611 | F37: =F17 -> 23444 | G37: =G17 -> 22628 | H37: =H17 -> 23876 | I37: =I17 -> 22082 | J37: =J17 -> 2336 | K37: =K17 -> 31 | L37: 6550 | M37: 10740 | N37: 12490 | O37: 9740 | P37: 22010
B38: % margin | E38: =E37/E34 -> 0.29653766 | F38: =F37/F34 -> 0.3309056 | G38: =G37/G34 -> 0.31443063 | H38: =H37/H34 -> 0.3066254 | I38: =I37/I34 -> 0.2794341 | J38: =J37/J34 -> 0.03704761 | K38: =K37/K34 -> 0.0005716604 | L38: =L37/L34 -> 0.1143306 | ... P38: =P37/P34 -> 0.25658662
B40: Taxes | E40: =E20 -> 10751 | F40: =F20 -> 2264 | G40: =G20 -> 3010 | H40: =H20 -> 4179 | I40: =I20 -> 1835 | J40: =J20 -> -249 | K40: =K20 -> -913 | L40: =L41*L37 -> 499.27741 | M40: =M41*M37 -> 818.66251 | N40: =N41*N37 -> 952.05724 | O40: =O41*O37 -> 742.43695 | P40: =P41*P37 -> 1677.7246
B41: % of EBIT | E41: =E40/E37 -> 0.57766912 | F41: =F40/F37 -> 0.096570551 | G41: =G40/G37 -> 0.13302104 | H41: =H40/H37 -> 0.17502932 | I41: =I40/I37 -> 0.083099357 | J41: =J40/J37 -> -0.10659247 | K41: =K40/K37 -> -29.451613 | L41: =AVERAGE(F41:J41) -> 0.076225559 | M41: =L41 -> 0.076225559 | N41: =M41 -> 0.076225559 | O41: =N41 -> 0.076225559 | P41: =O41 -> 0.076225559
B43: EBIAT | K43: =K37-K40 -> 944 | L43: =L37-L40 -> 6050.7226 | M43: =M37-M40 -> 9921.3375 | N43: =N37-N40 -> 11537.943 | O43: =O37-O40 -> 8997.5631 | P43: =P37-P40 -> 20332.275
B45: D&A | L45: =L46*L34 -> 21119.252 | M45: =M46*M34 -> 23563.319 | N45: =N46*N34 -> 25793.577 | O45: =O46*O34 -> 26766.781 | P45: =P46*P34 -> 31621.739
B46: % of sales | L46: =AVERAGE(I28:K28) -> 0.36863766 | M46: =L46 -> 0.36863766 | N46: =M46 -> 0.36863766 | O46: =N46 -> 0.36863766 | P46: =O46 -> 0.36863766
B48: CapEx | L48: 22080 | M48: 22930 | N48: 23010 | O48: 19050 | P48: 19450
B49: % of sales | L49: =L48/L34 -> 0.38540758 | M49: =M48/M34 -> 0.35872966 | N49: =N48/N34 -> 0.32885522 | O49: =O48/O34 -> 0.26236056 | P49: =P48/P34 -> 0.22674283
B51: Change in NWC | L51: =L52*L34 -> -3576.8674 | M51: =M52*M34 -> -3990.8075 | N51: =N52*N34 -> -4368.5357 | O51: =O52*O34 -> -4533.3625 | P51: =P52*P34 -> -5355.6237
B52: % of sales | L52: =AVERAGE(I31:K31) -> -0.06243441 | M52: =L52 -> -0.06243441 | N52: =M52 -> -0.06243441 | O52: =N52 -> -0.06243441 | P52: =O52 -> -0.06243441
B54: Unlevered FCF | L54: =L43+L45-L48-L51 -> 8666.8417 | M54: =M43+M45-M48-M51 -> 14545.464 | N54: =N43+N45-N48-N51 -> 18690.056 | O54: =O43+O45-O48-O51 -> 21247.706 | P54: =P43+P45-P48-P51 -> 37859.638
B55: Present Value of FCF | L55: =L54/(1+WACC)^L12 -> 8038.9311 | M55: =M54/(1+WACC)^M12 -> 12514.182 | N55: =N54/(1+WACC)^N12 -> 14914.989 | O55: =O54/(1+WACC)^O12 -> 15727.577 | P55: =P54/(1+WACC)^P12 -> 25993.435
A57: x | B57: Terminal Value | P57: =P54/(WACC-TGR) -> #NAME?
B58: Present Value of Terminal Value | P58: =P57/(1+WACC)^P12 -> #NAME?
...

Sheet Old_Main
Q2: Price | R2: 38.33
B3: Revenue by Division | C3: FY 2023 | F3: Revenue by Region | J3: FY 2023 | Q3: Shares | R3: 4212 | S3: Q423
B4: Crocs Brand | C4: 3013 | D4: =C4/$C$7 -> 0.76047451 | F4: United States | I4: 2573663 | J4: =I4/$I$6 -> 0.64952994 | Q4: MC | R4: =R2*R3 -> 161445.96
B5: HEYDUDE Brand | C5: 949 | D5: =C5/$C$7 -> 0.23952549 | F5: Asia/Pacific | I5: 1388684 | J5: =I5/$I$6 -> 0.35047006 | Q5: Cash | R5: =7079+17955 -> 25034 | S5: Q423
F6: Total | I6: =SUM(I4:I5) -> 3962347 | J6: =SUM(J4:J5) -> 1 | Q6: Debt | R6: =2288+46978 -> 49266 | S6: Q423
B7: Total | C7: =SUM(C4:C6) -> 3962 | D7: =C7/$C$7 -> 1 | Q7: EV | R7: =R4-R5+R6 -> 185677.96
S14: Year | T14: =U14-1 -> 2017 | U14: =V14-1 -> 2018 | V14: =W14-1 -> 2019 | W14: 2020 | X14: =W14+1 -> 2021 | Y14: =X14+1 -> 2022 | Z14: =Y14+1 -> 2023
S15: Revenue | T15: 62.761 | U15: 70.848 | V15: 71.965 | W15: 77.867 | X15: 79.024 | Y15: 63.054 | Z15: 54.228
S16: % Growth | U16: =U15/T15-1 -> 0.12885391 | V16: =V15/U15-1 -> 0.015766147 | W16: =W15/V15-1 -> 0.082012089 | X16: =X15/W15-1 -> 0.014858669 | Y16: =Y15/X15-1 -> -0.2020905 | Z16: =Z15/Y15-1 -> -0.13997526
S19: Year | T19: =U19-1 -> 2017 | U19: =V19-1 -> 2018 | V19: =W19-1 -> 2019 | W19: 2020 | X19: =W19+1 -> 2021 | Y19: =X19+1 -> 2022 | Z19: =Y19+1 -> 2023
S20: Gross Margin | T20: =T21-T23 -> 39098 | U20: =U21-U23 -> 43737 | V20: =V21-V23 -> 42140 | W20: =W21-W23 -> 43612 | X20: =X21-X23 -> 43815 | Y20: =Y21-Y23 -> 26866 | Z20: =Z21-Z23 -> 21711
S21: Revenue | T21: 62761 | U21: 70848 | V21: 71965 | W21: 77867 | X21: 79024 | Y21: 63054 | Z21: 54228
T23: 23663 | U23: 27111 | V23: 29825 | W23: 34255 | X23: 35209 | Y23: 36188 | Z23: 32517
S25: Intel | T25: 0.626
S26: AMD | T26: 0.334
C43: Desktop | D43: Notebook | E43: Other Computing | F43: Data Center and AI | G43: Network and Edge | H43: Mobileye | I43: Intet Foundy Services | J43: All other
C44: 0.18746773 | D44: 0.31330678 | E44: 0.038762263 | F44: 0.28621745 | G44: 0.10647636 | H44: 0.038338128 | I44: 0.017555506 | J44: 0.011875784
C46: CCG | D46: DCAI | E46: NEX | F46: Mobileye
C47: =SUM(C44:E44) -> 0.53953677 | D47: =F44 -> 0.28621745 | E47: =G44 -> 0.10647636 | F47: =H44 -> 0.038338128

Sheet Old_Multiples
B2: Year | C2: Revenue | D2: EBITDA | E2: EBITDA GROWTH | F2: Debt ST + LT | G2: Excess Cash | H2: Market Cap | I2: Enterprise Value | J2: EV/ EBITDA | K2: Net Debt/ EBITDA | M2: Year | N2: EBITDA | O2: Growth | Q2: Future Potential
B4: 2017 | C4: 62761 | D4: 26563 | E4: =IFERROR(D4/D3-1,"-") -> - | F4: 26813 | G4: 1814 | H4: 216020 | I4: =F4-G4+H4 -> 241019 | J4: {=I4:I8/D4:D8} -> 9.0734857 | K4: {=F4:F8/D4:D8} -> 1.0094116 | M4: 2022 | N4: =D8*(1+O4) -> 35882.589 | O4: =C10 -> 0.059295893 | R4: Weight | S4: Price
B5: =B4+1 -> 2018 | C5: 70848 | D5: 32329 | E5: =IFERROR(D5/D4-1,"-") -> 0.21706886 | F5: 26359 | G5: 2788 | H5: 211930 | I5: =F5-G5+H5 -> 235501 | J5: 7.2845124 | K5: 0.81533608 | M5: =M4+1 -> 2023 | N5: =N4*(1+O5) -> 37797.51 | O5: =O4*0.9 -> 0.053366304 | Q5: EBITDA Multiple | R5: 0.5 | S5: =N16 -> 72.497218
B6: =B5+1 -> 2019 | C6: 71867 | D6: 33254 | E6: =IFERROR(D6/D5-1,"-") -> 0.028612082 | F6: 29055 | G6: 1082 | H6: 256750 | I6: =F6-G6+H6 -> 284723 | J6: 8.5620677 | K6: 0.87372948 | M6: =M5+1 -> 2024 | N6: =N5*(1+O6) -> 39612.912 | O6: =O5*0.9 -> 0.048029673 | Q6: FCFE Yield | R6: 0.5 | S6: =N28 -> 59.869611
B7: =B6+1 -> 2020 | C7: 77867 | D7: 36115 | E7: =IFERROR(D7/D6-1,"-") -> 0.086034763 | F7: 36529 | G7: 2292 | H7: 204160 | I7: =F7-G7+H7 -> 238397 | J7: 6.6010522 | K7: 1.0114634 | M7: =M6+1 -> 2025 | N7: =N6*(1+O7) -> 41325.248 | O7: =O6*0.9 -> 0.043226706 | Q7: Share Price 2026 | S7: =R5*S5+R6*S6 -> 66.183415
B8: =B7+1 -> 2021 | C8: 79024 | D8: 33874 | E8: =IFERROR(D8/D7-1,"-") -> -0.062051779 | F8: 38641 | G8: 2103 | H8: 209600 | I8: =F8-G8+H8 -> 246138 | J8: 7.2662809 | K8: 1.1407274 | M8: =M7+1 -> 2026 | N8: =N7*(1+O8) -> 42932.967 | O8: =O7*0.9 -> 0.038904035
Q9: Current Share Price | S9: 36.34
B10: CGAR or AVG | C10: =((C8/C4)^(1/($B$8-$B$4)))-1 -> 0.059295893 | D10: =((D8/D4)^(1/($B$8-$B$4)))-1 -> 0.062667357 | F10: =((F8/F4)^(1/($B$8-$B$4)))-1 -> 0.095659824 | G10: =((G8/G4)^(1/($B$8-$B$4)))-1 -> 0.037649061 | H10: =((H8/H4)^(1/($B$8-$B$4)))-1 -> -0.0075141375 | I10: =((I8/I4)^(1/($B$8-$B$4)))-1 -> 0.0052679737 | J10: =AVERAGE(_xlfn.ANCHORARRAY(J4)) -> 7.7574798 | K10: =AVERAGE(_xlfn.ANCHORARRAY(K4)) -> 0.97013358 | M10: EBITDA Mutiple | N10: =J10 -> 7.7574798 | Q10: Annual Return | S10: =(S7/S9)^(1/5)-1 -> 0.12738655
M11: EV | N11: =N8*N10 -> 333051.62
M12: Less Debt | N12: =F8 -> 38641
M13: Add Cash | N13: =G8 -> 2103
M14: Market Cap | N14: =N11-N12+N13 -> 296513.62
M15: Shares | N15: =G25 -> 4090
M16: 2026 Price | N16: =N14/N15 -> 72.497218
B19: Year | C19: CFO | D19: CAPEX | E19: Debit Issue PMT | F19: FCFE | G19: Shares | H19: FCFE/SHR | I19: Share Price | J19: FCFE Yield | M19: Year | N19: FCFE/SHR | O19: Growth
B21: =2017 -> 2017 | C21: 22110 | D21: -11778 | E21: -364 | F21: =SUM(C21:E21) -> 9968 | G21: 4835 | H21: =F21/G21 -> 2.0616339 | I21: {=I4:I8/G21:G25} -> 49.848811 | J21: =H21/I21 -> 0.041357735 | M21: 2022 | N21: =$H$25*(1+O21) -> 3.1431821 | O21: {=O4:O8} -> 0.059295893
B22: =B21+1 -> 2018 | C22: 29432 | D22: -15181 | E22: -2603 | F22: =SUM(C22:E22) -> 11648 | G22: 4701 | H22: =F22/G22 -> 2.4777707 | I22: 50.095937 | J22: =H22/I22 -> 0.049460512 | M22: =M21+1 -> 2023 | N22: =N21*(1+O22) -> 3.3109222 | O22: 0.053366304
B23: =B22+1 -> 2019 | C23: 33145 | D23: -16213 | E23: 765 | F23: =SUM(C23:E23) -> 17697 | G23: 4473 | H23: =F23/G23 -> 3.9564051 | I23: 63.6537 | J23: =H23/I23 -> 0.062155147 | M23: =M22+1 -> 2024 | N23: =N22*(1+O23) -> 3.4699447 | O23: 0.048029673
B24: =B23+1 -> 2020 | C24: 35384 | D24: -14453 | E24: 5722 | F24: =SUM(C24:E24) -> 26653 | G24: 4232 | H24: =F24/G24 -> 6.2979679 | I24: 56.331994 | J24: =H24/I24 -> 0.1118009 | M24: =M23+1 -> 2025 | N24: =N23*(1+O24) -> 3.6199389 | O24: 0.043226706
B25: =B24+1 -> 2021 | C25: 29991 | D25: -20329 | E25: 2474 | F25: =SUM(C25:E25) -> 12136 | G25: 4090 | H25: =F25/G25 -> 2.9672372 | I25: 60.18044 | J25: =H25/I25 -> 0.049305674 | M25: =M24+1 -> 2026 | N25: =N24*(1+O25) -> 3.7607692 | O25: 0.038904035
B27: CGAR or AVG | C27: =((C25/C21)^(1/($B$8-$B$4)))-1 -> 0.079196557 | D27: =((D25/D21)^(1/($B$8-$B$4)))-1 -> 0.14620188 | F27: =((F25/F21)^(1/($B$8-$B$4)))-1 -> 0.050429439 | G27: =((G25/G21)^(1/($B$8-$B$4)))-1 -> -0.040971072 | H27: =((H25/H21)^(1/($B$8-$B$4)))-1 -> 0.09530527 | I27: =((I25/I21)^(1/($B$8-$B$4)))-1 -> 0.048214443 | J27: =AVERAGE(J21:J25) -> 0.062815994 | M27: FCFE Yield | N27: =J27 -> 0.062815994
M28: 2026 Price | N28: =N25/N27 -> 59.869611
