Workbook

Sheet Candelaria Inputs
G1: Units | H1: Average / Total | I1: 2023 | J1: =I1+1 -> 2024 | K1: =J1+1 -> 2025 | L1: =K1+1 -> 2026 | M1: =L1+1 -> 2027 | N1: =M1+1 -> 2028 | O1: =N1+1 -> 2029 | P1: =O1+1 -> 2030 | Q1: =P1+1 -> 2031 | ... AF1: =AE1+1 -> 2046
D2: Production | G2: Units | H2: Average / Total
D3: Candelaria Open Pit to Candelaria Plant
D4: Candelaria Open Pit Waste Mined | E4: Base Case | I4: =INDEX(I5:I9,MATCH($E4,$D5:$D9,0)) -> 72094 | J4: =INDEX(J5:J9,MATCH($E4,$D5:$D9,0)) -> 67516 | K4: =INDEX(K5:K9,MATCH($E4,$D5:$D9,0)) -> 64748 | L4: =INDEX(L5:L9,MATCH($E4,$D5:$D9,0)) -> 52918 | M4: =INDEX(M5:M9,MATCH($E4,$D5:$D9,0)) -> 61881 | N4: =INDEX(N5:N9,MATCH($E4,$D5:$D9,0)) -> 75416 | O4: =INDEX(O5:O9,MATCH($E4,$D5:$D9,0)) -> 73631 | P4: =INDEX(P5:P9,MATCH($E4,$D5:$D9,0)) -> 66729 | ... AF4: =INDEX(AF5:AF9,MATCH($E4,$D5:$D9,0)) -> 0
D5: Base Case | G5: Kt | I5: 72094 | J5: 67516 | K5: 64748 | L5: 52918 | M5: 61881 | N5: 75416 | O5: 73631 | P5: 66729 | Q5: 54220 | R5: 37531 | S5: 30774 | T5: 21924 | U5: 16842 | V5: 13896 | W5: 11263 | X5: 10226 | Y5: 7752 | Z5: 8992 | AA5: 5230 | AB5: 0 | AC5: 0 | AD5: 0 | AE5: 0 | AF5: 0
D6: Base Case + 10% | E6: 0.1 | G6: Kt | I6: =I5*(1+$E6) -> 79303.4 | J6: =J5*(1+$E6) -> 74267.6 | K6: =K5*(1+$E6) -> 71222.8 | L6: =L5*(1+$E6) -> 58209.8 | M6: =M5*(1+$E6) -> 68069.1 | N6: =N5*(1+$E6) -> 82957.6 | O6: =O5*(1+$E6) -> 80994.1 | P6: =P5*(1+$E6) -> 73401.9 | ... AF6: =AF5*(1+$E6) -> 0
D7: Base Case - 10% | E7: -0.1 | G7: Kt | I7: =I6*(1+$E7) -> 71373.06 | J7: =J6*(1+$E7) -> 66840.84 | K7: =K6*(1+$E7) -> 64100.52 | L7: =L6*(1+$E7) -> 52388.82 | M7: =M6*(1+$E7) -> 61262.19 | N7: =N6*(1+$E7) -> 74661.84 | O7: =O6*(1+$E7) -> 72894.69 | P7: =P6*(1+$E7) -> 66061.71 | ... AF7: =AF6*(1+$E7) -> 0
D8: Free #1 | G8: Kt | I8: 0 | J8: 0 | K8: 0 | L8: 0 | M8: 0 | N8: 0 | O8: 0 | P8: 0 | Q8: 0 | R8: 0 | S8: 0 | T8: 0 | U8: 0 | V8: 0 | W8: 0 | X8: 0 | Y8: 0 | Z8: 0 | AA8: 0 | AB8: 0 | AC8: 0 | AD8: 0 | AE8: 0 | AF8: 0
D9: Free #2 | G9: Kt | I9: 0 | J9: 0 | K9: 0 | L9: 0 | M9: 0 | N9: 0 | O9: 0 | P9: 0 | Q9: 0 | R9: 0 | S9: 0 | T9: 0 | U9: 0 | V9: 0 | W9: 0 | X9: 0 | Y9: 0 | Z9: 0 | AA9: 0 | AB9: 0 | AC9: 0 | AD9: 0 | AE9: 0 | AF9: 0
D11: Candelaria Open Pit Ore to Mill | E11: Base Case | I11: =INDEX(I12:I16,MATCH($E11,$D12:$D16,0)) -> 13723 | J11: =INDEX(J12:J16,MATCH($E11,$D12:$D16,0)) -> 17280 | K11: =INDEX(K12:K16,MATCH($E11,$D12:$D16,0)) -> 19122 | L11: =INDEX(L12:L16,MATCH($E11,$D12:$D16,0)) -> 16053 | M11: =INDEX(M12:M16,MATCH($E11,$D12:$D16,0)) -> 15601 | N11: =INDEX(N12:N16,MATCH($E11,$D12:$D16,0)) -> 12155 | O11: =INDEX(O12:O16,MATCH($E11,$D12:$D16,0)) -> 6100 | P11: =INDEX(P12:P16,MATCH($E11,$D12:$D16,0)) -> 2725 | ... AF11: =INDEX(AF12:AF16,MATCH($E11,$D12:$D16,0)) -> 0
D12: Base Case | G12: Kt | I12: 13723 | J12: 17280 | K12: 19122 | L12: 16053 | M12: 15601 | N12: 12155 | O12: 6100 | P12: 2725 | Q12: 3343 | R12: 8965 | S12: 9686 | T12: 7530 | U12: 7571 | V12: 8568 | W12: 12517 | X12: 13499 | Y12: 16352 | Z12: 8973 | AA12: 4771 | AB12: 0 | AC12: 0 | AD12: 0 | AE12: 0 | AF12: 0
D13: Base Case + 10% | E13: 0.1 | G13: Kt | I13: =I12*(1+$E13) -> 15095.3 | J13: =J12*(1+$E13) -> 19008 | K13: =K12*(1+$E13) -> 21034.2 | L13: =L12*(1+$E13) -> 17658.3 | M13: =M12*(1+$E13) -> 17161.1 | N13: =N12*(1+$E13) -> 13370.5 | O13: =O12*(1+$E13) -> 6710 | P13: =P12*(1+$E13) -> 2997.5 | ... AF13: =AF12*(1+$E13) -> 0
D14: Base Case - 10% | E14: -0.1 | G14: Kt | I14: =I13*(1+$E14) -> 13585.77 | J14: =J13*(1+$E14) -> 17107.2 | K14: =K13*(1+$E14) -> 18930.78 | L14: =L13*(1+$E14) -> 15892.47 | M14: =M13*(1+$E14) -> 15444.99 | N14: =N13*(1+$E14) -> 12033.45 | O14: =O13*(1+$E14) -> 6039 | P14: =P13*(1+$E14) -> 2697.75 | ... AF14: =AF13*(1+$E14) -> 0
D15: Free #1 | G15: Kt | I15: 0 | J15: 0 | K15: 0 | L15: 0 | M15: 0 | N15: 0 | O15: 0 | P15: 0 | Q15: 0 | R15: 0 | S15: 0 | T15: 0 | U15: 0 | V15: 0 | W15: 0 | X15: 0 | Y15: 0 | Z15: 0 | AA15: 0 | AB15: 0 | AC15: 0 | AD15: 0 | AE15: 0 | AF15: 0
D16: Free #2 | G16: Kt | I16: 0 | J16: 0 | K16: 0 | L16: 0 | M16: 0 | N16: 0 | O16: 0 | P16: 0 | Q16: 0 | R16: 0 | S16: 0 | T16: 0 | U16: 0 | V16: 0 | W16: 0 | X16: 0 | Y16: 0 | Z16: 0 | AA16: 0 | AB16: 0 | AC16: 0 | AD16: 0 | AE16: 0 | AF16: 0
D18: Cu Grade | E18: Base Case | I18: =INDEX(I19:I23,MATCH($E18,$D19:$D23,0)) -> 0.0057 | J18: =INDEX(J19:J23,MATCH($E18,$D19:$D23,0)) -> 0.0064 | K18: =INDEX(K19:K23,MATCH($E18,$D19:$D23,0)) -> 0.0051 | L18: =INDEX(L19:L23,MATCH($E18,$D19:$D23,0)) -> 0.0058 | M18: =INDEX(M19:M23,MATCH($E18,$D19:$D23,0)) -> 0.0058 | N18: =INDEX(N19:N23,MATCH($E18,$D19:$D23,0)) -> 0.0059 | O18: =INDEX(O19:O23,MATCH($E18,$D19:$D23,0)) -> 0.0054 | P18: =INDEX(P19:P23,MATCH($E18,$D19:$D23,0)) -> 0.0046 | ... AF18: =INDEX(AF19:AF23,MATCH($E18,$D19:$D23,0)) -> 0
D19: Base Case | G19: Cu (%) | I19: 0.0057 | J19: 0.0064 | K19: 0.0051 | L19: 0.0058 | M19: 0.0058 | N19: 0.0059 | O19: 0.0054 | P19: 0.0046 | Q19: 0.0091 | R19: 0.0084 | S19: 0.0059 | T19: 0.0049 | U19: 0.005 | V19: 0.0057 | W19: 0.0069 | X19: 0.0076 | Y19: 0.0065 | Z19: 0.0054 | AA19: 0.0055 | AB19: 0 | AC19: 0 | AD19: 0 | AE19: 0 | AF19: 0
D20: Base Case + 10% | E20: 0.1 | G20: Cu (%) | I20: =I19*(1+$E20) -> 0.00627 | J20: =J19*(1+$E20) -> 0.00704 | K20: =K19*(1+$E20) -> 0.00561 | L20: =L19*(1+$E20) -> 0.00638 | M20: =M19*(1+$E20) -> 0.00638 | N20: =N19*(1+$E20) -> 0.00649 | O20: =O19*(1+$E20) -> 0.00594 | P20: =P19*(1+$E20) -> 0.00506 | ... AF20: =AF19*(1+$E20) -> 0
D21: Base Case - 10% | E21: -0.1 | G21: Cu (%) | I21: =I20*(1+$E21) -> 0.005643 | J21: =J20*(1+$E21) -> 0.006336 | K21: =K20*(1+$E21) -> 0.005049 | L21: =L20*(1+$E21) -> 0.005742 | M21: =M20*(1+$E21) -> 0.005742 | N21: =N20*(1+$E21) -> 0.005841 | O21: =O20*(1+$E21) -> 0.005346 | P21: =P20*(1+$E21) -> 0.004554 | ... AF21: =AF20*(1+$E21) -> 0
D22: Free #1 | G22: Cu (%) | I22: 0 | J22: 0 | K22: 0 | L22: 0 | M22: 0 | N22: 0 | O22: 0 | P22: 0 | Q22: 0 | R22: 0 | S22: 0 | T22: 0 | U22: 0 | V22: 0 | W22: 0 | X22: 0 | Y22: 0 | Z22: 0 | AA22: 0 | AB22: 0 | AC22: 0 | AD22: 0 | AE22: 0 | AF22: 0
D23: Free #2 | G23: Cu (%) | I23: 0 | J23: 0 | K23: 0 | L23: 0 | M23: 0 | N23: 0 | O23: 0 | P23: 0 | Q23: 0 | R23: 0 | S23: 0 | T23: 0 | U23: 0 | V23: 0 | W23: 0 | X23: 0 | Y23: 0 | Z23: 0 | AA23: 0 | AB23: 0 | AC23: 0 | AD23: 0 | AE23: 0 | AF23: 0
D25: Au Grade | E25: Base Case | I25: =INDEX(I26:I30,MATCH($E25,$D26:$D30,0)) -> 0.13 | J25: =INDEX(J26:J30,MATCH($E25,$D26:$D30,0)) -> 0.16 | K25: =INDEX(K26:K30,MATCH($E25,$D26:$D30,0)) -> 0.12 | L25: =INDEX(L26:L30,MATCH($E25,$D26:$D30,0)) -> 0.13 | M25: =INDEX(M26:M30,MATCH($E25,$D26:$D30,0)) -> 0.13 | N25: =INDEX(N26:N30,MATCH($E25,$D26:$D30,0)) -> 0.13 | O25: =INDEX(O26:O30,MATCH($E25,$D26:$D30,0)) -> 0.12 | P25: =INDEX(P26:P30,MATCH($E25,$D26:$D30,0)) -> 0.11 | ... AF25: =INDEX(AF26:AF30,MATCH($E25,$D26:$D30,0)) -> 0
D26: Base Case | G26: Au (g/t) | I26: 0.13 | J26: 0.16 | K26: 0.12 | L26: 0.13 | M26: 0.13 | N26: 0.13 | O26: 0.12 | P26: 0.11 | Q26: 0.2 | R26: 0.19 | S26: 0.15 | T26: 0.13 | U26: 0.12 | V26: 0.13 | W26: 0.15 | X26: 0.17 | Y26: 0.14 | Z26: 0.12 | AA26: 0.13 | AB26: 0 | AC26: 0 | AD26: 0 | AE26: 0 | AF26: 0
D27: Base Case + 10% | E27: 0.1 | G27: Au (g/t) | I27: =I26*(1+$E27) -> 0.143 | J27: =J26*(1+$E27) -> 0.176 | K27: =K26*(1+$E27) -> 0.132 | L27: =L26*(1+$E27) -> 0.143 | M27: =M26*(1+$E27) -> 0.143 | N27: =N26*(1+$E27) -> 0.143 | O27: =O26*(1+$E27) -> 0.132 | P27: =P26*(1+$E27) -> 0.121 | ... AF27: =AF26*(1+$E27) -> 0
D28: Base Case - 10% | E28: -0.1 | G28: Au (g/t) | I28: =I27*(1+$E28) -> 0.1287 | J28: =J27*(1+$E28) -> 0.1584 | K28: =K27*(1+$E28) -> 0.1188 | L28: =L27*(1+$E28) -> 0.1287 | M28: =M27*(1+$E28) -> 0.1287 | N28: =N27*(1+$E28) -> 0.1287 | O28: =O27*(1+$E28) -> 0.1188 | P28: =P27*(1+$E28) -> 0.1089 | ... AF28: =AF27*(1+$E28) -> 0
D29: Free #1 | G29: Au (g/t) | I29: 0 | J29: 0 | K29: 0 | L29: 0 | M29: 0 | N29: 0 | O29: 0 | P29: 0 | Q29: 0 | R29: 0 | S29: 0 | T29: 0 | U29: 0 | V29: 0 | W29: 0 | X29: 0 | Y29: 0 | Z29: 0 | AA29: 0 | AB29: 0 | AC29: 0 | AD29: 0 | AE29: 0 | AF29: 0
D30: Free #2 | G30: Au (g/t) | I30: 0 | J30: 0 | K30: 0 | L30: 0 | M30: 0 | N30: 0 | O30: 0 | P30: 0 | Q30: 0 | R30: 0 | S30: 0 | T30: 0 | U30: 0 | V30: 0 | W30: 0 | X30: 0 | Y30: 0 | Z30: 0 | AA30: 0 | AB30: 0 | AC30: 0 | AD30: 0 | AE30: 0 | AF30: 0
D32: Ag Grade | E32: Base Case | I32: =INDEX(I33:I37,MATCH($E32,$D33:$D37,0)) -> 1.46 | J32: =INDEX(J33:J37,MATCH($E32,$D33:$D37,0)) -> 2.74 | K32: =INDEX(K33:K37,MATCH($E32,$D33:$D37,0)) -> 2.03 | L32: =INDEX(L33:L37,MATCH($E32,$D33:$D37,0)) -> 1.8 | M32: =INDEX(M33:M37,MATCH($E32,$D33:$D37,0)) -> 1.71 | N32: =INDEX(N33:N37,MATCH($E32,$D33:$D37,0)) -> 1.94 | O32: =INDEX(O33:O37,MATCH($E32,$D33:$D37,0)) -> 1.49 | P32: =INDEX(P33:P37,MATCH($E32,$D33:$D37,0)) -> 1.26 | ... AF32: =INDEX(AF33:AF37,MATCH($E32,$D33:$D37,0)) -> 0
D33: Base Case | G33: Ag (g/t) | I33: 1.46 | J33: 2.74 | K33: 2.03 | L33: 1.8 | M33: 1.71 | N33: 1.94 | O33: 1.49 | P33: 1.26 | Q33: 2.73 | R33: 2.29 | S33: 1.55 | T33: 1.19 | U33: 1.14 | V33: 1.22 | W33: 1.7 | X33: 2.4 | Y33: 2.224 | Z33: 1.53 | AA33: 1.27 | AB33: 0 | AC33: 0 | AD33: 0 | AE33: 0 | AF33: 0
D34: Base Case + 10% | E34: 0.1 | G34: Ag (g/t) | I34: =I33*(1+$E34) -> 1.606 | J34: =J33*(1+$E34) -> 3.014 | K34: =K33*(1+$E34) -> 2.233 | L34: =L33*(1+$E34) -> 1.98 | M34: =M33*(1+$E34) -> 1.881 | N34: =N33*(1+$E34) -> 2.134 | O34: =O33*(1+$E34) -> 1.639 | P34: =P33*(1+$E34) -> 1.386 | ... AF34: =AF33*(1+$E34) -> 0
D35: Base Case - 10% | E35: -0.1 | G35: Ag (g/t) | I35: =I34*(1+$E35) -> 1.4454 | J35: =J34*(1+$E35) -> 2.7126 | K35: =K34*(1+$E35) -> 2.0097 | L35: =L34*(1+$E35) -> 1.782 | M35: =M34*(1+$E35) -> 1.6929 | N35: =N34*(1+$E35) -> 1.9206 | O35: =O34*(1+$E35) -> 1.4751 | P35: =P34*(1+$E35) -> 1.2474 | ... AF35: =AF34*(1+$E35) -> 0
D36: Free #1 | G36: Ag (g/t) | I36: 0 | J36: 0 | K36: 0 | L36: 0 | M36: 0 | N36: 0 | O36: 0 | P36: 0 | Q36: 0 | R36: 0 | S36: 0 | T36: 0 | U36: 0 | V36: 0 | W36: 0 | X36: 0 | Y36: 0 | Z36: 0 | AA36: 0 | AB36: 0 | AC36: 0 | AD36: 0 | AE36: 0 | AF36: 0
D37: Free #2 | G37: Ag (g/t) | I37: 0 | J37: 0 | K37: 0 | L37: 0 | M37: 0 | N37: 0 | O37: 0 | P37: 0 | Q37: 0 | R37: 0 | S37: 0 | T37: 0 | U37: 0 | V37: 0 | W37: 0 | X37: 0 | Y37: 0 | Z37: 0 | AA37: 0 | AB37: 0 | AC37: 0 | AD37: 0 | AE37: 0 | AF37: 0
D39: Espanola to Candelaria Plant
D40: Espanola Open Pit Waste Mined | E40: Base Case | I40: =INDEX(I41:I45,MATCH($E40,$D41:$D45,0)) -> 0 | J40: =INDEX(J41:J45,MATCH($E40,$D41:$D45,0)) -> 9655 | K40: =INDEX(K41:K45,MATCH($E40,$D41:$D45,0)) -> 17090 | L40: =INDEX(L41:L45,MATCH($E40,$D41:$D45,0)) -> 19267 | M40: =INDEX(M41:M45,MATCH($E40,$D41:$D45,0)) -> 17113 | N40: =INDEX(N41:N45,MATCH($E40,$D41:$D45,0)) -> 15524 | O40: =INDEX(O41:O45,MATCH($E40,$D41:$D45,0)) -> 13588 | P40: =INDEX(P41:P45,MATCH($E40,$D41:$D45,0)) -> 12084 | ... AF40: =INDEX(AF41:AF45,MATCH($E40,$D41:$D45,0)) -> 0
D41: Base Case | G41: Kt | I41: 0 | J41: 9655 | K41: 17090 | L41: 19267 | M41: 17113 | N41: 15524 | O41: 13588 | P41: 12084 | Q41: 10635 | R41: 9952 | S41: 6643 | T41: 3865 | U41: 1424 | V41: 2049 | W41: 0 | X41: 0 | Y41: 0 | Z41: 0 | AA41: 0 | AB41: 0 | AC41: 0 | AD41: 0 | AE41: 0 | AF41: 0
D42: Base Case + 10% | E42: 0.1 | G42: Kt | I42: =I41*(1+$E42) -> 0 | J42: =J41*(1+$E42) -> 10620.5 | K42: =K41*(1+$E42) -> 18799 | L42: =L41*(1+$E42) -> 21193.7 | M42: =M41*(1+$E42) -> 18824.3 | N42: =N41*(1+$E42) -> 17076.4 | O42: =O41*(1+$E42) -> 14946.8 | P42: =P41*(1+$E42) -> 13292.4 | ... AF42: =AF41*(1+$E42) -> 0
D43: Base Case - 10% | E43: -0.1 | G43: Kt | I43: =I42*(1+$E43) -> 0 | J43: =J42*(1+$E43) -> 9558.45 | K43: =K42*(1+$E43) -> 16919.1 | L43: =L42*(1+$E43) -> 19074.33 | M43: =M42*(1+$E43) -> 16941.87 | N43: =N42*(1+$E43) -> 15368.76 | O43: =O42*(1+$E43) -> 13452.12 | P43: =P42*(1+$E43) -> 11963.16 | ... AF43: =AF42*(1+$E43) -> 0
D44: Free #1 | G44: Kt | I44: 0 | J44: 0 | K44: 0 | L44: 0 | M44: 0 | N44: 0 | O44: 0 | P44: 0 | Q44: 0 | R44: 0 | S44: 0 | T44: 0 | U44: 0 | V44: 0 | W44: 0 | X44: 0 | Y44: 0 | Z44: 0 | AA44: 0 | AB44: 0 | AC44: 0 | AD44: 0 | AE44: 0 | AF44: 0
D45: Free #2 | G45: Kt | I45: 0 | J45: 0 | K45: 0 | L45: 0 | M45: 0 | N45: 0 | O45: 0 | P45: 0 | Q45: 0 | R45: 0 | S45: 0 | T45: 0 | U45: 0 | V45: 0 | W45: 0 | X45: 0 | Y45: 0 | Z45: 0 | AA45: 0 | AB45: 0 | AC45: 0 | AD45: 0 | AE45: 0 | AF45: 0
...

Sheet Candelaria Opmod V2Cleaned
I1: 2023 | J1: =I1+1 -> 2024 | K1: =J1+1 -> 2025 | L1: =K1+1 -> 2026 | M1: =L1+1 -> 2027 | N1: =M1+1 -> 2028 | O1: =N1+1 -> 2029 | P1: =O1+1 -> 2030 | Q1: =P1+1 -> 2031 | ... AF1: =AE1+1 -> 2046
D2: Price Deck | G2: Units | H2: Average/Total
D3: Price Deck
D5: Live Price Deck
D6: Cu | I6: 3.82 | J6: 3.78 | K6: 3.63 | L6: 3.97 | M6: 3.97 | N6: 3.97 | O6: 3.97 | P6: 3.97 | Q6: 3.97 | R6: 3.97 | S6: 3.97 | T6: 3.97 | U6: 3.97 | V6: 3.97 | W6: 3.97 | X6: 3.97 | Y6: 3.97 | Z6: 3.97 | AA6: 3.97 | AB6: 3.97 | AC6: 3.97 | AD6: 3.97 | AE6: 3.97 | AF6: 3.97
D7: Au | I7: 1991 | J7: 1950 | K7: 1875 | L7: 1850 | M7: 1850 | N7: 1850 | O7: 1850 | P7: 1850 | Q7: 1850 | R7: 1850 | S7: 1850 | T7: 1850 | U7: 1850 | V7: 1850 | W7: 1850 | X7: 1850 | Y7: 1850 | Z7: 1850 | AA7: 1850 | AB7: 1850 | AC7: 1850 | AD7: 1850 | AE7: 1850 | AF7: 1850
D8: Ag | I8: 23.39 | J8: 22.7 | K8: 22.75 | L8: 22.25 | M8: 22.25 | N8: 22.25 | O8: 22.25 | P8: 22.25 | Q8: 22.25 | R8: 22.25 | S8: 22.25 | T8: 22.25 | U8: 22.25 | V8: 22.25 | W8: 22.25 | X8: 22.25 | Y8: 22.25 | Z8: 22.25 | AA8: 22.25 | AB8: 22.25 | AC8: 22.25 | AD8: 22.25 | AE8: 22.25 | AF8: 22.25
D10: Production | G10: Units | H10: Average/Total
D12: Mine Plan
D14: Candelaria Open Pit Ore to Mill
D15: Candelaria Open Pit Waste Mined | G15: Kt | H15: =SUM(I15:AF15) -> 753583 | I15: ='Candelaria Inputs'!I4 -> 72094 | J15: ='Candelaria Inputs'!J4 -> 67516 | K15: ='Candelaria Inputs'!K4 -> 64748 | L15: ='Candelaria Inputs'!L4 -> 52918 | M15: ='Candelaria Inputs'!M4 -> 61881 | N15: ='Candelaria Inputs'!N4 -> 75416 | O15: ='Candelaria Inputs'!O4 -> 73631 | P15: ='Candelaria Inputs'!P4 -> 66729 | ... AF15: ='Candelaria Inputs'!AF4 -> 0
D16: Ore to Candelaria Plant | G16: Kt | H16: =SUM(I16:AF16) -> 204534 | I16: ='Candelaria Inputs'!I11 -> 13723 | J16: ='Candelaria Inputs'!J11 -> 17280 | K16: ='Candelaria Inputs'!K11 -> 19122 | L16: ='Candelaria Inputs'!L11 -> 16053 | M16: ='Candelaria Inputs'!M11 -> 15601 | N16: ='Candelaria Inputs'!N11 -> 12155 | O16: ='Candelaria Inputs'!O11 -> 6100 | P16: ='Candelaria Inputs'!P11 -> 2725 | ... AF16: ='Candelaria Inputs'!AF11 -> 0
D17: Cu | G17: % | H17: =IF(SUM(I16:AF16)<>0,SUMPRODUCT(I16:AF16,I17:AF17)/SUM(I16:AF16),0) -> 0.0060797946 | I17: ='Candelaria Inputs'!I18 -> 0.0057 | J17: ='Candelaria Inputs'!J18 -> 0.0064 | K17: ='Candelaria Inputs'!K18 -> 0.0051 | L17: ='Candelaria Inputs'!L18 -> 0.0058 | M17: ='Candelaria Inputs'!M18 -> 0.0058 | N17: ='Candelaria Inputs'!N18 -> 0.0059 | O17: ='Candelaria Inputs'!O18 -> 0.0054 | P17: ='Candelaria Inputs'!P18 -> 0.0046 | ... AF17: ='Candelaria Inputs'!AF18 -> 0
D18: Au | G18: g/t | H18: =IF(SUM(I17:AF17)<>0,SUMPRODUCT(I17:AF17,I18:AF18)/SUM(I17:AF17),0) -> 0.14433391 | I18: ='Candelaria Inputs'!I25 -> 0.13 | J18: ='Candelaria Inputs'!J25 -> 0.16 | K18: ='Candelaria Inputs'!K25 -> 0.12 | L18: ='Candelaria Inputs'!L25 -> 0.13 | M18: ='Candelaria Inputs'!M25 -> 0.13 | N18: ='Candelaria Inputs'!N25 -> 0.13 | O18: ='Candelaria Inputs'!O25 -> 0.12 | P18: ='Candelaria Inputs'!P25 -> 0.11 | ... AF18: ='Candelaria Inputs'!AF25 -> 0
D19: Ag | G19: g/t | H19: =IF(SUM(I18:AF18)<>0,SUMPRODUCT(I18:AF18,I19:AF19)/SUM(I18:AF18),0) -> 1.8362632 | I19: ='Candelaria Inputs'!I32 -> 1.46 | J19: ='Candelaria Inputs'!J32 -> 2.74 | K19: ='Candelaria Inputs'!K32 -> 2.03 | L19: ='Candelaria Inputs'!L32 -> 1.8 | M19: ='Candelaria Inputs'!M32 -> 1.71 | N19: ='Candelaria Inputs'!N32 -> 1.94 | O19: ='Candelaria Inputs'!O32 -> 1.49 | P19: ='Candelaria Inputs'!P32 -> 1.26 | ... AF19: ='Candelaria Inputs'!AF32 -> 0
D21: Espanola Ore to Mill
D22: Espanola Open Pit Waste Mined | G22: Kt | H22: =SUM(I22:AF22) -> 138889 | I22: ='Candelaria Inputs'!I40 -> 0 | J22: ='Candelaria Inputs'!J40 -> 9655 | K22: ='Candelaria Inputs'!K40 -> 17090 | L22: ='Candelaria Inputs'!L40 -> 19267 | M22: ='Candelaria Inputs'!M40 -> 17113 | N22: ='Candelaria Inputs'!N40 -> 15524 | O22: ='Candelaria Inputs'!O40 -> 13588 | P22: ='Candelaria Inputs'!P40 -> 12084 | ... AF22: ='Candelaria Inputs'!AF40 -> 0
D23: Ore to Candelaria Plant | G23: Kt | H23: =SUM(I23:AF23) -> 48709 | I23: ='Candelaria Inputs'!I47 -> 0 | J23: ='Candelaria Inputs'!J47 -> 0 | K23: ='Candelaria Inputs'!K47 -> 0 | L23: ='Candelaria Inputs'!L47 -> 2395 | M23: ='Candelaria Inputs'!M47 -> 3965 | N23: ='Candelaria Inputs'!N47 -> 424 | O23: ='Candelaria Inputs'!O47 -> 6162 | P23: ='Candelaria Inputs'!P47 -> 7707 | ... AF23: ='Candelaria Inputs'!AF47 -> 0
D24: Cu | G24: % | H24: =IF(SUM(I23:AF23)<>0,SUMPRODUCT(I23:AF23,I24:AF24)/SUM(I23:AF23),0) -> 0.0042528814 | I24: ='Candelaria Inputs'!I54 -> 0 | J24: ='Candelaria Inputs'!J54 -> 0 | K24: ='Candelaria Inputs'!K54 -> 0 | L24: ='Candelaria Inputs'!L54 -> 0.0042 | M24: ='Candelaria Inputs'!M54 -> 0.004 | N24: ='Candelaria Inputs'!N54 -> 0.0043 | O24: ='Candelaria Inputs'!O54 -> 0.0042 | P24: ='Candelaria Inputs'!P54 -> 0.0044 | ... AF24: ='Candelaria Inputs'!AF54 -> 0
D25: Au | G25: g/t | H25: =IF(SUM(I24:AF24)<>0,SUMPRODUCT(I24:AF24,I25:AF25)/SUM(I24:AF24),0) -> 0.089137931 | I25: ='Candelaria Inputs'!I61 -> 0 | J25: ='Candelaria Inputs'!J61 -> 0 | K25: ='Candelaria Inputs'!K61 -> 0 | L25: ='Candelaria Inputs'!L61 -> 0.09 | M25: ='Candelaria Inputs'!M61 -> 0.08 | N25: ='Candelaria Inputs'!N61 -> 0.09 | O25: ='Candelaria Inputs'!O61 -> 0.09 | P25: ='Candelaria Inputs'!P61 -> 0.09 | ... AF25: ='Candelaria Inputs'!AF61 -> 0
D26: Ag | G26: g/t | H26: =IF(SUM(I25:AF25)<>0,SUMPRODUCT(I25:AF25,I26:AF26)/SUM(I25:AF25),0) -> 0.37397959 | I26: ='Candelaria Inputs'!I68 -> 0 | J26: ='Candelaria Inputs'!J68 -> 0 | K26: ='Candelaria Inputs'!K68 -> 0 | L26: ='Candelaria Inputs'!L68 -> 0.35 | M26: ='Candelaria Inputs'!M68 -> 0.37 | N26: ='Candelaria Inputs'!N68 -> 0.36 | O26: ='Candelaria Inputs'!O68 -> 0.33 | P26: ='Candelaria Inputs'!P68 -> 0.36 | ... AF26: ='Candelaria Inputs'!AF68 -> 0
D28: Candelaria Open Pit + Espanola to WIP
D29: Ore to Candelaria Plant | G29: Kt | H29: =SUM(I29:AF29) -> 174326 | I29: ='Candelaria Inputs'!I76 -> 4610 | J29: ='Candelaria Inputs'!J76 -> 12464 | K29: ='Candelaria Inputs'!K76 -> 13998 | L29: ='Candelaria Inputs'!L76 -> 19387 | M29: ='Candelaria Inputs'!M76 -> 13281 | N29: ='Candelaria Inputs'!N76 -> 13553 | O29: ='Candelaria Inputs'!O76 -> 10012 | P29: ='Candelaria Inputs'!P76 -> 7480 | ... AF29: ='Candelaria Inputs'!AF76 -> 0
D30: Cu | G30: % | H30: =IF(SUM(I29:AF29)<>0,SUMPRODUCT(I29:AF29,I30:AF30)/SUM(I29:AF29),0) -> 0.0023123585 | I30: ='Candelaria Inputs'!I83 -> 0.002 | J30: ='Candelaria Inputs'!J83 -> 0.0022 | K30: ='Candelaria Inputs'!K83 -> 0.0023 | L30: ='Candelaria Inputs'!L83 -> 0.0024 | M30: ='Candelaria Inputs'!M83 -> 0.0025 | N30: ='Candelaria Inputs'!N83 -> 0.0029 | O30: ='Candelaria Inputs'!O83 -> 0.0024 | P30: ='Candelaria Inputs'!P83 -> 0.0023 | ... AF30: ='Candelaria Inputs'!AF83 -> 0
D31: Au | G31: g/t | H31: =IF(SUM(I29:AF29)<>0,SUMPRODUCT(I29:AF29,I31:AF31)/SUM(I29:AF29),0) -> 0.062689616 | I31: ='Candelaria Inputs'!I90 -> 0.06 | J31: ='Candelaria Inputs'!J90 -> 0.07 | K31: ='Candelaria Inputs'!K90 -> 0.06 | L31: ='Candelaria Inputs'!L90 -> 0.07 | M31: ='Candelaria Inputs'!M90 -> 0.07 | N31: ='Candelaria Inputs'!N90 -> 0.07 | O31: ='Candelaria Inputs'!O90 -> 0.06 | P31: ='Candelaria Inputs'!P90 -> 0.06 | ... AF31: ='Candelaria Inputs'!AF90 -> 0
D32: Ag | G32: g/t | H32: =IF(SUM(I29:AF29)<>0,SUMPRODUCT(I29:AF29,I32:AF32)/SUM(I29:AF29),0) -> 0.88632092 | I32: ='Candelaria Inputs'!I97 -> 0.95 | J32: ='Candelaria Inputs'!J97 -> 1.26 | K32: ='Candelaria Inputs'!K97 -> 1.07 | L32: ='Candelaria Inputs'!L97 -> 1.25 | M32: ='Candelaria Inputs'!M97 -> 0.98 | N32: ='Candelaria Inputs'!N97 -> 0.75 | O32: ='Candelaria Inputs'!O97 -> 0.83 | P32: ='Candelaria Inputs'!P97 -> 0.67 | ... AF32: ='Candelaria Inputs'!AF97 -> 0
D34: WIP Rehandle Ore to Mill
D35: Ore to Candelaria Plant | G35: Kt | H35: =SUM(I35:AF35) -> 252669 | I35: ='Candelaria Inputs'!I105 -> 7133 | J35: ='Candelaria Inputs'!J105 -> 3106 | K35: ='Candelaria Inputs'!K105 -> 2395 | L35: ='Candelaria Inputs'!L105 -> 3673 | M35: ='Candelaria Inputs'!M105 -> 2612 | N35: ='Candelaria Inputs'!N105 -> 9639 | O35: ='Candelaria Inputs'!O105 -> 9784 | P35: ='Candelaria Inputs'!P105 -> 11540 | ... AF35: ='Candelaria Inputs'!AF105 -> 3235
D36: Cu | G36: % | H36: =IF(SUM(I35:AF35)<>0,SUMPRODUCT(I35:AF35,I36:AF36)/SUM(I35:AF35),0) -> 0.002478048 | I36: ='Candelaria Inputs'!I112 -> 0.0028 | J36: ='Candelaria Inputs'!J112 -> 0.0023 | K36: ='Candelaria Inputs'!K112 -> 0.0024 | L36: ='Candelaria Inputs'!L112 -> 0.0026 | M36: ='Candelaria Inputs'!M112 -> 0.0024 | N36: ='Candelaria Inputs'!N112 -> 0.0025 | O36: ='Candelaria Inputs'!O112 -> 0.0031 | P36: ='Candelaria Inputs'!P112 -> 0.0027 | ... AF36: ='Candelaria Inputs'!AF112 -> 0.0017
D37: Au | G37: g/t | H37: =IF(SUM(I35:AF35)<>0,SUMPRODUCT(I35:AF35,I37:AF37)/SUM(I35:AF35),0) -> 0.071079119 | I37: ='Candelaria Inputs'!I119 -> 0.08 | J37: ='Candelaria Inputs'!J119 -> 0.07 | K37: ='Candelaria Inputs'!K119 -> 0.07 | L37: ='Candelaria Inputs'!L119 -> 0.07 | M37: ='Candelaria Inputs'!M119 -> 0.07 | N37: ='Candelaria Inputs'!N119 -> 0.07 | O37: ='Candelaria Inputs'!O119 -> 0.08 | P37: ='Candelaria Inputs'!P119 -> 0.08 | ... AF37: ='Candelaria Inputs'!AF119 -> 0.05
D38: Ag | G38: g/t | H38: =IF(SUM(I35:AF35)<>0,SUMPRODUCT(I35:AF35,I38:AF38)/SUM(I35:AF35),0) -> 1.0685556 | I38: ='Candelaria Inputs'!I126 -> 1.2 | J38: ='Candelaria Inputs'!J126 -> 1.06 | K38: ='Candelaria Inputs'!K126 -> 1.06 | L38: ='Candelaria Inputs'!L126 -> 0.94 | M38: ='Candelaria Inputs'!M126 -> 1.1 | N38: ='Candelaria Inputs'!N126 -> 1.14 | O38: ='Candelaria Inputs'!O126 -> 0.71 | P38: ='Candelaria Inputs'!P126 -> 1.19 | ... AF38: ='Candelaria Inputs'!AF126 -> 0.93
D40: Candelaria Underground Ore to Mill
D41: Ore to Candelaria Plant | G41: Kt | H41: =SUM(I41:AF41) -> 131507 | I41: ='Candelaria Inputs'!I134 -> 5462 | J41: ='Candelaria Inputs'!J134 -> 5490 | K41: ='Candelaria Inputs'!K134 -> 5475 | L41: ='Candelaria Inputs'!L134 -> 5475 | M41: ='Candelaria Inputs'!M134 -> 5505 | N41: ='Candelaria Inputs'!N134 -> 5490 | O41: ='Candelaria Inputs'!O134 -> 5475 | P41: ='Candelaria Inputs'!P134 -> 5475 | ... AF41: ='Candelaria Inputs'!AF134 -> 5475
D42: Cu | G42: % | H42: =IF(SUM(I41:AF41)<>0,SUMPRODUCT(I41:AF41,I42:AF42)/SUM(I41:AF41),0) -> 0.0078751922 | I42: ='Candelaria Inputs'!I141 -> 0.0087 | J42: ='Candelaria Inputs'!J141 -> 0.0091 | K42: ='Candelaria Inputs'!K141 -> 0.0093 | L42: ='Candelaria Inputs'!L141 -> 0.0081 | M42: ='Candelaria Inputs'!M141 -> 0.0082 | N42: ='Candelaria Inputs'!N141 -> 0.0081 | O42: ='Candelaria Inputs'!O141 -> 0.0095 | P42: ='Candelaria Inputs'!P141 -> 0.0086 | ... AF42: ='Candelaria Inputs'!AF141 -> 0.0063
D43: Au | G43: g/t | H43: =IF(SUM(I41:AF41)<>0,SUMPRODUCT(I41:AF41,I43:AF43)/SUM(I41:AF41),0) -> 0.17959538 | I43: ='Candelaria Inputs'!I148 -> 0.2 | J43: ='Candelaria Inputs'!J148 -> 0.2 | K43: ='Candelaria Inputs'!K148 -> 0.2 | L43: ='Candelaria Inputs'!L148 -> 0.19 | M43: ='Candelaria Inputs'!M148 -> 0.22 | N43: ='Candelaria Inputs'!N148 -> 0.19 | O43: ='Candelaria Inputs'!O148 -> 0.2 | P43: ='Candelaria Inputs'!P148 -> 0.19 | ... AF43: ='Candelaria Inputs'!AF148 -> 0.15
D44: Ag | G44: g/t | H44: =IF(SUM(I41:AF41)<>0,SUMPRODUCT(I41:AF41,I44:AF44)/SUM(I41:AF41),0) -> 3.2032639 | I44: ='Candelaria Inputs'!I155 -> 3.69 | J44: ='Candelaria Inputs'!J155 -> 3.34 | K44: ='Candelaria Inputs'!K155 -> 2.78 | L44: ='Candelaria Inputs'!L155 -> 3 | M44: ='Candelaria Inputs'!M155 -> 2.66 | N44: ='Candelaria Inputs'!N155 -> 2.86 | O44: ='Candelaria Inputs'!O155 -> 4.37 | P44: ='Candelaria Inputs'!P155 -> 3.68 | ... AF44: ='Candelaria Inputs'!AF155 -> 2.72
D46: Santos Ore to Candelaria Mill
D47: Ore to Candelaria Plant | G47: Kt | H47: =SUM(I47:AF47) -> 1534 | I47: ='Candelaria Inputs'!I163 -> 511 | J47: ='Candelaria Inputs'!J163 -> 512 | K47: ='Candelaria Inputs'!K163 -> 511 | L47: ='Candelaria Inputs'!L163 -> 0 | M47: ='Candelaria Inputs'!M163 -> 0 | N47: ='Candelaria Inputs'!N163 -> 0 | O47: ='Candelaria Inputs'!O163 -> 0 | P47: ='Candelaria Inputs'!P163 -> 0 | ... AF47: ='Candelaria Inputs'!AF163 -> 0
D48: Cu | G48: % | H48: =IF(SUM(I47:AF47)<>0,SUMPRODUCT(I47:AF47,I48:AF48)/SUM(I47:AF47),0) -> 0.0085331812 | I48: ='Candelaria Inputs'!I170 -> 0.0085 | J48: ='Candelaria Inputs'!J170 -> 0.0083 | K48: ='Candelaria Inputs'!K170 -> 0.0088 | L48: ='Candelaria Inputs'!L170 -> 0 | M48: ='Candelaria Inputs'!M170 -> 0 | N48: ='Candelaria Inputs'!N170 -> 0 | O48: ='Candelaria Inputs'!O170 -> 0 | P48: ='Candelaria Inputs'!P170 -> 0 | ... AF48: ='Candelaria Inputs'!AF170 -> 0
D49: Au | G49: g/t | H49: =IF(SUM(I47:AF47)<>0,SUMPRODUCT(I47:AF47,I49:AF49)/SUM(I47:AF47),0) -> 0.19 | I49: ='Candelaria Inputs'!I177 -> 0.18 | J49: ='Candelaria Inputs'!J177 -> 0.19 | K49: ='Candelaria Inputs'!K177 -> 0.2 | L49: ='Candelaria Inputs'!L177 -> 0 | M49: ='Candelaria Inputs'!M177 -> 0 | N49: ='Candelaria Inputs'!N177 -> 0 | O49: ='Candelaria Inputs'!O177 -> 0 | P49: ='Candelaria Inputs'!P177 -> 0 | ... AF49: ='Candelaria Inputs'!AF177 -> 0
...
