Workbook
Name Cash_to_sales_ratio: CCA!$AF$52
Name cs_fd_outstanding: 'Main Financials'!$N$83
Name MarginalTax: #REF!
Name MarginalTax: #REF!
Name TGR: Valuation!$D$10

Sheet __FDSCACHE__
B1: This sheet contains FactSet XML data for use with this workbook's =FDS codes. Modifying the worksheet's contents may damage the workbook's =FDS functionality.

Sheet Cover
C3: Price for Renault Group
C5: Rotterdam School of Management
C6: Msc. Finance & Investment
C8: Last Update: | D8: 45988
C10: Authors: Jordy Dikken (673670), Jorick Stoel (694007),
C11: Rikus van der Vegt (666665) & Theodor Hogan (754441)
C13: Note:
C15: #VALUE!
C21: Format: | E21: =D2*1.1+25*A2 -> 0
C22: Hardcode | D22: XXX
C23: Sheet Link | D23: XXX
C24: Ext. Link | D24: XXX | E24: Note: FactSet live links have been broken for compatability.
C25: Mixed Formula | D25: XXX | E25: =_xlfn.FORMULATEXT(E21) -> =D2*1.1+25*A2
C26: Assumptions | D26: XXX
C28: Font | D28: Arial
C29: Default | D29: 10 pt
C31: Input Field | D31: [Input]

Sheet Assignment Manager
B2: Basics
B4: Company | E4: Renault SA
B5: $/Share Estimate Deadline | E5: 45962
B6: Final Document Deadline | E6: 45989
B7: OUR DEADLINE | E7: 45983
B9: Grading Rubric
B11: Team Members | E11: ID | G11: Abbreviation
B12: Jordy Dikken | E12: 673670 | G12: JD
B13: Jorick Stoel | E13: 694007 | G13: JS
B14: Rikus van der Vegt | E14: 666665 | G14: RV
B15: Theodor Hogan | E15: 754441 | G15: TH
B17: Grading Rubric
B19: Evaluation Criterion | H19: Weight
B20: Reorganizing balancsheet and income statement | H20: 0.1 | I20: TH
B21: Adjustments to income statement and balancesheet; calculating key ratios | H21: 0.1 | I21: JD
B22: Projections of future cash cashflows and continuing (i.e. stable) growth rate | H22: 0.2 | I22: TH, RV
B23: Estimating the cost of debt, cost of equity, cost of capital | H23: 0.2 | I23: JD, JS
B24: Implemeting WACC; appropriate post DCF value adj. to estime $/shr | H24: 0.15 | I24: TH, RV
B25: Sensititivity analysis | H25: 0.05 | I25: RV
B26: Correctly identifiying peers and implementing multiples valuation | H26: 0.15 | I26: JD, JS
B27: General presentation and readability of Excel file | H27: 0.05 | I27: JD, JS, RV, TH
B28: Total | H28: =SUM(H20:H27) -> 1

Sheet Main Financials
B2: Income Statement
B4: Income Statement Adjusted and Reorganized
B5: All figures in EUR(€) millions unless stated
E6: 2015 | F6: =+E6+1 -> 2016 | G6: =+F6+1 -> 2017 | H6: =+G6+1 -> 2018 | I6: =+H6+1 -> 2019 | J6: =+I6+1 -> 2020 | K6: =+J6+1 -> 2021 | L6: =+K6+1 -> 2022 | M6: =+L6+1 -> 2023 | ... U6: =+T6+1 -> 2031
E7: 2015 | F7: =E7+1 -> 2016 | G7: =F7+1 -> 2017 | H7: =G7+1 -> 2018 | I7: =H7+1 -> 2019 | J7: =I7+1 -> 2020 | K7: =J7+1 -> 2021 | L7: =K7+1 -> 2022 | M7: =L7+1 -> 2023 | ... U7: =T7+1 -> 2031
B8: Revenues | E8: =E32+E39+E41 -> 45327 | F8: =F32+F39+F41 -> 51243 | G8: =G32+G39+G41 -> 56066 | H8: =H32+H39+H41 -> 54588 | I8: =I32+I39+I41 -> 52537 | J8: =J32+J39+J41 -> 41022 | K8: =K32+K39+K41 -> 43600 | L8: =L32+L39+L41 -> 46391 | ... U8: =U32+U39+U41 -> 65725.275
B9: Cost of sales (excl. D&A exp.) | E9: =E49-E413-E440 -> -33385 | F9: =F49-F413-F440-F25 -> -37374 | G9: =G49-G413-G440-G25 -> -43370 | H9: =H49-H413-H440-H25 -> -42072 | I9: =I49-I413-I440 -> -40860 | J9: =J49-J413-J440 -> -31508 | K9: =K49-K413-K440 -> -33481 | L9: =L49-L413-L440 -> -31348 | M9: =M49-M413-M440 -> -38229 | N9: =N49-N413-N440 -> -41332 | O9: =O346 -> -40730.819 | P9: =P346 -> -42301.955 | Q9: =Q346 -> -43958.884 | R9: =R346 -> -44767.303 | S9: =S346 -> -46492.074 | T9: =T346 -> -44247.227 | U9: =U346 -> -45576.103
B10: Gross profit | E10: =E8+E9 -> 11942 | F10: =F8+F9 -> 13869 | G10: =G8+G9 -> 12696 | H10: =H8+H9 -> 12516 | I10: =I8+I9 -> 11677 | J10: =J8+J9 -> 9514 | K10: =K8+K9 -> 10119 | L10: =L8+L9 -> 15043 | ... U10: =U8+U9 -> 20149.172
B11: Total SGA + other operating expenses (excl. D&A) | E11: =E348+E389+E373-E413-E440 -> -7104 | F11: =F348+F389+F373-F413-F440-F24 -> -7810.8045 | G11: =G348+G389+G373-G413-G440-G24 -> -5994.2932 | H11: =H348+H389+H373-H413-H440-H24 -> -6298.7443 | I11: =I348+I389+I373-I413-I440 -> -5686 | J11: =J348+J389+J373-J413-J440 -> -6767 | K11: =K348+K389+K373-K413-K440 -> -4676 | L11: =L348+L389+L373-L413-L440 -> -7031 | M11: =M348+M389+M373-M413-M440 -> -8478 | N11: =N348+N389+N373-N413-N440 -> -9154 | O11: =O348+O389+O373-O413-O440 -> -10007.358 | P11: =P348+P389+P373-P413-P440 -> -10682.17 | ... U11: =U348+U389+U373-U413-U440 -> -12050.705
B12: EBITDA | E12: =E10+E11 -> 4838 | F12: =F10+F11 -> 6058.1955 | G12: =G10+G11 -> 6701.7068 | H12: =H10+H11 -> 6217.2557 | I12: =I10+I11 -> 5991 | J12: =J10+J11 -> 2747 | K12: =K10+K11 -> 5443 | L12: =L10+L11 -> 8012 | ... U12: =U10+U11 -> 8098.4674
B13: Depreciation expenses | E13: =E413-E26 -> -1916 | F13: =F413-F26 -> -1963 | G13: =G413-G26 -> -2061 | H13: =H413-H26 -> -2294 | I13: =I413-I26 -> -2549 | J13: =J413-J26 -> -2869 | K13: =K413-K26 -> -2792 | L13: =L413-L26 -> -3522 | ... U13: =U413-U26 -> -2629.011
B14: Depreciation on right-of-use assets (i.e., operating lease assets) | E14: =E26 -> 0 | F14: =F26 -> -36.1955 | G14: =G26 -> -75.706794 | H14: =H26 -> -89.25565 | I14: =I26 -> 0 | J14: =J26 -> 0 | K14: =K26 -> 0 | L14: =L26 -> 0 | ... U14: =U26 -> 0
B15: EBITA | E15: =E12+E13+E14 -> 2922 | F15: =F12+F13+F14 -> 4059 | G15: =G12+G13+G14 -> 4565 | H15: =H12+H13+H14 -> 3834 | I15: =I12+I13+I14 -> 3442 | J15: =J12+J13+J14 -> -122 | K15: =K12+K13+K14 -> 2651 | L15: =L12+L13+L14 -> 4490 | ... U15: =U12+U13+U14 -> 5469.4564
B16: Amortization expenses | E16: =E440 -> -812 | F16: =F440 -> -877 | G16: =G440 -> -961 | H16: =H440 -> -950 | I16: =I440 -> -1256 | J16: =J440 -> -1880 | K16: =K440 -> -1253 | L16: =L440 -> -2275 | ... U16: =U440 -> -1643.1319
B17: EBIT before non-recurring items | E17: =E15+E16 -> 2110 | F17: =F15+F16 -> 3182 | G17: =G15+G16 -> 3604 | H17: =H15+H16 -> 2884 | I17: =I15+I16 -> 2186 | J17: =J15+J16 -> -2002 | K17: =K15+K16 -> 1398 | L17: =L15+L16 -> 2215 | ... U17: =U15+U16 -> 3826.3245
B19: Adjustments to Income Statement
B20: All figures in EUR(€) millions unless stated
E21: 2015 | F21: =+E21+1 -> 2016 | G21: =+F21+1 -> 2017 | H21: =+G21+1 -> 2018 | I21: =+H21+1 -> 2019 | J21: =+I21+1 -> 2020 | K21: =+J21+1 -> 2021 | L21: =+K21+1 -> 2022 | M21: =+L21+1 -> 2023 | N21: =+M21+1 -> 2024
E22: 2015 | F22: =E22+1 -> 2016 | G22: =F22+1 -> 2017 | H22: =G22+1 -> 2018 | I22: =H22+1 -> 2019 | J22: =I22+1 -> 2020 | K22: =J22+1 -> 2021 | L22: =K22+1 -> 2022 | M22: =L22+1 -> 2023 | N22: =M22+1 -> 2024
B24: Operating lease costs expensed | E24: =E263 -> 0 | F24: =F263 -> 42 | G24: =G263 -> 85 | H24: =H263 -> 101 | I24: =I263 -> 0 | J24: =J263 -> 0 | K24: =K263 -> 0 | L24: =L263 -> 0 | ... N24: =N263 -> 0
B25: Interest expense on right-of-use asset (i.e., operating lease asset) | E25: =E264 -> 0 | F25: =F264 -> -5.8045 | G25: =G264 -> -9.2932056 | H25: =H264 -> -11.74435 | I25: =I264 -> 0 | J25: =J264 -> 0 | K25: =K264 -> 0 | L25: =L264 -> 0 | ... N25: =N264 -> 0
B26: Depreciation expense on right-of-use asset (i.e., operating lease asset) | E26: =E265 -> 0 | F26: =F265 -> -36.1955 | G26: =G265 -> -75.706794 | H26: =H265 -> -89.25565 | I26: =I265 -> 0 | J26: =J265 -> 0 | K26: =K265 -> 0 | L26: =L265 -> 0 | ... N26: =N265 -> 0
B28: Revenue Breakdown and Forecast unadj.
B29: All figures in EUR(€) millions unless stated
E30: 2015 | F30: =+E30+1 -> 2016 | G30: =+F30+1 -> 2017 | H30: =+G30+1 -> 2018 | I30: =+H30+1 -> 2019 | J30: =+I30+1 -> 2020 | K30: =+J30+1 -> 2021 | L30: =+K30+1 -> 2022 | M30: =+L30+1 -> 2023 | ... U30: =+T30+1 -> 2031
E31: 2015 | F31: =E31+1 -> 2016 | G31: =F31+1 -> 2017 | H31: =G31+1 -> 2018 | I31: =H31+1 -> 2019 | J31: =I31+1 -> 2020 | K31: =J31+1 -> 2021 | L31: =K31+1 -> 2022 | M31: =L31+1 -> 2023 | ... U31: =T31+1 -> 2031
B32: Total Automotive | E32: =+E33+E34+E35+E36+E37 -> 43108 | F32: =+F33+F34+F35+F36+F37 -> 48995 | G32: =+G33+G34+G35+G36+G37 -> 53553 | H32: =+H33+H34+H35+H36+H37 -> 51380 | I32: =+I33+I34+I35+I36+I37 -> 49132 | J32: =+J33+J34+J35+J36+J37 -> 37865 | K32: =+K33+K34+K35+K36+K37 -> 40641 | L32: =+L33+L34+L35+L36+L37 -> 43121 | ... U32: =+U33+U34+U35+U36+U37 -> 57490.338
B33: ACEA Europe | E33: =E316 -> 24772.652 | F33: =F316 -> 27791.582 | G33: =G316 -> 27208.61 | H33: =H316 -> 25406.856 | I33: =I316 -> 25468.602 | J33: =J316 -> 18539.589 | K33: =K316 -> 21529.684 | L33: =L316 -> 27629.195 | ... U33: =U316 -> 39598.558
B34: Eurasia | E34: =E321 -> 5466.7725 | F34: =F321 -> 5610.55 | G34: =G321 -> 10432.405 | H34: =H321 -> 9888.9994 | I34: =I321 -> 9824.1278 | J34: =J321 -> 9537.0455 | K34: =K321 -> 9947.184 | L34: =L321 -> 3231.8348 | ... U34: =U321 -> 6395.7338
B35: Africa & Middle East | E35: =E326 -> 5525.2898 | F35: =F326 -> 7561.0363 | G35: =G326 -> 7579.4549 | H35: =H326 -> 5938.6616 | I35: =I326 -> 5932.1779 | J35: =J326 -> 4441.6774 | K35: =K326 -> 2272.6335 | L35: =L326 -> 2751.3596 | ... U35: =U326 -> 3214.8507
B36: Asia-Pacific | E36: =E331 -> 1909.417 | F36: =F331 -> 2576.4739 | G36: =G331 -> 2788.5149 | H36: =H331 -> 4361.7302 | I36: =I331 -> 2350.3818 | J36: =J331 -> 2005.8001 | K36: =K331 -> 2926.1087 | L36: =L331 -> 3506.6589 | ... U36: =U331 -> 2663.2185
B37: Americas | E37: =E336 -> 5433.869 | F37: =F336 -> 5455.3578 | G37: =G336 -> 5544.0151 | H37: =H336 -> 5783.7528 | I37: =I336 -> 5556.7105 | J37: =J336 -> 3340.8879 | K37: =K336 -> 3965.3899 | L37: =L336 -> 6001.9517 | ... U37: =U336 -> 5617.9779
B39: Total Sales Financing | E39: =E359 -> 2219 | F39: =F359 -> 2248 | G39: =G359 -> 2513 | H39: =H359 -> 3208 | I39: =I359 -> 3405 | J39: =J359 -> 3138 | K39: =K359 -> 2935 | L39: =L359 -> 3235 | ... U39: =U359 -> 7891.377
B41: Total Mobility Services | E41: =E381 -> 0 | F41: =F381 -> 0 | G41: =G381 -> 0 | H41: =H381 -> 0 | I41: =I381 -> 0 | J41: =J381 -> 19 | K41: =K381 -> 24 | L41: =L381 -> 35 | ... U41: =U381 -> 343.55985
B44: Income Statement Historical IFRS
B45: All figures in EUR(€) millions unless stated
E46: 2015 | F46: =+E46+1 -> 2016 | G46: =+F46+1 -> 2017 | H46: =+G46+1 -> 2018 | I46: =+H46+1 -> 2019 | J46: =+I46+1 -> 2020 | K46: =+J46+1 -> 2021 | L46: =+K46+1 -> 2022 | M46: =+L46+1 -> 2023 | N46: =+M46+1 -> 2024
E47: 2015 | F47: =E47+1 -> 2016 | G47: =F47+1 -> 2017 | H47: =G47+1 -> 2018 | I47: =H47+1 -> 2019 | J47: =I47+1 -> 2020 | K47: =J47+1 -> 2021 | L47: =K47+1 -> 2022 | M47: =L47+1 -> 2023 | N47: =M47+1 -> 2024
B48: Revenues | E48: 45327 | F48: 51243 | G48: 58770 | H48: 57419 | I48: 55537 | J48: 43474 | K48: 46213 | L48: 46391 | M48: 52376 | N48: 56232
B49: Cost of goods and services sold | E49: -36113 | F49: -40256 | G49: -46477 | H49: -45417 | I49: -44665 | J49: -36257 | K49: -37526 | L49: -37145 | M49: -41414 | N49: -44500
...

Sheet WACC
B2: Levered β Assumptions | F2: Macro Factors | R2: Country Equity Risk Premium Calculation
B3: Method | C3: β | D3: Weight | I3: 2025 | J3: =+I3+1 -> 2026 | K3: =+J3+1 -> 2027 | L3: =+K3+1 -> 2028 | M3: =+L3+1 -> 2029 | N3: =+M3+1 -> 2030 | O3: =+N3+1 -> 2031 | P3: Terminal | R3: Country | S3: ERP | T3: GDP 2023 | U3: Weight GDP
B4: Regression | C4: =Beta!C23 -> 1.6732075 | D4: 0.5 | F4: EU inflation | I4: =Macro!O6 -> 0.02253 | J4: =Macro!P6 -> 0.02074 | K4: =Macro!Q6 -> 0.02157 | L4: =Macro!R6 -> 0.02097 | M4: =Macro!S6 -> 0.02122 | N4: =Macro!T6 -> 0.02065 | O4: =Macro!U6 -> 0.02 | P4: =Macro!U6 -> 0.02 | R4: Austria | S4: 0.0486 | T4: 477837.3 | U4: =T4/$T$31 -> 0.027688969
B5: Bottom-up | C5: =Beta!C24 -> 2.6130474 | D5: =1-D4 -> 0.5 | F5: Risk-free rate | I5: =U45 -> 0.01973334 | J5: =V45 -> 0.01964279 | K5: =W45 -> 0.02135805 | L5: =X45 -> 0.02349382 | M5: =Y45 -> 0.02544581 | N5: =Z45 -> 0.02741186 | O5: =AA45 -> 0.02904171 | P5: =AB45 -> 0.031974435 | R5: Belgium | S5: 0.0513 | T5: 602376.3 | U5: =T5/$T$31 -> 0.034905561
B6: WA β | C6: =SUMPRODUCT(C4:C5,D4:D5) -> 2.1431275 | D6: =SUM(D4:D5) -> 1 | F6: Expected loss from default | I6: 0.003 | J6: 0.003 | K6: 0.003 | L6: 0.003 | M6: 0.003 | N6: 0.003 | O6: 0.003 | P6: 0.003 | R6: Bulgaria | S6: 0.0646 | T6: 94526.6 | U6: =T6/$T$31 -> 0.0054774797
R7: Croatia | S7: 0.0593 | T7: 79186.3 | U7: =T7/$T$31 -> 0.004588564
B8: Debt to Equity Forecast | F8: Assumptions for Cost of Equity | R8: Cyprus | S8: 0.0593 | T8: 32439.2 | U8: =T8/$T$31 -> 0.0018797361
B9: Year | C9: Ratio | I9: 2025 | J9: =+I9+1 -> 2026 | K9: =+J9+1 -> 2027 | L9: =+K9+1 -> 2028 | M9: =+L9+1 -> 2029 | N9: =+M9+1 -> 2030 | O9: =+N9+1 -> 2031 | P9: Terminal | R9: Czech Republic | S9: 0.0513 | T9: 319099.1 | U9: =T9/$T$31 -> 0.018490656
B10: 2025 | C10: =CCA!J54/CCA!H54 -> 7.584024 | D10: Explainer | F10: Levered β | I10: =$C$6 -> 2.1431275 | J10: =$C$6 -> 2.1431275 | K10: =$C$6 -> 2.1431275 | L10: =$C$6 -> 2.1431275 | M10: =$C$6 -> 2.1431275 | N10: =$C$6 -> 2.1431275 | O10: =$C$6 -> 2.1431275 | P10: =$C$6 -> 2.1431275 | R10: Denmark | S10: 0.0433 | T10: 374173.6 | U10: =T10/$T$31 -> 0.021682027
B11: =+B10+1 -> 2026 | C11: =C10+0.01 -> 7.594024 | F11: Risk-free rate | I11: =I5 -> 0.01973334 | J11: =J5 -> 0.01964279 | K11: =K5 -> 0.02135805 | L11: =L5 -> 0.02349382 | M11: =M5 -> 0.02544581 | N11: =N5 -> 0.02741186 | O11: =O5 -> 0.02904171 | P11: =P5 -> 0.031974435 | R11: Estonia | S11: 0.0527 | T11: 38353.4 | U11: =T11/$T$31 -> 0.0022224429
B12: =+B11+1 -> 2027 | C12: =C11+0.01 -> 7.604024 | F12: Equity risk premium | I12: =$U$32 -> 0.05352576 | J12: =$U$32 -> 0.05352576 | K12: =$U$32 -> 0.05352576 | L12: =$U$32 -> 0.05352576 | M12: =$U$32 -> 0.05352576 | N12: =$U$32 -> 0.05352576 | O12: =$U$32 -> 0.05352576 | P12: =$U$32 -> 0.05352576 | R12: Finland | S12: 0.0486 | T12: 272848 | U12: =T12/$T$31 -> 0.01581057
B13: =+B12+1 -> 2028 | C13: =C12+0.01 -> 7.614024 | F13: Cost of Equity | I13: =I11+I10*(I12) -> 0.13444587 | J13: =J11+J10*(J12) -> 0.13435532 | K13: =K11+K10*(K12) -> 0.13607058 | L13: =L11+L10*(L12) -> 0.13820635 | M13: =M11+M10*(M12) -> 0.14015834 | N13: =N11+N10*(N12) -> 0.14212439 | O13: =O11+O10*(O12) -> 0.14375424 | P13: =P11+P10*(P12) -> 0.14668696 | R13: France | S13: 0.0513 | T13: 2826541.5 | U13: =T13/$T$31 -> 0.16378801
B14: =+B13+1 -> 2029 | C14: =C13+0.01 -> 7.624024 | R14: Germany | S14: 0.0433 | T14: 4219310 | U14: =T14/$T$31 -> 0.24449398
B15: =+B14+1 -> 2030 | C15: =C14+0.01 -> 7.634024 | F15: Assumptions for Cost of Debt | R15: Greece | S15: 0.0767 | T15: 224686.2 | U15: =T15/$T$31 -> 0.013019765
B16: =+B15+1 -> 2031 | C16: =C15+0.01 -> 7.644024 | I16: 2025 | J16: =+I16+1 -> 2026 | K16: =+J16+1 -> 2027 | L16: =+K16+1 -> 2028 | M16: =+L16+1 -> 2029 | N16: =+M16+1 -> 2030 | O16: =+N16+1 -> 2031 | P16: Terminal | R16: Hungary | S16: 0.0687 | T16: 197178.7 | U16: =T16/$T$31 -> 0.011425803
B17: Terminal | C17: =C16 -> 7.644024 | F17: Accounting cost of debt adj. | I17: =$E$54 -> 0.029861358 | J17: =$I$17*(J5/J4) -> 0.0282816 | K17: =$I$17*(K5/K4) -> 0.029567936 | L17: =$I$17*(L5/L4) -> 0.033455287 | M17: =$I$17*(M5/M4) -> 0.035808032 | N17: =$I$17*(N5/N4) -> 0.039639485 | O17: =$I$17*(O5/O4) -> 0.043361245 | P17: =$I$17*(P5/P4) -> 0.047740002 | R17: Ireland | S17: 0.0513 | T17: 524728.8 | U17: =T17/$T$31 -> 0.030406165
F18: Credit Spread | I18: =$D$67 -> 0.016321429 | J18: =$D$67 -> 0.016321429 | K18: =$D$67 -> 0.016321429 | L18: =$D$67 -> 0.016321429 | M18: =$D$67 -> 0.016321429 | N18: =$D$67 -> 0.016321429 | O18: =$D$67 -> 0.016321429 | P18: =$D$67 -> 0.016321429 | R18: Italy | S18: 0.0726 | T18: 2142601.7 | U18: =T18/$T$31 -> 0.12415614
F19: Expected loss from default | I19: =I6 -> 0.003 | J19: =J6 -> 0.003 | K19: =K6 -> 0.003 | L19: =L6 -> 0.003 | M19: =M6 -> 0.003 | N19: =N6 -> 0.003 | O19: =O6 -> 0.003 | P19: =P6 -> 0.003 | R19: Latvia | S19: 0.0593 | T19: 39564.2 | U19: =T19/$T$31 -> 0.0022926044
F20: Cost of Debt | I20: =I17+I18-I19 -> 0.043182787 | J20: =J17+J18-J19 -> 0.041603029 | K20: =K17+K18-K19 -> 0.042889364 | L20: =L17+L18-L19 -> 0.046776716 | M20: =M17+M18-M19 -> 0.049129461 | N20: =N17+N18-N19 -> 0.052960914 | O20: =O17+O18-O19 -> 0.056682674 | P20: =P17+P18-P19 -> 0.061061431 | R20: Lithuania | S20: 0.0546 | T20: 74317 | U20: =T20/$T$31 -> 0.0043064054
R21: Luxembourg | S21: 0.0433 | T21: 82115.5 | U21: =T21/$T$31 -> 0.0047583007
F22: WACC | R22: Malta | S22: 0.0546 | T22: 20911.2 | U22: =T22/$T$31 -> 0.0012117295
I23: 2025 | J23: =+I23+1 -> 2026 | K23: =+J23+1 -> 2027 | L23: =+K23+1 -> 2028 | M23: =+L23+1 -> 2029 | N23: =+M23+1 -> 2030 | O23: =+N23+1 -> 2031 | P23: Terminal | R23: Netherlands | S23: 0.0433 | T23: 1050133 | U23: =T23/$T$31 -> 0.060851466
F24: Weight of equity | I24: =1-I26 -> 0.11649548 | J24: =1-J26 -> 0.11635993 | K24: =1-K26 -> 0.11622469 | L24: =1-L26 -> 0.11608976 | M24: =1-M26 -> 0.11595515 | N24: =1-N26 -> 0.11582085 | O24: =1-O26 -> 0.11568686 | P24: =1-P26 -> 0.11568686 | R24: Poland | S24: 0.0546 | T24: 751931.7 | U24: =T24/$T$31 -> 0.043571763
F25: Cost of Equity | I25: =I13 -> 0.13444587 | J25: =J13 -> 0.13435532 | K25: =K13 -> 0.13607058 | L25: =L13 -> 0.13820635 | M25: =M13 -> 0.14015834 | N25: =N13 -> 0.14212439 | O25: =O13 -> 0.14375424 | P25: =P13 -> 0.14668696 | R25: Portugal | S25: 0.0593 | T25: 270352.6 | U25: =T25/$T$31 -> 0.01566597
F26: Weight of Debt | I26: =C10/(1+C10) -> 0.88350452 | J26: =C11/(1+C11) -> 0.88364007 | K26: =C12/(1+C12) -> 0.88377531 | L26: =C13/(1+C13) -> 0.88391024 | M26: =C14/(1+C14) -> 0.88404485 | N26: =C15/(1+C15) -> 0.88417915 | O26: =C16/(1+C16) -> 0.88431314 | P26: =C17/(1+C17) -> 0.88431314 | R26: Romania | S26: 0.0726 | T26: 321577.9 | U26: =T26/$T$31 -> 0.018634294
F27: Tax Rate | I27: =Macro!O17 -> 0.25 | J27: =Macro!P17 -> 0.25 | K27: =Macro!Q17 -> 0.25 | L27: =Macro!R17 -> 0.25 | M27: =Macro!S17 -> 0.25 | N27: =Macro!T17 -> 0.25 | O27: =Macro!U17 -> 0.25 | P27: =Macro!U17 -> 0.25 | R27: Slovakia | S27: 0.0593 | T27: 123538.7 | U27: =T27/$T$31 -> 0.0071586276
F28: Cost of Debt | I28: =I20 -> 0.043182787 | J28: =J20 -> 0.041603029 | K28: =K20 -> 0.042889364 | L28: =L20 -> 0.046776716 | M28: =M20 -> 0.049129461 | N28: =N20 -> 0.052960914 | O28: =O20 -> 0.056682674 | P28: =P20 -> 0.061061431 | R28: Slovenia | S28: 0.0593 | T28: 64050 | U28: =T28/$T$31 -> 0.0037114693
F29: WACC | I29: =I24*I25+I26*(1-I27)*I28 -> 0.044276476 | J29: =J24*J25+J26*(1-J27)*J28 -> 0.043205152 | K29: =K24*K25+K26*(1-K27)*K28 -> 0.044243181 | L29: =L24*L25+L26*(1-L27)*L28 -> 0.047054155 | M29: =M24*M25+M26*(1-M27)*M28 -> 0.048826566 | N29: =N24*N25+N26*(1-N27)*N28 -> 0.051581169 | O29: =O24*O25+O26*(1-O27)*O28 -> 0.054224401 | P29: =P24*P25+P26*(1-P27)*P28 -> 0.057467823 | R29: Spain | S29: 0.0646 | T29: 1497761 | U29: =T29/$T$31 -> 0.086789914
R30: Sweden | S30: 0.0433 | T30: 535176.8 | U30: =T30/$T$31 -> 0.031011589
F31: WACC | I31: {=INDEX(I33:I35,Valuation!$E$9)} -> 0.047752691 | J31: {=INDEX(J33:J35,Valuation!$E$9)} -> 0.046679585 | K31: {=INDEX(K33:K35,Valuation!$E$9)} -> 0.047715836 | L31: {=INDEX(L33:L35,Valuation!$E$9)} -> 0.050525036 | M31: {=INDEX(M33:M35,Valuation!$E$9)} -> 0.052295677 | N31: {=INDEX(N33:N35,Valuation!$E$9)} -> 0.055048514 | O31: {=INDEX(O33:O35,Valuation!$E$9)} -> 0.057689985 | P31: {=INDEX(P33:P35,Valuation!$E$9)} -> 0.060933407 | R31: Total GDP | T31: =SUM(T4:T30) -> 17257316
R32: Weighted average ERP by GDP | U32: =SUMPRODUCT(S4:S30,U4:U30) -> 0.05352576
F33: Best Case | I33: 0.039574598 | J33: 0.038330559 | K33: 0.039233985 | L33: 0.04202971 | M33: 0.044062299 | N33: 0.047052911 | O33: 0.050053871 | P33: 0.055243347
F34: Base Case | I34: =I29 -> 0.044276476 | J34: =J29 -> 0.043205152 | K34: =K29 -> 0.044243181 | L34: =L29 -> 0.047054155 | M34: =M29 -> 0.048826566 | N34: =N29 -> 0.051581169 | O34: =O29 -> 0.054224401 | P34: =P29 -> 0.057467823
F35: Worst Case | I35: 0.047752691 | J35: 0.046679585 | K35: 0.047715836 | L35: 0.050525036 | M35: 0.052295677 | N35: 0.055048514 | O35: 0.057689985 | P35: 0.060933407
B38: Debt and Ratings | R38: Risk-free Rate Assumptions
U39: 2025 | V39: =+U39+1 -> 2026 | W39: =+V39+1 -> 2027 | X39: =+W39+1 -> 2028 | Y39: =+X39+1 -> 2029 | Z39: =+Y39+1 -> 2030 | AA39: =Z39+1 -> 2031 | AB39: Terminal
B40: Debt Breakdown 2024 | I40: Synthetic rating | R40: Instantaneous Forward AAA EU gov. bonds | U40: 0.01896668 | V40: 0.01928558 | W40: 0.0207661 | X40: 0.02288764 | Y40: 0.02524162 | Z40: 0.02757372 | AA40: 0.02973342 | AB40: 0.03559887
E41: Non-current | F41: Current | G41: Total | I41: If interest coverage ratio is greater than | J41: to ≤ | K41: Rating | L41: Spread | M41: Debt-Recovery Rates | O41: Drop in EBITDA | R41: EURIBOR 3 month swap futures | U41: =(100-97.95)/100 -> 0.0205 | V41: =(100-98)/100 -> 0.02 | W41: =(100-97.805)/100 -> 0.02195 | X41: =(100-97.59)/100 -> 0.0241 | Y41: =(100-97.435)/100 -> 0.02565 | Z41: =(100-97.275)/100 -> 0.02725 | AA41: =(100-97.165)/100 -> 0.02835 | AB41: =(100-97.165)/100 -> 0.02835
B42: Renault SA redeemable shares | E42: 260 | F42: 0 | I42: 8.5 | J42: 100000 | K42: Aaa/AAA | L42: 0.0045 | M42: 1 | O42: 0
B43: Bonds | E43: 4631 | F43: 2283 | I43: 6.5 | J43: 8.5 | K43: Aa2/AA | L43: 0.006 | M43: 0.954 | O43: 0 | R43: Instantaneous weight | T43: 0.5
...

Sheet Beta
B2: Comparable Companies Unlevered Beta Calculation
B3: Companies | C3: €/ Share | D3: FD Shares | E3: Market Cap | F3: Total Debt | G3: Levered β | H3: Tax Rate | I3: Unlevered β | J3: Last Report
B4: Renault | C4: =CCA!F54 -> 33.79 | D4: =CCA!G54 -> 273.46 | E4: =C4*D4 -> 9240.2134 | F4: =CCA!J54 -> 70078 | G4: =M33 -> 1.6732075 | H4: =F19 -> 0.2583 | I4: =G4/(1+(1-H4)*(F4/E4)) -> 0.25255693 | J4: 45838
B5: Stellantis | C5: {=INDIRECT($B5&"!F9")} -> 8.778 | D5: {=INDIRECT($B5&"!R29")} -> 2888.724 | E5: =C5*D5 -> 25357.219 | F5: {=INDIRECT($B5&"!R27")} -> 40799 | G5: =P33 -> 1.5370731 | H5: =Macro!N22 -> 0.24 | I5: =G5/(1+(1-H5)*(F5/E5)) -> 0.69149778 | J5: {=INDIRECT($B5&"!I6")} -> 45838
B6: Volkswagen | C6: {=INDIRECT(B6&"!F9")} -> 91.35 | D6: {=INDIRECT($B6&"!R29")} -> 501.29526 | E6: =C6*D6 -> 45793.322 | F6: {=INDIRECT($B6&"!R27")} -> 271470 | G6: =R33 -> 1.384302 | H6: =Macro!N23 -> 0.15825 | I6: =G6/(1+(1-H6)*(F6/E6)) -> 0.23110117 | J6: {=INDIRECT($B6&"!I6")} -> 09/30/2025
B7: Nissan | C7: {=INDIRECT(B7&"!F9")} -> 1.9880741 | D7: {=INDIRECT($B7&"!R29")} -> 3495.7389 | E7: =C7*D7 -> 6949.788 | F7: {=INDIRECT($B7&"!R27")} -> 51122.825 | G7: =T33 -> 0.68546068 | H7: =Macro!N24 -> 0.232 | I7: =G7/(1+(1-H7)*(F7/E7)) -> 0.10308566 | J7: {=INDIRECT($B7&"!I6")} -> 09/30/2025
B8: BMW | C8: {=INDIRECT(B8&"!F9")} -> 80.72 | D8: {=INDIRECT($B8&"!R29")} -> 609.81512 | E8: =C8*D8 -> 49224.277 | F8: {=INDIRECT($B8&"!R27")} -> 107748 | G8: =V33 -> 1.2319778 | H8: =Macro!N25 -> 0.15825 | I8: =G8/(1+(1-H8)*(F8/E8)) -> 0.43340992 | J8: {=INDIRECT($B8&"!I6")} -> 09/30/2025
B9: MercedesBenz | C9: {=INDIRECT(B9&"!F9")} -> 56.21 | D9: {=INDIRECT($B9&"!R29")} -> 962.9037 | E9: =C9*D9 -> 54124.817 | F9: {=INDIRECT($B9&"!R27")} -> 102343 | G9: =X33 -> 1.5464015 | H9: =Macro!N26 -> 0.15825 | I9: =G9/(1+(1-H9)*(F9/E9)) -> 0.5966884 | J9: {=INDIRECT($B9&"!I6")} -> 09/30/2025
B10: Ford | C10: {=INDIRECT(B10&"!F9")} -> 11.375845 | D10: {=INDIRECT($B10&"!R29")} -> 4203 | E10: =C10*D10 -> 47812.677 | F10: {=INDIRECT($B10&"!R27")} -> 139899.58 | G10: =Z33 -> 1.2815918 | H10: =Macro!N27 -> 0.232 | I10: =G10/(1+(1-H10)*(F10/E10)) -> 0.39468046 | J10: {=INDIRECT($B10&"!I6")} -> 09/30/2025
B11: Toyota | C11: {=INDIRECT(B11&"!F9")} -> 17.648024 | D11: {=INDIRECT($B11&"!R29")} -> 13033.389 | E11: =C11*D11 -> 230013.57 | F11: {=INDIRECT($B11&"!R27")} -> 229725.74 | G11: =AB33 -> 0.59175927 | H11: =Macro!N28 -> 0.232 | I11: =G11/(1+(1-H11)*(F11/E11)) -> 0.33488751 | J11: {=INDIRECT($B11&"!I6")} -> 09/30/2025
B12: GeneralMotors | C12: {=INDIRECT(B12&"!F9")} -> 59.85964 | D12: {=INDIRECT($B12&"!R29")} -> 933 | E12: =C12*D12 -> 55849.044 | F12: {=INDIRECT($B12&"!R27")} -> 112768.51 | G12: =AD33 -> 1.2630494 | H12: =Macro!N29 -> 0.21 | I12: =G12/(1+(1-H12)*(F12/E12)) -> 0.48669771 | J12: {=INDIRECT($B12&"!I6")} -> 09/30/2025
B13: Honda | C13: {=INDIRECT(B13&"!F9")} -> 8.7733965 | D13: {=INDIRECT($B13&"!R29")} -> 3892.5506 | E13: =C13*D13 -> 34150.89 | F13: {=INDIRECT($B13&"!R27")} -> 72636.764 | G13: =AF33 -> 0.73802082 | H13: =Macro!N30 -> 0.21 | I13: =G13/(1+(1-H13)*(F13/E13)) -> 0.27535218 | J13: {=INDIRECT($B13&"!I6")} -> 09/30/2025
B14: Mean | I14: =AVERAGE(I5:I13) -> 0.39415564
B15: Median | I15: =MEDIAN(I5:I13) -> 0.39468046
B17: Bottom Up Beta
C18: Unlevered β | D18: Market Cap | E18: Total Debt | F18: Tax Rate | G18: Levered β
B19: Mean | C19: =I14 -> 0.39415564 | D19: =$E$4 -> 9240.2134 | E19: =$F$4 -> 70078 | F19: =Macro!$N$17 -> 0.2583 | G19: =C19*(1+(1-F19)*(E19/D19)) -> 2.611309
B20: Median | C20: =I15 -> 0.39468046 | D20: =$E$4 -> 9240.2134 | E20: =$F$4 -> 70078 | F20: =Macro!$N$17 -> 0.2583 | G20: =C20*(1+(1-F20)*(E20/D20)) -> 2.6147859
B22: Beta Summary
B23: Regression β | C23: =M33 -> 1.6732075
B24: Bottom up β | C24: =AVERAGE(G19:G20) -> 2.6130474
B26: Stock Return History and Levered Beta Calculations
B27: All return values are taken from FactSet as total return measures and converted to € by their currency conversion, yields are also taken from FactSet as Yield-to-Maturity values.
B29: Risk Free Data | E29: Return Data and Levered Beta Calculations | O29: Comparables Levered Beta Calculations
B30: Eurozone 10-year Bond | E30: Date | F30: 45962 | H30: Frequency | J30: W | L30: Currency | M30: EUR
B31: Note: Negative in '20-'21 | E31: Start | F31: 43831 | H31: Return Convention | J31: 7-DAY | O31: Stellantis | Q31: Volkswagen | S31: Nissan | U31: BMW | W31: Mercedez-Benz | Y31: Ford | AA31: Toyota | AC31: General Motors | AE31: Honda
O32: Stock Levered β | Q32: Stock Levered β | S32: Stock Levered β | U32: Stock Levered β | W32: Stock Levered β | Y32: Stock Levered β | AA32: Stock Levered β | AC32: Stock Levered β | AE32: Stock Levered β
B33: EU10YR | F33: RNO | G33: STOXX600 | H33: RNO | I33: STOXX600 | K33: Renault Levered β | M33: =_xlfn.COVARIANCE.P(H35:H339,I35:I339)/_xlfn.VAR.P(I35:I339) -> 1.6732075 | P33: =_xlfn.COVARIANCE.P(P35:P339,$I$35:$I$339)/_xlfn.VAR.P($I$35:$I$339) -> 1.5370731 | R33: =_xlfn.COVARIANCE.P(R35:R339,$I$35:$I$339)/_xlfn.VAR.P($I$35:$I$339) -> 1.384302 | T33: =_xlfn.COVARIANCE.P(T35:T339,$I$35:$I$339)/_xlfn.VAR.P($I$35:$I$339) -> 0.68546068 | V33: =_xlfn.COVARIANCE.P(V35:V339,$I$35:$I$339)/_xlfn.VAR.P($I$35:$I$339) -> 1.2319778 | X33: =_xlfn.COVARIANCE.P(X35:X339,$I$35:$I$339)/_xlfn.VAR.P($I$35:$I$339) -> 1.5464015 | Z33: =_xlfn.COVARIANCE.P(Z35:Z339,$I$35:$I$339)/_xlfn.VAR.P($I$35:$I$339) -> 1.2815918 | AB33: =_xlfn.COVARIANCE.P(AB35:AB339,$I$35:$I$339)/_xlfn.VAR.P($I$35:$I$339) -> 0.59175927 | AD33: =_xlfn.COVARIANCE.P(AD35:AD339,$I$35:$I$339)/_xlfn.VAR.P($I$35:$I$339) -> 1.2630494 | AF33: =_xlfn.COVARIANCE.P(AF35:AF339,$I$35:$I$339)/_xlfn.VAR.P($I$35:$I$339) -> 0.73802082
B34: YTM | C34: Weekly rf | E34: Date | F34: Return | G34: Return | H34: Excess | I34: Excess | O34: Return | P34: Excess | Q34: Return | R34: Excess | S34: Return | T34: Excess | U34: Return | V34: Excess | W34: Return | X34: Excess | Y34: Return | Z34: Excess | AA34: Return | AB34: Excess | AC34: Return | AD34: Excess | AE34: Return | AF34: Excess
B35: 0.02644 | C35: =(1+B35)^(1/52)-1 -> 0.00050198181 | E35: 45961 | F35: -0.019493699 | G35: -0.006721556 | H35: =F35-$C35 -> -0.019995681 | I35: =G35-C35 -> -0.0072235378 | O35: -0.070619345 | P35: =O35-$C35 -> -0.071121327 | Q35: -0.0010935068 | R35: =Q35-$C35 -> -0.0015954886 | S35: -0.06036663 | T35: =S35-$C35 -> -0.060868612 | U35: -0.0054214 | V35: =U35-$C35 -> -0.0059233818 | W35: 0.045767426 | X35: =W35-$C35 -> 0.045265444 | Y35: -0.04439622 | Z35: =Y35-$C35 -> -0.044898202 | AA35: 0.0024225712 | AB35: =AA35-$C35 -> 0.0019205894 | AC35: -0.00096452236 | AD35: =AC35-$C35 -> -0.0014665042 | AE35: -0.02270466 | AF35: =AE35-$C35 -> -0.023206642
B36: 0.02627 | C36: =(1+B36)^(1/52)-1 -> 0.00049879493 | E36: 45954 | F36: -0.00058156252 | G36: 0.016812682 | H36: =F36-C36 -> -0.0010803575 | I36: =G36-C36 -> 0.016313887 | O36: 0.05945039 | P36: =O36-$C36 -> 0.058951595 | Q36: -0.011351407 | R36: =Q36-$C36 -> -0.011850202 | S36: 0.05584359 | T36: =S36-$C36 -> 0.055344795 | U36: 0.011717796 | V36: =U36-$C36 -> 0.011219001 | W36: 0.0071201324 | X36: =W36-$C36 -> 0.0066213375 | Y36: 0.16521824 | Z36: =Y36-$C36 -> 0.16471945 | AA36: 0.053311944 | AB36: =AA36-$C36 -> 0.052813149 | AC36: 0.19747602 | AD36: =AC36-$C36 -> 0.19697723 | AE36: 0.038271666 | AF36: =AE36-$C36 -> 0.037772871
B37: 0.02583 | C37: =(1+B37)^(1/52)-1 -> 0.00049054414 | E37: 45947 | F37: 0.0017477274 | G37: 0.003686905 | H37: =F37-C37 -> 0.0012571833 | I37: =G37-C37 -> 0.0031963609 | O37: 0.04147196 | P37: =O37-$C37 -> 0.040981416 | Q37: 0.018161774 | R37: =Q37-$C37 -> 0.01767123 | S37: -0.012245059 | T37: =S37-$C37 -> -0.012735603 | U37: 0.02217126 | V37: =U37-$C37 -> 0.021680716 | W37: 0.003195405 | X37: =W37-$C37 -> 0.0027048609 | Y37: 0.03686297 | Z37: =Y37-$C37 -> 0.036372426 | AA37: 0.017873764 | AB37: =AA37-$C37 -> 0.01738322 | AC37: 0.04683256 | AD37: =AC37-$C37 -> 0.046342016 | AE37: -0.019155204 | AF37: =AE37-$C37 -> -0.019645748
B38: 0.02667 | C38: =(1+B38)^(1/52)-1 -> 0.00050629264 | E38: 45940 | F38: -0.04052538 | G38: -0.011026442 | H38: =F38-C38 -> -0.041031673 | I38: =G38-C38 -> -0.011532735 | O38: -0.05099779 | P38: =O38-$C38 -> -0.051504083 | Q38: -0.035562634 | R38: =Q38-$C38 -> -0.036068927 | S38: -0.023082614 | T38: =S38-$C38 -> -0.023588907 | U38: -0.0918768 | V38: =U38-$C38 -> -0.092383093 | W38: -0.039884508 | X38: =W38-$C38 -> -0.040390801 | Y38: -0.0869658 | Z38: =Y38-$C38 -> -0.087472093 | AA38: 0.0011146069 | AB38: =AA38-$C38 -> 0.00060831422 | AC38: -0.066736164 | AD38: =AC38-$C38 -> -0.067242457 | AE38: 0.0010011196 | AF38: =AE38-$C38 -> 0.00049482696
B39: 0.02703 | C39: =(1+B39)^(1/52)-1 -> 0.00051303813 | E39: 45933 | F39: 0.029640198 | G39: 0.028727531 | H39: =F39-C39 -> 0.02912716 | I39: =G39-C39 -> 0.028214493 | O39: 0.1410501 | P39: =O39-$C39 -> 0.14053706 | Q39: 0.017278552 | R39: =Q39-$C39 -> 0.016765514 | S39: -0.022078216 | T39: =S39-$C39 -> -0.022591254 | U39: 0.007930994 | V39: =U39-$C39 -> 0.0074179559 | W39: 0.039197326 | X39: =W39-$C39 -> 0.038684288 | Y39: 0.05059612 | Z39: =Y39-$C39 -> 0.050083082 | AA39: -0.03445673 | AB39: =AA39-$C39 -> -0.034969768 | AC39: -0.02218157 | AD39: =AC39-$C39 -> -0.022694608 | AE39: -0.067053614 | AF39: =AE39-$C39 -> -0.067566652
B40: 0.02741 | C40: =(1+B40)^(1/52)-1 -> 0.00052015586 | E40: 45926 | F40: -0.017528951 | G40: 0.00072193146 | H40: =F40-C40 -> -0.018049107 | I40: =G40-C40 -> 0.0002017756 | O40: -0.06416476 | P40: =O40-$C40 -> -0.064684916 | Q40: -0.057985783 | R40: =Q40-$C40 -> -0.058505939 | S40: 0.0066804886 | T40: =S40-$C40 -> 0.0061603327 | U40: 0.02978611 | V40: =U40-$C40 -> 0.029265954 | W40: 0.035742044 | X40: =W40-$C40 -> 0.035221888 | Y40: 0.03939712 | Z40: =Y40-$C40 -> 0.038876964 | AA40: 0.010572672 | AB40: =AA40-$C40 -> 0.010052516 | AC40: 0.0441792 | AD40: =AC40-$C40 -> 0.043659044 | AE40: 0.0063358545 | AF40: =AE40-$C40 -> 0.0058156986
B41: 0.02738 | C41: =(1+B41)^(1/52)-1 -> 0.00051959402 | E41: 45919 | F41: 0.029095173 | G41: -0.0012977123 | H41: =F41-C41 -> 0.028575579 | I41: =G41-C41 -> -0.0018173063 | O41: 0.056535244 | P41: =O41-$C41 -> 0.05601565 | Q41: -0.047480583 | R41: =Q41-$C41 -> -0.048000177 | S41: 0.0022317171 | T41: =S41-$C41 -> 0.0017121231 | U41: -0.0066809654 | V41: =U41-$C41 -> -0.0072005594 | W41: -0.0040626526 | X41: =W41-$C41 -> -0.0045822466 | Y41: -0.0077599883 | Z41: =Y41-$C41 -> -0.0082795823 | AA41: 0.007668376 | AB41: =AA41-$C41 -> 0.007148782 | AC41: 0.0055470467 | AD41: =AC41-$C41 -> 0.0050274527 | AE41: -0.015222728 | AF41: =AE41-$C41 -> -0.015742322
B42: 0.02704 | C42: =(1+B42)^(1/52)-1 -> 0.00051322547 | E42: 45912 | F42: 0.041199684 | G42: 0.010251045 | H42: =F42-C42 -> 0.040686459 | I42: =G42-C42 -> 0.0097378195 | O42: 0.031612873 | P42: =O42-$C42 -> 0.031099648 | Q42: 0.017751455 | R42: =Q42-$C42 -> 0.01723823 | S42: 0.053081512 | T42: =S42-$C42 -> 0.052568287 | U42: -0.05223882 | V42: =U42-$C42 -> -0.052752045 | W42: -0.023242593 | X42: =W42-$C42 -> -0.023755818 | Y42: -0.0043047667 | Z42: =Y42-$C42 -> -0.0048179922 | AA42: -0.027985632 | AB42: =AA42-$C42 -> -0.028498857 | AC42: 0.0047603846 | AD42: =AC42-$C42 -> 0.0042471591 | AE42: -0.02886659 | AF42: =AE42-$C42 -> -0.029379815
B43: 0.02663 | C43: =(1+B43)^(1/52)-1 -> 0.000505543 | E43: 45905 | F43: -0.017559528 | G43: -0.0016904473 | H43: =F43-C43 -> -0.018065071 | I43: =G43-C43 -> -0.0021959903 | O43: -0.05303031 | P43: =O43-$C43 -> -0.053535853 | Q43: -0.007827759 | R43: =Q43-$C43 -> -0.008333302 | S43: 0.033361077 | T43: =S43-$C43 -> 0.032855534 | U43: -0.011401713 | V43: =U43-$C43 -> -0.011907256 | W43: -0.0080599785 | X43: =W43-$C43 -> -0.0085655215 | Y43: -0.0052259564 | Z43: =Y43-$C43 -> -0.0057314994 | AA43: 0.0266366 | AB43: =AA43-$C43 -> 0.026131057 | AC43: -0.008130908 | AD43: =AC43-$C43 -> -0.008636451 | AE43: 0.02654457 | AF43: =AE43-$C43 -> 0.026039027
B44: 0.02713 | C44: =(1+B44)^(1/52)-1 -> 0.00051491147 | E44: 45898 | F44: 0.0011918545 | G44: -0.019882381 | H44: =F44-C44 -> 0.00067694303 | I44: =G44-C44 -> -0.020397292 | O44: -0.053435087 | P44: =O44-$C44 -> -0.053949998 | Q44: -0.0266667 | R44: =Q44-$C44 -> -0.027181611 | S44: -0.054171267 | T44: =S44-$C44 -> -0.054686178 | U44: -0.021439493 | V44: =U44-$C44 -> -0.021954404 | W44: -0.032462835 | X44: =W44-$C44 -> -0.032977746 | Y44: 0.003668785 | Z44: =Y44-$C44 -> 0.0031538735 | AA44: -0.02250141 | AB44: =AA44-$C44 -> -0.023016321 | AC44: 0.0048837662 | AD44: =AC44-$C44 -> 0.0043688547 | AE44: -0.02075076 | AF44: =AE44-$C44 -> -0.021265671
B45: 0.02727 | C45: =(1+B45)^(1/52)-1 -> 0.00051753384 | E45: 45891 | F45: 0.013591051 | G45: 0.013982177 | H45: =F45-C45 -> 0.013073517 | I45: =G45-C45 -> 0.013464643 | O45: 0.038683295 | P45: =O45-$C45 -> 0.038165761 | Q45: 0.029411793 | R45: =Q45-$C45 -> 0.028894259 | S45: 0.04378557 | T45: =S45-$C45 -> 0.043268036 | U45: 0.014200091 | V45: =U45-$C45 -> 0.013682557 | W45: 0.03046167 | X45: =W45-$C45 -> 0.029944136 | Y45: 0.025698304 | Z45: =Y45-$C45 -> 0.02518077 | AA45: 0.0307616 | AB45: =AA45-$C45 -> 0.030244066 | AC45: 0.036052346 | AD45: =AC45-$C45 -> 0.035534812 | AE45: 0.024923205 | AF45: =AE45-$C45 -> 0.024405671
...

Sheet CCA
B2: Comparable Companies Analysis
B4: =N87 -> Valuation Summary - Renault | G4: =S87 -> Implied Per Share Multiples Value Range | J4: Football Field
F5: =R88 -> 25th | H5: =T88 -> 75th
B6: =N89 -> Comparables | E6: =Q89 -> Minimum | F6: =R89 -> Percentile | G6: =S89 -> Median | H6: =T89 -> Percentile | I6: =U89 -> Maximum
B7: =N90 -> 2027E Enterprise Value / Revenue | E7: =Q90 | F7: =R90 | G7: =S90 -> 9.9641178 | H7: =T90 -> 27.369287 | I7: =U90 -> 138.58244
B8: =N91 -> 2026E Enterprise Value / Revenue | E8: =Q91 | F8: =R91 | G8: =S91 -> 5.5871732 | H8: =T91 -> 26.75349 | I8: =U91 -> 135.45151
B9: =N92 -> 2025E Enterprise Value / Revenue | E9: =Q92 | F9: =R92 | G9: =S92 | H9: =T92 -> 23.417907 | I9: =U92 -> 130.74177
E10: =Q93 | F10: =R93 | G10: =S93 | H10: =T93 | I10: =U93
B11: =N94 -> 2027E Enterprise Value / EBITDA | E11: =Q94 | F11: =R94 | G11: =S94 -> 32.812612 | H11: =T94 -> 114.0622 | I11: =U94 -> 167.98164
B12: =N95 -> 2026E Enterprise Value / EBITDA | E12: =Q95 | F12: =R95 | G12: =S95 -> 29.976955 | H12: =T95 -> 122.18452 | I12: =U95 -> 230.6229
B13: =N96 -> 2025E Enterprise Value / EBITDA | E13: =Q96 | F13: =R96 | G13: =S96 -> 48.711798 | H13: =T96 -> 140.50703 | I13: =U96 -> 630.11649
B15: =N98 -> 2027E P/E Ratio | E15: =Q98 -> 26.000423 | F15: =R98 -> 42.575907 | G15: =S98 -> 51.979337 | H15: =T98 -> 63.193527 | I15: =U98 -> 76.0307
B16: =N99 -> 2026E P/E Ratio | E16: =Q99 -> 31.233211 | F16: =R99 -> 45.010506 | G16: =S99 -> 60.326446 | H16: =T99 -> 70.31905 | I16: =U99 -> 683.35123
B17: =N100 -> 2025E P/E Ratio | E17: =Q100 -> 0 | F17: =R100 -> 0 | G17: =S100 -> 0 | H17: =T100 -> 0 | I17: =U100 -> 0
B19: =N102 -> 2027E Price / Sales | E19: =Q102 -> 22.739119 | F19: =R102 -> 34.774634 | G19: =S102 -> 65.680217 | H19: =T102 -> 77.538196 | I19: =U102 -> 180.59822
B20: =N103 -> 2026E Price / Sales | E20: =Q103 -> 22.362181 | F20: =R103 -> 34.787437 | G20: =S103 -> 65.505591 | H20: =T103 -> 75.931122 | I20: =U103 -> 178.85444
B21: =N104 -> 2025E Price / Sales | E21: =Q104 -> 21.910685 | F21: =R104 -> 35.008505 | G21: =S104 -> 63.892517 | H21: =T104 -> 74.738867 | I21: =U104 -> 176.23135
B23: Valuation Summary - Renault | G23: Implied Per Share Multiples Value Range
F24: 25th | H24: 75th
B25: Comparables | E25: Minimum | F25: Percentile | G25: Median | H25: Percentile | I25: Maximum
B26: CCA EV/Sales | E26: =F126 | F26: =G126 | G26: =H126 -> 8.5051363 | H26: =I126 -> 25.846895 | I26: =J126 -> 134.92524
B27: CCA EV/EBITDA | E27: =F127 | F27: =G127 | G27: =H127 -> 37.167122 | H27: =I127 -> 125.58458 | I27: =J127 -> 342.90701
B28: CCA P/E Multiple | E28: =F128 -> 28.616817 | F28: =G128 -> 43.793207 | G28: =H128 -> 56.152892 | H28: =I128 -> 66.756289 | I28: =J128 -> 379.69096
B29: CCA Price/Sales | E29: =F129 -> 22.337328 | F29: =G129 -> 34.856859 | G29: =H129 -> 65.026108 | H29: =I129 -> 76.069395 | I29: =J129 -> 178.56134
B31: DCF Bear Case | E31: =F131 -> 20.86042 | F31: =G131 -> 25.102995 | G31: =H131 -> 29.933881 | H31: =I131 -> 35.690848 | I31: =J131 -> 42.393804
B32: DCF Base Case | E32: =F132 -> 33.62765 | F32: =G132 -> 40.073925 | G32: =H132 -> 47.649078 | H32: =I132 -> 57.111045 | I32: =J132 -> 68.637101
B33: DCF Bull Case | E33: =F133 -> 51.522008 | F33: =G133 -> 61.420805 | G33: =H133 -> 73.488656 | H33: =I133 -> 89.453925 | I33: =J133 -> 110.06476
B35: CCA Average Value | E35: =F135 -> 24.849124 | F35: =G135 -> 38.431398 | G35: =H135 -> 40.40008 | H35: =I135 -> 74.1832 | I35: =J135 -> 248.05115
B36: DCF Average Value | E36: =F136 -> 35.336693 | F36: =G136 -> 42.199242 | G36: =H136 -> 50.357205 | H36: =I136 -> 60.75194 | I36: =J136 -> 73.698554 | L36: Price on Nov 1st: 33.79
B39: CCA - Comparable Companies Analysis | AC39: Operating cash assessment
AC40: Cash to Sales | AF40: 2017 | AG40: =+AF40+1 -> 2018 | AH40: =+AG40+1 -> 2019 | AI40: =+AH40+1 -> 2020 | AJ40: =+AI40+1 -> 2021 | AK40: =+AJ40+1 -> 2022 | AL40: =+AK40+1 -> 2023 | AM40: =+AL40+1 -> 2024
B41: Operating Statistics | E41: Capitalization | N41: Revenue | Q41: EBITDA | T41: Net Income | Y41: EBITDA Margin | AC41: Stellantis | AF41: {=INDIRECT($AC41&"!E26")/INDIRECT($AC41&"!E16")} -> 0.12413695 | AG41: {=INDIRECT($AC41&"!F26")/INDIRECT($AC41&"!F16")} -> 0.11832953 | AH41: {=INDIRECT($AC41&"!G26")/INDIRECT($AC41&"!G16")} -> 0.14497121 | AI41: {=INDIRECT($AC41&"!H26")/INDIRECT($AC41&"!H16")} -> 0.5 | AJ41: {=INDIRECT($AC41&"!I26")/INDIRECT($AC41&"!I16")} -> 0.34444749 | AK41: {=INDIRECT($AC41&"!J26")/INDIRECT($AC41&"!J16")} -> 0.2800069 | AL41: {=INDIRECT($AC41&"!K26")/INDIRECT($AC41&"!K16")} -> 0.25575064 | AM41: {=INDIRECT($AC41&"!L26")/INDIRECT($AC41&"!L16")} -> 0.23702495
H42: Equity Value € | K42: Enterprise € | W42: Projected | X42: Projected | AC42: Volkswagen | AF42: {=INDIRECT($AC42&"!E26")/INDIRECT($AC42&"!E16")} -> 0.16223481 | AG42: {=INDIRECT($AC42&"!F26")/INDIRECT($AC42&"!F16")} -> 0.20379565 | AH42: {=INDIRECT($AC42&"!G26")/INDIRECT($AC42&"!G16")} -> 0.16898889 | AI42: {=INDIRECT($AC42&"!H26")/INDIRECT($AC42&"!H16")} -> 0.24708368 | AJ42: {=INDIRECT($AC42&"!I26")/INDIRECT($AC42&"!I16")} -> 0.24882094 | AK42: {=INDIRECT($AC42&"!J26")/INDIRECT($AC42&"!J16")} -> 0.23787135 | AL42: {=INDIRECT($AC42&"!K26")/INDIRECT($AC42&"!K16")} -> 0.21788547 | AM42: {=INDIRECT($AC42&"!L26")/INDIRECT($AC42&"!L16")} -> 0.20828816
B43: Company Name | E43: Share Price | G43: Diluted Shares | H43: Millions | I43: Cash | J43: Debt | K43: Value | L43: ROE | M43: ROIC | N43: 2025E | O43: 2026E | P43: 2027E | Q43: 2025E | R43: 2026E | S43: 2027E | T43: 2025E | U43: 2026E | V43: 2027E | W43: Revenue Growth | X43: EBITDA Growth | Y43: 2025E | Z43: 2026E | AA43: 2027E | AC43: Nissan | AF43: {=INDIRECT($AC43&"!E26")/INDIRECT($AC43&"!E16")} -> 0.099928232 | AG43: {=INDIRECT($AC43&"!F26")/INDIRECT($AC43&"!F16")} -> 0.12126319 | AH43: {=INDIRECT($AC43&"!G26")/INDIRECT($AC43&"!G16")} -> 0.16960048 | AI43: {=INDIRECT($AC43&"!H26")/INDIRECT($AC43&"!H16")} -> 0.24617634 | AJ43: {=INDIRECT($AC43&"!I26")/INDIRECT($AC43&"!I16")} -> 0.20564118 | AK43: {=INDIRECT($AC43&"!J26")/INDIRECT($AC43&"!J16")} -> 0.18528059 | AL43: {=INDIRECT($AC43&"!K26")/INDIRECT($AC43&"!K16")} -> 0.16121065 | AM43: {=INDIRECT($AC43&"!L26")/INDIRECT($AC43&"!L16")} -> 0.17624228
B44: Stellantis | F44: {=INDIRECT(B44&"!F9")} -> 8.778 | G44: {=INDIRECT(B44&"!R29")} -> 2888.724 | H44: =G44*F44 -> 25357.219 | I44: {=INDIRECT(B44&"!R26")} -> 32836 | J44: {=INDIRECT(B44&"!R27")} -> 40799 | K44: =H44-I44+J44 -> 33320.219 | L44: {=INDIRECT(B44&"!R30")} -> -0.05829118 | M44: {=INDIRECT(B44&"!R31")} -> 0.01005186 | N44: {=INDIRECT($B44&"!M16")} -> 152552.69 | O44: {=INDIRECT($B44&"!N16")} -> 160481.22 | P44: {=INDIRECT($B44&"!O16")} -> 166401.67 | Q44: {=INDIRECT($B44&"!M18")} -> 8945.5205 | R44: {=INDIRECT($B44&"!N18")} -> 13659.609 | S44: {=INDIRECT($B44&"!O18")} -> 16062.637 | T44: {=INDIRECT($B44&"!M22")} -> 2086.0842 | U44: {=INDIRECT($B44&"!N22")} -> 4879.009 | V44: {=INDIRECT($B44&"!O22")} -> 6472.0327 | W44: =SQRT(P44/N44)-1 -> 0.044404911 | X44: =IFERROR(SQRT(S44/Q44)-1,"N/A") -> 0.34000252 | Y44: =Q44/N44 -> 0.058638891 | Z44: =R44/O44 -> 0.085116558 | AA44: =S44/P44 -> 0.096529302 | AC44: BMW | AF44: {=INDIRECT($AC44&"!E26")/INDIRECT($AC44&"!E16")} -> 0.091970045 | AG44: {=INDIRECT($AC44&"!F26")/INDIRECT($AC44&"!F16")} -> 0.11335502 | AH44: {=INDIRECT($AC44&"!G26")/INDIRECT($AC44&"!G16")} -> 0.11549755 | AI44: {=INDIRECT($AC44&"!H26")/INDIRECT($AC44&"!H16")} -> 0.13675119 | AJ44: {=INDIRECT($AC44&"!I26")/INDIRECT($AC44&"!I16")} -> 0.14391535 | AK44: {=INDIRECT($AC44&"!J26")/INDIRECT($AC44&"!J16")} -> 0.11829465 | AL44: {=INDIRECT($AC44&"!K26")/INDIRECT($AC44&"!K16")} -> 0.11142909 | AM44: {=INDIRECT($AC44&"!L26")/INDIRECT($AC44&"!L16")} -> 0.13546144
B45: Volkswagen | F45: {=INDIRECT(B45&"!F9")} -> 91.35 | G45: {=INDIRECT(B45&"!R29")} -> 501.29526 | H45: =G45*F45 -> 45793.322 | I45: {=INDIRECT(B45&"!R26")} -> 65550 | J45: {=INDIRECT(B45&"!R27")} -> 271470 | K45: =H45-I45+J45 -> 251713.32 | L45: {=INDIRECT(B45&"!R30")} -> 0.040037059 | M45: {=INDIRECT(B45&"!R31")} -> 0.021366767 | N45: {=INDIRECT($B45&"!M16")} -> 324823.84 | O45: {=INDIRECT($B45&"!N16")} -> 331772.66 | P45: {=INDIRECT($B45&"!O16")} -> 340765.84 | Q45: {=INDIRECT($B45&"!M18")} -> 38573.105 | R45: {=INDIRECT($B45&"!N18")} -> 46299.426 | S45: {=INDIRECT($B45&"!O18")} -> 50404.945 | T45: {=INDIRECT($B45&"!M22")} -> 4917.487 | U45: {=INDIRECT($B45&"!N22")} -> 10889.342 | V45: {=INDIRECT($B45&"!O22")} -> 13216.16 | W45: =SQRT(P45/N45)-1 -> 0.024245532 | X45: =IFERROR(SQRT(S45/Q45)-1,"N/A") -> 0.14312645 | Y45: =Q45/N45 -> 0.11875084 | Z45: =R45/O45 -> 0.13955166 | AA45: =S45/P45 -> 0.14791666 | AC45: MercedesBenz | AF45: {=INDIRECT($AC45&"!E26")/INDIRECT($AC45&"!E16")} -> 0.12881197 | AG45: {=INDIRECT($AC45&"!F26")/INDIRECT($AC45&"!F16")} -> 0.14763208 | AH45: {=INDIRECT($AC45&"!G26")/INDIRECT($AC45&"!G16")} -> 0.15495673 | AI45: {=INDIRECT($AC45&"!H26")/INDIRECT($AC45&"!H16")} -> 0.2332441 | AJ45: {=INDIRECT($AC45&"!I26")/INDIRECT($AC45&"!I16")} -> 0.22275997 | AK45: {=INDIRECT($AC45&"!J26")/INDIRECT($AC45&"!J16")} -> 0.15942193 | AL45: {=INDIRECT($AC45&"!K26")/INDIRECT($AC45&"!K16")} -> 0.14516044 | AM45: {=INDIRECT($AC45&"!L26")/INDIRECT($AC45&"!L16")} -> 0.14833716
B46: Nissan | F46: {=INDIRECT(B46&"!F9")} -> 1.9880741 | G46: {=INDIRECT(B46&"!R29")} -> 3495.7389 | H46: =F46*G46 -> 6949.788 | I46: {=INDIRECT(B46&"!R26")} -> 13094.437 | J46: {=INDIRECT(B46&"!R27")} -> 51122.825 | K46: =H46-I46+J46 -> 44978.175 | L46: {=INDIRECT(B46&"!R30")} -> -0.17337875 | M46: {=INDIRECT(B46&"!R31")} -> -0.088023497 | N46: {=INDIRECT($B46&"!M16")} -> 66804.76 | O46: {=INDIRECT($B46&"!N16")} -> 68423.05 | P46: {=INDIRECT($B46&"!O16")} -> 69745.555 | Q46: {=INDIRECT($B46&"!M18")} -> 1382.472 | R46: {=INDIRECT($B46&"!N18")} -> 2853.257 | S46: {=INDIRECT($B46&"!O18")} -> 3462.0366 | T46: {=INDIRECT($B46&"!M22")} -> -1686.8341 | U46: {=INDIRECT($B46&"!N22")} -> 75.53421 | V46: {=INDIRECT($B46&"!O22")} -> 773.1631 | W46: =SQRT(P46/N46)-1 -> 0.021773331 | X46: =IFERROR(SQRT(S46/Q46)-1,"N/A") -> 0.58247791 | Y46: =Q46/N46 -> 0.020694214 | Z46: =R46/O46 -> 0.041700231 | AA46: =S46/P46 -> 0.049638097 | AC46: Ford | AF46: {=INDIRECT($AC46&"!E26")/INDIRECT($AC46&"!E16")} -> 0.2332301 | AG46: {=INDIRECT($AC46&"!F26")/INDIRECT($AC46&"!F16")} -> 0.21852582 | AH46: {=INDIRECT($AC46&"!G26")/INDIRECT($AC46&"!G16")} -> 0.22162048 | AI46: {=INDIRECT($AC46&"!H26")/INDIRECT($AC46&"!H16")} -> 0.36610752 | AJ46: {=INDIRECT($AC46&"!I26")/INDIRECT($AC46&"!I16")} -> 0.37806592 | AK46: {=INDIRECT($AC46&"!J26")/INDIRECT($AC46&"!J16")} -> 0.27457137 | AL46: {=INDIRECT($AC46&"!K26")/INDIRECT($AC46&"!K16")} -> 0.22313946 | AM46: {=INDIRECT($AC46&"!L26")/INDIRECT($AC46&"!L16")} -> 0.21654231
B47: BMW | F47: {=INDIRECT(B47&"!F9")} -> 80.72 | G47: {=INDIRECT(B47&"!R29")} -> 609.81512 | H47: =F47*G47 -> 49224.277 | I47: {=INDIRECT(B47&"!R26")} -> 19257 | J47: {=INDIRECT(B47&"!R27")} -> 107748 | K47: =H47-I47+J47 -> 137715.28 | L47: {=INDIRECT(B47&"!R30")} -> 0.076269943 | M47: {=INDIRECT(B47&"!R31")} -> 0.045064564 | N47: {=INDIRECT($B47&"!M16")} -> 138715.39 | O47: {=INDIRECT($B47&"!N16")} -> 142726.48 | P47: {=INDIRECT($B47&"!O16")} -> 147509.86 | Q47: {=INDIRECT($B47&"!M18")} -> 19217.615 | R47: {=INDIRECT($B47&"!N18")} -> 20805.014 | S47: {=INDIRECT($B47&"!O18")} -> 22766.3 | T47: {=INDIRECT($B47&"!M22")} -> 6489.721 | U47: {=INDIRECT($B47&"!N22")} -> 6961.953 | V47: {=INDIRECT($B47&"!O22")} -> 7871.975 | W47: =SQRT(P47/N47)-1 -> 0.031212578 | X47: =IFERROR(SQRT(S47/Q47)-1,"N/A") -> 0.088419923 | Y47: =Q47/N47 -> 0.13853989 | Z47: =R47/O47 -> 0.14576842 | AA47: =S47/P47 -> 0.15433748 | AC47: Toyota | AF47: {=INDIRECT($AC47&"!E26")/INDIRECT($AC47&"!E16")} -> 0.19282519 | AG47: {=INDIRECT($AC47&"!F26")/INDIRECT($AC47&"!F16")} -> 0.19914121 | AH47: {=INDIRECT($AC47&"!G26")/INDIRECT($AC47&"!G16")} -> 0.1399382 | AI47: {=INDIRECT($AC47&"!H26")/INDIRECT($AC47&"!H16")} -> 0.17835929 | AJ47: {=INDIRECT($AC47&"!I26")/INDIRECT($AC47&"!I16")} -> 0.18828154 | AK47: {=INDIRECT($AC47&"!J26")/INDIRECT($AC47&"!J16")} -> 0.19719277 | AL47: {=INDIRECT($AC47&"!K26")/INDIRECT($AC47&"!K16")} -> 0.20019118 | AM47: {=INDIRECT($AC47&"!L26")/INDIRECT($AC47&"!L16")} -> 0.18945754
B48: Mercedes Benz | F48: =MercedesBenz!F9 -> 56.21 | G48: =MercedesBenz!R29 -> 962.9037 | H48: =F48*G48 -> 54124.817 | I48: =MercedesBenz!R26 -> 22496 | J48: =MercedesBenz!R27 -> 102343 | K48: =H48-I48+J48 -> 133971.82 | L48: =MercedesBenz!R30 -> 0.068815547 | M48: =MercedesBenz!R31 -> 0.039276434 | N48: =MercedesBenz!M16 -> 134542.77 | O48: =MercedesBenz!N16 -> 135827.06 | P48: =MercedesBenz!O16 -> 140007.02 | Q48: =MercedesBenz!M18 -> 14753.084 | R48: =MercedesBenz!N18 -> 16532.469 | S48: =MercedesBenz!O18 -> 18476.857 | T48: =MercedesBenz!M22 -> 5118.2974 | U48: =MercedesBenz!N22 -> 6663.537 | V48: =MercedesBenz!O22 -> 7813.5654 | W48: =SQRT(P48/N48)-1 -> 0.020104641 | X48: =IFERROR(SQRT(S48/Q48)-1,"N/A") -> 0.11910965 | Y48: =Q48/N48 -> 0.10965349 | Z48: =R48/O48 -> 0.12171705 | AA48: =S48/P48 -> 0.13197093 | AC48: GeneralMotors | AF48: {=INDIRECT($AC48&"!E26")/INDIRECT($AC48&"!E16")} -> 0.16497509 | AG48: {=INDIRECT($AC48&"!F26")/INDIRECT($AC48&"!F16")} -> 0.20277631 | AH48: {=INDIRECT($AC48&"!G26")/INDIRECT($AC48&"!G16")} -> 0.19322753 | AI48: {=INDIRECT($AC48&"!H26")/INDIRECT($AC48&"!H16")} -> 0.24051304 | AJ48: {=INDIRECT($AC48&"!I26")/INDIRECT($AC48&"!I16")} -> 0.25869883 | AK48: {=INDIRECT($AC48&"!J26")/INDIRECT($AC48&"!J16")} -> 0.21147604 | AL48: {=INDIRECT($AC48&"!K26")/INDIRECT($AC48&"!K16")} -> 0.16556296 | AM48: {=INDIRECT($AC48&"!L26")/INDIRECT($AC48&"!L16")} -> 0.16576776
B49: Toyota | F49: {=INDIRECT(B49&"!F9")} -> 17.648024 | G49: {=INDIRECT(B49&"!R29")} -> 13033.389 | H49: =F49*G49 -> 230013.57 | I49: {=INDIRECT(B49&"!R26")} -> 46752.309 | J49: {=INDIRECT(B49&"!R27")} -> 229725.74 | K49: =H49-I49+J49 -> 412987 | L49: {=INDIRECT(B49&"!R30")} -> 0.12889945 | M49: {=INDIRECT(B49&"!R31")} -> 0.079094679 | N49: {=INDIRECT(B49&"!M16")} -> 274892 | O49: {=INDIRECT($B49&"!N16")} -> 283138.38 | P49: {=INDIRECT($B49&"!O16")} -> 290642.16 | Q49: {=INDIRECT($B49&"!M18")} -> 31747.256 | R49: {=INDIRECT($B49&"!N18")} -> 35426.26 | S49: {=INDIRECT($B49&"!O18")} -> 37506.48 | T49: {=INDIRECT($B49&"!M22")} -> 18217.3 | U49: {=INDIRECT($B49&"!N22")} -> 21142.232 | V49: {=INDIRECT($B49&"!O22")} -> 22701.158 | W49: =SQRT(P49/N49)-1 -> 0.028248905 | X49: =IFERROR(SQRT(S49/Q49)-1,"N/A") -> 0.086926198 | Y49: =Q49/N49 -> 0.11548992 | Z49: =R49/O49 -> 0.12511995 | AA49: =S49/P49 -> 0.12904694 | AC49: Honda | AF49: {=INDIRECT($AC49&"!E26")/INDIRECT($AC49&"!E16")} -> 0.14546115 | AG49: {=INDIRECT($AC49&"!F26")/INDIRECT($AC49&"!F16")} -> 0.162112 | AH49: {=INDIRECT($AC49&"!G26")/INDIRECT($AC49&"!G16")} -> 0.18251826 | AI49: {=INDIRECT($AC49&"!H26")/INDIRECT($AC49&"!H16")} -> 0.19927324 | AJ49: {=INDIRECT($AC49&"!I26")/INDIRECT($AC49&"!I16")} -> 0.24403868 | AK49: {=INDIRECT($AC49&"!J26")/INDIRECT($AC49&"!J16")} -> 0.21923011 | AL49: {=INDIRECT($AC49&"!K26")/INDIRECT($AC49&"!K16")} -> 0.23262394 | AM49: {=INDIRECT($AC49&"!L26")/INDIRECT($AC49&"!L16")} -> 0.21156329
...

Sheet Valuation
B2: Financial Model
B4: Assumptions & Drivers
B6: Date | D6: =DATE(2025,11,1) -> 45962 | H6: TGR Assumptions:
B7: FYE | D7: =DATE(2025,12,31) -> 46022 | H7: Conservative Est | L7: 0.01
H8: European Union | L8: 0.015
B9: WACC Case | D9: {=INDEX(WACC!F33:F35,Valuation!$E$9)} -> Worst Case | E9: 3 | H9: NOPAT | L9: =L114 -> 0.029709657
B10: TGR | D10: =MIN(MAX(INDEX(L7:L10,Valuation!$E$10),0),L129-0.01%) -> 0.02 | E10: 4 | H10: Custom | L10: 0.02
B12: Supporting Schedules
B14: Income Statement Adjusted and Reorganized
B15: All figures in EUR(€) millions unless stated
E16: 2024 | F16: 2025 | G16: 2026 | H16: 2027 | I16: 2028 | J16: 2029 | K16: 2030 | L16: =+K16+1 -> 2031
E17: 2024 | F17: 2025 | G17: 2026 | H17: 2027 | I17: 2028 | J17: 2029 | K17: 2030 | L17: =+K17+1 -> 2031
B18: Revenues | E18: ='Main Financials'!N8 -> 56232 | F18: ='Main Financials'!O8 -> 57595.111 | G18: ='Main Financials'!P8 -> 60205.87 | H18: ='Main Financials'!Q8 -> 62404 | I18: ='Main Financials'!R8 -> 63485.794 | J18: ='Main Financials'!S8 -> 66042.052 | K18: ='Main Financials'!T8 -> 63615.972 | L18: ='Main Financials'!U8 -> 65725.275
B19: Cost of sales (excl. D&A exp.) | E19: ='Main Financials'!N9 -> -41332 | F19: ='Main Financials'!O9 -> -40730.819 | G19: ='Main Financials'!P9 -> -42301.955 | H19: ='Main Financials'!Q9 -> -43958.884 | I19: ='Main Financials'!R9 -> -44767.303 | J19: ='Main Financials'!S9 -> -46492.074 | K19: ='Main Financials'!T9 -> -44247.227 | L19: ='Main Financials'!U9 -> -45576.103
B20: Gross profit | E20: =SUM(E18:E19) -> 14900 | F20: =SUM(F18:F19) -> 16864.293 | G20: =SUM(G18:G19) -> 17903.915 | H20: =SUM(H18:H19) -> 18445.116 | I20: =SUM(I18:I19) -> 18718.491 | J20: =SUM(J18:J19) -> 19549.978 | K20: =SUM(K18:K19) -> 19368.746 | L20: =SUM(L18:L19) -> 20149.172
B21: Total SGA + other operating expenses (excl. D&A) | E21: ='Main Financials'!N11 -> -9154 | F21: ='Main Financials'!O11 -> -10007.358 | G21: ='Main Financials'!P11 -> -10682.17 | H21: ='Main Financials'!Q11 -> -11001.03 | I21: ='Main Financials'!R11 -> -11083.06 | J21: ='Main Financials'!S11 -> -11632.474 | K21: ='Main Financials'!T11 -> -11583.787 | L21: ='Main Financials'!U11 -> -12050.705
B22: EBITDA | E22: =SUM(E20:E21) -> 5746 | F22: =SUM(F20:F21) -> 6856.9353 | G22: =SUM(G20:G21) -> 7221.7443 | H22: =SUM(H20:H21) -> 7444.0856 | I22: =SUM(I20:I21) -> 7635.4309 | J22: =SUM(J20:J21) -> 7917.5036 | K22: =SUM(K20:K21) -> 7784.9587 | L22: =SUM(L20:L21) -> 8098.4674
B23: Depreciation expenses | E23: ='Main Financials'!N13 -> -2120 | F23: ='Main Financials'!O13 -> -2303.8045 | G23: ='Main Financials'!P13 -> -2408.2348 | H23: ='Main Financials'!Q13 -> -2496.16 | I23: ='Main Financials'!R13 -> -2539.4318 | J23: ='Main Financials'!S13 -> -2641.6821 | K23: ='Main Financials'!T13 -> -2544.6389 | L23: ='Main Financials'!U13 -> -2629.011
B24: Depreciation on right-of-use assets (i.e., operating lease assets) | E24: ='Main Financials'!N14 -> 0 | F24: ='Main Financials'!O14 -> 0 | G24: ='Main Financials'!P14 -> 0 | H24: ='Main Financials'!Q14 -> 0 | I24: ='Main Financials'!R14 -> 0 | J24: ='Main Financials'!S14 -> 0 | K24: ='Main Financials'!T14 -> 0 | L24: ='Main Financials'!U14 -> 0
B25: EBITA | E25: =SUM(E22:E24) -> 3626 | F25: =SUM(F22:F24) -> 4553.1309 | G25: =SUM(G22:G24) -> 4813.5095 | H25: =SUM(H22:H24) -> 4947.9255 | I25: =SUM(I22:I24) -> 5095.9991 | J25: =SUM(J22:J24) -> 5275.8216 | K25: =SUM(K22:K24) -> 5240.3198 | L25: =SUM(L22:L24) -> 5469.4564
B26: Amortization expenses | E26: ='Main Financials'!N16 -> -1048 | F26: ='Main Financials'!O16 -> -1439.8778 | G26: ='Main Financials'!P16 -> -1505.1467 | H26: ='Main Financials'!Q16 -> -1560.1 | I26: ='Main Financials'!R16 -> -1587.1449 | J26: ='Main Financials'!S16 -> -1651.0513 | K26: ='Main Financials'!T16 -> -1590.3993 | L26: ='Main Financials'!U16 -> -1643.1319
B27: EBIT before non-recurring items | E27: =SUM(E25:E26) -> 2578 | F27: =SUM(F25:F26) -> 3113.2531 | G27: =SUM(G25:G26) -> 3308.3628 | H27: =SUM(H25:H26) -> 3387.8255 | I27: =SUM(I25:I26) -> 3508.8543 | J27: =SUM(J25:J26) -> 3624.7703 | K27: =SUM(K25:K26) -> 3649.9205 | L27: =SUM(L25:L26) -> 3826.3245
B29: Reorganized Balance Sheet
B30: All figures in EUR(€) millions unless stated
E31: 2024 | F31: 2025 | G31: 2026 | H31: 2027 | I31: 2028 | J31: 2029 | K31: 2030 | L31: =+K31+1 -> 2031
E32: 2024 | F32: 2025 | G32: 2026 | H32: 2027 | I32: 2028 | J32: 2029 | K32: 2030 | L32: =+K32+1 -> 2031
B33: Operating fixed assets | E33: =SUM(E34:E36) -> 20078 | F33: =SUM(F34:F36) -> 21987.818 | G33: =SUM(G34:G36) -> 23917.111 | H33: =SUM(H34:H36) -> 25948.689 | I33: =SUM(I34:I36) -> 28011.956 | J33: =SUM(J34:J36) -> 30215.56 | K33: =SUM(K34:K36) -> 32290.498 | L33: =SUM(L34:L36) -> 34530.454
B34: Intangible assets and goodwill | E34: ='Main Financials'!N93 -> 5164 | F34: ='Main Financials'!O93 -> 5798.7009 | G34: ='Main Financials'!P93 -> 6460.8188 | H34: ='Main Financials'!Q93 -> 7161.8147 | I34: ='Main Financials'!R93 -> 7883.3701 | J34: ='Main Financials'!S93 -> 8645.0337 | K34: ='Main Financials'!T93 -> 9396.0973 | L34: ='Main Financials'!U93 -> 10175.547
B35: Property, plant and equipment | E35: ='Main Financials'!N94 -> 13861 | F35: ='Main Financials'!O94 -> 15037.215 | G35: ='Main Financials'!P94 -> 16252.175 | H35: ='Main Financials'!Q94 -> 17538.794 | I35: ='Main Financials'!R94 -> 18858.87 | J35: ='Main Financials'!S94 -> 20249.686 | K35: ='Main Financials'!T94 -> 21622.081 | L35: ='Main Financials'!U94 -> 23040.402
B36: Other non-current assets | E36: ='Main Financials'!N95 -> 1053 | F36: ='Main Financials'!O95 -> 1151.9022 | G36: ='Main Financials'!P95 -> 1204.1174 | H36: ='Main Financials'!Q95 -> 1248.08 | I36: ='Main Financials'!R95 -> 1269.7159 | J36: ='Main Financials'!S95 -> 1320.841 | K36: ='Main Financials'!T95 -> 1272.3194 | L36: ='Main Financials'!U95 -> 1314.5055
B38: Operating net working capital | E38: =SUM(E39:E45) -> 18272.41 | F38: =SUM(F39:F45) -> 18047.101 | G38: =SUM(G39:G45) -> 18880.6 | H38: =SUM(H39:H45) -> 19545.751 | I38: =SUM(I39:I45) -> 19873.87 | J38: =SUM(J39:J45) -> 20669.538 | K38: =SUM(K39:K45) -> 19981.01 | L38: =SUM(L39:L45) -> 20647.895
B39: Inventories | E39: ='Main Financials'!N98 -> 5468 | F39: ='Main Financials'!O98 -> 5579.5642 | G39: ='Main Financials'!P98 -> 5794.7884 | H39: ='Main Financials'!Q98 -> 6021.765 | I39: ='Main Financials'!R98 -> 6132.5072 | J39: ='Main Financials'!S98 -> 6368.7772 | K39: ='Main Financials'!T98 -> 6061.2639 | L39: ='Main Financials'!U98 -> 6243.3018
B40: Sales financing recievables | E40: ='Main Financials'!N99 -> 54355 | F40: ='Main Financials'!O99 -> 53650.241 | G40: ='Main Financials'!P99 -> 56082.18 | H40: ='Main Financials'!Q99 -> 58129.754 | I40: ='Main Financials'!R99 -> 59137.452 | J40: ='Main Financials'!S99 -> 61518.624 | K40: ='Main Financials'!T99 -> 59258.714 | L40: ='Main Financials'!U99 -> 61223.544
B41: Automotive recivable & other current assets (excl. tax and current tax due) | E41: ='Main Financials'!N100 -> 6137 | F41: ='Main Financials'!O100 -> 6311.793 | G41: ='Main Financials'!P100 -> 6597.9035 | H41: ='Main Financials'!Q100 -> 6838.7946 | I41: ='Main Financials'!R100 -> 6957.3473 | J41: ='Main Financials'!S100 -> 7237.4851 | K41: ='Main Financials'!T100 -> 6971.6134 | L41: ='Main Financials'!U100 -> 7202.7699
B42: Derivatives of financing operations by the Automotive segment | E42: ='Main Financials'!N101 -> 356 | F42: ='Main Financials'!O101 -> 324.8 | G42: ='Main Financials'!P101 -> 324.8 | H42: ='Main Financials'!Q101 -> 324.8 | I42: ='Main Financials'!R101 -> 324.8 | J42: ='Main Financials'!S101 -> 324.8 | K42: ='Main Financials'!T101 -> 324.8 | L42: ='Main Financials'!U101 -> 324.8
B43: Operating Cash | E43: ='Main Financials'!N102 -> 22203.41 | F43: ='Main Financials'!O102 -> 22185.952 | G43: ='Main Financials'!P102 -> 23191.631 | H43: ='Main Financials'!Q102 -> 24038.363 | I43: ='Main Financials'!R102 -> 24455.076 | J43: ='Main Financials'!S102 -> 25439.76 | K43: ='Main Financials'!T102 -> 24505.221 | L43: ='Main Financials'!U102 -> 25317.736
B44: Sales financing debts | E44: ='Main Financials'!N103 -> -60438 | F44: ='Main Financials'!O103 -> -59962.034 | G44: ='Main Financials'!P103 -> -62680.084 | H44: ='Main Financials'!Q103 -> -64968.548 | I44: ='Main Financials'!R103 -> -66094.799 | J44: ='Main Financials'!S103 -> -68756.109 | K44: ='Main Financials'!T103 -> -66230.327 | L44: ='Main Financials'!U103 -> -68426.314
B45: Trade payables (current) | E45: ='Main Financials'!N104 -> -9809 | F45: ='Main Financials'!O104 -> -10043.216 | G45: ='Main Financials'!P104 -> -10430.619 | H45: ='Main Financials'!Q104 -> -10839.177 | I45: ='Main Financials'!R104 -> -11038.513 | J45: ='Main Financials'!S104 -> -11463.799 | K45: ='Main Financials'!T104 -> -10910.275 | L45: ='Main Financials'!U104 -> -11237.943
B47: Operating Liabilities | E47: =SUM(E48:E51) -> -15980 | F47: =SUM(F48:F51) -> -16239.518 | G47: =SUM(G48:G51) -> -16975.647 | H47: =SUM(H48:H51) -> -17595.432 | I47: =SUM(I48:I51) -> -17900.455 | J47: =SUM(J48:J51) -> -18621.217 | K47: =SUM(K48:K51) -> -17937.16 | L47: =SUM(L48:L51) -> -18531.899
B48: Net deferred tax liabilities associated with operating ítems | E48: ='Main Financials'!N107 -> -1269 | F48: ='Main Financials'!O107 -> -1290.1305 | G48: ='Main Financials'!P107 -> -1348.6115 | H48: ='Main Financials'!Q107 -> -1397.8496 | I48: ='Main Financials'!R107 -> -1422.0818 | J48: ='Main Financials'!S107 -> -1479.342 | K48: ='Main Financials'!T107 -> -1424.9978 | L48: ='Main Financials'!U107 -> -1472.2462
...

Sheet Macro
B2: Inflation Input
E4: 2015 | F4: 2016 | G4: 2017 | H4: 2018 | I4: 2019 | J4: 2020 | K4: 2021 | L4: 2022 | M4: 2023 | N4: 2024 | O4: 2025 | P4: 2026 | Q4: 2027 | R4: 2028 | S4: 2029 | T4: 2030 | U4: =+T4+1 -> 2031
B6: European Union | E6: 0.03 | F6: 0.011 | G6: 0.01499 | H6: 0.01695 | I6: 0.01559 | J6: 0.00157 | K6: 0.05346 | L6: 0.10762 | M6: 0.03215 | N6: 0.02655 | O6: 0.02253 | P6: 0.02074 | Q6: 0.02157 | R6: 0.02097 | S6: 0.02122 | T6: 0.02065 | U6: 0.02
B8: Compounded inflation multiple | E8: =F8*(1+F6) -> 1.3123329 | F8: =G8*(1+G6) -> 1.2980543 | G8: =H8*(1+H6) -> 1.2788838 | H8: =I8*(1+I6) -> 1.257568 | I8: =J8*(1+J6) -> 1.2382635 | J8: =K8*(1+K6) -> 1.2363225 | K8: =L8*(1+L6) -> 1.1735827 | L8: =M8*(1+M6) -> 1.0595536 | M8: =N8*(1+N6) -> 1.02655 | N8: 1 | O8: =N8*(1+O6) -> 1.02253 | P8: =O8*(1+P6) -> 1.0437373 | Q8: =P8*(1+Q6) -> 1.0662507 | R8: =Q8*(1+R6) -> 1.08861 | S8: =R8*(1+S6) -> 1.1117103 | T8: =S8*(1+T6) -> 1.1346671 | U8: =T8*(1+U6) -> 1.1573604
B11: Tax Rates
