Workbook
Name Cash_to_sales_ratio: #REF!
Name cs_fd_outstanding: #REF!
Name MarginalTax: #REF!
Name TGR: #REF!

Sheet __FDSCACHE__
B1: This sheet contains FactSet XML data for use with this workbook's =FDS codes. Modifying the worksheet's contents may damage the workbook's =FDS functionality.

Sheet Assignment Manager
B2: Basics
B4: Company | E4: Renault SA
B5: $/Share Estimate Deadline | E5: 45962
B6: Final Document Deadline | E6: 45989
B7: OUR DEADLINE | E7: 45983
B9: Grading Rubric
B11: Team Members | E11: ID | G11: Abbreviation
B12: Jordy Dikken | E12: 673670 | G12: JD
B13: Jorick Stoel | E13: 694007 | G13: JS
B14: Rikus van der Vegt | E14: 666665 | G14: RV
B15: Theodor Hogan | E15: 754441 | G15: TH
B17: Grading Rubric
B19: Evaluation Criterion | H19: Weight
B20: Reorganizing balancsheet and income statement | H20: 0.1 | I20: TH
B21: Adjustments to income statement and balancesheet; calculating key ratios | H21: 0.1 | I21: JD
B22: Projections of future cash cashflows and continuing (i.e. stable) growth rate | H22: 0.2 | I22: TH, RV
B23: Estimating the cost of debt, cost of equity, cost of capital | H23: 0.2 | I23: JD, JS
B24: Implemeting WACC; appropriate post DCF value adj. to estime $/shr | H24: 0.15 | I24: TH, RV
B25: Sensititivity analysis | H25: 0.05 | I25: RV
B26: Correctly identifiying peers and implementing multiples valuation | H26: 0.15 | I26: JD, JS
B27: General presentation and readability of Excel file | H27: 0.05 | I27: JD, JS, RV, TH
B28: Total | H28: =SUM(H20:H27) -> 1

Sheet Cover
C3: Kion Recapitalization Proposal
C5: Rotterdam School of Management
C6: Msc. Finance & Investment
C8: Last Update: | D8: 46011
C10: Authors: Jordy Dikken (673670), Jorick Stoel (694007),
C11: Rikus van der Vegt (666665) & Theodor Hogan (754441)
C15: #VALUE!
C21: Format: | E21: =D2*1.1+25*A2 -> 0
C22: Hardcode | D22: XXX
C23: Sheet Link | D23: XXX
C24: Ext. Link | D24: XXX | E24: Note: FactSet live links have been broken for compatability.
C25: Mixed Formula | D25: XXX | E25: =_xlfn.FORMULATEXT(E21) -> =D2*1.1+25*A2
C26: Assumptions | D26: XXX
C28: Font | D28: Arial
C29: Default | D29: 10 pt
C31: Input Field | D31: [Input]

Sheet Recapitalization
B2: Recapitalization Summary
B4: Active Scenario | C4: =IF(C27 = 1, "Base", "Adverse") -> Base
B6: Summary and Forecast | E6: =2019 -> 2019 | F6: =E6+1 -> 2020 | G6: =F6+1 -> 2021 | H6: =G6+1 -> 2022 | I6: =H6+1 -> 2023 | J6: =I6+1 -> 2024 | K6: =J6+1 -> 2025 | L6: =K6+1 -> 2026 | M6: =L6+1 -> 2027
B7: Key Figures
B8: Revenue | E8: =I30 -> 8806.5 | F8: =J30 -> 8341.6 | G8: =K30 -> 10294.3 | H8: =L30 -> 11135.6 | I8: =M30 -> 11433.7 | J8: =N30 -> 11503.2 | K8: =R30 -> 12653.52 | L8: =S30 -> 13792.337 | M8: =T30 -> 14895.724
B9: EBITDA | E9: =I40 -> 1646.7 | F9: =J40 -> 1413.8 | G9: =K40 -> 1845.7 | H9: =L40 -> 1306.1 | I9: =M40 -> 1833 | J9: =N40 -> 2037.5 | K9: =R40 -> 2277.6336 | L9: =S40 -> 2482.6206 | M9: =T40 -> 2681.2303
B10: EBIT | E10: =I43 -> 755.7 | F10: =J43 -> 497.7 | G10: =K43 -> 906.8 | H10: =L43 -> 292.8 | I10: =M43 -> 786.5 | J10: =N43 -> 926.7 | K10: =R43 -> 1025.8198 | L10: =S43 -> 1118.1435 | M10: =T43 -> 1207.595
B11: Net income | E11: =I50 -> 454.8 | F11: =J50 -> 215.3 | G11: =K50 -> 568.3 | H11: =L50 -> 98 | I11: =M50 -> 305.8 | J11: =N50 -> 360.4 | K11: =R50 -> 405.21254 | L11: =S50 -> 469.93151 | M11: =T50 -> 532.637 | W11: =2019 -> 2019 | X11: =W11+1 -> 2020 | Y11: =X11+1 -> 2021 | Z11: =Y11+1 -> 2022 | AA11: =Z11+1 -> 2023 | AB11: =AA11+1 -> 2024 | AC11: =AB11+1 -> 2025 | AD11: =AC11+1 -> 2026 | AE11: =AD11+1 -> 2027
B12: Free cashflow to equity holders | E12: =I62 -> 184.7 | F12: =J62 -> -538.4 | G12: =K62 -> 244.4 | H12: =L62 -> 48.8 | I12: =M62 -> 26.8 | J12: =N62 -> 659.5 | K12: =R62 -> 2084.7488 | L12: =S62 -> 129.10099 | M12: =T62 -> 172.07333 | V12: Payout ratio | W12: 0.82620466 | X12: 1.4114042 | Y12: 0.80482815 | Z12: 0.5102459 | AA12: 3.4253731 | AB12: 0.16300227 | AC12: 0.95934819 | AD12: 0.8 | AE12: 0.8
B13: Payouts to equity holders | E13: =I66 -> 152.6 | F13: =J66 -> -759.9 | G13: =K66 -> 196.7 | H13: =L66 -> 24.9 | I13: =M66 -> 91.8 | J13: =N66 -> 107.5 | K13: =R66 -> 2000 | L13: =S66 -> 103.28079 | M13: =T66 -> 137.65866 | V13: Net Leverage Ratio | W13: 3.1386409 | X13: 3.2583109 | Y13: 2.5120009 | Z13: 4.5756833 | AA13: 3.4259684 | AB13: 3.363092 | AC13: 3.8866216 | AD13: 3.5657079 | AE13: 3.3015814
B14: Retained cashflow | E14: =I56-I66 -> 542 | F14: =J56-J66 -> 1109.1 | G14: =K56-K66 -> 513.5 | H14: =L56-L66 -> -543.3 | I14: =M56-M66 -> 836.8 | J14: =N56-N66 -> 982.1 | K14: =R56-R66 -> -1473.2237 | L14: =S56-S66 -> 507.63017 | M14: =T56-T66 -> 554.76944 | V14: Interest Coverage Ratio | W14: 14.046468 | X14: 12.198529 | Y14: 57.757962 | Z14: 8.5865103 | AA14: 5.6664265 | AB14: 5.3566474 | AC14: 4.2452838 | AD14: 4.6273593 | AE14: 4.9975481
B16: Ratios
B17: EPS | E17: =I53 -> 3.8240982 | F17: =J53 -> 1.6410061 | G17: =K53 -> 4.3315549 | H17: =L53 -> 0.74695122 | I17: =M53 -> 2.3307927 | J17: =N53 -> 2.7469512 | K17: =R53 -> 3.0885102 | L17: =S53 -> 3.581795 | M17: =T53 -> 4.0597332
B18: Interest coverage ratio | E18: =I43/ABS(I44) -> 14.046468 | F18: =J43/ABS(J44) -> 12.198529 | G18: =K43/ABS(K44) -> 57.757962 | H18: =L43/ABS(L44) -> 8.5865103 | I18: =M43/ABS(M44) -> 5.6664265 | J18: =N43/ABS(N44) -> 5.3566474 | K18: =R43/ABS(R44) -> 4.2452838 | L18: =S43/ABS(S44) -> 4.6273593 | M18: =T43/ABS(T44) -> 4.9975481
B19: Net leverage ratio | E19: =I83/I40 -> 3.1386409 | F19: =J83/J40 -> 3.2583109 | G19: =K83/K40 -> 2.5120009 | H19: =L83/L40 -> 4.5756833 | I19: =M83/M40 -> 3.4259684 | J19: =N83/N40 -> 3.363092 | K19: =R83/R40 -> 3.8866216 | L19: =S83/S40 -> 3.5657079 | M19: =T83/T40 -> 3.3015814
B20: Payout ratio | E20: =I67 -> 0.82620466 | F20: =J67 -> 1.4114042 | G20: =K67 -> 0.80482815 | H20: =L67 -> 0.5102459 | I20: =M67 -> 3.4253731 | J20: =N67 -> 0.16300227 | K20: =R67 -> 0.95934819 | L20: =S67 -> 0.8 | M20: =T67 -> 0.8
B21: Retained cashflow/ net debt | E21: =E14/I83 -> 0.10486804 | F21: =F14/J83 -> 0.24076325 | G21: =G14/K83 -> 0.11075403 | H21: =H14/L83 -> -0.090909091 | I21: =I14/M83 -> 0.13325265 | J21: =J14/N83 -> 0.14332414 | K21: =K14/R83 -> -0.1664227 | L21: =L14/S83 -> 0.057344438 | M21: =M14/T83 -> 0.062669525 | W21: 2019 | X21: 2020 | Y21: 2021 | Z21: 2022 | AA21: 2023 | AB21: 2024 | AC21: 2025 | AD21: 2026 | AE21: 2027
B22: EBITDA Margin | E22: =E9/E$8 -> 0.18698688 | F22: =F9/F$8 -> 0.16948787 | G22: =G9/G$8 -> 0.1792934 | H22: =H9/H$8 -> 0.11729049 | I22: =I9/I$8 -> 0.16031556 | J22: =J9/J$8 -> 0.17712463 | K22: =K9/K$8 -> 0.18 | L22: =L9/L$8 -> 0.18 | M22: =M9/M$8 -> 0.18 | V22: EBITDA | W22: =E9 -> 1646.7 | X22: =F9 -> 1413.8 | Y22: =G9 -> 1845.7 | Z22: =H9 -> 1306.1 | AA22: =I9 -> 1833 | AB22: =J9 -> 2037.5 | AC22: =K9 -> 2277.6336 | AD22: =L9 -> 2482.6206 | AE22: =M9 -> 2681.2303
B23: EBIT Margin | E23: =E10/E$8 -> 0.085811616 | F23: =F10/F$8 -> 0.059664813 | G23: =G10/G$8 -> 0.088087582 | H23: =H10/H$8 -> 0.026294048 | I23: =I10/I$8 -> 0.068787881 | J23: =J10/J$8 -> 0.080560192 | K23: =K10/K$8 -> 0.081069913 | L23: =L10/L$8 -> 0.081069913 | M23: =M10/M$8 -> 0.081069913 | V23: EBIT | W23: =E10 -> 755.7 | X23: =F10 -> 497.7 | Y23: =G10 -> 906.8 | Z23: =H10 -> 292.8 | AA23: =I10 -> 786.5 | AB23: =J10 -> 926.7 | AC23: =K10 -> 1025.8198 | AD23: =L10 -> 1118.1435 | AE23: =M10 -> 1207.595
V24: EBITDA Margin | W24: 0.18698688 | X24: 0.16948787 | Y24: 0.1792934 | Z24: 0.11729049 | AA24: 0.16031556 | AB24: 0.17712463 | AC24: 0.18 | AD24: 0.18 | AE24: 0.18
B25: Forecast | V25: EBIT Margin | W25: 0.085811616 | X25: 0.059664813 | Y25: 0.088087582 | Z25: 0.026294048 | AA25: 0.068787881 | AB25: 0.080560192 | AC25: 0.081069913 | AD25: 0.081069913 | AE25: 0.081069913
B27: Scenario Switch | C27: 1 | D27: 1 is Base Case, 2 is Adverse scenario
B29: Income Statement | E29: 2015 | F29: =+E29+1 -> 2016 | G29: =+F29+1 -> 2017 | H29: =+G29+1 -> 2018 | I29: =+H29+1 -> 2019 | J29: =+I29+1 -> 2020 | K29: =+J29+1 -> 2021 | L29: =+K29+1 -> 2022 | M29: =+L29+1 -> 2023 | N29: =+M29+1 -> 2024 | P29: Avg/CAGR | R29: =N29+1 -> 2025 | S29: =R29+1 -> 2026 | T29: =S29+1 -> 2027
B30: Revenue | E30: =Financials!E5 -> 5097.9 | F30: =Financials!F5 -> 5587.2 | G30: =Financials!G5 -> 7653.6 | H30: =Financials!H5 -> 7995.7 | I30: =Financials!I5 -> 8806.5 | J30: =Financials!J5 -> 8341.6 | K30: =Financials!K5 -> 10294.3 | L30: =Financials!L5 -> 11135.6 | ... N30: =Financials!N5 -> 11503.2 | P30: =(N30/E30)^(1/(N29-E29))-1 -> 0.094635948 | R30: =N30*(1+R31) -> 12653.52 | S30: =R30*(1+S31) -> 13792.337 | T30: =S30*(1+T31) -> 14895.724
B31: % growth | F31: =F30/E30-1 -> 0.095980698 | G31: =G30/F30-1 -> 0.36984536 | H31: =H30/G30-1 -> 0.04469792 | I31: =I30/H30-1 -> 0.1014045 | J31: =J30/I30-1 -> -0.052790552 | K31: =K30/J30-1 -> 0.23409178 | L31: =L30/K30-1 -> 0.081724838 | M31: =M30/L30-1 -> 0.026769999 | N31: =N30/M30-1 -> 0.0060785223 | P31: =AVERAGE(E31:N31) -> 0.10086701 | R31: =CHOOSE($C$27,R32,R33) -> 0.1 | S31: =CHOOSE($C$27,S32,S33) -> 0.09 | T31: =CHOOSE($C$27,T32,T33) -> 0.08
B32: Based Case | R32: 0.1 | S32: 0.09 | T32: 0.08
B33: Adverse Case | R33: -0.15 | S33: 0 | T33: 0.15
B34: GOGS | E34: =Financials!E6 -> -3601.7 | F34: =Financials!F6 -> -4091.6 | G34: =Financials!G6 -> -5768.1 | H34: =Financials!H6 -> -5974.7 | I34: =Financials!I6 -> -6474.6 | J34: =Financials!J6 -> -6296.8 | K34: =Financials!K6 -> -7870.6 | L34: =Financials!L6 -> -9124.1 | ... N34: =Financials!N6 -> -8525.9 | R34: =-R30*R35 -> -9490.14 | S34: =-S30*S35 -> -10344.253 | T34: =-T30*T35 -> -11171.793
B35: % revenue | E35: =ABS(E34)/E30 -> 0.7065066 | F35: =ABS(F34)/F30 -> 0.73231672 | G35: =ABS(G34)/G30 -> 0.75364534 | H35: =ABS(H34)/H30 -> 0.74723914 | I35: =ABS(I34)/I30 -> 0.73520695 | J35: =ABS(J34)/J30 -> 0.75486717 | K35: =ABS(K34)/K30 -> 0.76455903 | L35: =ABS(L34)/L30 -> 0.81936312 | ... N35: =ABS(N34)/N30 -> 0.74117637 | P35: =AVERAGE(E35:N35) -> 0.752192 | R35: =CHOOSE($C$27,R36,R37) -> 0.75 | S35: =CHOOSE($C$27,S36,S37) -> 0.75 | T35: =CHOOSE($C$27,T36,T37) -> 0.75
B36: Based Case | R36: 0.75 | S36: 0.75 | T36: 0.75
B37: Adverse Case | R37: =R36*1.2 -> 0.9 | S37: =S36*1.2 -> 0.9 | T37: 0.75
B38: OpEx | E38: =Financials!E8+Financials!E9 -> -647.2 | F38: =Financials!F8+Financials!F9 -> -450.5 | G38: =Financials!G8+Financials!G9 -> -423.8 | H38: =Financials!H8+Financials!H9 -> -391.5 | I38: =Financials!I8+Financials!I9 -> -685.2 | J38: =Financials!J8+Financials!J9 -> -631 | K38: =Financials!K8+Financials!K9 -> -578 | L38: =Financials!L8+Financials!L9 -> -705.4 | ... N38: =Financials!N8+Financials!N9 -> -939.8 | R38: =-R39*R30 -> -885.7464 | S38: =-S39*S30 -> -965.46358 | T38: =-T39*T30 -> -1042.7007
B39: % revenue | E39: =ABS(E38)/E30 -> 0.12695424 | F39: =ABS(F38)/F30 -> 0.080630727 | G39: =ABS(G38)/G30 -> 0.055372635 | H39: =ABS(H38)/H30 -> 0.048963818 | I39: =ABS(I38)/I30 -> 0.077806166 | J39: =ABS(J38)/J30 -> 0.07564496 | K39: =ABS(K38)/K30 -> 0.056147577 | L39: =ABS(L38)/L30 -> 0.063346385 | ... N39: =ABS(N38)/N30 -> 0.081699005 | P39: =AVERAGE(E39:N39) -> 0.073921041 | R39: 0.07 | S39: 0.07 | T39: 0.07
B40: EBITDA | E40: =E30+E34+E38 -> 849 | F40: =F30+F34+F38 -> 1045.1 | G40: =G30+G34+G38 -> 1461.7 | H40: =H30+H34+H38 -> 1629.5 | I40: =I30+I34+I38 -> 1646.7 | J40: =J30+J34+J38 -> 1413.8 | K40: =K30+K34+K38 -> 1845.7 | L40: =L30+L34+L38 -> 1306.1 | ... N40: =N30+N34+N38 -> 2037.5 | R40: =R30+R34+R38 -> 2277.6336 | S40: =S30+S34+S38 -> 2482.6206 | T40: =T30+T34+T38 -> 2681.2303
B41: Depreciation & amortization | E41: =Financials!E13+Financials!E11 -> -397.3 | F41: =Financials!F13+Financials!F11 -> -511.7 | G41: =Financials!G13+Financials!G11 -> -690.4 | H41: =Financials!H13+Financials!H11 -> -968.1 | I41: =Financials!I13+Financials!I11 -> -891 | J41: =Financials!J13+Financials!J11 -> -916.1 | K41: =Financials!K13+Financials!K11 -> -938.9 | L41: =Financials!L13+Financials!L11 -> -1013.3 | ... N41: =Financials!N13+Financials!N11 -> -1110.8 | R41: =R42*R58 -> -1251.8138 | S41: =S42*S58 -> -1364.4771 | T41: =T42*T58 -> -1473.6352
B42: % capital expenditure | E42: =ABS(E41)/ABS(E58) -> 3.0918288 | F42: =ABS(F41)/ABS(F58) -> 3.1921397 | G42: =ABS(G41)/ABS(G58) -> 3.2216519 | H42: =ABS(H41)/ABS(H58) -> 3.820442 | I42: =ABS(I41)/ABS(I58) -> 3.1395349 | J42: =ABS(J41)/ABS(J58) -> 3.2941388 | K42: =ABS(K41)/ABS(K58) -> 2.9618297 | L42: =ABS(L41)/ABS(L58) -> 2.700693 | ... N42: =ABS(N41)/ABS(N58) -> 2.4483139 | P42: =AVERAGE(E42:N42) -> 3.0317953 | R42: =AVERAGE(I42:N42) -> 2.8319818 | S42: =R42 -> 2.8319818 | T42: =S42 -> 2.8319818
B43: EBIT | E43: =E40+E41 -> 451.7 | F43: =F40+F41 -> 533.4 | G43: =G40+G41 -> 771.3 | H43: =H40+H41 -> 661.4 | I43: =I40+I41 -> 755.7 | J43: =J40+J41 -> 497.7 | K43: =K40+K41 -> 906.8 | L43: =L40+L41 -> 292.8 | ... N43: =N40+N41 -> 926.7 | R43: =R40+R41 -> 1025.8198 | S43: =S40+S41 -> 1118.1435 | T43: =T40+T41 -> 1207.595
B44: Interest expense | E44: =Financials!E15 -> -45.7 | F44: =Financials!F15 -> -50.9 | G44: =Financials!G15 -> -53.2 | H44: =Financials!H15 -> -63.6 | I44: =Financials!I15 -> -53.8 | J44: =Financials!J15 -> -40.8 | K44: =Financials!K15 -> -15.7 | L44: =Financials!L15 -> -34.1 | ... N44: =Financials!N15 -> -173 | R44: =R89 -> -241.6375 | S44: =S89 -> -241.6375 | T44: =T89 -> -241.6375
B45: % of net debt | E45: =ABS(E44)/E82 -> 0.024964493 | F45: =ABS(F44)/F82 -> 0.011724329 | G45: =ABS(G44)/G82 -> 0.014340782 | H45: =ABS(H44)/H82 -> 0.013366961 | I45: =ABS(I44)/I82 -> 0.010409411 | J45: =ABS(J44)/J82 -> 0.0088568576 | K45: =ABS(K44)/K82 -> 0.003386248 | L45: =ABS(L44)/L82 -> 0.0057058715 | ... N45: =ABS(N44)/N82 -> 0.025246997 | P45: =AVERAGE(E45:N45) -> 0.014010456 | R45: =ABS(R44)/R83 -> 0.027296578 | S45: =ABS(S44)/S83 -> 0.027296578 | T45: =ABS(T44)/T83 -> 0.027296578
B46: Taxes | E46: =Financials!E17 -> -109.2 | F46: =Financials!F17 -> -93.1 | G46: =Financials!G17 -> -41.9 | H46: =Financials!H17 -> -143.7 | I46: =Financials!I17 -> -176.8 | J46: =Financials!J17 -> -90.7 | K46: =Financials!K17 -> -191.7 | L46: =Financials!L17 -> -32.2 | ... N46: =Financials!N17 -> -220.5 | R46: =-R47*(R43-R44) -> -378.96972 | S46: =-S47*(S43-S44) -> -406.57453 | T46: =-T47*(T43-T44) -> -433.32052
...

Sheet Peer Analysis
B2: Comparables
B4: Year Ended | E4: 2019 | F4: 2020 | G4: 2021 | H4: 2022 | I4: 2023 | J4: 2024 | K4: LTM/Cur. Q
B6: Profitability Ratios
B8: Gross Profit Margin
B9: Honeywell_International | E9: =INDEX(INDIRECT($B9&"!C53:N78"),MATCH($B$8,INDIRECT($B9&"!B53:B78"),0),MATCH(E$4,INDIRECT($B9&"!C52:N52"),0)) -> 0.38503242 | F9: =INDEX(INDIRECT($B9&"!C53:N78"),MATCH($B$8,INDIRECT($B9&"!B53:B78"),0),MATCH(F$4,INDIRECT($B9&"!C52:N52"),0)) -> 0.3723652 | G9: =INDEX(INDIRECT($B9&"!C53:N78"),MATCH($B$8,INDIRECT($B9&"!B53:B78"),0),MATCH(G$4,INDIRECT($B9&"!C52:N52"),0)) -> 0.37144851 | H9: =INDEX(INDIRECT($B9&"!C53:N78"),MATCH($B$8,INDIRECT($B9&"!B53:B78"),0),MATCH(H$4,INDIRECT($B9&"!C52:N52"),0)) -> 0.38400135 | I9: =INDEX(INDIRECT($B9&"!C53:N78"),MATCH($B$8,INDIRECT($B9&"!B53:B78"),0),MATCH(I$4,INDIRECT($B9&"!C52:N52"),0)) -> 0.39004557 | J9: =INDEX(INDIRECT($B9&"!C53:N78"),MATCH($B$8,INDIRECT($B9&"!B53:B78"),0),MATCH(J$4,INDIRECT($B9&"!C52:N52"),0)) -> 0.38336451 | K9: =INDEX(INDIRECT($B9&"!C53:N78"),MATCH($B$8,INDIRECT($B9&"!B53:B78"),0),MATCH(K$4,INDIRECT($B9&"!C52:N52"),0)) -> 0.38066436 | P9: Kion | Q9: Honeywell International | R9: Daifuku | S9: Hyster Yale | T9: Mitsubishi Logisnext | U9: Toyota Industries | V9: Symbotic | W9: KENGIC | X9: Jungheinrich | Y9: ManitouBF
B10: Daifuku | E10: =INDEX(INDIRECT($B10&"!C53:N78"),MATCH($B$8,INDIRECT($B10&"!B53:B78"),0),MATCH(E$4,INDIRECT($B10&"!C52:N52"),0)) -> 0.20153078 | F10: =INDEX(INDIRECT($B10&"!C53:N78"),MATCH($B$8,INDIRECT($B10&"!B53:B78"),0),MATCH(F$4,INDIRECT($B10&"!C52:N52"),0)) -> 0.19341974 | G10: =INDEX(INDIRECT($B10&"!C53:N78"),MATCH($B$8,INDIRECT($B10&"!B53:B78"),0),MATCH(G$4,INDIRECT($B10&"!C52:N52"),0)) -> 0.19238758 | H10: =INDEX(INDIRECT($B10&"!C53:N78"),MATCH($B$8,INDIRECT($B10&"!B53:B78"),0),MATCH(H$4,INDIRECT($B10&"!C52:N52"),0)) -> 0.18782666 | I10: =INDEX(INDIRECT($B10&"!C53:N78"),MATCH($B$8,INDIRECT($B10&"!B53:B78"),0),MATCH(I$4,INDIRECT($B10&"!C52:N52"),0)) -> - | J10: =INDEX(INDIRECT($B10&"!C53:N78"),MATCH($B$8,INDIRECT($B10&"!B53:B78"),0),MATCH(J$4,INDIRECT($B10&"!C52:N52"),0)) -> 0.22661871 | K10: =INDEX(INDIRECT($B10&"!C53:N78"),MATCH($B$8,INDIRECT($B10&"!B53:B78"),0),MATCH(K$4,INDIRECT($B10&"!C52:N52"),0)) -> 0.2399198 | O10: EBITDA Margin | P10: =M222 -> 0.17712463 | Q10: =INDEX(INDIRECT($B23&"!C53:N78"),MATCH($B$22,INDIRECT($B23&"!B53:B78"),0),MATCH(K$4,INDIRECT($B23&"!C52:N52"),0)) -> 0.24140051 | R10: =INDEX(INDIRECT($B24&"!C53:N78"),MATCH($B$22,INDIRECT($B24&"!B53:B78"),0),MATCH(K$4,INDIRECT($B24&"!C52:N52"),0)) -> 0.1585306 | S10: =INDEX(INDIRECT($B25&"!C53:N78"),MATCH($B$22,INDIRECT($B25&"!B53:B78"),0),MATCH(K$4,INDIRECT($B25&"!C52:N52"),0)) -> 0.051895954 | T10: =INDEX(INDIRECT($B26&"!C53:N78"),MATCH($B$22,INDIRECT($B26&"!B53:B78"),0),MATCH(K$4,INDIRECT($B26&"!C52:N52"),0)) -> 0.083073068 | U10: =INDEX(INDIRECT($B27&"!C53:N78"),MATCH($B$22,INDIRECT($B27&"!B53:B78"),0),MATCH(K$4,INDIRECT($B27&"!C52:N52"),0)) -> 0.125042 | V10: =INDEX(INDIRECT($B28&"!C53:N78"),MATCH($B$22,INDIRECT($B28&"!B53:B78"),0),MATCH(K$4,INDIRECT($B28&"!C52:N52"),0)) -> -0.0017771358 | W10: =INDEX(INDIRECT($B29&"!C53:N78"),MATCH($B$22,INDIRECT($B29&"!B53:B78"),0),MATCH(K$4,INDIRECT($B29&"!C52:N52"),0)) -> - | X10: =INDEX(INDIRECT($B30&"!C53:N78"),MATCH($B$22,INDIRECT($B30&"!B53:B78"),0),MATCH(K$4,INDIRECT($B30&"!C52:N52"),0)) -> 0.16530251 | Y10: =INDEX(INDIRECT($B31&"!C53:N78"),MATCH($B$22,INDIRECT($B31&"!B53:B78"),0),MATCH(K$4,INDIRECT($B31&"!C52:N52"),0)) -> 0.086141812
B11: Hyster_Yale | E11: =INDEX(INDIRECT($B11&"!C53:N78"),MATCH($B$8,INDIRECT($B11&"!B53:B78"),0),MATCH(E$4,INDIRECT($B11&"!C52:N52"),0)) -> 0.17176013 | F11: =INDEX(INDIRECT($B11&"!C53:N78"),MATCH($B$8,INDIRECT($B11&"!B53:B78"),0),MATCH(F$4,INDIRECT($B11&"!C52:N52"),0)) -> 0.17012197 | G11: =INDEX(INDIRECT($B11&"!C53:N78"),MATCH($B$8,INDIRECT($B11&"!B53:B78"),0),MATCH(G$4,INDIRECT($B11&"!C52:N52"),0)) -> 0.11955002 | H11: =INDEX(INDIRECT($B11&"!C53:N78"),MATCH($B$8,INDIRECT($B11&"!B53:B78"),0),MATCH(H$4,INDIRECT($B11&"!C52:N52"),0)) -> 0.14122256 | I11: =INDEX(INDIRECT($B11&"!C53:N78"),MATCH($B$8,INDIRECT($B11&"!B53:B78"),0),MATCH(I$4,INDIRECT($B11&"!C52:N52"),0)) -> 0.20085958 | J11: =INDEX(INDIRECT($B11&"!C53:N78"),MATCH($B$8,INDIRECT($B11&"!B53:B78"),0),MATCH(J$4,INDIRECT($B11&"!C52:N52"),0)) -> 0.21779397 | K11: =INDEX(INDIRECT($B11&"!C53:N78"),MATCH($B$8,INDIRECT($B11&"!B53:B78"),0),MATCH(K$4,INDIRECT($B11&"!C52:N52"),0)) -> 0.19904947 | O11: EBIT Margin | P11: =M223 -> 0.080560192 | Q11: =INDEX(INDIRECT($B37&"!C53:N78"),MATCH($B$36,INDIRECT($B37&"!B53:B78"),0),MATCH(K$4,INDIRECT($B37&"!C52:N52"),0)) -> 0.20324064 | R11: =INDEX(INDIRECT($B38&"!C53:N78"),MATCH($B$36,INDIRECT($B38&"!B53:B78"),0),MATCH(K$4,INDIRECT($B38&"!C52:N52"),0)) -> 0.14606494 | S11: =INDEX(INDIRECT($B39&"!C53:N78"),MATCH($B$36,INDIRECT($B39&"!B53:B78"),0),MATCH(K$4,INDIRECT($B39&"!C52:N52"),0)) -> 0.040167621 | T11: =INDEX(INDIRECT($B40&"!C53:N78"),MATCH($B$36,INDIRECT($B40&"!B53:B78"),0),MATCH(K$4,INDIRECT($B40&"!C52:N52"),0)) -> 0.020403643 | U11: =INDEX(INDIRECT($B41&"!C53:N78"),MATCH($B$36,INDIRECT($B41&"!B53:B78"),0),MATCH(K$4,INDIRECT($B41&"!C52:N52"),0)) -> 0.043718371 | V11: =INDEX(INDIRECT($B42&"!C53:N78"),MATCH($B$36,INDIRECT($B42&"!B53:B78"),0),MATCH(K$4,INDIRECT($B42&"!C52:N52"),0)) -> -0.020168845 | W11: =INDEX(INDIRECT($B43&"!C53:N78"),MATCH($B$36,INDIRECT($B43&"!B53:B78"),0),MATCH(K$4,INDIRECT($B43&"!C52:N52"),0)) -> -0.075104141 | X11: =INDEX(INDIRECT($B44&"!C53:N78"),MATCH($B$36,INDIRECT($B44&"!B53:B78"),0),MATCH(K$4,INDIRECT($B44&"!C52:N52"),0)) -> 0.077929765 | Y11: =INDEX(INDIRECT($B45&"!C53:N78"),MATCH($B$36,INDIRECT($B45&"!B53:B78"),0),MATCH(K$4,INDIRECT($B45&"!C52:N52"),0)) -> 0.053908518
B12: Mitsubishi_Logisnext | E12: =INDEX(INDIRECT($B12&"!C53:N78"),MATCH($B$8,INDIRECT($B12&"!B53:B78"),0),MATCH(E$4,INDIRECT($B12&"!C52:N52"),0)) -> 0.22745802 | F12: =INDEX(INDIRECT($B12&"!C53:N78"),MATCH($B$8,INDIRECT($B12&"!B53:B78"),0),MATCH(F$4,INDIRECT($B12&"!C52:N52"),0)) -> 0.22136114 | G12: =INDEX(INDIRECT($B12&"!C53:N78"),MATCH($B$8,INDIRECT($B12&"!B53:B78"),0),MATCH(G$4,INDIRECT($B12&"!C52:N52"),0)) -> 0.21082023 | H12: =INDEX(INDIRECT($B12&"!C53:N78"),MATCH($B$8,INDIRECT($B12&"!B53:B78"),0),MATCH(H$4,INDIRECT($B12&"!C52:N52"),0)) -> 0.21488217 | I12: =INDEX(INDIRECT($B12&"!C53:N78"),MATCH($B$8,INDIRECT($B12&"!B53:B78"),0),MATCH(I$4,INDIRECT($B12&"!C52:N52"),0)) -> 0.24655086 | J12: =INDEX(INDIRECT($B12&"!C53:N78"),MATCH($B$8,INDIRECT($B12&"!B53:B78"),0),MATCH(J$4,INDIRECT($B12&"!C52:N52"),0)) -> 0.23027251 | K12: =INDEX(INDIRECT($B12&"!C53:N78"),MATCH($B$8,INDIRECT($B12&"!B53:B78"),0),MATCH(K$4,INDIRECT($B12&"!C52:N52"),0)) -> 0.23149125 | O12: EBITDA Mean | P12: =$J$33 -> 0.097115411 | Q12: =$J$33 -> 0.097115411 | R12: =$J$33 -> 0.097115411 | S12: =$J$33 -> 0.097115411 | T12: =$J$33 -> 0.097115411 | U12: =$J$33 -> 0.097115411 | V12: =$J$33 -> 0.097115411 | W12: =$J$33 -> 0.097115411 | ... Y12: =$J$33 -> 0.097115411
B13: Toyota_Industries | E13: =INDEX(INDIRECT($B13&"!C53:N78"),MATCH($B$8,INDIRECT($B13&"!B53:B78"),0),MATCH(E$4,INDIRECT($B13&"!C52:N52"),0)) -> 0.23290618 | F13: =INDEX(INDIRECT($B13&"!C53:N78"),MATCH($B$8,INDIRECT($B13&"!B53:B78"),0),MATCH(F$4,INDIRECT($B13&"!C52:N52"),0)) -> 0.23118469 | G13: =INDEX(INDIRECT($B13&"!C53:N78"),MATCH($B$8,INDIRECT($B13&"!B53:B78"),0),MATCH(G$4,INDIRECT($B13&"!C52:N52"),0)) -> 0.22436819 | H13: =INDEX(INDIRECT($B13&"!C53:N78"),MATCH($B$8,INDIRECT($B13&"!B53:B78"),0),MATCH(H$4,INDIRECT($B13&"!C52:N52"),0)) -> 0.2234788 | I13: =INDEX(INDIRECT($B13&"!C53:N78"),MATCH($B$8,INDIRECT($B13&"!B53:B78"),0),MATCH(I$4,INDIRECT($B13&"!C52:N52"),0)) -> 0.23461959 | J13: =INDEX(INDIRECT($B13&"!C53:N78"),MATCH($B$8,INDIRECT($B13&"!B53:B78"),0),MATCH(J$4,INDIRECT($B13&"!C52:N52"),0)) -> 0.23236835 | K13: =INDEX(INDIRECT($B13&"!C53:N78"),MATCH($B$8,INDIRECT($B13&"!B53:B78"),0),MATCH(K$4,INDIRECT($B13&"!C52:N52"),0)) -> 0.22392472 | O13: EBIT Mean | P13: =$J$47 -> 0.058723411 | Q13: =$J$47 -> 0.058723411 | R13: =$J$47 -> 0.058723411 | S13: =$J$47 -> 0.058723411 | T13: =$J$47 -> 0.058723411 | U13: =$J$47 -> 0.058723411 | V13: =$J$47 -> 0.058723411 | W13: =$J$47 -> 0.058723411 | ... Y13: =$J$47 -> 0.058723411
B14: Symbotic | E14: =INDEX(INDIRECT($B14&"!C53:N78"),MATCH($B$8,INDIRECT($B14&"!B53:B78"),0),MATCH(E$4,INDIRECT($B14&"!C52:N52"),0)) -> - | F14: =INDEX(INDIRECT($B14&"!C53:N78"),MATCH($B$8,INDIRECT($B14&"!B53:B78"),0),MATCH(F$4,INDIRECT($B14&"!C52:N52"),0)) -> - | G14: =INDEX(INDIRECT($B14&"!C53:N78"),MATCH($B$8,INDIRECT($B14&"!B53:B78"),0),MATCH(G$4,INDIRECT($B14&"!C52:N52"),0)) -> 0.16795042 | H14: =INDEX(INDIRECT($B14&"!C53:N78"),MATCH($B$8,INDIRECT($B14&"!B53:B78"),0),MATCH(H$4,INDIRECT($B14&"!C52:N52"),0)) -> 0.16122054 | I14: =INDEX(INDIRECT($B14&"!C53:N78"),MATCH($B$8,INDIRECT($B14&"!B53:B78"),0),MATCH(I$4,INDIRECT($B14&"!C52:N52"),0)) -> 0.13738334 | J14: =INDEX(INDIRECT($B14&"!C53:N78"),MATCH($B$8,INDIRECT($B14&"!B53:B78"),0),MATCH(J$4,INDIRECT($B14&"!C52:N52"),0)) -> 0.17480091 | K14: =INDEX(INDIRECT($B14&"!C53:N78"),MATCH($B$8,INDIRECT($B14&"!B53:B78"),0),MATCH(K$4,INDIRECT($B14&"!C52:N52"),0)) -> 0.17898562
B15: KENGIC | E15: =INDEX(INDIRECT($B15&"!C53:N78"),MATCH($B$8,INDIRECT($B15&"!B53:B78"),0),MATCH(E$4,INDIRECT($B15&"!C52:N52"),0)) -> 0.23852087 | F15: =INDEX(INDIRECT($B15&"!C53:N78"),MATCH($B$8,INDIRECT($B15&"!B53:B78"),0),MATCH(F$4,INDIRECT($B15&"!C52:N52"),0)) -> 0.23207883 | G15: =INDEX(INDIRECT($B15&"!C53:N78"),MATCH($B$8,INDIRECT($B15&"!B53:B78"),0),MATCH(G$4,INDIRECT($B15&"!C52:N52"),0)) -> 0.20948648 | H15: =INDEX(INDIRECT($B15&"!C53:N78"),MATCH($B$8,INDIRECT($B15&"!B53:B78"),0),MATCH(H$4,INDIRECT($B15&"!C52:N52"),0)) -> 0.19963167 | I15: =INDEX(INDIRECT($B15&"!C53:N78"),MATCH($B$8,INDIRECT($B15&"!B53:B78"),0),MATCH(I$4,INDIRECT($B15&"!C52:N52"),0)) -> 0.095067994 | J15: =INDEX(INDIRECT($B15&"!C53:N78"),MATCH($B$8,INDIRECT($B15&"!B53:B78"),0),MATCH(J$4,INDIRECT($B15&"!C52:N52"),0)) -> 0.12347494 | K15: =INDEX(INDIRECT($B15&"!C53:N78"),MATCH($B$8,INDIRECT($B15&"!B53:B78"),0),MATCH(K$4,INDIRECT($B15&"!C52:N52"),0)) -> 0.14822545
B16: Jungheinrich | E16: =INDEX(INDIRECT($B16&"!C53:N78"),MATCH($B$8,INDIRECT($B16&"!B53:B78"),0),MATCH(E$4,INDIRECT($B16&"!C52:N52"),0)) -> 0.2919199 | F16: =INDEX(INDIRECT($B16&"!C53:N78"),MATCH($B$8,INDIRECT($B16&"!B53:B78"),0),MATCH(F$4,INDIRECT($B16&"!C52:N52"),0)) -> 0.30405805 | G16: =INDEX(INDIRECT($B16&"!C53:N78"),MATCH($B$8,INDIRECT($B16&"!B53:B78"),0),MATCH(G$4,INDIRECT($B16&"!C52:N52"),0)) -> 0.31403163 | H16: =INDEX(INDIRECT($B16&"!C53:N78"),MATCH($B$8,INDIRECT($B16&"!B53:B78"),0),MATCH(H$4,INDIRECT($B16&"!C52:N52"),0)) -> 0.31209705 | I16: =INDEX(INDIRECT($B16&"!C53:N78"),MATCH($B$8,INDIRECT($B16&"!B53:B78"),0),MATCH(I$4,INDIRECT($B16&"!C52:N52"),0)) -> 0.31189619 | J16: =INDEX(INDIRECT($B16&"!C53:N78"),MATCH($B$8,INDIRECT($B16&"!B53:B78"),0),MATCH(J$4,INDIRECT($B16&"!C52:N52"),0)) -> 0.319837 | K16: =INDEX(INDIRECT($B16&"!C53:N78"),MATCH($B$8,INDIRECT($B16&"!B53:B78"),0),MATCH(K$4,INDIRECT($B16&"!C52:N52"),0)) -> 0.32620149
B17: Manitou_BF | E17: =INDEX(INDIRECT($B17&"!C53:N78"),MATCH($B$8,INDIRECT($B17&"!B53:B78"),0),MATCH(E$4,INDIRECT($B17&"!C52:N52"),0)) -> 0.16019521 | F17: =INDEX(INDIRECT($B17&"!C53:N78"),MATCH($B$8,INDIRECT($B17&"!B53:B78"),0),MATCH(F$4,INDIRECT($B17&"!C52:N52"),0)) -> 0.1510329 | G17: =INDEX(INDIRECT($B17&"!C53:N78"),MATCH($B$8,INDIRECT($B17&"!B53:B78"),0),MATCH(G$4,INDIRECT($B17&"!C52:N52"),0)) -> 0.16465102 | H17: =INDEX(INDIRECT($B17&"!C53:N78"),MATCH($B$8,INDIRECT($B17&"!B53:B78"),0),MATCH(H$4,INDIRECT($B17&"!C52:N52"),0)) -> 0.12831366 | I17: =INDEX(INDIRECT($B17&"!C53:N78"),MATCH($B$8,INDIRECT($B17&"!B53:B78"),0),MATCH(I$4,INDIRECT($B17&"!C52:N52"),0)) -> 0.16513601 | J17: =INDEX(INDIRECT($B17&"!C53:N78"),MATCH($B$8,INDIRECT($B17&"!B53:B78"),0),MATCH(J$4,INDIRECT($B17&"!C52:N52"),0)) -> 0.1823467 | K17: =INDEX(INDIRECT($B17&"!C53:N78"),MATCH($B$8,INDIRECT($B17&"!B53:B78"),0),MATCH(K$4,INDIRECT($B17&"!C52:N52"),0)) -> 0.17579505
B19: Mean | E19: =IFERROR(AVERAGE(E9:E17),"-") -> 0.23866544 | F19: =IFERROR(AVERAGE(F9:F17),"-") -> 0.23445281 | G19: =IFERROR(AVERAGE(G9:G17),"-") -> 0.21941045 | H19: =IFERROR(AVERAGE(H9:H17),"-") -> 0.21696383 | I19: =IFERROR(AVERAGE(I9:I17),"-") -> 0.22269489 | J19: =IFERROR(AVERAGE(J9:J17),"-") -> 0.23231973 | K19: =IFERROR(AVERAGE(K9:K17),"-") -> 0.23380636
B20: Median | E20: =IFERROR(MEDIAN(E9:E17),"-") -> 0.2301821 | F20: =IFERROR(MEDIAN(F9:F17),"-") -> 0.22627292 | G20: =IFERROR(MEDIAN(G9:G17),"-") -> 0.20948648 | H20: =IFERROR(MEDIAN(H9:H17),"-") -> 0.19963167 | I20: =IFERROR(MEDIAN(I9:I17),"-") -> 0.21773959 | J20: =IFERROR(MEDIAN(J9:J17),"-") -> 0.22661871 | K20: =IFERROR(MEDIAN(K9:K17),"-") -> 0.22392472
B22: EBITDA Margin
B23: Honeywell_International | E23: =INDEX(INDIRECT($B23&"!C53:N78"),MATCH($B$22,INDIRECT($B23&"!B53:B78"),0),MATCH(E$4,INDIRECT($B23&"!C52:N52"),0)) -> 0.22925407 | F23: =INDEX(INDIRECT($B23&"!C53:N78"),MATCH($B$22,INDIRECT($B23&"!B53:B78"),0),MATCH(F$4,INDIRECT($B23&"!C52:N52"),0)) -> 0.22340686 | G23: =INDEX(INDIRECT($B23&"!C53:N78"),MATCH($B$22,INDIRECT($B23&"!B53:B78"),0),MATCH(G$4,INDIRECT($B23&"!C52:N52"),0)) -> 0.23171547 | H23: =INDEX(INDIRECT($B23&"!C53:N78"),MATCH($B$22,INDIRECT($B23&"!B53:B78"),0),MATCH(H$4,INDIRECT($B23&"!C52:N52"),0)) -> 0.23800525 | I23: =INDEX(INDIRECT($B23&"!C53:N78"),MATCH($B$22,INDIRECT($B23&"!B53:B78"),0),MATCH(I$4,INDIRECT($B23&"!C52:N52"),0)) -> 0.24692335 | J23: =INDEX(INDIRECT($B23&"!C53:N78"),MATCH($B$22,INDIRECT($B23&"!B53:B78"),0),MATCH(J$4,INDIRECT($B23&"!C52:N52"),0)) -> 0.23908978 | K23: =INDEX(INDIRECT($B23&"!C53:N78"),MATCH($B$22,INDIRECT($B23&"!B53:B78"),0),MATCH(K$4,INDIRECT($B23&"!C52:N52"),0)) -> 0.24140051
B24: Daifuku | E24: =INDEX(INDIRECT($B24&"!C53:N78"),MATCH($B$22,INDIRECT($B24&"!B53:B78"),0),MATCH(E$4,INDIRECT($B24&"!C52:N52"),0)) -> 0.10591083 | F24: =INDEX(INDIRECT($B24&"!C53:N78"),MATCH($B$22,INDIRECT($B24&"!B53:B78"),0),MATCH(F$4,INDIRECT($B24&"!C52:N52"),0)) -> 0.10901621 | G24: =INDEX(INDIRECT($B24&"!C53:N78"),MATCH($B$22,INDIRECT($B24&"!B53:B78"),0),MATCH(G$4,INDIRECT($B24&"!C52:N52"),0)) -> 0.1136495 | H24: =INDEX(INDIRECT($B24&"!C53:N78"),MATCH($B$22,INDIRECT($B24&"!B53:B78"),0),MATCH(H$4,INDIRECT($B24&"!C52:N52"),0)) -> 0.11311765 | I24: =INDEX(INDIRECT($B24&"!C53:N78"),MATCH($B$22,INDIRECT($B24&"!B53:B78"),0),MATCH(I$4,INDIRECT($B24&"!C52:N52"),0)) -> - | J24: =INDEX(INDIRECT($B24&"!C53:N78"),MATCH($B$22,INDIRECT($B24&"!B53:B78"),0),MATCH(J$4,INDIRECT($B24&"!C52:N52"),0)) -> 0.14252487 | K24: =INDEX(INDIRECT($B24&"!C53:N78"),MATCH($B$22,INDIRECT($B24&"!B53:B78"),0),MATCH(K$4,INDIRECT($B24&"!C52:N52"),0)) -> 0.1585306
B25: Hyster_Yale | E25: =INDEX(INDIRECT($B25&"!C53:N78"),MATCH($B$22,INDIRECT($B25&"!B53:B78"),0),MATCH(E$4,INDIRECT($B25&"!C52:N52"),0)) -> 0.036818762 | F25: =INDEX(INDIRECT($B25&"!C53:N78"),MATCH($B$22,INDIRECT($B25&"!B53:B78"),0),MATCH(F$4,INDIRECT($B25&"!C52:N52"),0)) -> 0.039187794 | G25: =INDEX(INDIRECT($B25&"!C53:N78"),MATCH($B$22,INDIRECT($B25&"!B53:B78"),0),MATCH(G$4,INDIRECT($B25&"!C52:N52"),0)) -> -0.010371626 | H25: =INDEX(INDIRECT($B25&"!C53:N78"),MATCH($B$22,INDIRECT($B25&"!B53:B78"),0),MATCH(H$4,INDIRECT($B25&"!C52:N52"),0)) -> 0.021024151 | I25: =INDEX(INDIRECT($B25&"!C53:N78"),MATCH($B$22,INDIRECT($B25&"!B53:B78"),0),MATCH(I$4,INDIRECT($B25&"!C52:N52"),0)) -> 0.072189983 | J25: =INDEX(INDIRECT($B25&"!C53:N78"),MATCH($B$22,INDIRECT($B25&"!B53:B78"),0),MATCH(J$4,INDIRECT($B25&"!C52:N52"),0)) -> 0.083213405 | K25: =INDEX(INDIRECT($B25&"!C53:N78"),MATCH($B$22,INDIRECT($B25&"!B53:B78"),0),MATCH(K$4,INDIRECT($B25&"!C52:N52"),0)) -> 0.051895954
B26: Mitsubishi_Logisnext | E26: =INDEX(INDIRECT($B26&"!C53:N78"),MATCH($B$22,INDIRECT($B26&"!B53:B78"),0),MATCH(E$4,INDIRECT($B26&"!C52:N52"),0)) -> 0.087987115 | F26: =INDEX(INDIRECT($B26&"!C53:N78"),MATCH($B$22,INDIRECT($B26&"!B53:B78"),0),MATCH(F$4,INDIRECT($B26&"!C52:N52"),0)) -> 0.082358441 | G26: =INDEX(INDIRECT($B26&"!C53:N78"),MATCH($B$22,INDIRECT($B26&"!B53:B78"),0),MATCH(G$4,INDIRECT($B26&"!C52:N52"),0)) -> 0.07429857 | H26: =INDEX(INDIRECT($B26&"!C53:N78"),MATCH($B$22,INDIRECT($B26&"!B53:B78"),0),MATCH(H$4,INDIRECT($B26&"!C52:N52"),0)) -> 0.07845036 | I26: =INDEX(INDIRECT($B26&"!C53:N78"),MATCH($B$22,INDIRECT($B26&"!B53:B78"),0),MATCH(I$4,INDIRECT($B26&"!C52:N52"),0)) -> 0.11373812 | J26: =INDEX(INDIRECT($B26&"!C53:N78"),MATCH($B$22,INDIRECT($B26&"!B53:B78"),0),MATCH(J$4,INDIRECT($B26&"!C52:N52"),0)) -> 0.093244531 | K26: =INDEX(INDIRECT($B26&"!C53:N78"),MATCH($B$22,INDIRECT($B26&"!B53:B78"),0),MATCH(K$4,INDIRECT($B26&"!C52:N52"),0)) -> 0.083073068 | P26: Kion | Q26: Honeywell International | R26: Daifuku | S26: Hyster Yale | T26: Mitsubishi Logisnext | U26: Toyota Industries | V26: Symbotic | W26: KENGIC | X26: Jungheinrich | Y26: ManitouBF
B27: Toyota_Industries | E27: =INDEX(INDIRECT($B27&"!C53:N78"),MATCH($B$22,INDIRECT($B27&"!B53:B78"),0),MATCH(E$4,INDIRECT($B27&"!C52:N52"),0)) -> 0.15315828 | F27: =INDEX(INDIRECT($B27&"!C53:N78"),MATCH($B$22,INDIRECT($B27&"!B53:B78"),0),MATCH(F$4,INDIRECT($B27&"!C52:N52"),0)) -> 0.15338228 | G27: =INDEX(INDIRECT($B27&"!C53:N78"),MATCH($B$22,INDIRECT($B27&"!B53:B78"),0),MATCH(G$4,INDIRECT($B27&"!C52:N52"),0)) -> 0.13881834 | H27: =INDEX(INDIRECT($B27&"!C53:N78"),MATCH($B$22,INDIRECT($B27&"!B53:B78"),0),MATCH(H$4,INDIRECT($B27&"!C52:N52"),0)) -> 0.12624135 | I27: =INDEX(INDIRECT($B27&"!C53:N78"),MATCH($B$22,INDIRECT($B27&"!B53:B78"),0),MATCH(I$4,INDIRECT($B27&"!C52:N52"),0)) -> 0.13762243 | J27: =INDEX(INDIRECT($B27&"!C53:N78"),MATCH($B$22,INDIRECT($B27&"!B53:B78"),0),MATCH(J$4,INDIRECT($B27&"!C52:N52"),0)) -> 0.1344982 | K27: =INDEX(INDIRECT($B27&"!C53:N78"),MATCH($B$22,INDIRECT($B27&"!B53:B78"),0),MATCH(K$4,INDIRECT($B27&"!C52:N52"),0)) -> 0.125042 | O27: EBITDA Margin | P27: =K222 -> 0.17388696 | Q27: =AVERAGE(E23:J23) -> 0.23473246 | R27: =AVERAGE(E24:J24) -> 0.11684381 | S27: =AVERAGE(E25:J25) -> 0.040343745 | T27: =AVERAGE(E26:J26) -> 0.08834619 | U27: =AVERAGE(E27:J27) -> 0.14062015 | V27: =AVERAGE(E28:J28) -> -0.10921565 | W27: =AVERAGE(E29:J29) -> 0.011587778 | X27: =AVERAGE(E30:J30) -> 0.16509884 | Y27: =AVERAGE(E31:J31) -> 0.088549726
B28: Symbotic | E28: =INDEX(INDIRECT($B28&"!C53:N78"),MATCH($B$22,INDIRECT($B28&"!B53:B78"),0),MATCH(E$4,INDIRECT($B28&"!C52:N52"),0)) -> - | F28: =INDEX(INDIRECT($B28&"!C53:N78"),MATCH($B$22,INDIRECT($B28&"!B53:B78"),0),MATCH(F$4,INDIRECT($B28&"!C52:N52"),0)) -> - | G28: =INDEX(INDIRECT($B28&"!C53:N78"),MATCH($B$22,INDIRECT($B28&"!B53:B78"),0),MATCH(G$4,INDIRECT($B28&"!C52:N52"),0)) -> -0.2265014 | H28: =INDEX(INDIRECT($B28&"!C53:N78"),MATCH($B$22,INDIRECT($B28&"!B53:B78"),0),MATCH(H$4,INDIRECT($B28&"!C52:N52"),0)) -> -0.16044816 | I28: =INDEX(INDIRECT($B28&"!C53:N78"),MATCH($B$22,INDIRECT($B28&"!B53:B78"),0),MATCH(I$4,INDIRECT($B28&"!C52:N52"),0)) -> -0.033268484 | J28: =INDEX(INDIRECT($B28&"!C53:N78"),MATCH($B$22,INDIRECT($B28&"!B53:B78"),0),MATCH(J$4,INDIRECT($B28&"!C52:N52"),0)) -> -0.016644548 | K28: =INDEX(INDIRECT($B28&"!C53:N78"),MATCH($B$22,INDIRECT($B28&"!B53:B78"),0),MATCH(K$4,INDIRECT($B28&"!C52:N52"),0)) -> -0.0017771358 | O28: EBIT Margin | P28: =K223 -> 0.077677502 | Q28: =AVERAGE(E37:J37) -> 0.20196437 | R28: =AVERAGE(E38:J38) -> 0.10164539 | S28: =AVERAGE(E39:J39) -> 0.027400179 | T28: =AVERAGE(E40:J40) -> 0.02439985 | U28: =AVERAGE(E41:J41) -> 0.056015256 | V28: =AVERAGE(E42:J42) -> -0.12194452 | W28: =AVERAGE(E43:J43) -> 0.0070461438 | X28: =AVERAGE(E44:J44) -> 0.076874602 | Y28: =AVERAGE(E45:J45) -> 0.062353465
B29: KENGIC | E29: =INDEX(INDIRECT($B29&"!C53:N78"),MATCH($B$22,INDIRECT($B29&"!B53:B78"),0),MATCH(E$4,INDIRECT($B29&"!C52:N52"),0)) -> 0.024125615 | F29: =INDEX(INDIRECT($B29&"!C53:N78"),MATCH($B$22,INDIRECT($B29&"!B53:B78"),0),MATCH(F$4,INDIRECT($B29&"!C52:N52"),0)) -> 0.082948008 | G29: =INDEX(INDIRECT($B29&"!C53:N78"),MATCH($B$22,INDIRECT($B29&"!B53:B78"),0),MATCH(G$4,INDIRECT($B29&"!C52:N52"),0)) -> 0.066231477 | H29: =INDEX(INDIRECT($B29&"!C53:N78"),MATCH($B$22,INDIRECT($B29&"!B53:B78"),0),MATCH(H$4,INDIRECT($B29&"!C52:N52"),0)) -> 0.057992202 | I29: =INDEX(INDIRECT($B29&"!C53:N78"),MATCH($B$22,INDIRECT($B29&"!B53:B78"),0),MATCH(I$4,INDIRECT($B29&"!C52:N52"),0)) -> -0.090891504 | J29: =INDEX(INDIRECT($B29&"!C53:N78"),MATCH($B$22,INDIRECT($B29&"!B53:B78"),0),MATCH(J$4,INDIRECT($B29&"!C52:N52"),0)) -> -0.07087913 | K29: =INDEX(INDIRECT($B29&"!C53:N78"),MATCH($B$22,INDIRECT($B29&"!B53:B78"),0),MATCH(K$4,INDIRECT($B29&"!C52:N52"),0)) -> - | O29: EBITDA Mean | P29: =AVERAGE(E33:J33) -> 0.094075953 | Q29: =P29 -> 0.094075953 | R29: =Q29 -> 0.094075953 | S29: =R29 -> 0.094075953 | T29: =S29 -> 0.094075953 | U29: =T29 -> 0.094075953 | V29: =U29 -> 0.094075953 | W29: =V29 -> 0.094075953 | X29: =W29 -> 0.094075953 | Y29: =X29 -> 0.094075953
B30: Jungheinrich | E30: =INDEX(INDIRECT($B30&"!C53:N78"),MATCH($B$22,INDIRECT($B30&"!B53:B78"),0),MATCH(E$4,INDIRECT($B30&"!C52:N52"),0)) -> 0.16383182 | F30: =INDEX(INDIRECT($B30&"!C53:N78"),MATCH($B$22,INDIRECT($B30&"!B53:B78"),0),MATCH(F$4,INDIRECT($B30&"!C52:N52"),0)) -> 0.16752208 | G30: =INDEX(INDIRECT($B30&"!C53:N78"),MATCH($B$22,INDIRECT($B30&"!B53:B78"),0),MATCH(G$4,INDIRECT($B30&"!C52:N52"),0)) -> 0.17313491 | H30: =INDEX(INDIRECT($B30&"!C53:N78"),MATCH($B$22,INDIRECT($B30&"!B53:B78"),0),MATCH(H$4,INDIRECT($B30&"!C52:N52"),0)) -> 0.16327378 | I30: =INDEX(INDIRECT($B30&"!C53:N78"),MATCH($B$22,INDIRECT($B30&"!B53:B78"),0),MATCH(I$4,INDIRECT($B30&"!C52:N52"),0)) -> 0.15761735 | J30: =INDEX(INDIRECT($B30&"!C53:N78"),MATCH($B$22,INDIRECT($B30&"!B53:B78"),0),MATCH(J$4,INDIRECT($B30&"!C52:N52"),0)) -> 0.16521312 | K30: =INDEX(INDIRECT($B30&"!C53:N78"),MATCH($B$22,INDIRECT($B30&"!B53:B78"),0),MATCH(K$4,INDIRECT($B30&"!C52:N52"),0)) -> 0.16530251 | O30: EBIT Mean | P30: =AVERAGE(E47:K47) -> 0.054580909 | Q30: =P30 -> 0.054580909 | R30: =Q30 -> 0.054580909 | S30: =R30 -> 0.054580909 | T30: =S30 -> 0.054580909 | U30: =T30 -> 0.054580909 | V30: =U30 -> 0.054580909 | W30: =V30 -> 0.054580909 | X30: =W30 -> 0.054580909 | Y30: =X30 -> 0.054580909
B31: Manitou_BF | E31: =INDEX(INDIRECT($B31&"!C53:N78"),MATCH($B$22,INDIRECT($B31&"!B53:B78"),0),MATCH(E$4,INDIRECT($B31&"!C52:N52"),0)) -> 0.0915973 | F31: =INDEX(INDIRECT($B31&"!C53:N78"),MATCH($B$22,INDIRECT($B31&"!B53:B78"),0),MATCH(F$4,INDIRECT($B31&"!C52:N52"),0)) -> 0.086563982 | G31: =INDEX(INDIRECT($B31&"!C53:N78"),MATCH($B$22,INDIRECT($B31&"!B53:B78"),0),MATCH(G$4,INDIRECT($B31&"!C52:N52"),0)) -> 0.094522889 | H31: =INDEX(INDIRECT($B31&"!C53:N78"),MATCH($B$22,INDIRECT($B31&"!B53:B78"),0),MATCH(H$4,INDIRECT($B31&"!C52:N52"),0)) -> 0.059263381 | I31: =INDEX(INDIRECT($B31&"!C53:N78"),MATCH($B$22,INDIRECT($B31&"!B53:B78"),0),MATCH(I$4,INDIRECT($B31&"!C52:N52"),0)) -> 0.095572338 | J31: =INDEX(INDIRECT($B31&"!C53:N78"),MATCH($B$22,INDIRECT($B31&"!B53:B78"),0),MATCH(J$4,INDIRECT($B31&"!C52:N52"),0)) -> 0.10377847 | K31: =INDEX(INDIRECT($B31&"!C53:N78"),MATCH($B$22,INDIRECT($B31&"!B53:B78"),0),MATCH(K$4,INDIRECT($B31&"!C52:N52"),0)) -> 0.086141812
B33: Mean | E33: =IFERROR(AVERAGE(E23:E31),"-") -> 0.11158547 | F33: =IFERROR(AVERAGE(F23:F31),"-") -> 0.11804821 | G33: =IFERROR(AVERAGE(G23:G31),"-") -> 0.072833125 | H33: =IFERROR(AVERAGE(H23:H31),"-") -> 0.07743555 | I33: =IFERROR(AVERAGE(I23:I31),"-") -> 0.087437948 | J33: =IFERROR(AVERAGE(J23:J31),"-") -> 0.097115411 | K33: =IFERROR(AVERAGE(K23:K31),"-") -> 0.11370116
B34: Median | E34: =IFERROR(MEDIAN(E23:E31),"-") -> 0.098754065 | F34: =IFERROR(MEDIAN(F23:F31),"-") -> 0.097790096 | G34: =IFERROR(MEDIAN(G23:G31),"-") -> 0.094522889 | H34: =IFERROR(MEDIAN(H23:H31),"-") -> 0.07845036 | I34: =IFERROR(MEDIAN(I23:I31),"-") -> 0.10465523 | J34: =IFERROR(MEDIAN(J23:J31),"-") -> 0.10377847 | K34: =IFERROR(MEDIAN(K23:K31),"-") -> 0.1055919
B36: EBIT Margin (Operating Margin)
B37: Honeywell_International | E37: =INDEX(INDIRECT($B37&"!C53:N78"),MATCH($B$36,INDIRECT($B37&"!B53:B78"),0),MATCH(E$4,INDIRECT($B37&"!C52:N52"),0)) -> 0.19961314 | F37: =INDEX(INDIRECT($B37&"!C53:N78"),MATCH($B$36,INDIRECT($B37&"!B53:B78"),0),MATCH(F$4,INDIRECT($B37&"!C52:N52"),0)) -> 0.19270833 | G37: =INDEX(INDIRECT($B37&"!C53:N78"),MATCH($B$36,INDIRECT($B37&"!B53:B78"),0),MATCH(G$4,INDIRECT($B37&"!C52:N52"),0)) -> 0.19614971 | H37: =INDEX(INDIRECT($B37&"!C53:N78"),MATCH($B$36,INDIRECT($B37&"!B53:B78"),0),MATCH(H$4,INDIRECT($B37&"!C52:N52"),0)) -> 0.20404479 | I37: =INDEX(INDIRECT($B37&"!C53:N78"),MATCH($B$36,INDIRECT($B37&"!B53:B78"),0),MATCH(I$4,INDIRECT($B37&"!C52:N52"),0)) -> 0.21483341 | J37: =INDEX(INDIRECT($B37&"!C53:N78"),MATCH($B$36,INDIRECT($B37&"!B53:B78"),0),MATCH(J$4,INDIRECT($B37&"!C52:N52"),0)) -> 0.20443682 | K37: =INDEX(INDIRECT($B37&"!C53:N78"),MATCH($B$36,INDIRECT($B37&"!B53:B78"),0),MATCH(K$4,INDIRECT($B37&"!C52:N52"),0)) -> 0.20324064
B38: Daifuku | E38: =INDEX(INDIRECT($B38&"!C53:N78"),MATCH($B$36,INDIRECT($B38&"!B53:B78"),0),MATCH(E$4,INDIRECT($B38&"!C52:N52"),0)) -> 0.091274617 | F38: =INDEX(INDIRECT($B38&"!C53:N78"),MATCH($B$36,INDIRECT($B38&"!B53:B78"),0),MATCH(F$4,INDIRECT($B38&"!C52:N52"),0)) -> 0.094042651 | G38: =INDEX(INDIRECT($B38&"!C53:N78"),MATCH($B$36,INDIRECT($B38&"!B53:B78"),0),MATCH(G$4,INDIRECT($B38&"!C52:N52"),0)) -> 0.098100994 | H38: =INDEX(INDIRECT($B38&"!C53:N78"),MATCH($B$36,INDIRECT($B38&"!B53:B78"),0),MATCH(H$4,INDIRECT($B38&"!C52:N52"),0)) -> 0.09777845 | I38: =INDEX(INDIRECT($B38&"!C53:N78"),MATCH($B$36,INDIRECT($B38&"!B53:B78"),0),MATCH(I$4,INDIRECT($B38&"!C52:N52"),0)) -> - | J38: =INDEX(INDIRECT($B38&"!C53:N78"),MATCH($B$36,INDIRECT($B38&"!B53:B78"),0),MATCH(J$4,INDIRECT($B38&"!C52:N52"),0)) -> 0.12703026 | K38: =INDEX(INDIRECT($B38&"!C53:N78"),MATCH($B$36,INDIRECT($B38&"!B53:B78"),0),MATCH(K$4,INDIRECT($B38&"!C52:N52"),0)) -> 0.14606494
B39: Hyster_Yale | E39: =INDEX(INDIRECT($B39&"!C53:N78"),MATCH($B$36,INDIRECT($B39&"!B53:B78"),0),MATCH(E$4,INDIRECT($B39&"!C52:N52"),0)) -> 0.023664863 | F39: =INDEX(INDIRECT($B39&"!C53:N78"),MATCH($B$36,INDIRECT($B39&"!B53:B78"),0),MATCH(F$4,INDIRECT($B39&"!C52:N52"),0)) -> 0.023932292 | G39: =INDEX(INDIRECT($B39&"!C53:N78"),MATCH($B$36,INDIRECT($B39&"!B53:B78"),0),MATCH(G$4,INDIRECT($B39&"!C52:N52"),0)) -> -0.025392595 | H39: =INDEX(INDIRECT($B39&"!C53:N78"),MATCH($B$36,INDIRECT($B39&"!B53:B78"),0),MATCH(H$4,INDIRECT($B39&"!C52:N52"),0)) -> 0.0087929435 | I39: =INDEX(INDIRECT($B39&"!C53:N78"),MATCH($B$36,INDIRECT($B39&"!B53:B78"),0),MATCH(I$4,INDIRECT($B39&"!C52:N52"),0)) -> 0.061238861 | J39: =INDEX(INDIRECT($B39&"!C53:N78"),MATCH($B$36,INDIRECT($B39&"!B53:B78"),0),MATCH(J$4,INDIRECT($B39&"!C52:N52"),0)) -> 0.072164709 | K39: =INDEX(INDIRECT($B39&"!C53:N78"),MATCH($B$36,INDIRECT($B39&"!B53:B78"),0),MATCH(K$4,INDIRECT($B39&"!C52:N52"),0)) -> 0.040167621
B40: Mitsubishi_Logisnext | E40: =INDEX(INDIRECT($B40&"!C53:N78"),MATCH($B$36,INDIRECT($B40&"!B53:B78"),0),MATCH(E$4,INDIRECT($B40&"!C52:N52"),0)) -> 0.018794078 | F40: =INDEX(INDIRECT($B40&"!C53:N78"),MATCH($B$36,INDIRECT($B40&"!B53:B78"),0),MATCH(F$4,INDIRECT($B40&"!C52:N52"),0)) -> 0.004074117 | G40: =INDEX(INDIRECT($B40&"!C53:N78"),MATCH($B$36,INDIRECT($B40&"!B53:B78"),0),MATCH(G$4,INDIRECT($B40&"!C52:N52"),0)) -> 0.0077201409 | H40: =INDEX(INDIRECT($B40&"!C53:N78"),MATCH($B$36,INDIRECT($B40&"!B53:B78"),0),MATCH(H$4,INDIRECT($B40&"!C52:N52"),0)) -> 0.023900711 | I40: =INDEX(INDIRECT($B40&"!C53:N78"),MATCH($B$36,INDIRECT($B40&"!B53:B78"),0),MATCH(I$4,INDIRECT($B40&"!C52:N52"),0)) -> 0.06070935 | J40: =INDEX(INDIRECT($B40&"!C53:N78"),MATCH($B$36,INDIRECT($B40&"!B53:B78"),0),MATCH(J$4,INDIRECT($B40&"!C52:N52"),0)) -> 0.031200702 | K40: =INDEX(INDIRECT($B40&"!C53:N78"),MATCH($B$36,INDIRECT($B40&"!B53:B78"),0),MATCH(K$4,INDIRECT($B40&"!C52:N52"),0)) -> 0.020403643
B41: Toyota_Industries | E41: =INDEX(INDIRECT($B41&"!C53:N78"),MATCH($B$36,INDIRECT($B41&"!B53:B78"),0),MATCH(E$4,INDIRECT($B41&"!C52:N52"),0)) -> 0.057221873 | F41: =INDEX(INDIRECT($B41&"!C53:N78"),MATCH($B$36,INDIRECT($B41&"!B53:B78"),0),MATCH(F$4,INDIRECT($B41&"!C52:N52"),0)) -> 0.054322283 | G41: =INDEX(INDIRECT($B41&"!C53:N78"),MATCH($B$36,INDIRECT($B41&"!B53:B78"),0),MATCH(G$4,INDIRECT($B41&"!C52:N52"),0)) -> 0.056111546 | H41: =INDEX(INDIRECT($B41&"!C53:N78"),MATCH($B$36,INDIRECT($B41&"!B53:B78"),0),MATCH(H$4,INDIRECT($B41&"!C52:N52"),0)) -> 0.049977943 | I41: =INDEX(INDIRECT($B41&"!C53:N78"),MATCH($B$36,INDIRECT($B41&"!B53:B78"),0),MATCH(I$4,INDIRECT($B41&"!C52:N52"),0)) -> 0.063288032 | J41: =INDEX(INDIRECT($B41&"!C53:N78"),MATCH($B$36,INDIRECT($B41&"!B53:B78"),0),MATCH(J$4,INDIRECT($B41&"!C52:N52"),0)) -> 0.055169861 | K41: =INDEX(INDIRECT($B41&"!C53:N78"),MATCH($B$36,INDIRECT($B41&"!B53:B78"),0),MATCH(K$4,INDIRECT($B41&"!C52:N52"),0)) -> 0.043718371
B42: Symbotic | E42: =INDEX(INDIRECT($B42&"!C53:N78"),MATCH($B$36,INDIRECT($B42&"!B53:B78"),0),MATCH(E$4,INDIRECT($B42&"!C52:N52"),0)) -> - | F42: =INDEX(INDIRECT($B42&"!C53:N78"),MATCH($B$36,INDIRECT($B42&"!B53:B78"),0),MATCH(F$4,INDIRECT($B42&"!C52:N52"),0)) -> - | G42: =INDEX(INDIRECT($B42&"!C53:N78"),MATCH($B$36,INDIRECT($B42&"!B53:B78"),0),MATCH(G$4,INDIRECT($B42&"!C52:N52"),0)) -> -0.23659558 | H42: =INDEX(INDIRECT($B42&"!C53:N78"),MATCH($B$36,INDIRECT($B42&"!B53:B78"),0),MATCH(H$4,INDIRECT($B42&"!C52:N52"),0)) -> -0.16849903 | I42: =INDEX(INDIRECT($B42&"!C53:N78"),MATCH($B$36,INDIRECT($B42&"!B53:B78"),0),MATCH(I$4,INDIRECT($B42&"!C52:N52"),0)) -> -0.046399159 | J42: =INDEX(INDIRECT($B42&"!C53:N78"),MATCH($B$36,INDIRECT($B42&"!B53:B78"),0),MATCH(J$4,INDIRECT($B42&"!C52:N52"),0)) -> -0.036284304 | K42: =INDEX(INDIRECT($B42&"!C53:N78"),MATCH($B$36,INDIRECT($B42&"!B53:B78"),0),MATCH(K$4,INDIRECT($B42&"!C52:N52"),0)) -> -0.020168845
B43: KENGIC | E43: =INDEX(INDIRECT($B43&"!C53:N78"),MATCH($B$36,INDIRECT($B43&"!B53:B78"),0),MATCH(E$4,INDIRECT($B43&"!C52:N52"),0)) -> 0.020460619 | F43: =INDEX(INDIRECT($B43&"!C53:N78"),MATCH($B$36,INDIRECT($B43&"!B53:B78"),0),MATCH(F$4,INDIRECT($B43&"!C52:N52"),0)) -> 0.081390825 | G43: =INDEX(INDIRECT($B43&"!C53:N78"),MATCH($B$36,INDIRECT($B43&"!B53:B78"),0),MATCH(G$4,INDIRECT($B43&"!C52:N52"),0)) -> 0.063192723 | H43: =INDEX(INDIRECT($B43&"!C53:N78"),MATCH($B$36,INDIRECT($B43&"!B53:B78"),0),MATCH(H$4,INDIRECT($B43&"!C52:N52"),0)) -> 0.053584208 | I43: =INDEX(INDIRECT($B43&"!C53:N78"),MATCH($B$36,INDIRECT($B43&"!B53:B78"),0),MATCH(I$4,INDIRECT($B43&"!C52:N52"),0)) -> -0.098653914 | J43: =INDEX(INDIRECT($B43&"!C53:N78"),MATCH($B$36,INDIRECT($B43&"!B53:B78"),0),MATCH(J$4,INDIRECT($B43&"!C52:N52"),0)) -> -0.077697599 | K43: =INDEX(INDIRECT($B43&"!C53:N78"),MATCH($B$36,INDIRECT($B43&"!B53:B78"),0),MATCH(K$4,INDIRECT($B43&"!C52:N52"),0)) -> -0.075104141
B44: Jungheinrich | E44: =INDEX(INDIRECT($B44&"!C53:N78"),MATCH($B$36,INDIRECT($B44&"!B53:B78"),0),MATCH(E$4,INDIRECT($B44&"!C52:N52"),0)) -> 0.070211496 | F44: =INDEX(INDIRECT($B44&"!C53:N78"),MATCH($B$36,INDIRECT($B44&"!B53:B78"),0),MATCH(F$4,INDIRECT($B44&"!C52:N52"),0)) -> 0.070510104 | G44: =INDEX(INDIRECT($B44&"!C53:N78"),MATCH($B$36,INDIRECT($B44&"!B53:B78"),0),MATCH(G$4,INDIRECT($B44&"!C52:N52"),0)) -> 0.084779171 | H44: =INDEX(INDIRECT($B44&"!C53:N78"),MATCH($B$36,INDIRECT($B44&"!B53:B78"),0),MATCH(H$4,INDIRECT($B44&"!C52:N52"),0)) -> 0.079458039 | I44: =INDEX(INDIRECT($B44&"!C53:N78"),MATCH($B$36,INDIRECT($B44&"!B53:B78"),0),MATCH(I$4,INDIRECT($B44&"!C52:N52"),0)) -> 0.077777099 | J44: =INDEX(INDIRECT($B44&"!C53:N78"),MATCH($B$36,INDIRECT($B44&"!B53:B78"),0),MATCH(J$4,INDIRECT($B44&"!C52:N52"),0)) -> 0.078511704 | K44: =INDEX(INDIRECT($B44&"!C53:N78"),MATCH($B$36,INDIRECT($B44&"!B53:B78"),0),MATCH(K$4,INDIRECT($B44&"!C52:N52"),0)) -> 0.077929765
B45: Manitou_BF | E45: =INDEX(INDIRECT($B45&"!C53:N78"),MATCH($B$36,INDIRECT($B45&"!B53:B78"),0),MATCH(E$4,INDIRECT($B45&"!C52:N52"),0)) -> 0.069332535 | F45: =INDEX(INDIRECT($B45&"!C53:N78"),MATCH($B$36,INDIRECT($B45&"!B53:B78"),0),MATCH(F$4,INDIRECT($B45&"!C52:N52"),0)) -> 0.054552853 | G45: =INDEX(INDIRECT($B45&"!C53:N78"),MATCH($B$36,INDIRECT($B45&"!B53:B78"),0),MATCH(G$4,INDIRECT($B45&"!C52:N52"),0)) -> 0.065827973 | H45: =INDEX(INDIRECT($B45&"!C53:N78"),MATCH($B$36,INDIRECT($B45&"!B53:B78"),0),MATCH(H$4,INDIRECT($B45&"!C52:N52"),0)) -> 0.036012037 | I45: =INDEX(INDIRECT($B45&"!C53:N78"),MATCH($B$36,INDIRECT($B45&"!B53:B78"),0),MATCH(I$4,INDIRECT($B45&"!C52:N52"),0)) -> 0.074416852 | J45: =INDEX(INDIRECT($B45&"!C53:N78"),MATCH($B$36,INDIRECT($B45&"!B53:B78"),0),MATCH(J$4,INDIRECT($B45&"!C52:N52"),0)) -> 0.073978537 | K45: =INDEX(INDIRECT($B45&"!C53:N78"),MATCH($B$36,INDIRECT($B45&"!B53:B78"),0),MATCH(K$4,INDIRECT($B45&"!C52:N52"),0)) -> 0.053908518
B47: Mean | E47: =IFERROR(AVERAGE(E37:E45),"-") -> 0.068821653 | F47: =IFERROR(AVERAGE(F37:F45),"-") -> 0.071941682 | G47: =IFERROR(AVERAGE(G37:G45),"-") -> 0.034432675 | H47: =IFERROR(AVERAGE(H37:H45),"-") -> 0.042783344 | I47: =IFERROR(AVERAGE(I37:I45),"-") -> 0.050901317 | J47: =IFERROR(AVERAGE(J37:J45),"-") -> 0.058723411 | K47: =IFERROR(AVERAGE(K37:K45),"-") -> 0.054462279
B48: Median | E48: =IFERROR(MEDIAN(E37:E45),"-") -> 0.063277204 | F48: =IFERROR(MEDIAN(F37:F45),"-") -> 0.062531479 | G48: =IFERROR(MEDIAN(G37:G45),"-") -> 0.063192723 | H48: =IFERROR(MEDIAN(H37:H45),"-") -> 0.049977943 | I48: =IFERROR(MEDIAN(I37:I45),"-") -> 0.062263447 | J48: =IFERROR(MEDIAN(J37:J45),"-") -> 0.072164709 | K48: =IFERROR(MEDIAN(K37:K45),"-") -> 0.043718371
B50: Profit Margin
...

Sheet Financials
B2: Income Statement Standardized | P2: Year | Q2: 2019 | R2: 2020 | S2: 2021 | T2: 2022 | U2: 2023 | V2: 2024
P3: Revenue | Q3: =I5 -> 8806.5 | R3: =J5 -> 8341.6 | S3: =K5 -> 10294.3 | T3: =L5 -> 11135.6 | U3: =M5 -> 11433.7 | V3: =N5 -> 11503.2 | W3: CAGR
B4: Year Ended | E4: 2015 | F4: =+E4+1 -> 2016 | G4: =+F4+1 -> 2017 | H4: =+G4+1 -> 2018 | I4: =+H4+1 -> 2019 | J4: =+I4+1 -> 2020 | K4: =+J4+1 -> 2021 | L4: =+K4+1 -> 2022 | M4: =+L4+1 -> 2023 | N4: =+M4+1 -> 2024 | P4: Growth | Q4: =I5/H5-1 -> 0.1014045 | R4: =J5/I5-1 -> -0.052790552 | S4: =K5/J5-1 -> 0.23409178 | T4: =L5/K5-1 -> 0.081724838 | U4: =M5/L5-1 -> 0.026769999 | V4: =N5/M5-1 -> 0.0060785223 | W4: =(V3/Q3)^(1/(V2-Q2))-1 -> 0.054880019
B5: Revenue from Goods & Services | E5: =IS!B19 -> 5097.9 | F5: =IS!C19 -> 5587.2 | G5: =IS!D19 -> 7653.6 | H5: =IS!E19 -> 7995.7 | I5: =IS!F19 -> 8806.5 | J5: =IS!G19 -> 8341.6 | K5: =IS!H19 -> 10294.3 | L5: =IS!I19 -> 11135.6 | ... N5: =IS!K19 -> 11503.2
B6: Cost of Revenue (excl. D&A) | E6: =-IS!B22-IS!B24 -> -3601.7 | F6: =-IS!C22-IS!C24 -> -4091.6 | G6: =-IS!D22-IS!D24 -> -5768.1 | H6: =-IS!E22-IS!E24 -> -5974.7 | I6: =-IS!F22-IS!F24 -> -6474.6 | J6: =-IS!G22-IS!G24 -> -6296.8 | K6: =-IS!H22-IS!H24 -> -7870.6 | L6: =-IS!I22-IS!I24 -> -9124.1 | ... N6: =-IS!K22-IS!K24 -> -8525.9
B7: Gross Profit | E7: =E5+E6 -> 1496.2 | F7: =F5+F6 -> 1495.6 | G7: =G5+G6 -> 1885.5 | H7: =H5+H6 -> 2021 | I7: =I5+I6 -> 2331.9 | J7: =J5+J6 -> 2044.8 | K7: =K5+K6 -> 2423.7 | L7: =L5+L6 -> 2011.5 | ... N7: =N5+N6 -> 2977.3
B8: SG&A (excl. D&A) | E8: =-IS!B26+IS!B129+IS!B24 -> -719.6 | F8: =-IS!C26+IS!C129+IS!C24 -> -580.5 | G8: =-IS!D26+IS!D129+IS!D24 -> -664 | H8: =-IS!E26+IS!E129+IS!E24 -> -445.6 | I8: =-IS!F26+IS!F129+IS!F24 -> -751.4 | J8: =-IS!G26+IS!G129+IS!G24 -> -710.9 | K8: =-IS!H26+IS!H129+IS!H24 -> -721.1 | L8: =-IS!I26+IS!I129+IS!I24 -> -852 | ... N8: =-IS!K26+IS!K129+IS!K24 -> -1074
B9: Other Operating Expenses | E9: =-IS!B29 -> 72.4 | F9: =-IS!C29 -> 130 | G9: =-IS!D29 -> 240.2 | H9: =-IS!E29 -> 54.1 | I9: =-IS!F29 -> 66.2 | J9: =-IS!G29 -> 79.9 | K9: =-IS!H29 -> 143.1 | L9: =-IS!I29 -> 146.6 | ... N9: =-IS!K29 -> 134.2
B10: EBITDA | E10: =E7+E8+E9 -> 849 | F10: =F7+F8+F9 -> 1045.1 | G10: =G7+G8+G9 -> 1461.7 | H10: =H7+H8+H9 -> 1629.5 | I10: =I7+I8+I9 -> 1646.7 | J10: =J7+J8+J9 -> 1413.8 | K10: =K7+K8+K9 -> 1845.7 | L10: =L7+L8+L9 -> 1306.1 | ... N10: =N7+N8+N9 -> 2037.5
B11: Depreciation Expense | E11: =-IS!B130 -> -310.4 | F11: =-IS!C130 -> -339.5 | G11: =-IS!D130 -> -404 | H11: =-IS!E130 -> -708.7 | I11: =-IS!F130 -> -733.2 | J11: =-IS!G130 -> -743.7 | K11: =-IS!H130 -> -768.4 | L11: =-IS!I130 -> -824.4 | ... N11: =-IS!K130 -> -917.5
B12: EBITA | E12: =E10+E11 -> 538.6 | F12: =F10+F11 -> 705.6 | G12: =G10+G11 -> 1057.7 | H12: =H10+H11 -> 920.8 | I12: =I10+I11 -> 913.5 | J12: =J10+J11 -> 670.1 | K12: =K10+K11 -> 1077.3 | L12: =L10+L11 -> 481.7 | ... N12: =N10+N11 -> 1120
B13: Amortization Expense | E13: =-IS!B132 -> -86.9 | F13: =-IS!C132 -> -172.2 | G13: =-IS!D132 -> -286.4 | H13: =-IS!E132 -> -259.4 | I13: =-IS!F132 -> -157.8 | J13: =-IS!G132 -> -172.4 | K13: =-IS!H132 -> -170.5 | L13: =-IS!I132 -> -188.9 | ... N13: =-IS!K132 -> -193.3
B14: EBIT | E14: =E12+E13 -> 451.7 | F14: =F12+F13 -> 533.4 | G14: =G12+G13 -> 771.3 | H14: =H12+H13 -> 661.4 | I14: =I12+I13 -> 755.7 | J14: =J12+J13 -> 497.7 | K14: =K12+K13 -> 906.8 | L14: =L12+L13 -> 292.8 | ... N14: =N12+N13 -> 926.7
B15: Interest Expense, Net | E15: =-IS!B39 -> -45.7 | F15: =-IS!C39 -> -50.9 | G15: =-IS!D39 -> -53.2 | H15: =-IS!E39 -> -63.6 | I15: =-IS!F39 -> -53.8 | J15: =-IS!G39 -> -40.8 | K15: =-IS!H39 -> -15.7 | L15: =-IS!I39 -> -34.1 | ... N15: =-IS!K39 -> -173 | P15: GOGS % | Q15: =ABS(N6)/N5 -> 0.74117637
B16: EBT | E16: =SUM(E14:E15) -> 406 | F16: =SUM(F14:F15) -> 482.5 | G16: =SUM(G14:G15) -> 718.1 | H16: =SUM(H14:H15) -> 597.8 | I16: =SUM(I14:I15) -> 701.9 | J16: =SUM(J14:J15) -> 456.9 | K16: =SUM(K14:K15) -> 891.1 | L16: =SUM(L14:L15) -> 258.7 | ... N16: =SUM(N14:N15) -> 753.7 | P16: OpEx % | Q16: =ABS(SUM(N8:N9))/N5 -> 0.081699005
B17: Taxes | E17: =-IS!B63 -> -109.2 | F17: =-IS!C63 -> -93.1 | G17: =-IS!D63 -> -41.9 | H17: =-IS!E63 -> -143.7 | I17: =-IS!F63 -> -176.8 | J17: =-IS!G63 -> -90.7 | K17: =-IS!H63 -> -191.7 | L17: =-IS!I63 -> -32.2 | ... N17: =-IS!K63 -> -220.5 | P17: Dep. % | Q17: =ABS(N11)/N5 -> 0.079760414
B18: Adj. NI | E18: =SUM(E16:E17) -> 296.8 | F18: =SUM(F16:F17) -> 389.4 | G18: =SUM(G16:G17) -> 676.2 | H18: =SUM(H16:H17) -> 454.1 | I18: =SUM(I16:I17) -> 525.1 | J18: =SUM(J16:J17) -> 366.2 | K18: =SUM(K16:K17) -> 699.4 | L18: =SUM(L16:L17) -> 226.5 | ... N18: =SUM(N16:N17) -> 533.2 | P18: Amort. % | Q18: =ABS(N13)/N5 -> 0.01680402
B19: Exceptional Items, Net | E19: =IS!B37+IS!B52-E15-SUM(IS!B73,IS!B70) -> -79.8 | F19: =IS!C37+IS!C52-F15-SUM(IS!C73,IS!C70) -> -143.8 | G19: =IS!D37+IS!D52-G15-SUM(IS!D73,IS!D70) -> -251.4 | H19: =IS!E37+IS!E52-H15-SUM(IS!E73,IS!E70) -> -54.3 | I19: =IS!F37+IS!F52-I15-SUM(IS!F73,IS!F70) -> -70.3 | J19: =IS!G37+IS!G52-J15-SUM(IS!G73,IS!G70) -> -150.9 | K19: =IS!H37+IS!H52-K15-SUM(IS!H73,IS!H70) -> -131.1 | L19: =IS!I37+IS!I52-L15-SUM(IS!I73,IS!I70) -> -128.5 | ... N19: =IS!K37+IS!K52-N15-SUM(IS!K73,IS!K70) -> -172.8 | P19: Int. Exp. % | Q19: =ABS(N15)/N5 -> 0.015039293
B20: NI | E20: =SUM(E18:E19) -> 217 | F20: =SUM(F18:F19) -> 245.6 | G20: =SUM(G18:G19) -> 424.8 | H20: =SUM(H18:H19) -> 399.8 | I20: =SUM(I18:I19) -> 454.8 | J20: =SUM(J18:J19) -> 215.3 | K20: =SUM(K18:K19) -> 568.3 | L20: =SUM(L18:L19) -> 98 | ... N20: =SUM(N18:N19) -> 360.4 | P20: Tax % | Q20: =ABS(N17)/N5 -> 0.019168579
P21: Ex. Item % | Q21: =ABS(N19)/N5 -> 0.015021907
B22: Free Cash Flow to Equity Holders | P22: NI % | Q22: =N20/N5 -> 0.031330412
P23: Revenue | Q23: =SUM(Q15:Q22) -> 1
B24: Year Ended | E24: 2015 | F24: =+E24+1 -> 2016 | G24: =+F24+1 -> 2017 | H24: =+G24+1 -> 2018 | I24: =+H24+1 -> 2019 | J24: =+I24+1 -> 2020 | K24: =+J24+1 -> 2021 | L24: =+K24+1 -> 2022 | M24: =+L24+1 -> 2023 | N24: =+M24+1 -> 2024
B25: CFO | E25: =CF!B32 -> 424.3 | F25: =CF!C32 -> 332.4 | G25: =CF!D32 -> 554.2 | H25: =CF!E32 -> 620.3 | I25: =CF!F32 -> 694.6 | J25: =CF!G32 -> 349.2 | K25: =CF!H32 -> 710.2 | L25: =CF!I32 -> -518.4 | ... N25: =CF!K32 -> 1089.6
B26: CapEx | E26: =-CF!B34 -> -128.5 | F26: =-CF!C34 -> -160.3 | G26: =-CF!D34 -> -214.3 | H26: =-CF!E34 -> -253.4 | I26: =-CF!F34 -> -283.8 | J26: =-CF!G34 -> -278.1 | K26: =-CF!H34 -> -317 | L26: =-CF!I34 -> -375.2 | ... N26: =-CF!K34 -> -453.7 | P26: EBITDA | Q26: =I10 -> 1646.7 | R26: =J10 -> 1413.8 | S26: =K10 -> 1845.7 | T26: =L10 -> 1306.1 | U26: =M10 -> 1833 | V26: =N10 -> 2037.5 | W26: Average
B27: Debt Payment | E27: =CF!B51 -> -223.9 | F27: =CF!C51 -> 1744 | G27: =CF!D51 -> -914.7 | H27: =CF!E51 -> -230.9 | I27: =CF!F51 -> -226.1 | J27: =CF!G51 -> -609.5 | K27: =CF!H51 -> -148.8 | L27: =CF!I51 -> 942.4 | ... N27: =CF!K51 -> 23.6 | P27: EBITDA Margin | Q27: =Q26/Q3 -> 0.18698688 | R27: =R26/R3 -> 0.16948787 | S27: =S26/S3 -> 0.1792934 | T27: =T26/T3 -> 0.11729049 | U27: =U26/U3 -> 0.16031556 | V27: =V26/V3 -> 0.17712463 | W27: =AVERAGE(Q27:V27) -> 0.16508314
B28: FCFE | E28: =E25+E26+E27 -> 71.9 | F28: =F25+F26+F27 -> 1916.1 | G28: =G25+G26+G27 -> -574.8 | H28: =H25+H26+H27 -> 136 | I28: =I25+I26+I27 -> 184.7 | J28: =J25+J26+J27 -> -538.4 | K28: =K25+K26+K27 -> 244.4 | L28: =L25+L26+L27 -> 48.8 | ... N28: =N25+N26+N27 -> 659.5
B30: Balancesheet
B32: Year Ended | E32: 2015 | F32: =+E32+1 -> 2016 | G32: =+F32+1 -> 2017 | H32: =+G32+1 -> 2018 | I32: =+H32+1 -> 2019 | J32: =+I32+1 -> 2020 | K32: =+J32+1 -> 2021 | L32: =+K32+1 -> 2022 | M32: =+L32+1 -> 2023 | N32: =+M32+1 -> 2024
B33: Current Assets
B34: Cash & Short-Term Investments | E34: =BS!D17 -> 140.5 | F34: =BS!E17 -> 326.5 | G34: =BS!F17 -> 231.5 | H34: =BS!G17 -> 211.4 | I34: =BS!H17 -> 249 | J34: =BS!I17 -> 359.8 | K34: =BS!J17 -> 517.6 | L34: =BS!K17 -> 355.9 | ... N34: =BS!M17 -> 839.8
B35: Derivative Financial Instruments - ST | E35: =BS!D21 -> 5.3 | F35: =BS!E21 -> 10.3 | G35: =BS!F21 -> 30 | H35: =BS!G21 -> 8.9 | I35: =BS!H21 -> 9.4 | J35: =BS!I21 -> 15 | K35: =BS!J21 -> 8.9 | L35: =BS!K21 -> 20.5 | ... N35: =BS!M21 -> 12.7
B36: Loans & Receivables - ST | E36: =BS!D22 -> 898.3 | F36: =BS!E22 -> 1292.3 | G36: =BS!F22 -> 1410.8 | H36: =BS!G22 -> 1550.3 | I36: =BS!H22 -> 1666.3 | J36: =BS!I22 -> 1861.7 | K36: =BS!J22 -> 2481.6 | L36: =BS!K22 -> 2846.3 | ... N36: =BS!M22 -> 2884.9
B37: Inventories | E37: =BS!D29 -> 553.5 | F37: =BS!E29 -> 672.4 | G37: =BS!F29 -> 768.6 | H37: =BS!G29 -> 994.8 | I37: =BS!H29 -> 1085.3 | J37: =BS!I29 -> 1101 | K37: =BS!J29 -> 1632.1 | L37: =BS!K29 -> 1804.6 | ... N37: =BS!M29 -> 1748.6
B38: Assets Held for Sale/Discontinued Operations - ST | E38: =BS!D34 -> 0 | F38: =BS!E34 -> 0 | G38: =BS!F34 -> 0 | H38: =BS!G34 -> 0 | I38: =BS!H34 -> 0 | J38: =BS!I34 -> 0 | K38: =BS!J34 -> 0 | L38: =BS!K34 -> 27.4 | ... N38: =BS!M34 -> 0
B39: Other Current Assets - Total | E39: =BS!D35 -> 32.3 | F39: =BS!E35 -> 53.1 | G39: =BS!F35 -> 40.6 | H39: =BS!G35 -> 52.8 | I39: =BS!H35 -> 58.8 | J39: =BS!I35 -> 51.9 | K39: =BS!J35 -> 57.7 | L39: =BS!K35 -> 61.1 | ... N39: =BS!M35 -> 83 | P39: Net Income | Q39: =I20 -> 454.8 | R39: =J20 -> 215.3 | S39: =K20 -> 568.3 | T39: =L20 -> 98 | U39: =M20 -> 305.8 | V39: =N20 -> 360.4 | W39: Average
B40: Total Current Assets | E40: =SUM(E34:E39) -> 1629.9 | F40: =SUM(F34:F39) -> 2354.6 | G40: =SUM(G34:G39) -> 2481.5 | H40: =SUM(H34:H39) -> 2818.2 | I40: =SUM(I34:I39) -> 3068.8 | J40: =SUM(J34:J39) -> 3389.4 | K40: =SUM(K34:K39) -> 4697.9 | L40: =SUM(L34:L39) -> 5115.8 | ... N40: =SUM(N34:N39) -> 5569 | P40: Net Income Margin | Q40: =Q39/Q3 -> 0.051643672 | R40: =R39/R3 -> 0.025810396 | S40: =S39/S3 -> 0.055205308 | T40: =T39/T3 -> 0.0088006035 | U40: =U39/U3 -> 0.026745498 | V40: =V39/V3 -> 0.031330412 | W40: =AVERAGE(Q40:V40) -> 0.033255982
B42: Non-Current Assets
B43: Investments - LT | E43: =BS!D41 -> 43.2 | F43: =BS!E41 -> 42.9 | G43: =BS!F41 -> 54.9 | H43: =BS!G41 -> 51.8 | I43: =BS!H41 -> 60.8 | J43: =BS!I41 -> 80 | K43: =BS!J41 -> 95 | L43: =BS!K41 -> 106.3 | ... N43: =BS!M41 -> 161.5
B44: Investments in J&V, Associates | E44: =BS!D43 -> 73.6 | F44: =BS!E43 -> 72.7 | G44: =BS!F43 -> 80.3 | H44: =BS!G43 -> 82.3 | I44: =BS!H43 -> 84.5 | J44: =BS!I43 -> 78.8 | K44: =BS!J43 -> 84.3 | L44: =BS!K43 -> 94.7 | ... N44: =BS!M43 -> 110.3
...

Sheet BS
A1: Company Fundamentals - Balance Sheet
A2: Company Name | D2: Kion Group AG (KGX.DE)
A3: Country of Exchange | D3: Germany
A4: Country of Headquarters | D4: Germany
A5: TRBC Industry Group | D5: Machinery, Tools, Heavy Vehicles, Trains & Ships
A6: CF Template | D6: IND
A7: Consolidation Basis | D7: Consolidated
A8: Scaling | D8: Millions
A9: Period | D9: Annual
A10: Export Date | D10: 45993.357
A11: Statement Data | D11: 2015 | E11: 2016 | F11: 2017 | G11: 2018 | H11: 2019 | I11: 2020 | J11: 2021 | K11: 2022 | L11: 2023 | M11: 2024
A12: Period End Date | D12: 42369 | E12: 42735 | F12: 43100 | G12: 43465 | H12: 43830 | I12: 44196 | J12: 44561 | K12: 44926 | L12: 45291 | M12: 45657
A13: Standardized Currency | D13: EUR | E13: EUR | F13: EUR | G13: EUR | H13: EUR | I13: EUR | J13: EUR | K13: EUR | L13: EUR | M13: EUR
A14: Balance Sheet - Standardized (Currency: Euro)
A15: Field Name | D15: 31-12-2015 | E15: 31-12-2016 | F15: 31-12-2017 | G15: 31-12-2018 | H15: 31-12-2019 | I15: 31-12-2020 | J15: 31-12-2021 | K15: 31-12-2022 | L15: 31-12-2023 | M15: 31-12-2024
A16: Current Assets
A17: Cash & Short-Term Investments | D17: 140.5 | E17: 326.5 | F17: 231.5 | G17: 211.4 | H17: 249 | I17: 359.8 | J17: 517.6 | K17: 355.9 | L17: 354.5 | M17: 839.8
A18: Cash & Cash Equivalents | D18: 102.8 | E18: 276.1 | F18: 172.8 | G18: 171.6 | H18: 207.4 | I18: 307.2 | J18: 473.7 | K18: 306.2 | L18: 309.7 | M18: 786.5
A19: Short-Term Investments - Total | D19: 37.7 | E19: 50.4 | F19: 58.7 | G19: 39.8 | H19: 41.6 | I19: 52.6 | J19: 43.9 | K19: 49.7 | L19: 44.8 | M19: 53.3
A20: Financial Assets - Short-Term | D20: 37.7 | E20: 50.4 | F20: 58.7 | G20: 39.8 | H20: 41.6 | I20: 52.6 | J20: 43.9 | K20: 49.7 | L20: 44.8 | M20: 53.3
A21: Derivative Financial Instruments - Hedging - Short-Term | D21: 5.3 | E21: 10.3 | F21: 30 | G21: 8.9 | H21: 9.4 | I21: 15 | J21: 8.9 | K21: 20.5 | L21: 10.2 | M21: 12.7
A22: Loans & Receivables - Net - Short-Term | D22: 898.3 | E22: 1292.3 | F22: 1410.8 | G22: 1550.3 | H22: 1666.3 | I22: 1861.7 | J22: 2481.6 | K22: 2846.3 | L22: 2923.8 | M22: 2884.9
