Workbook
Name estimate_start: model!$D$73
Name scenario_name: 'Scenario Manager'!$D$10
Name scenario_number: 'Scenario Manager'!$D$11

Sheet Financial Valuation
C2: Financial Output
C4: Live Scenario | D4: =scenario_number -> 2
C5: Scenario Name | D5: =scenario_name -> Street

Sheet Financial Output
C2: Financial Output
C4: Live Scenario | D4: =scenario_number -> 2
C5: Scenario Name | D5: =scenario_name -> Street
B8: 1 | C8: Income Statement | E8: Units
C10: Year Ended | G10: =H10-1 -> 2020 | H10: =I10-1 -> 2021 | I10: =J10-1 -> 2022 | J10: =K10-1 -> 2023 | K10: =L10-1 -> 2024 | L10: =estimate_start -> 2025 | M10: =+L10+1 -> 2026 | N10: =+M10+1 -> 2027 | O10: =+N10+1 -> 2028 | P10: =+O10+1 -> 2029
C12: Revenue | E12: (US$m) | G12: {=INDEX(model!$N3:$AZ3,,MATCH('Financial Output'!G$10,model!$N$2:$AZ$2,0))} -> 3532.157 | H12: {=INDEX(model!$N3:$AZ3,,MATCH('Financial Output'!H$10,model!$N$2:$AZ$2,0))} -> 3620.684 | I12: {=INDEX(model!$N3:$AZ3,,MATCH('Financial Output'!I$10,model!$N$2:$AZ$2,0))} -> 3632.661 | J12: {=INDEX(model!$N3:$AZ3,,MATCH('Financial Output'!J$10,model!$N$2:$AZ$2,0))} -> 4386.549 | K12: {=INDEX(model!$N3:$AZ3,,MATCH('Financial Output'!K$10,model!$N$2:$AZ$2,0))} -> 4014.955 | L12: {=INDEX(model!$N3:$AZ3,,MATCH('Financial Output'!L$10,model!$N$2:$AZ$2,0))} -> 4577.0487 | M12: {=INDEX(model!$N3:$AZ3,,MATCH('Financial Output'!M$10,model!$N$2:$AZ$2,0))} -> 5034.7536 | N12: {=INDEX(model!$N3:$AZ3,,MATCH('Financial Output'!N$10,model!$N$2:$AZ$2,0))} -> 5487.8814 | ... P12: {=INDEX(model!$N3:$AZ3,,MATCH('Financial Output'!P$10,model!$N$2:$AZ$2,0))} -> 6640.3365
C13: Cost of Goods Sold | E13: (US$m) | G13: {=INDEX(model!$N4:$AZ4,,MATCH('Financial Output'!G$10,model!$N$2:$AZ$2,0))} -> -1879.266 | H13: {=INDEX(model!$N4:$AZ4,,MATCH('Financial Output'!H$10,model!$N$2:$AZ$2,0))} -> -1898.705 | I13: {=INDEX(model!$N4:$AZ4,,MATCH('Financial Output'!I$10,model!$N$2:$AZ$2,0))} -> -2072.317 | J13: {=INDEX(model!$N4:$AZ4,,MATCH('Financial Output'!J$10,model!$N$2:$AZ$2,0))} -> -2507.698 | K13: {=INDEX(model!$N4:$AZ4,,MATCH('Financial Output'!K$10,model!$N$2:$AZ$2,0))} -> -2295.365 | L13: {=INDEX(model!$N4:$AZ4,,MATCH('Financial Output'!L$10,model!$N$2:$AZ$2,0))} -> -2654.6882 | M13: {=INDEX(model!$N4:$AZ4,,MATCH('Financial Output'!M$10,model!$N$2:$AZ$2,0))} -> -2819.462 | N13: {=INDEX(model!$N4:$AZ4,,MATCH('Financial Output'!N$10,model!$N$2:$AZ$2,0))} -> -3018.3348 | ... P13: {=INDEX(model!$N4:$AZ4,,MATCH('Financial Output'!P$10,model!$N$2:$AZ$2,0))} -> -3320.1682
C15: Gross Profit | E15: (US$m) | G15: =+G12+G13 -> 1652.891 | H15: =+H12+H13 -> 1721.979 | I15: =+I12+I13 -> 1560.344 | J15: =+J12+J13 -> 1878.851 | K15: =+K12+K13 -> 1719.59 | L15: =+L12+L13 -> 1922.3605 | M15: =+M12+M13 -> 2215.2916 | N15: =+N12+N13 -> 2469.5466 | ... P15: =+P12+P13 -> 3320.1682
C16: Gross Margin | E16: (%) | G16: =G15/G12 -> 0.46795513 | H16: =H15/H12 -> 0.47559494 | I16: =I15/I12 -> 0.42953196 | J16: =J15/J12 -> 0.42832099 | K16: =K15/K12 -> 0.42829621 | L16: =L15/L12 -> 0.42 | M16: =M15/M12 -> 0.44 | N16: =N15/N12 -> 0.45 | ... P16: =P15/P12 -> 0.5
C18: Sales and Marketing | E18: (US$m) | G18: {=INDEX(model!$N6:$AZ6,,MATCH('Financial Output'!G$10,model!$N$2:$AZ$2,0))} -> -416.425 | H18: {=INDEX(model!$N6:$AZ6,,MATCH('Financial Output'!H$10,model!$N$2:$AZ$2,0))} -> -452.214 | I18: {=INDEX(model!$N6:$AZ6,,MATCH('Financial Output'!I$10,model!$N$2:$AZ$2,0))} -> -466.565 | J18: {=INDEX(model!$N6:$AZ6,,MATCH('Financial Output'!J$10,model!$N$2:$AZ$2,0))} -> -490.804 | K18: {=INDEX(model!$N6:$AZ6,,MATCH('Financial Output'!K$10,model!$N$2:$AZ$2,0))} -> -510.668 | L18: {=INDEX(model!$N6:$AZ6,,MATCH('Financial Output'!L$10,model!$N$2:$AZ$2,0))} -> -543.33617 | M18: {=INDEX(model!$N6:$AZ6,,MATCH('Financial Output'!M$10,model!$N$2:$AZ$2,0))} -> -597.66979 | N18: {=INDEX(model!$N6:$AZ6,,MATCH('Financial Output'!N$10,model!$N$2:$AZ$2,0))} -> -651.46007 | ... P18: {=INDEX(model!$N6:$AZ6,,MATCH('Financial Output'!P$10,model!$N$2:$AZ$2,0))} -> -695.52943
C19: Research and Development | E19: (US$m) | G19: {=INDEX(model!$N7:$AZ7,,MATCH('Financial Output'!G$10,model!$N$2:$AZ$2,0))} -> -529.888 | H19: {=INDEX(model!$N7:$AZ7,,MATCH('Financial Output'!H$10,model!$N$2:$AZ$2,0))} -> -536.666 | I19: {=INDEX(model!$N7:$AZ7,,MATCH('Financial Output'!I$10,model!$N$2:$AZ$2,0))} -> -624.656 | J19: {=INDEX(model!$N7:$AZ7,,MATCH('Financial Output'!J$10,model!$N$2:$AZ$2,0))} -> -750.559 | K19: {=INDEX(model!$N7:$AZ7,,MATCH('Financial Output'!K$10,model!$N$2:$AZ$2,0))} -> -767.497 | L19: {=INDEX(model!$N7:$AZ7,,MATCH('Financial Output'!L$10,model!$N$2:$AZ$2,0))} -> -778.09828 | M19: {=INDEX(model!$N7:$AZ7,,MATCH('Financial Output'!M$10,model!$N$2:$AZ$2,0))} -> -855.90811 | N19: {=INDEX(model!$N7:$AZ7,,MATCH('Financial Output'!N$10,model!$N$2:$AZ$2,0))} -> -932.93984 | ... P19: {=INDEX(model!$N7:$AZ7,,MATCH('Financial Output'!P$10,model!$N$2:$AZ$2,0))} -> -1128.8572
C20: General and Administrative | E20: (US$m) | G20: {=INDEX(model!$N8:$AZ8,,MATCH('Financial Output'!G$10,model!$N$2:$AZ$2,0))} -> -173.579 | H20: {=INDEX(model!$N8:$AZ8,,MATCH('Financial Output'!H$10,model!$N$2:$AZ$2,0))} -> -184.446 | I20: {=INDEX(model!$N8:$AZ8,,MATCH('Financial Output'!I$10,model!$N$2:$AZ$2,0))} -> -179.98 | J20: {=INDEX(model!$N8:$AZ8,,MATCH('Financial Output'!J$10,model!$N$2:$AZ$2,0))} -> -218.758 | K20: {=INDEX(model!$N8:$AZ8,,MATCH('Financial Output'!K$10,model!$N$2:$AZ$2,0))} -> -220.647 | L20: {=INDEX(model!$N8:$AZ8,,MATCH('Financial Output'!L$10,model!$N$2:$AZ$2,0))} -> -234.76211 | M20: {=INDEX(model!$N8:$AZ8,,MATCH('Financial Output'!M$10,model!$N$2:$AZ$2,0))} -> -258.23832 | N20: {=INDEX(model!$N8:$AZ8,,MATCH('Financial Output'!N$10,model!$N$2:$AZ$2,0))} -> -281.47977 | ... P20: {=INDEX(model!$N8:$AZ8,,MATCH('Financial Output'!P$10,model!$N$2:$AZ$2,0))} -> -300.52105
C22: EBITDA | E22: (US$m) | G22: =G15+G18+G19+G20-G25 -> 665.526 | H22: =H15+H18+H19+H20-H25 -> 680.919 | I22: =I15+I18+I19+I20-I25 -> 429.346 | J22: =J15+J18+J19+J20-J25 -> 560.91 | K22: =K15+K18+K19+K20-K25 -> 354.248 | L22: =L15+L18+L19+L20-L25 -> 480.59011 | M22: =M15+M18+M19+M20-M25 -> 604.17043 | N22: =N15+N18+N19+N20-N25 -> 713.42458 | ... P22: =P15+P18+P19+P20-P25 -> 1328.0673
C23: EBITDA Margin | E23: (%)
C25: Depreciation and Amortization | E25: (US$m) | G25: {=-INDEX(model!$N50:$AZ50,,MATCH('Financial Output'!G$10,model!$N$2:$AZ$2,0))} -> -132.527 | H25: {=-INDEX(model!$N50:$AZ50,,MATCH('Financial Output'!H$10,model!$N$2:$AZ$2,0))} -> -132.266 | I25: {=-INDEX(model!$N50:$AZ50,,MATCH('Financial Output'!I$10,model!$N$2:$AZ$2,0))} -> -140.203 | J25: {=-INDEX(model!$N50:$AZ50,,MATCH('Financial Output'!J$10,model!$N$2:$AZ$2,0))} -> -142.18 | K25: {=-INDEX(model!$N50:$AZ50,,MATCH('Financial Output'!K$10,model!$N$2:$AZ$2,0))} -> -133.47 | L25: {=-INDEX(model!$N50:$AZ50,,MATCH('Financial Output'!L$10,model!$N$2:$AZ$2,0))} -> -114.42622 | M25: {=-INDEX(model!$N50:$AZ50,,MATCH('Financial Output'!M$10,model!$N$2:$AZ$2,0))} -> -100.69507 | N25: {=-INDEX(model!$N50:$AZ50,,MATCH('Financial Output'!N$10,model!$N$2:$AZ$2,0))} -> -109.75763 | ... P25: {=-INDEX(model!$N50:$AZ50,,MATCH('Financial Output'!P$10,model!$N$2:$AZ$2,0))} -> -132.80673
C27: EBIT | E27: (US$m) | G27: =+G15+G18+G19+G20 -> 532.999 | H27: =+H15+H18+H19+H20 -> 548.653 | I27: =+I15+I18+I19+I20 -> 289.143 | J27: =+J15+J18+J19+J20 -> 418.73 | K27: =+K15+K18+K19+K20 -> 220.778 | L27: =+L15+L18+L19+L20 -> 366.1639 | M27: =+M15+M18+M19+M20 -> 503.47536 | N27: =+N15+N18+N19+N20 -> 603.66695 | ... P27: =+P15+P18+P19+P20 -> 1195.2606
C28: EBIT Margin | E28: (%) | G28: =G27/G12 -> 0.15089901 | H28: =H27/H12 -> 0.15153297 | I28: =I27/I12 -> 0.079595371 | J28: =J27/J12 -> 0.095457728 | K28: =K27/K12 -> 0.05498891 | L28: =L27/L12 -> 0.08 | M28: =M27/M12 -> 0.1 | N28: =N27/N12 -> 0.11 | ... P28: =P27/P12 -> 0.18
C30: Interest Expense | E30: (US$m) | G30: {=INDEX(model!$N11:$AZ11,,MATCH('Financial Output'!G$10,model!$N$2:$AZ$2,0))} -> -31.003 | H30: {=INDEX(model!$N11:$AZ11,,MATCH('Financial Output'!H$10,model!$N$2:$AZ$2,0))} -> -32.605 | I30: {=INDEX(model!$N11:$AZ11,,MATCH('Financial Output'!I$10,model!$N$2:$AZ$2,0))} -> -40.303 | J30: {=INDEX(model!$N11:$AZ11,,MATCH('Financial Output'!J$10,model!$N$2:$AZ$2,0))} -> -33.892 | K30: {=INDEX(model!$N11:$AZ11,,MATCH('Financial Output'!K$10,model!$N$2:$AZ$2,0))} -> -46.767 | L30: {=INDEX(model!$N11:$AZ11,,MATCH('Financial Output'!L$10,model!$N$2:$AZ$2,0))} -> -38.460574 | M30: {=INDEX(model!$N11:$AZ11,,MATCH('Financial Output'!M$10,model!$N$2:$AZ$2,0))} -> -36.328192 | N30: {=INDEX(model!$N11:$AZ11,,MATCH('Financial Output'!N$10,model!$N$2:$AZ$2,0))} -> -28.363881 | ... P30: {=INDEX(model!$N11:$AZ11,,MATCH('Financial Output'!P$10,model!$N$2:$AZ$2,0))} -> 6.0653429
C32: Pre-Tax Income | E32: (US$m) | G32: =G27+G30 -> 501.996 | H32: =H27+H30 -> 516.048 | I32: =I27+I30 -> 248.84 | J32: =J27+J30 -> 384.838 | K32: =K27+K30 -> 174.011 | L32: =L27+L30 -> 327.70332 | M32: =M27+M30 -> 467.14717 | N32: =N27+N30 -> 575.30307 | ... P32: =P27+P30 -> 1201.3259
C33: Pre-Tax Margin | E33: (%) | G33: =G32/G12 -> 0.14212166 | H33: =H32/H12 -> 0.14252777 | I33: =I32/I12 -> 0.068500749 | J33: =J32/J12 -> 0.087731381 | K33: =K32/K12 -> 0.04334071 | L33: =L32/L12 -> 0.07159708 | M33: =M32/M12 -> 0.092784514 | N33: =N32/N12 -> 0.10483154 | ... P33: =P32/P12 -> 0.18091341
C35: Net Tax Expense | E35: (US$m) | G35: {=INDEX(model!$N13:$AZ13,,MATCH('Financial Output'!G$10,model!$N$2:$AZ$2,0))} -> -94.67 | H35: {=INDEX(model!$N13:$AZ13,,MATCH('Financial Output'!H$10,model!$N$2:$AZ$2,0))} -> 37.445 | I35: {=INDEX(model!$N13:$AZ13,,MATCH('Financial Output'!I$10,model!$N$2:$AZ$2,0))} -> -29.603 | J35: {=INDEX(model!$N13:$AZ13,,MATCH('Financial Output'!J$10,model!$N$2:$AZ$2,0))} -> -68.826 | K35: {=INDEX(model!$N13:$AZ13,,MATCH('Financial Output'!K$10,model!$N$2:$AZ$2,0))} -> -35.894 | L35: {=INDEX(model!$N13:$AZ13,,MATCH('Financial Output'!L$10,model!$N$2:$AZ$2,0))} -> -81.92583 | M35: {=INDEX(model!$N13:$AZ13,,MATCH('Financial Output'!M$10,model!$N$2:$AZ$2,0))} -> -116.78679 | N35: {=INDEX(model!$N13:$AZ13,,MATCH('Financial Output'!N$10,model!$N$2:$AZ$2,0))} -> -143.82577 | ... P35: {=INDEX(model!$N13:$AZ13,,MATCH('Financial Output'!P$10,model!$N$2:$AZ$2,0))} -> -300.33148
C36: Effective Tax Rate | E36: (%) | G36: =-G35/G32 -> 0.18858716 | H36: =-H35/H32 -> -0.07256108 | I36: =-I35/I32 -> 0.11896399 | J36: =-J35/J32 -> 0.17884409 | K36: =-K35/K32 -> 0.20627432 | L36: =-L35/L32 -> 0.25 | M36: =-M35/M32 -> 0.25 | N36: =-N35/N32 -> 0.25 | ... P36: =-P35/P32 -> 0.25
C38: Net Income | E38: (US$m) | G38: =G32+G35 -> 407.326 | H38: =H32+H35 -> 553.493 | I38: =I32+I35 -> 219.237 | J38: =J32+J35 -> 316.012 | K38: =K32+K35 -> 138.117 | L38: =L32+L35 -> 245.77749 | M38: =M32+M35 -> 350.36037 | N38: =N32+N35 -> 431.4773 | ... P38: =P32+P35 -> 900.99443
C39: Net Margin | G39: =G38/G12 -> 0.11531934 | H39: =H38/H12 -> 0.15286973 | I39: =I38/I12 -> 0.060351627 | J39: =J38/J12 -> 0.072041142 | K39: =K38/K12 -> 0.034400635 | L39: =L38/L12 -> 0.05369781 | M39: =M38/M12 -> 0.069588386 | N39: =N38/N12 -> 0.078623657 | ... P39: =P38/P12 -> 0.13568506
C41: Shares Outstanding (f.d.) | E41: (millions) | G41: {=INDEX(model!$N16:$AZ16,,MATCH('Financial Output'!G$10,model!$N$2:$AZ$2,0))} -> 155.955 | H41: {=INDEX(model!$N16:$AZ16,,MATCH('Financial Output'!H$10,model!$N$2:$AZ$2,0))} -> 156.743 | I41: {=INDEX(model!$N16:$AZ16,,MATCH('Financial Output'!I$10,model!$N$2:$AZ$2,0))} -> 152.193 | J41: {=INDEX(model!$N16:$AZ16,,MATCH('Financial Output'!J$10,model!$N$2:$AZ$2,0))} -> 149.38 | K41: {=INDEX(model!$N16:$AZ16,,MATCH('Financial Output'!K$10,model!$N$2:$AZ$2,0))} -> 145.964 | L41: {=INDEX(model!$N16:$AZ16,,MATCH('Financial Output'!L$10,model!$N$2:$AZ$2,0))} -> 146 | M41: {=INDEX(model!$N16:$AZ16,,MATCH('Financial Output'!M$10,model!$N$2:$AZ$2,0))} -> 146 | N41: {=INDEX(model!$N16:$AZ16,,MATCH('Financial Output'!N$10,model!$N$2:$AZ$2,0))} -> 146 | ... P41: {=INDEX(model!$N16:$AZ16,,MATCH('Financial Output'!P$10,model!$N$2:$AZ$2,0))} -> 146
C43: Earnings per Share (diluted) | E43: (US$/share) | G43: =G38/G41 -> 2.6118175 | H43: =H38/H41 -> 3.5312135 | I43: =I38/I41 -> 1.4405196 | J43: =J38/J41 -> 2.1154907 | K43: =K38/K41 -> 0.94624017 | L43: =L38/L41 -> 1.6834075 | M43: =M38/M41 -> 2.3997286 | N43: =N38/N41 -> 2.955324 | ... P43: =P38/P41 -> 6.1711947
C45: Imprield Forward Price-to-Earnings | E45: (x)
B47: 2 | C47: Balance Sheet | E47: Units
C49: Year Ended | G49: =H49-1 -> 2020 | H49: =I49-1 -> 2021 | I49: =J49-1 -> 2022 | J49: =K49-1 -> 2023 | K49: =L49-1 -> 2024 | L49: =estimate_start -> 2025 | M49: =+L49+1 -> 2026 | N49: =+M49+1 -> 2027 | O49: =+N49+1 -> 2028 | P49: =+O49+1 -> 2029
C51: Current Assets
C52: Cash & Cash Eqivalents | E52: (US$m) | G52: {=INDEX(model!$N23:$AZ23,,MATCH('Financial Output'!G$10,model!$N$2:$AZ$2,0))} -> 1239.291 | H52: {=INDEX(model!$N23:$AZ23,,MATCH('Financial Output'!H$10,model!$N$2:$AZ$2,0))} -> 1604.029 | I52: {=INDEX(model!$N23:$AZ23,,MATCH('Financial Output'!I$10,model!$N$2:$AZ$2,0))} -> 1148.341 | J52: {=INDEX(model!$N23:$AZ23,,MATCH('Financial Output'!J$10,model!$N$2:$AZ$2,0))} -> 1115.371 | K52: {=INDEX(model!$N23:$AZ23,,MATCH('Financial Output'!K$10,model!$N$2:$AZ$2,0))} -> 1251.206 | L52: {=INDEX(model!$N23:$AZ23,,MATCH('Financial Output'!L$10,model!$N$2:$AZ$2,0))} -> 1283.1276 | M52: {=INDEX(model!$N23:$AZ23,,MATCH('Financial Output'!M$10,model!$N$2:$AZ$2,0))} -> 1426.7348 | N52: {=INDEX(model!$N23:$AZ23,,MATCH('Financial Output'!N$10,model!$N$2:$AZ$2,0))} -> 1744.4763 | ... P52: {=INDEX(model!$N23:$AZ23,,MATCH('Financial Output'!P$10,model!$N$2:$AZ$2,0))} -> 2747.696
C53: Accounts Recievable | E53: (US$m) | G53: {=INDEX(model!$N24:$AZ24,,MATCH('Financial Output'!G$10,model!$N$2:$AZ$2,0))} -> 719.405 | H53: {=INDEX(model!$N24:$AZ24,,MATCH('Financial Output'!H$10,model!$N$2:$AZ$2,0))} -> 884.958 | I53: {=INDEX(model!$N24:$AZ24,,MATCH('Financial Output'!I$10,model!$N$2:$AZ$2,0))} -> 920.772 | J53: {=INDEX(model!$N24:$AZ24,,MATCH('Financial Output'!J$10,model!$N$2:$AZ$2,0))} -> 1003.876 | K53: {=INDEX(model!$N24:$AZ24,,MATCH('Financial Output'!K$10,model!$N$2:$AZ$2,0))} -> 908.597 | L53: {=INDEX(model!$N24:$AZ24,,MATCH('Financial Output'!L$10,model!$N$2:$AZ$2,0))} -> 1144.2622 | M53: {=INDEX(model!$N24:$AZ24,,MATCH('Financial Output'!M$10,model!$N$2:$AZ$2,0))} -> 1195.754 | N53: {=INDEX(model!$N24:$AZ24,,MATCH('Financial Output'!N$10,model!$N$2:$AZ$2,0))} -> 1238.2032 | ... P53: {=INDEX(model!$N24:$AZ24,,MATCH('Financial Output'!P$10,model!$N$2:$AZ$2,0))} -> 1352.1489
C54: % of Revenue | G54: =G53/G12 -> 0.203673 | H54: =H53/H12 -> 0.24441735 | I54: =I53/I12 -> 0.25347039 | J54: =J53/J12 -> 0.22885325 | K54: =K53/K12 -> 0.22630316 | L54: =L53/L12 -> 0.25 | M54: =M53/M12 -> 0.2375 | N54: =N53/N12 -> 0.225625 | ... P54: =P53/P12 -> 0.20362656
C56: Inventories | E56: (US$m) | G56: {=INDEX(model!$N25:$AZ25,,MATCH('Financial Output'!G$10,model!$N$2:$AZ$2,0))} -> 344.379 | H56: {=INDEX(model!$N25:$AZ25,,MATCH('Financial Output'!H$10,model!$N$2:$AZ$2,0))} -> 374.265 | I56: {=INDEX(model!$N25:$AZ25,,MATCH('Financial Output'!I$10,model!$N$2:$AZ$2,0))} -> 946.73 | J56: {=INDEX(model!$N25:$AZ25,,MATCH('Financial Output'!J$10,model!$N$2:$AZ$2,0))} -> 1050.838 | K56: {=INDEX(model!$N25:$AZ25,,MATCH('Financial Output'!K$10,model!$N$2:$AZ$2,0))} -> 820.43 | L56: {=INDEX(model!$N25:$AZ25,,MATCH('Financial Output'!L$10,model!$N$2:$AZ$2,0))} -> 915.40974 | M56: {=INDEX(model!$N25:$AZ25,,MATCH('Financial Output'!M$10,model!$N$2:$AZ$2,0))} -> 1006.9507 | N56: {=INDEX(model!$N25:$AZ25,,MATCH('Financial Output'!N$10,model!$N$2:$AZ$2,0))} -> 1097.5763 | ... P56: {=INDEX(model!$N25:$AZ25,,MATCH('Financial Output'!P$10,model!$N$2:$AZ$2,0))} -> 1328.0673
C57: Prepaid Expenses and Other | E57: (US$m) | G57: {=INDEX(model!$N26:$AZ26,,MATCH('Financial Output'!G$10,model!$N$2:$AZ$2,0))} -> 308.084 | H57: {=INDEX(model!$N26:$AZ26,,MATCH('Financial Output'!H$10,model!$N$2:$AZ$2,0))} -> 325.654 | I57: {=INDEX(model!$N26:$AZ26,,MATCH('Financial Output'!I$10,model!$N$2:$AZ$2,0))} -> 370.053 | J57: {=INDEX(model!$N26:$AZ26,,MATCH('Financial Output'!J$10,model!$N$2:$AZ$2,0))} -> 405.694 | K57: {=INDEX(model!$N26:$AZ26,,MATCH('Financial Output'!K$10,model!$N$2:$AZ$2,0))} -> 564.183 | L57: {=INDEX(model!$N26:$AZ26,,MATCH('Financial Output'!L$10,model!$N$2:$AZ$2,0))} -> 643.43465 | M57: {=INDEX(model!$N26:$AZ26,,MATCH('Financial Output'!M$10,model!$N$2:$AZ$2,0))} -> 707.77812 | N57: {=INDEX(model!$N26:$AZ26,,MATCH('Financial Output'!N$10,model!$N$2:$AZ$2,0))} -> 771.47815 | ... P57: {=INDEX(model!$N26:$AZ26,,MATCH('Financial Output'!P$10,model!$N$2:$AZ$2,0))} -> 933.48856
C59: Total Current Assets | E59: (US$m) | G59: =G52+G53+G56+G57 -> 2611.159 | H59: =H52+H53+H56+H57 -> 3188.906 | I59: =I52+I53+I56+I57 -> 3385.896 | J59: =J52+J53+J56+J57 -> 3575.779 | K59: =K52+K53+K56+K57 -> 3544.416 | L59: =L52+L53+L56+L57 -> 3986.2342 | M59: =M52+M53+M56+M57 -> 4337.2176 | N59: =N52+N53+N56+N57 -> 4851.734 | ... P59: =P52+P53+P56+P57 -> 6361.4007
C61: Non-Current Assets
C62: Investments | E62: (US$m) | G62: {=INDEX(model!$N27:$AZ27,,MATCH('Financial Output'!G$10,model!$N$2:$AZ$2,0))} -> 82.226 | H62: {=INDEX(model!$N27:$AZ27,,MATCH('Financial Output'!H$10,model!$N$2:$AZ$2,0))} -> 70.038 | I62: {=INDEX(model!$N27:$AZ27,,MATCH('Financial Output'!I$10,model!$N$2:$AZ$2,0))} -> 35.385 | J62: {=INDEX(model!$N27:$AZ27,,MATCH('Financial Output'!J$10,model!$N$2:$AZ$2,0))} -> 134.278 | K62: {=INDEX(model!$N27:$AZ27,,MATCH('Financial Output'!K$10,model!$N$2:$AZ$2,0))} -> 80.92 | L62: {=INDEX(model!$N27:$AZ27,,MATCH('Financial Output'!L$10,model!$N$2:$AZ$2,0))} -> 81 | M62: {=INDEX(model!$N27:$AZ27,,MATCH('Financial Output'!M$10,model!$N$2:$AZ$2,0))} -> 81 | N62: {=INDEX(model!$N27:$AZ27,,MATCH('Financial Output'!N$10,model!$N$2:$AZ$2,0))} -> 81 | ... P62: {=INDEX(model!$N27:$AZ27,,MATCH('Financial Output'!P$10,model!$N$2:$AZ$2,0))} -> 81
C64: Leases | E64: (US$m) | G64: {=INDEX(model!$N29:$AZ29,,MATCH('Financial Output'!G$10,model!$N$2:$AZ$2,0))} -> 57.026 | H64: {=INDEX(model!$N29:$AZ29,,MATCH('Financial Output'!H$10,model!$N$2:$AZ$2,0))} -> 44.285 | I64: {=INDEX(model!$N29:$AZ29,,MATCH('Financial Output'!I$10,model!$N$2:$AZ$2,0))} -> 45.108 | J64: {=INDEX(model!$N29:$AZ29,,MATCH('Financial Output'!J$10,model!$N$2:$AZ$2,0))} -> 35.14 | K64: {=INDEX(model!$N29:$AZ29,,MATCH('Financial Output'!K$10,model!$N$2:$AZ$2,0))} -> 27.417 | L64: {=INDEX(model!$N29:$AZ29,,MATCH('Financial Output'!L$10,model!$N$2:$AZ$2,0))} -> 35 | M64: {=INDEX(model!$N29:$AZ29,,MATCH('Financial Output'!M$10,model!$N$2:$AZ$2,0))} -> 35 | N64: {=INDEX(model!$N29:$AZ29,,MATCH('Financial Output'!N$10,model!$N$2:$AZ$2,0))} -> 35 | ... P64: {=INDEX(model!$N29:$AZ29,,MATCH('Financial Output'!P$10,model!$N$2:$AZ$2,0))} -> 35
C65: Property, Plant and Equipment | E65: (US$m) | G65: {=INDEX(model!$N28:$AZ28,,MATCH('Financial Output'!G$10,model!$N$2:$AZ$2,0))} -> 272.377 | H65: {=INDEX(model!$N28:$AZ28,,MATCH('Financial Output'!H$10,model!$N$2:$AZ$2,0))} -> 284.968 | I65: {=INDEX(model!$N28:$AZ28,,MATCH('Financial Output'!I$10,model!$N$2:$AZ$2,0))} -> 267.779 | J65: {=INDEX(model!$N28:$AZ28,,MATCH('Financial Output'!J$10,model!$N$2:$AZ$2,0))} -> 280.147 | K65: {=INDEX(model!$N28:$AZ28,,MATCH('Financial Output'!K$10,model!$N$2:$AZ$2,0))} -> 337.722 | L65: {=INDEX(model!$N28:$AZ28,,MATCH('Financial Output'!L$10,model!$N$2:$AZ$2,0))} -> 360.60724 | M65: {=INDEX(model!$N28:$AZ28,,MATCH('Financial Output'!M$10,model!$N$2:$AZ$2,0))} -> 410.95478 | N65: {=INDEX(model!$N28:$AZ28,,MATCH('Financial Output'!N$10,model!$N$2:$AZ$2,0))} -> 465.83359 | ... P65: {=INDEX(model!$N28:$AZ28,,MATCH('Financial Output'!P$10,model!$N$2:$AZ$2,0))} -> 592.60365
...

Sheet Scenario Manager
B3: Market Rates | F3: =estimate_start -> 2025 | G3: =F3+1 -> 2026 | H3: =G3+1 -> 2027 | I3: =H3+1 -> 2028 | J3: =I3+1 -> 2029
C4: SOFR | F4: 0.0411 | G4: 0.0336 | H4: 0.0341 | I4: 0.0356 | J4: 0.0371
B9: Live Scenario
B10: Scenario Name | D10: Street
B11: # | D11: =IF(scenario_name = "Bear", 1, IF(scenario_name = "Street", 2, IF(scenario_name = "Bull", 3, ""))) -> 2
C14: Revenue Growth | F14: =CHOOSE(scenario_number,F39,F61,F83) -> 0.14 | G14: =CHOOSE(scenario_number,G39,G61,G83) -> 0.1 | H14: =CHOOSE(scenario_number,H39,H61,H83) -> 0.09 | I14: =CHOOSE(scenario_number,I39,I61,I83) -> 0.1 | J14: =CHOOSE(scenario_number,J39,J61,J83) -> 0.1
C15: COGS % of Rev | F15: =CHOOSE(scenario_number,F40,F62,F84) -> 0.58 | G15: =CHOOSE(scenario_number,G40,G62,G84) -> 0.56 | H15: =CHOOSE(scenario_number,H40,H62,H84) -> 0.55 | I15: =CHOOSE(scenario_number,I40,I62,I84) -> 0.5 | J15: =CHOOSE(scenario_number,J40,J62,J84) -> 0.5
C16: R&D % of Rev | F16: =CHOOSE(scenario_number,F41,F63,F85) -> 0.17 | G16: =CHOOSE(scenario_number,G41,G63,G85) -> 0.17 | H16: =CHOOSE(scenario_number,H41,H63,H85) -> 0.17 | I16: =CHOOSE(scenario_number,I41,I63,I85) -> 0.17 | J16: =CHOOSE(scenario_number,J41,J63,J85) -> 0.17
C17: SG&A % of Rev | F17: =CHOOSE(scenario_number,F42,F64,F86) -> 0.17 | G17: =CHOOSE(scenario_number,G42,G64,G86) -> 0.17 | H17: =CHOOSE(scenario_number,H42,H64,H86) -> 0.17 | I17: =CHOOSE(scenario_number,I42,I64,I86) -> 0.16 | J17: =CHOOSE(scenario_number,J42,J64,J86) -> 0.15
C18: D&A % of Rev | F18: =CHOOSE(scenario_number,F43,F65,F87) -> 0.025 | G18: =CHOOSE(scenario_number,G43,G65,G87) -> 0.02 | H18: =CHOOSE(scenario_number,H43,H65,H87) -> 0.02 | I18: =CHOOSE(scenario_number,I43,I65,I87) -> 0.02 | J18: =CHOOSE(scenario_number,J43,J65,J87) -> 0.02
C19: D&A % of CapEx | F19: =CHOOSE(scenario_number,F44,F66,F88) -> 1.2 | G19: =CHOOSE(scenario_number,G44,G66,G88) -> 1.2 | H19: =CHOOSE(scenario_number,H44,H66,H88) -> 1.2 | I19: =CHOOSE(scenario_number,I44,I66,I88) -> 1.2 | J19: =CHOOSE(scenario_number,J44,J66,J88) -> 1.2
C20: Int Exp % of Debt | F20: =CHOOSE(scenario_number,F45,F67,F89) -> 0.05 | G20: =CHOOSE(scenario_number,G45,G67,G89) -> 0.05 | H20: =CHOOSE(scenario_number,H45,H67,H89) -> 0.05 | I20: =CHOOSE(scenario_number,I45,I67,I89) -> 0.05 | J20: =CHOOSE(scenario_number,J45,J67,J89) -> 0.05
C21: Taxes % of EBIT | F21: =CHOOSE(scenario_number,F46,F68,F90) -> 0.25 | G21: =CHOOSE(scenario_number,G46,G68,G90) -> 0.25 | H21: =CHOOSE(scenario_number,H46,H68,H90) -> 0.25 | I21: =CHOOSE(scenario_number,I46,I68,I90) -> 0.25 | J21: =CHOOSE(scenario_number,J46,J68,J90) -> 0.25
C23: AR % of Rev | F23: =CHOOSE(scenario_number,F48,F70,F92) -> 0.25 | G23: =CHOOSE(scenario_number,G48,G70,G92) -> 0.2375 | H23: =CHOOSE(scenario_number,H48,H70,H92) -> 0.225625 | I23: =CHOOSE(scenario_number,I48,I70,I92) -> 0.21434375 | J23: =CHOOSE(scenario_number,J48,J70,J92) -> 0.20362656
C24: Inv % of Rev | F24: =CHOOSE(scenario_number,F49,F71,F93) -> 0.2 | G24: =CHOOSE(scenario_number,G49,G71,G93) -> 0.2 | H24: =CHOOSE(scenario_number,H49,H71,H93) -> 0.2 | I24: =CHOOSE(scenario_number,I49,I71,I93) -> 0.2 | J24: =CHOOSE(scenario_number,J49,J71,J93) -> 0.2
C25: OA % of Rev | F25: =CHOOSE(scenario_number,F50,F72,F94) -> 0.4 | G25: =CHOOSE(scenario_number,G50,G72,G94) -> 0.4 | H25: =CHOOSE(scenario_number,H50,H72,H94) -> 0.4 | I25: =CHOOSE(scenario_number,I50,I72,I94) -> 0.4 | J25: =CHOOSE(scenario_number,J50,J72,J94) -> 0.4
C26: CapEx | F26: =CHOOSE(scenario_number,F51,F73,F95) -> 0 | G26: =CHOOSE(scenario_number,G51,G73,G95) -> 0 | H26: =CHOOSE(scenario_number,H51,H73,H95) -> 0 | I26: =CHOOSE(scenario_number,I51,I73,I95) -> 0 | J26: =CHOOSE(scenario_number,J51,J73,J95) -> 0
... C33: SBC % of SG&A | F33: =CHOOSE(scenario_number,F58,F80,F102) -> 0.2 | G33: =CHOOSE(scenario_number,G58,G80,G102) -> 0.2 | H33: =CHOOSE(scenario_number,H58,H80,H102) -> 0.2 | I33: =CHOOSE(scenario_number,I58,I80,I102) -> 0.2 | J33: =CHOOSE(scenario_number,J58,J80,J102) -> 0.2
B38: Bear Case | D38: 1 | F38: =estimate_start -> 2025 | G38: =+F38+1 -> 2026 | H38: =+G38+1 -> 2027 | I38: =+H38+1 -> 2028 | J38: =+I38+1 -> 2029
C39: Revenue Growth | F39: 0.05 | G39: 0.05 | H39: 0.05 | I39: 0.05 | J39: 0.05
C40: COGS % of Rev | F40: 0.55 | G40: 0.55 | H40: 0.55 | I40: 0.55 | J40: 0.55
C41: R&D % of Rev | F41: 0.17 | G41: 0.17 | H41: 0.17 | I41: 0.17 | J41: 0.17
C42: SG&A % of Rev | F42: 0.2 | G42: 0.2 | H42: 0.2 | I42: 0.2 | J42: 0.2
C43: D&A % of Rev | F43: 0.04 | G43: 0.04 | H43: 0.04 | I43: 0.04 | J43: 0.04
C44: D&A % of CapEx | F44: 1.2 | G44: 1.2 | H44: 1.2 | I44: 1.2 | J44: 1.2
C45: Int Exp % of Debt | F45: 0.05 | G45: 0.05 | H45: 0.05 | I45: 0.05 | J45: 0.05
C46: Taxes % of EBIT | F46: 0.2 | G46: 0.2 | H46: 0.2 | I46: 0.2 | J46: 0.2
C48: AR % of Rev | F48: 0.25 | G48: 0.25 | H48: 0.25 | I48: 0.25 | J48: 0.25
C49: Inv % of Rev | F49: 0.2 | G49: 0.2 | H49: 0.2 | I49: 0.2 | J49: 0.2
C50: OA % of Rev | F50: 0.4 | G50: 0.4 | H50: 0.4 | I50: 0.4 | J50: 0.4
C51: CapEx
C52: CapEx % of Rev | F52: 0.03 | G52: 0.03 | H52: 0.03 | I52: 0.03 | J52: 0.03
C53: AP % of COGS | F53: 0.2 | G53: 0.2 | H53: 0.2 | I53: 0.2 | J53: 0.2
C54: AE % of OpEx | F54: 0.25 | G54: 0.25 | H54: 0.25 | I54: 0.25 | J54: 0.25
C55: OL % of Rev | F55: 0.04 | G55: 0.04 | H55: 0.04 | I55: 0.04 | J55: 0.04
C57: CFFO growth | F57: 0.03 | G57: 0.03 | H57: 0.03 | I57: 0.03 | J57: 0.03
C58: SBC % of SG&A | F58: 0.2 | G58: 0.2 | H58: 0.2 | I58: 0.2 | J58: 0.2
B60: Street Case | D60: 2 | F60: =estimate_start -> 2025 | G60: =+F60+1 -> 2026 | H60: =+G60+1 -> 2027 | I60: =+H60+1 -> 2028 | J60: =+I60+1 -> 2029
C61: Revenue Growth | F61: 0.14 | G61: 0.1 | H61: 0.09 | I61: 0.1 | J61: 0.1
C62: COGS % of Rev | F62: 0.58 | G62: 0.56 | H62: 0.55 | I62: 0.5 | J62: 0.5
...

Sheet model
B1: CIEN | N1: 42307 | O1: 42674 | P1: 43039 | Q1: 43404 | R1: 43769 | S1: 44134 | T1: 44498 | U1: 44865 | V1: 45230 | W1: 45596
N2: 2015 | O2: =N2+1 -> 2016 | P2: =O2+1 -> 2017 | Q2: =P2+1 -> 2018 | R2: =Q2+1 -> 2019 | S2: =R2+1 -> 2020 | T2: =S2+1 -> 2021 | U2: =T2+1 -> 2022 | V2: =U2+1 -> 2023 | ... AB2: =AA2+1 -> 2029
A3: x | B3: Revenue | N3: =IS_Static!D12 -> 2445.669 | O3: =IS_Static!E12 -> 2600.573 | P3: =IS_Static!F12 -> 2801.687 | Q3: =IS_Static!G12 -> 3094.286 | R3: =IS_Static!H12 -> 3572.131 | S3: =IS_Static!I12 -> 3532.157 | T3: =IS_Static!J12 -> 3620.684 | U3: =IS_Static!K12 -> 3632.661 | ... W3: =IS_Static!M12 -> 4014.955 | X3: =W3*(1+X77) -> 4577.0487 | Y3: =X3*(1+Y77) -> 5034.7536 | Z3: =Y3*(1+Z77) -> 5487.8814 | AA3: =Z3*(1+AA77) -> 6036.6695 | AB3: =AA3*(1+AB77) -> 6640.3365
B4: COGS | N4: =IS_Static!D15 -> -1370.106 | O4: =IS_Static!E15 -> -1438.997 | P4: =IS_Static!F15 -> -1555.901 | Q4: =IS_Static!G15 -> -1779.596 | R4: =IS_Static!H15 -> -2030.065 | S4: =IS_Static!I15 -> -1879.266 | T4: =IS_Static!J15 -> -1898.705 | U4: =IS_Static!K15 -> -2072.317 | ... W4: =IS_Static!M15 -> -2295.365 | X4: =-X3*X78 -> -2654.6882 | Y4: =-Y3*Y78 -> -2819.462 | Z4: =-Z3*Z78 -> -3018.3348 | AA4: =-AA3*AA78 -> -3018.3348 | AB4: =-AB3*AB78 -> -3320.1682
B5: Gross Profit | N5: =N3+N4 -> 1075.563 | O5: =O3+O4 -> 1161.576 | P5: =P3+P4 -> 1245.786 | Q5: =Q3+Q4 -> 1314.69 | R5: =R3+R4 -> 1542.066 | S5: =S3+S4 -> 1652.891 | T5: =T3+T4 -> 1721.979 | U5: =U3+U4 -> 1560.344 | ... AB5: =AB3+AB4 -> 3320.1682
B6: S&M | N6: =IS_Static!D21 -> -333.836 | O6: =IS_Static!E21 -> -349.731 | P6: =IS_Static!F21 -> -356.169 | Q6: =IS_Static!G21 -> -394.06 | R6: =IS_Static!H21 -> -423.046 | S6: =IS_Static!I21 -> -416.425 | T6: =IS_Static!J21 -> -452.214 | U6: =IS_Static!K21 -> -466.565 | ... W6: =IS_Static!M21 -> -510.668 | X6: =-X3*X80*(W6/(W6+W8)) -> -543.33617 | Y6: =-Y3*Y80*(X6/(X6+X8)) -> -597.66979 | Z6: =-Z3*Z80*(Y6/(Y6+Y8)) -> -651.46007 | AA6: =-AA3*AA80*(Z6/(Z6+Z8)) -> -674.45278 | AB6: =-AB3*AB80*(AA6/(AA6+AA8)) -> -695.52943
B7: R&D | N7: =IS_Static!D20 -> -414.201 | O7: =IS_Static!E20 -> -451.794 | P7: =IS_Static!F20 -> -475.329 | Q7: =IS_Static!G20 -> -491.564 | R7: =IS_Static!H20 -> -548.139 | S7: =IS_Static!I20 -> -529.888 | T7: =IS_Static!J20 -> -536.666 | U7: =IS_Static!K20 -> -624.656 | ... W7: =IS_Static!M20 -> -767.497 | X7: =-X79*X3 -> -778.09828 | Y7: =-Y79*Y3 -> -855.90811 | Z7: =-Z79*Z3 -> -932.93984 | AA7: =-AA79*AA3 -> -1026.2338 | AB7: =-AB79*AB3 -> -1128.8572
B8: G&A | N8: =IS_Static!D22 -> -148.941 | O8: =IS_Static!E22 -> -137.441 | P8: =IS_Static!F22 -> -142.604 | Q8: =IS_Static!G22 -> -165.244 | R8: =IS_Static!H22 -> -177.769 | S8: =IS_Static!I22 -> -173.579 | T8: =IS_Static!J22 -> -184.446 | U8: =IS_Static!K22 -> -179.98 | ... W8: =IS_Static!M22 -> -220.647 | X8: =-X3*X80*(W8/(W6+W8)) -> -234.76211 | Y8: =-Y3*Y80*(X8/(X6+X8)) -> -258.23832 | Z8: =-Z3*Z80*(Y8/(Y6+Y8)) -> -281.47977 | AA8: =-AA3*AA80*(Z8/(Z6+Z8)) -> -291.41435 | AB8: =-AB3*AB80*(AA8/(AA6+AA8)) -> -300.52105
B9: Operating Expenses | N9: =N8+N7+N6 -> -896.978 | O9: =O8+O7+O6 -> -938.966 | P9: =P8+P7+P6 -> -974.102 | Q9: =Q8+Q7+Q6 -> -1050.868 | R9: =R8+R7+R6 -> -1148.954 | S9: =S8+S7+S6 -> -1119.892 | T9: =T8+T7+T6 -> -1173.326 | U9: =U8+U7+U6 -> -1271.201 | ... W9: =W8+W7+W6 -> -1498.812 | X9: =+X8+X7+X6 -> -1556.1966 | Y9: =+Y8+Y7+Y6 -> -1711.8162 | Z9: =+Z8+Z7+Z6 -> -1865.8797 | AA9: =+AA8+AA7+AA6 -> -1992.1009 | AB9: =+AB8+AB7+AB6 -> -2124.9077
B10: Operating Income | N10: =N5+N9 -> 178.585 | O10: =O5+O9 -> 222.61 | P10: =P5+P9 -> 271.684 | Q10: =Q5+Q9 -> 263.822 | R10: =R5+R9 -> 393.112 | S10: =S5+S9 -> 532.999 | T10: =T5+T9 -> 548.653 | U10: =U5+U9 -> 289.143 | ... W10: =W5+W9 -> 220.778 | X10: =X9+X5 -> 366.1639 | Y10: =Y9+Y5 -> 503.47536 | Z10: =Z9+Z5 -> 603.66695 | AA10: =AA9+AA5 -> 1026.2338 | AB10: =AB9+AB5 -> 1195.2606
B11: Interest Exp, net | N11: =IS_Static!D33+IS_Static!D36 -> -76.684 | O11: =IS_Static!E33+IS_Static!E36 -> -69.451 | P11: =IS_Static!F33+IS_Static!F36 -> -58.596 | Q11: =IS_Static!G33+IS_Static!G36 -> -81.165 | R11: =IS_Static!H33+IS_Static!H36 -> -33.576 | S11: =IS_Static!I33+IS_Static!I36 -> -31.003 | T11: =IS_Static!J33+IS_Static!J36 -> -32.605 | U11: =IS_Static!K33+IS_Static!K36 -> -40.303 | ... W11: =IS_Static!M33+IS_Static!M36 -> -46.767 | X11: =X129+X107 -> -38.460574 | Y11: =Y129+Y107 -> -36.328192 | Z11: =Z129+Z107 -> -28.363881 | AA11: =AA129+AA107 -> -13.773113 | AB11: =AB129+AB107 -> 6.0653429
B12: Pretax Income | N12: =N10+N11 -> 101.901 | O12: =O10+O11 -> 153.159 | P12: =P10+P11 -> 213.088 | Q12: =Q10+Q11 -> 182.657 | R12: =R10+R11 -> 359.536 | S12: =S10+S11 -> 501.996 | T12: =T10+T11 -> 516.048 | U12: =U10+U11 -> 248.84 | ... AB12: =AB10+AB11 -> 1201.3259
B13: Taxes | N13: =IS_Static!D42 -> -12.097 | O13: =IS_Static!E42 -> -14.134 | P13: =IS_Static!F42 -> 1105.827 | Q13: =IS_Static!G42 -> -493.471 | R13: =IS_Static!H42 -> -59.756 | S13: =IS_Static!I42 -> -94.67 | T13: =IS_Static!J42 -> 37.445 | U13: =IS_Static!K42 -> -29.603 | ... W13: =IS_Static!M42 -> -35.894 | X13: =X12*-X84 -> -81.92583 | Y13: =Y12*-Y84 -> -116.78679 | Z13: =Z12*-Z84 -> -143.82577 | AA13: =AA12*-AA84 -> -253.11518 | AB13: =AB12*-AB84 -> -300.33148
B14: Net Income | N14: =N12+N13 -> 89.804 | O14: =O12+O13 -> 139.025 | P14: =P12+P13 -> 1318.915 | Q14: =Q12+Q13 -> -310.814 | R14: =R12+R13 -> 299.78 | S14: =S12+S13 -> 407.326 | T14: =T12+T13 -> 553.493 | U14: =U12+U13 -> 219.237 | ... AB14: =AB12+AB13 -> 900.99443
B15: EPS | N15: =N14/N16 -> 0.74773732 | O15: =O14/O16 -> 0.92250372 | P15: =P14/P16 -> 7.7620219 | Q15: =Q14/Q16 -> -2.1623649 | R15: =R14/R16 -> 1.9020125 | S15: =S14/S16 -> 2.6118175 | T15: =T14/T16 -> 3.5312135 | U15: =U14/U16 -> 1.4405196 | ... AB15: =AB14/AB16 -> 6.1711947
B16: Shares | N16: =IS_Static!D49 -> 120.101 | O16: =IS_Static!E49 -> 150.704 | P16: =IS_Static!F49 -> 169.919 | Q16: =IS_Static!G49 -> 143.738 | R16: =IS_Static!H49 -> 157.612 | S16: =IS_Static!I49 -> 155.955 | T16: =IS_Static!J49 -> 156.743 | U16: =IS_Static!K49 -> 152.193 | ... W16: =IS_Static!M49 -> 145.964 | X16: 146 | Y16: 146 | Z16: 146 | AA16: 146 | AB16: 146
B18: EBIT | N18: =N10 -> 178.585 | O18: =O10 -> 222.61 | P18: =P10 -> 271.684 | Q18: =Q10 -> 263.822 | R18: =R10 -> 393.112 | S18: =S10 -> 532.999 | T18: =T10 -> 548.653 | U18: =U10 -> 289.143 | ... AB18: =AB10 -> 1195.2606
B19: EBITDA | N19: =N18+N50 -> 314.352 | O19: =O18+O50 -> 364.302 | P19: =P18+P50 -> 394.586 | Q19: =Q18+Q50 -> 373.842 | R19: =R18+R50 -> 515.824 | S19: =S18+S50 -> 665.526 | T19: =T18+T50 -> 680.919 | U19: =U18+U50 -> 429.346 | ... AB19: =AB18+AB50 -> 1328.0673
B20: % of sales | N20: =N19/N3 -> 0.12853416 | O20: =O19/O3 -> 0.14008528 | P20: =P19/P3 -> 0.14083872 | Q20: =Q19/Q3 -> 0.12081689 | R20: =R19/R3 -> 0.14440232 | S20: =S19/S3 -> 0.18841914 | T20: =T19/T3 -> 0.18806364 | U20: =U19/U3 -> 0.11819049 | ... AB20: =AB19/AB3 -> 0.2
B22: Net Cash
B23: Cash | N23: =BS_Static!D14+BS_Static!D15 -> 926.078 | O23: =BS_Static!E14+BS_Static!E15 -> 1052.863 | P23: =BS_Static!F14+BS_Static!F15 -> 919.646 | Q23: =BS_Static!G14+BS_Static!G15 -> 894.404 | R23: =BS_Static!H14+BS_Static!H15 -> 1013.985 | S23: =BS_Static!I14+BS_Static!I15 -> 1239.291 | T23: =BS_Static!J14+BS_Static!J15 -> 1604.029 | U23: =BS_Static!K14+BS_Static!K15 -> 1148.341 | ... W23: =BS_Static!M14+BS_Static!M15 -> 1251.206 | X23: =W23+X69 -> 1283.1276 | Y23: =X23+Y69 -> 1426.7348 | Z23: =Y23+Z69 -> 1744.4763 | AA23: =Z23+AA69 -> 2210.4319 | AB23: =AA23+AB69 -> 2747.696
B24: AR | N24: =BS_Static!D16 -> 550.792 | O24: =BS_Static!E16 -> 576.235 | P24: =BS_Static!F16 -> 622.183 | Q24: =BS_Static!G16 -> 786.502 | R24: =BS_Static!H16 -> 724.854 | S24: =BS_Static!I16 -> 719.405 | T24: =BS_Static!J16 -> 884.958 | U24: =BS_Static!K16 -> 920.772 | ... W24: =BS_Static!M16 -> 908.597 | X24: =X87*X3 -> 1144.2622 | Y24: =Y87*Y3 -> 1195.754 | Z24: =Z87*Z3 -> 1238.2032 | AA24: =AA87*AA3 -> 1293.9224 | AB24: =AB87*AB3 -> 1352.1489
B25: Inventory | N25: =BS_Static!D17 -> 191.162 | O25: =BS_Static!E17 -> 211.251 | P25: =BS_Static!F17 -> 267.143 | Q25: =BS_Static!G17 -> 262.751 | R25: =BS_Static!H17 -> 345.049 | S25: =BS_Static!I17 -> 344.379 | T25: =BS_Static!J17 -> 374.265 | U25: =BS_Static!K17 -> 946.73 | ... W25: =BS_Static!M17 -> 820.43 | X25: =X3*X88 -> 915.40974 | Y25: =Y3*Y88 -> 1006.9507 | Z25: =Z3*Z88 -> 1097.5763 | AA25: =AA3*AA88 -> 1207.3339 | AB25: =AB3*AB88 -> 1328.0673
B26: Prepaids | N26: =BS_Static!D18 -> 196.178 | O26: =BS_Static!E18 -> 172.843 | P26: =BS_Static!F18 -> 197.339 | Q26: =BS_Static!G18 -> 198.945 | R26: =BS_Static!H18 -> 297.914 | S26: =BS_Static!I18 -> 308.084 | T26: =BS_Static!J18 -> 325.654 | U26: =BS_Static!K18 -> 370.053 | ... W26: =BS_Static!M18 -> 564.183 | X26: =X$89*X$3*(W26/(W$26+W$32+W$33)) -> 643.43465 | Y26: =Y$89*Y$3*(X26/(X$26+X$32+X$33)) -> 707.77812 | Z26: =Z$89*Z$3*(Y26/(Y$26+Y$32+Y$33)) -> 771.47815 | AA26: =AA$89*AA$3*(Z26/(Z$26+Z$32+Z$33)) -> 848.62596 | AB26: =AB$89*AB$3*(AA26/(AA$26+AA$32+AA$33)) -> 933.48856
B27: LT Investments | N27: =BS_Static!D19 -> 95.105 | O27: =BS_Static!E19 -> 90.172 | P27: =BS_Static!F19 -> 49.783 | Q27: =BS_Static!G19 -> 58.97 | R27: =BS_Static!H19 -> 10.014 | S27: =BS_Static!I19 -> 82.226 | T27: =BS_Static!J19 -> 70.038 | U27: =BS_Static!K19 -> 35.385 | ... W27: =BS_Static!M19 -> 80.92 | X27: 81 | Y27: 81 | Z27: 81 | AA27: 81 | AB27: 81
B28: PP&E | N28: =BS_Static!D20 -> 191.973 | O28: =BS_Static!E20 -> 288.406 | P28: =BS_Static!F20 -> 308.465 | Q28: =BS_Static!G20 -> 292.067 | R28: =BS_Static!H20 -> 286.884 | S28: =BS_Static!I20 -> 272.377 | T28: =BS_Static!J20 -> 284.968 | U28: =BS_Static!K20 -> 267.779 | ... W28: =BS_Static!M20 -> 337.722 | X28: =W28-X60-X50 -> 360.60724 | Y28: =X28-Y60-Y50 -> 410.95478 | Z28: =Y28-Z60-Z50 -> 465.83359 | AA28: =Z28-AA60-AA50 -> 526.20029 | AB28: =AA28-AB60-AB50 -> 592.60365
B29: Leases | N29: =BS_Static!D21 -> - | O29: =BS_Static!E21 -> - | P29: =BS_Static!F21 -> - | Q29: =BS_Static!G21 -> - | R29: =BS_Static!H21 -> 0 | S29: =BS_Static!I21 -> 57.026 | T29: =BS_Static!J21 -> 44.285 | U29: =BS_Static!K21 -> 45.108 | ... W29: =BS_Static!M21 -> 27.417 | X29: 35 | Y29: 35 | Z29: 35 | AA29: 35 | AB29: 35
B30: Goodwill | N30: =BS_Static!D22 -> 256.434 | O30: =BS_Static!E22 -> 266.974 | P30: =BS_Static!F22 -> 267.458 | Q30: =BS_Static!G22 -> 297.968 | R30: =BS_Static!H22 -> 297.937 | S30: =BS_Static!I22 -> 310.847 | T30: =BS_Static!J22 -> 311.645 | U30: =BS_Static!K22 -> 328.322 | ... W30: =BS_Static!M22 -> 444.707 | X30: 445 | Y30: 445 | Z30: 445 | AA30: 445 | AB30: 445
B31: Other Intangible | N31: =BS_Static!D23 -> 202.673 | O31: =BS_Static!E23 -> 146.711 | P31: =BS_Static!F23 -> 100.997 | Q31: =BS_Static!G23 -> 148.225 | R31: =BS_Static!H23 -> 112.781 | S31: =BS_Static!I23 -> 96.647 | T31: =BS_Static!J23 -> 65.314 | U31: =BS_Static!K23 -> 69.517 | ... W31: =BS_Static!M23 -> 165.02 | X31: 165 | Y31: 165 | Z31: 165 | AA31: 165 | AB31: 165
B32: Deferred Taxes | N32: =BS_Static!D25 -> 0 | O32: =BS_Static!E25 -> 1.116 | P32: =BS_Static!F25 -> 1155.104 | Q32: =BS_Static!G25 -> 745.039 | R32: =BS_Static!H25 -> 714.942 | S32: =BS_Static!I25 -> 647.805 | T32: =BS_Static!J25 -> 800.18 | U32: =BS_Static!K25 -> 824.008 | ... W32: =BS_Static!M25 -> 886.441 | X32: =X$89*X$3*(W32/(W$26+W$32+W$33)) -> 1010.9607 | Y32: =Y$89*Y$3*(X32/(X$26+X$32+X$33)) -> 1112.0568 | Z32: =Z$89*Z$3*(Y32/(Y$26+Y$32+Y$33)) -> 1212.1419 | AA32: =AA$89*AA$3*(Z32/(Z$26+Z$32+Z$33)) -> 1333.3561 | AB32: =AB$89*AB$3*(AA32/(AA$26+AA$32+AA$33)) -> 1466.6917
B33: Other Assets | N33: =BS_Static!D24 -> 84.656 | O33: =BS_Static!E26 -> 67.004 | P33: =BS_Static!F26 -> 63.593 | Q33: =BS_Static!G26 -> 71.652 | R33: =BS_Static!H26 -> 88.986 | S33: =BS_Static!I26 -> 102.83 | T33: =BS_Static!J26 -> 99.891 | U33: =BS_Static!K26 -> 113.617 | V33: =BS_Static!L26 -> 116.453 | W33: =BS_Static!M26 -> 154.694 | X33: =X$89*X$3*(W33/(W$26+W$32+W$33)) -> 176.4241 | Y33: =Y$89*Y$3*(X33/(X$26+X$32+X$33)) -> 194.06651 | Z33: =Z$89*Z$3*(Y33/(Y$26+Y$32+Y$33)) -> 211.5325 | AA33: =AA$89*AA$3*(Z33/(Z$26+Z$32+Z$33)) -> 232.68575 | AB33: =AB$89*AB$3*(AA33/(AA$26+AA$32+AA$33)) -> 255.95432
B34: Assets | N34: =SUM(N23:N33) -> 2695.051 | O34: =SUM(O23:O33) -> 2873.575 | P34: =SUM(P23:P33) -> 3951.711 | Q34: =SUM(Q23:Q33) -> 3756.523 | R34: =SUM(R23:R33) -> 3893.346 | S34: =SUM(S23:S33) -> 4180.917 | T34: =SUM(T23:T33) -> 4865.227 | U34: =SUM(U23:U33) -> 5069.632 | ... AB34: =SUM(AB23:AB33) -> 9402.6504
B36: AP | N36: =BS_Static!D30 -> 222.14 | O36: =BS_Static!E30 -> 235.942 | P36: =BS_Static!F30 -> 260.098 | Q36: =BS_Static!G30 -> 340.582 | R36: =BS_Static!H30 -> 344.819 | S36: =BS_Static!I30 -> 291.904 | T36: =BS_Static!J30 -> 356.176 | U36: =BS_Static!K30 -> 516.047 | ... W36: =BS_Static!M30 -> 423.401 | X36: =-X92*X4 -> 265.46882 | Y36: =-Y92*Y4 -> 281.9462 | Z36: =-Z92*Z4 -> 301.83348 | AA36: =-AA92*AA4 -> 301.83348 | AB36: =-AB92*AB4 -> 332.01682
B37: Accurred Expenses | N37: =BS_Static!D31 -> 316.283 | O37: =BS_Static!E31 -> 310.353 | P37: =BS_Static!F31 -> 322.934 | Q37: =BS_Static!G31 -> 340.075 | R37: =BS_Static!H31 -> 382.74 | S37: =BS_Static!I31 -> 334.132 | T37: =BS_Static!J31 -> 409.285 | U37: =BS_Static!K31 -> 360.782 | ... W37: =BS_Static!M31 -> 393.905 | X37: =X9*-X93 -> 389.04914 | Y37: =Y9*-Y93 -> 427.95405 | Z37: =Z9*-Z93 -> 466.46992 | AA37: =AA9*-AA93 -> 498.02524 | AB37: =AB9*-AB93 -> 531.22692
B38: Debt | N38: =BS_Static!D40+BS_Static!D49 -> 1274.139 | O38: =BS_Static!E40+BS_Static!E49 -> 1253.682 | P38: =BS_Static!F40+BS_Static!F49 -> 935.981 | Q38: =BS_Static!G40+BS_Static!G49+BS_Static!G41 -> 857.662 | R38: =BS_Static!H40+BS_Static!H49 -> 687.406 | S38: =BS_Static!I40+BS_Static!I49 -> 683.286 | T38: =BS_Static!J40+BS_Static!J49 -> 677.285 | U38: =BS_Static!K40+BS_Static!K49 -> 1068.055 | V38: =BS_Static!L40+BS_Static!L49 -> 1555.106 | W38: =BS_Static!M40+BS_Static!M49 -> 1544.774 | X38: =X123 -> 1558.3 | Y38: =Y123 -> 1558.3 | Z38: =Z123 -> 1558.3 | AA38: =AA123 -> 1558.3 | AB38: =AB123 -> 1558.3
B39: Deferred Rev | N39: =BS_Static!D36+BS_Static!D42 -> 189.073 | O39: =BS_Static!E36+BS_Static!E42 -> 182.863 | P39: =BS_Static!F36+BS_Static!F42 -> 185.007 | Q39: =BS_Static!G36+BS_Static!G42 -> 169.457 | R39: =BS_Static!H36+BS_Static!H42 -> 156.873 | S39: =BS_Static!I36+BS_Static!I42 -> 158.363 | T39: =BS_Static!J36+BS_Static!J42 -> 175.464 | U39: =BS_Static!K36+BS_Static!K42 -> 200.235 | ... W39: =BS_Static!M36+BS_Static!M42 -> 237.619 | X39: 200 | Y39: 200 | Z39: 200 | AA39: 200 | AB39: 200
B40: Lease | N40: =BS_Static!D39+BS_Static!D48 -> 0 | O40: =BS_Static!E39+BS_Static!E48 -> 0 | P40: =BS_Static!F39+BS_Static!F48 -> 0 | Q40: =BS_Static!G39+BS_Static!G48 -> 0 | R40: =BS_Static!H39+BS_Static!H48 -> 0 | S40: =BS_Static!I39+BS_Static!I48 -> 80.45 | T40: =BS_Static!J39+BS_Static!J48 -> 60.196 | U40: =BS_Static!K39+BS_Static!K48 -> 61.317 | ... W40: =BS_Static!M39+BS_Static!M48 -> 39.562 | X40: 50 | Y40: 50 | Z40: 50 | AA40: 50 | AB40: 50
B41: Other Liabilities | N41: =BS_Static!D44 -> 72.54 | O41: =BS_Static!E44 -> 124.394 | P41: =BS_Static!F44 -> 111.349 | Q41: =BS_Static!G44 -> 119.413 | R41: =BS_Static!H44 -> 148.747 | S41: =BS_Static!I44 -> 123.185 | T41: =BS_Static!J44 -> 166.803 | U41: =BS_Static!K44 -> 150.335 | ... W41: =BS_Static!M44 -> 185.938 | X41: =X94*X3 -> 183.08195 | Y41: =Y94*Y3 -> 201.39014 | Z41: =Z94*Z3 -> 219.51526 | AA41: =AA94*AA3 -> 241.46678 | AB41: =AB94*AB3 -> 265.61346
B42: Retained Earnings | N42: =BS_Static!D57 -> -5998.79 | O42: =BS_Static!E57 -> -5926.206 | P42: =BS_Static!F57 -> -4664.253 | Q42: =BS_Static!G57 -> -4947.652 | R42: =BS_Static!H57 -> -4644.413 | S42: =BS_Static!I57 -> -4283.122 | T42: =BS_Static!J57 -> -3785.132 | U42: =BS_Static!K57 -> -3632.23 | ... W42: =BS_Static!M57 -> -3293.447 | X42: =W42+X14 -> -3047.6695 | Y42: =X42+Y14 -> -2697.3091 | Z42: =Y42+Z14 -> -2265.8318 | AA42: =Z42+AA14 -> -1506.4863 | AB42: =AA42+AB14 -> -605.49187
B43: Total Paid in Capital | N43: =BS_Static!D51+BS_Static!D52+BS_Static!D53 -> 6641.792 | O43: =BS_Static!E51+BS_Static!E52+BS_Static!E53 -> 6716.876 | P43: =BS_Static!F51+BS_Static!F52+BS_Static!F53 -> 6811.612 | Q43: =BS_Static!G51+BS_Static!G52+BS_Static!G53 -> 6882.766 | R43: =BS_Static!H51+BS_Static!H52+BS_Static!H53 -> 6839.258 | S43: =BS_Static!I51+BS_Static!I52+BS_Static!I53 -> 6828.077 | T43: =BS_Static!J51+BS_Static!J52+BS_Static!J53 -> 6804.711 | U43: =BS_Static!K51+BS_Static!K52+BS_Static!K53 -> 6391.736 | ... W43: =BS_Static!M51+BS_Static!M52+BS_Static!M53 -> 6156.296 | X43: =X142 -> 5983.2243 | Y43: =Y142 -> 5829.6317 | Z43: =Z142 -> 5692.2157 | AA43: =AA142 -> 5645.0478 | AB43: =AB142 -> 5604.2184
...

Sheet historical>>>

Sheet IS_Static
I1: Next Report Date: | J1: 45904 | K1: Last Refresh: | L1: 45828
I2: FYE Date: | J2: 45598
K3: Identifier | L3: CIEN-US | M3: 1 | P3: original | Q3: restated | R3: Units | S3: M
K4: Start Date | L4: -9 | O4: 1 | P4: ANN | Q4: ANN_R | R4: Billions | S4: B
K5: End Date | L5: 0 | O5: 2 | P5: QTR | Q5: QTR_R | R5: Millions | S5: M
K6: Frequency | L6: Fiscal Years | M6: ANN | N6: ANN_R | O6: 3 | P6: SEMI | Q6: SEMI_R | R6: Thousands | S6: T
K7: Report Basis | L7: Restated | M7: ANN_R | O7: 4 | P7: YTD | Q7: YTD_R
K8: Units | L8: Millions
B9: Ciena Corporation
B11: Income Statement | D11: 42307 | E11: 42674 | F11: 43039 | G11: 43404 | H11: 43769 | I11: 44134 | J11: 44498 | K11: 44865 | L11: 45230 | M11: 45596
B12: Total revenue | C12: RV | D12: 2445.669 | E12: 2600.573 | F12: 2801.687 | G12: 3094.286 | H12: 3572.131 | I12: 3532.157 | J12: 3620.684 | K12: 3632.661 | L12: 4386.549 | M12: 4014.955
B13: Products | C13: PRODUCTS | D13: 2002.395 | E13: 2117.472 | F13: 2318.581 | G13: 2565.46 | H13: 2983.815 | I13: 2914.79 | J13: 2932.602 | K13: 2888.848 | L13: 3581.039 | M13: 3159.021
B14: Services | C14: SERVICES | D14: 443.274 | E14: 483.101 | F14: 483.106 | G14: 528.826 | H14: 588.316 | I14: 617.367 | J14: 688.082 | K14: 743.813 | L14: 805.51 | M14: 855.934
B15: Total cost of goods sold | C15: TOTAL COST OF GOODS SOLD | D15: -1370.106 | E15: -1438.997 | F15: -1555.901 | G15: -1779.596 | H15: -2030.065 | I15: -1879.266 | J15: -1898.705 | K15: -2072.317 | L15: -2507.698 | M15: -2295.365
B16: Products | C16: PRODUCTS2 | D16: -1120.373 | E16: -1176.304 | F16: -1308.295 | G16: -1507.157 | H16: -1716.358 | I16: -1573.791 | J16: -1545.269 | K16: -1699.631 | L16: -2088.44 | M16: -1861.317
B17: Services | C17: SERVICES2 | D17: -249.733 | E17: -262.693 | F17: -247.606 | G17: -272.439 | H17: -313.707 | I17: -305.475 | J17: -353.436 | K17: -372.686 | L17: -419.258 | M17: -434.048
B18: Gross profit | C18: GROSS PROFIT | D18: 1075.563 | E18: 1161.576 | F18: 1245.786 | G18: 1314.69 | H18: 1542.066 | I18: 1652.891 | J18: 1721.979 | K18: 1560.344 | L18: 1878.851 | M18: 1719.59
B19: Total operating expenses | C19: TOTAL OPERATING EXPENSES | D19: -975.115 | E19: -1005.407 | F19: -1031.064 | G19: -1084.744 | H19: -1195.3 | I19: -1165.927 | J19: -1226.623 | K19: -1337.536 | L19: -1521.306 | M19: -1552.973
B20: Research and development | C20: RESEARCH AND DEVELOPMENT | D20: -414.201 | E20: -451.794 | F20: -475.329 | G20: -491.564 | H20: -548.139 | I20: -529.888 | J20: -536.666 | K20: -624.656 | L20: -750.559 | M20: -767.497
B21: Selling and marketing | C21: SELLING AND MARKETING | D21: -333.836 | E21: -349.731 | F21: -356.169 | G21: -394.06 | H21: -423.046 | I21: -416.425 | J21: -452.214 | K21: -466.565 | L21: -490.804 | M21: -510.668
B22: General and administrative | C22: GENERAL AND ADMINISTRATIVE | D22: -148.941 | E22: -137.441 | F22: -142.604 | G22: -165.244 | H22: -177.769 | I22: -173.579 | J22: -184.446 | K22: -179.98 | L22: -218.758 | M22: -220.647
B23: General and administrative excluding provision for / recovery of doubtful accounts and acquisition and integration costs | C23: GENERAL AND ADMINISTRATIVE EXCLUDING PROVISION FOR / RECOVERY OF DOUBTFUL ACCOUNTS AND ACQUISITION AND INTEGRATION COSTS | D23: -123.402 | E23: -132.828 | F23: -142.604 | G23: -160.133 | H23: -174.399 | I23: -169.548 | J23: -181.874 | K23: -179.382 | L23: -215.284 | M23: -220.647
B24: Provision for / recovery of doubtful accounts | C24: PROVISION FOR / RECOVERY OF DOUBTFUL ACCOUNTS | D24: - | E24: - | F24: - | G24: - | H24: - | I24: - | J24: - | K24: - | L24: - | M24: -
B25: Acquisition and integration costs | C25: ACQUISITION AND INTEGRATION COSTS | D25: -25.539 | E25: -4.613 | F25: 0 | G25: -5.111 | H25: -3.37 | I25: -4.031 | J25: -2.572 | K25: -0.598 | L25: -3.474 | M25: 0
B26: Gain on lease settlement | C26: GAIN ON LEASE SETTLEMENT | D26: 0 | E26: 0 | F26: 0 | G26: 0 | H26: 0 | I26: 0 | J26: 0 | K26: 0 | L26: 0 | M26: 0
B27: Goodwill impairment | C27: GOODWILL IMPAIRMENT | D27: 0 | E27: 0 | F27: 0 | G27: 0 | H27: 0 | I27: 0 | J27: 0 | K27: 0 | L27: 0 | M27: 0
B28: Long-lived asset impairment | C28: LONG-LIVED ASSET IMPAIRMENT | D28: 0 | E28: 0 | F28: 0 | G28: 0 | H28: 0 | I28: 0 | J28: 0 | K28: 0 | L28: 0 | M28: 0
B29: Change in fair value of contingent consideration | C29: CHANGE IN FAIR VALUE OF CONTINGENT CONSIDERATION | D29: 0 | E29: 0 | F29: 0 | G29: 0 | H29: 0 | I29: 0 | J29: 0 | K29: 0 | L29: 0 | M29: 0
B30: Restructuring costs / recoveries | C30: RESTRUCTURING COSTS / RECOVERIES | D30: -8.626 | E30: -4.933 | F30: -23.933 | G30: -18.139 | H30: -24.538 | I30: -22.652 | J30: -29.565 | K30: -33.824 | L30: -23.834 | M30: -24.592
B31: Amortization of intangible assets | C31: AMORTIZATION OF INTANGIBLE ASSETS | D31: -69.511 | E31: -61.508 | F31: -33.029 | G31: -15.737 | H31: -21.808 | I31: -23.383 | J31: -23.732 | K31: -32.511 | L31: -37.351 | M31: -29.569
B32: Income / loss from operations | C32: INCOME / LOSS FROM OPERATIONS | D32: 100.448 | E32: 156.169 | F32: 214.722 | G32: 229.946 | H32: 346.766 | I32: 486.964 | J32: 495.356 | K32: 222.808 | L32: 357.545 | M32: 166.617
B33: Interest and other income / loss, net | C33: INTEREST AND OTHER INCOME / LOSS NET | D33: -25.505 | E33: -12.795 | F33: -2.744 | G33: -25.916 | H33: 3.876 | I33: 0.318 | J33: -1.768 | K33: 6.747 | L33: 54.134 | M33: 50.261
B34: Interest and other income / loss, net excluding loss on extinguishment and modification of debt | C34: INTEREST AND OTHER INCOME / LOSS NET EXCLUDING LOSS ON EXTINGUISHMENT AND MODIFICATION OF DEBT | D34: 0 | E34: -12.569 | F34: 0.913 | G34: -12.029 | H34: 3.876 | I34: 0.964 | J34: -1.768 | K34: 6.747 | L34: 62.008 | M34: 50.261
B35: Loss on extinguishment and modification of debt | C35: LOSS ON EXTINGUISHMENT AND MODIFICATION OF DEBT | D35: 0 | E35: -0.226 | F35: -3.657 | G35: -13.887 | H35: 0 | I35: -0.646 | J35: 0 | K35: 0 | L35: -7.874 | M35: 0
B36: Interest expense | C36: INTEREST EXPENSE | D36: -51.179 | E36: -56.656 | F36: -55.852 | G36: -55.249 | H36: -37.452 | I36: -31.321 | J36: -30.837 | K36: -47.05 | L36: -88.026 | M36: -97.028
... B43: Net loss / income | C43: NI | D43: 11.667 | E43: 72.584 | F43: 1261.953 | G43: -344.69 | H43: 253.434 | I43: 361.291 | J43: 500.196 | K43: 152.902 | L43: 254.827 | M43: 83.956
B44: Per share | C44: PER SHARE | D44: - | E44: - | F44: - | G44: - | H44: - | I44: - | J44: - | K44: - | L44: - | M44: -
B45: Basic | C45: BASIC | D45: 0.1 | E45: 0.52 | F45: 8.89 | G45: -2.4 | H45: 1.63 | I45: 2.34 | J45: 3.22 | K45: 1.01 | L45: 1.71 | M45: 0.58
B46: Diluted | C46: DILUTED | D46: 0.1 | E46: 0.51 | F46: 7.53 | G46: -2.49 | H46: 1.61 | I46: 2.32 | J46: 3.19 | K46: 1 | L46: 1.71 | M46: 0.58
B47: Weighted average shares | C47: WEIGHTED AVERAGE SHARES | D47: - | E47: - | F47: - | G47: - | H47: - | I47: - | J47: - | K47: - | L47: - | M47: -
...

Sheet CF_Static
I1: Next Report Date: | J1: 45904 | K1: Last Refresh: | L1: 45828
I2: FYE Date: | J2: 45598
K3: Identifier | L3: CIEN-US | M3: 1 | P3: original | Q3: restated | R3: Units | S3: M
K4: Start Date | L4: -9 | O4: 1 | P4: ANN | Q4: ANN_R | R4: Billions | S4: B
K5: End Date | L5: 0 | O5: 2 | P5: QTR | Q5: QTR_R | R5: Millions | S5: M
K6: Frequency | L6: Fiscal Years | M6: ANN | N6: ANN_R | O6: 3 | P6: SEMI | Q6: SEMI_R | R6: Thousands | S6: T
K7: Report Basis | L7: Restated | M7: ANN_R | O7: 4 | P7: YTD | Q7: YTD_R
K8: Units | L8: Millions
B9: Ciena Corporation
B11: Cash Flow | D11: 42307 | E11: 42674 | F11: 43039 | G11: 43404 | H11: 43769 | I11: 44134 | J11: 44498 | K11: 44865 | L11: 45230 | M11: 45596
B12: Net cash provided by / used in operating activities | C12: NET CASH PROVIDED BY / USED IN OPERATING ACTIVITIES | D12: 262.112 | E12: 289.52 | F12: 234.882 | G12: 229.261 | H12: 413.14 | I12: 493.654 | J12: 541.646 | K12: -167.756 | L12: 168.332 | M12: 514.532
B13: Net loss / income | C13: NET LOSS / INCOME | D13: 11.667 | E13: 72.584 | F13: 1261.953 | G13: -344.69 | H13: 253.434 | I13: 361.291 | J13: 500.196 | K13: 152.902 | L13: 254.827 | M13: 83.956
B14: Adjustments to reconcile net loss / income to net cash provided by / used in operating activities | C14: ADJUSTMENTS TO RECONCILE NET LOSS / INCOME TO NET CASH PROVIDED BY / USED IN OPERATING ACTIVITIES | D14: 250.445 | E14: 216.936 | F14: -1027.071 | G14: 573.951 | H14: 159.706 | I14: 132.363 | J14: 41.45 | K14: -320.658 | L14: -86.495 | M14: 430.576
B15: Gain / loss on extinguishment of debt | C15: GAIN / LOSS ON EXTINGUISHMENT OF DEBT | D15: - | E15: 0 | F15: 0 | G15: 10.039 | H15: - | I15: - | J15: 0 | K15: 0 | L15: 1.864 | M15: 0
B16: Realized loss due to impairment of marketable debt investments | C16: REALIZED LOSS DUE TO IMPAIRMENT OF MARKETABLE DEBT INVESTMENTS | D16: - | E16: - | F16: - | G16: - | H16: - | I16: - | J16: - | K16: - | L16: - | M16: -
B17: Non-cash impairment of long-lived assets | C17: NON-CASH IMPAIRMENT OF LONG-LIVED ASSETS | D17: - | E17: - | F17: - | G17: - | H17: - | I17: - | J17: - | K17: - | L17: - | M17: -
B18: Change in fair value of contingent consideration | C18: CHANGE IN FAIR VALUE OF CONTINGENT CONSIDERATION | D18: - | E18: - | F18: - | G18: - | H18: - | I18: - | J18: - | K18: - | L18: - | M18: -
B19: Loss on fair value of debt conversion liability | C19: LOSS ON FAIR VALUE OF DEBT CONVERSION LIABILITY | D19: - | E19: 0 | F19: 0 | G19: 12.07 | H19: - | I19: - | J19: - | K19: - | L19: - | M19: -
B20: Depreciation of equipment, building, furniture and fixtures, and amortization of leasehold improvements | C20: DEPRECIATION OF EQUIPMENT BUILDING FURNITURE AND FIXTURES AND AMORTIZATION OF LEASEHOLD IMPROVEMENTS | D20: 55.901 | E20: 63.394 | F20: 77.189 | G20: 84.214 | H20: 87.576 | I20: 93.908 | J20: 96.233 | K20: 95.922 | L20: 92.564 | M20: 92.846
B21: Share-based compensation costs | C21: SHARE-BASED COMPENSATION COSTS | D21: 55.34 | E21: 51.993 | F21: 48.36 | G21: 52.972 | H21: 59.736 | I21: 67.758 | J21: 84.336 | K21: 105.131 | L21: 130.455 | M21: 156.404
B22: Impairment of goodwill | C22: IMPAIRMENT OF GOODWILL | D22: - | E22: - | F22: - | G22: - | H22: - | I22: - | J22: - | K22: - | L22: - | M22: -
B23: Amortization of intangible assets | C23: AMORTIZATION OF INTANGIBLE ASSETS | D23: 79.866 | E23: 78.298 | F23: 45.713 | G23: 25.806 | H23: 35.136 | I23: 38.619 | J23: 36.033 | K23: 44.281 | L23: 49.616 | M23: 40.624
B24: Other | C24: OTHER | D24: 27.373 | E24: 25.514 | F24: -1086.094 | G24: 488.016 | H24: 25.695 | I24: 84.822 | J24: -141.944 | K24: -27.502 | L24: -25.449 | M24: -65.042
B25: Change in fair value of embedded redemption feature | C25: CHANGE IN FAIR VALUE OF EMBEDDED REDEMPTION FEATURE | D25: 0 | E25: 0 | F25: 0 | G25: 0 | H25: 0 | I25: 0 | J25: 0 | K25: 0 | L25: 0 | M25: 0
B26: Other excluding change in fair value of embedded redemption feature | C26: OTHER EXCLUDING CHANGE IN FAIR VALUE OF EMBEDDED REDEMPTION FEATURE | D26: 27.373 | E26: 25.514 | F26: -1086.094 | G26: 488.016 | H26: 25.695 | I26: 84.822 | J26: -141.944 | K26: -27.502 | L26: -25.449 | M26: -65.042
B27: Amortization of discount / premium on marketable securities | C27: AMORTIZATION OF DISCOUNT / PREMIUM ON MARKETABLE SECURITIES | D27: - | E27: - | F27: - | G27: - | H27: - | I27: - | J27: - | K27: - | L27: - | M27: -
B28: Other excluding amortization of discount / premium on marketable securities | C28: OTHER EXCLUDING AMORTIZATION OF DISCOUNT / PREMIUM ON MARKETABLE SECURITIES | D28: 27.373 | E28: 25.514 | F28: -1086.094 | G28: 488.016 | H28: 25.695 | I28: 84.822 | J28: -141.944 | K28: -27.502 | L28: -25.449 | M28: -65.042
B29: Deferred tax provision / benefit | C29: DEFERRED TAX PROVISION / BENEFIT | D29: 0 | E29: -1.116 | F29: -1126.732 | G29: 463.631 | H29: 19.865 | I29: 64.339 | J29: -156.469 | K29: -27.502 | L29: -14.852 | M29: -76.81
B30: Other excluding deferred tax provision / benefit | C30: OTHER EXCLUDING DEFERRED TAX PROVISION / BENEFIT | D30: 27.373 | E30: 26.63 | F30: 40.638 | G30: 24.385 | H30: 5.83 | I30: 20.483 | J30: 14.525 | K30: 0 | L30: -10.597 | M30: 11.768
B31: Provision for doubtful accounts | C31: PROVISION FOR DOUBTFUL ACCOUNTS | D31: 1.576 | E31: 1.701 | F31: 18.221 | G31: 2.7 | H31: - | I31: - | J31: - | K31: - | L31: - | M31: -
B32: Gain on cost method equity investments, net | C32: GAIN ON COST METHOD EQUITY INVESTMENTS NET | D32: - | E32: - | F32: - | G32: - | H32: - | I32: - | J32: -0.164 | K32: -4.12 | L32: -26.368 | M32: 0
B33: Other excluding provision for doubtful accounts | C33: OTHER EXCLUDING PROVISION FOR DOUBTFUL ACCOUNTS | D33: 25.797 | E33: 24.929 | F33: 22.417 | G33: 21.685 | H33: - | I33: - | J33: 14.689 | K33: 4.12 | L33: 15.771 | M33: 11.768
B34: Gain / loss on cost method investments | C34: GAIN / LOSS ON COST METHOD INVESTMENTS | D34: - | E34: - | F34: - | G34: - | H34: - | I34: - | J34: - | K34: - | L34: - | M34: -
B35: Provision for inventory excess and obsolescence | C35: PROVISION FOR INVENTORY EXCESS AND OBSOLESCENCE | D35: 26.846 | E35: 33.713 | F35: 35.459 | G35: 30.615 | H35: 28.085 | I35: 24.701 | J35: 17.85 | K35: 16.184 | L35: 29.464 | M35: 77.341
B36: Provision for warranty | C36: PROVISION FOR WARRANTY | D36: 17.881 | E36: 15.483 | F36: 7.965 | G36: 20.992 | H36: 23.105 | I36: 22.417 | J36: 17.093 | K36: 17.44 | L36: 31.742 | M36: 25.643
B37: Changes in assets and liabilities | C37: CHANGES IN ASSETS AND LIABILITIES | D37: -12.762 | E37: -51.459 | F37: -155.663 | G37: -150.773 | H37: -99.627 | I37: -199.862 | J37: -68.151 | K37: -572.114 | L37: -396.751 | M37: 102.76
B38: Accounts receivable | C38: ACCOUNTS RECEIVABLE | D38: -37.297 | E38: -26.074 | F38: -66.123 | G38: -168.357 | H38: 65.712 | I38: -17.299 | J38: -174.377 | K38: -47.069 | L38: -94.565 | M38: 80.313
B39: Inventories | C39: INVENTORIES | D39: 46.898 | E39: -53 | F39: -91.567 | G39: -27.445 | H39: -112.941 | I39: -25.044 | J39: -47.567 | K39: -589.113 | L39: -132.497 | M39: 153.021
B40: Prepaid expenses and other | C40: PREPAID EXPENSES AND OTHER | D40: -46.383 | E40: 30.047 | F40: -33.834 | G40: -21.425 | H40: -96.618 | I40: -38.998 | J40: -19.691 | K40: -58.996 | L40: -51.965 | M40: -198.91
B41: Operating lease right-of-use assets | C41: OPERATING LEASE RIGHT-OF-USE ASSETS | D41: 0 | E41: 0 | F41: 0 | G41: 0 | H41: 0 | I41: 16.787 | J41: 16.632 | K41: 16.453 | L41: 14.19 | M41: 11.837
...

Sheet BS_Static
I1: Next Report Date: | J1: 45904 | K1: Last Refresh: | L1: 45828
I2: FYE Date: | J2: 45598
K3: Identifier | L3: CIEN-US | M3: 1 | P3: original | Q3: restated | R3: Units | S3: M
K4: Start Date | L4: -9 | O4: 1 | P4: ANN | Q4: ANN_R | R4: Billions | S4: B
K5: End Date | L5: 0 | O5: 2 | P5: QTR | Q5: QTR_R | R5: Millions | S5: M
K6: Frequency | L6: Fiscal Years | M6: ANN | N6: ANN_R | O6: 3 | P6: SEMI | Q6: SEMI_R | R6: Thousands | S6: T
K7: Report Basis | L7: Restated | M7: ANN_R | O7: 4 | P7: YTD | Q7: YTD_R
K8: Units | L8: Millions
B9: Ciena Corporation
B11: Balance Sheet | D11: 42307 | E11: 42674 | F11: 43039 | G11: 43404 | H11: 43769 | I11: 44134 | J11: 44498 | K11: 44865 | L11: 45230 | M11: 45596
B12: Total assets | C12: TA | D12: 2695.051 | E12: 2873.575 | F12: 3951.711 | G12: 3756.523 | H12: 3893.346 | I12: 4180.917 | J12: 4865.227 | K12: 5069.632 | L12: 5601.495 | M12: 5641.337
B13: Total current assets | C13: TOTAL CURRENT ASSETS | D13: 1864.21 | E13: 2013.192 | F13: 2006.311 | G13: 2142.602 | H13: 2381.802 | I13: 2611.159 | J13: 3188.906 | K13: 3385.896 | L13: 3575.779 | M13: 3544.416
B14: Cash and cash equivalents | C14: CASH AND CASH EQUIVALENTS | D14: 790.971 | E14: 777.615 | F14: 640.513 | G14: 745.423 | H14: 904.045 | I14: 1088.624 | J14: 1422.546 | K14: 994.352 | L14: 1010.618 | M14: 934.863
B15: Short-term investments | C15: SHORT-TERM INVESTMENTS | D15: 135.107 | E15: 275.248 | F15: 279.133 | G15: 148.981 | H15: 109.94 | I15: 150.667 | J15: 181.483 | K15: 153.989 | L15: 104.753 | M15: 316.343
B16: Accounts receivable, net of allowance for doubtful accounts | C16: ACCOUNTS RECEIVABLE NET OF ALLOWANCE FOR DOUBTFUL ACCOUNTS | D16: 550.792 | E16: 576.235 | F16: 622.183 | G16: 786.502 | H16: 724.854 | I16: 719.405 | J16: 884.958 | K16: 920.772 | L16: 1003.876 | M16: 908.597
B17: Inventories | C17: INVENTORIES | D17: 191.162 | E17: 211.251 | F17: 267.143 | G17: 262.751 | H17: 345.049 | I17: 344.379 | J17: 374.265 | K17: 946.73 | L17: 1050.838 | M17: 820.43
B18: Prepaid expenses and other | C18: PREPAID EXPENSES AND OTHER | D18: 196.178 | E18: 172.843 | F18: 197.339 | G18: 198.945 | H18: 297.914 | I18: 308.084 | J18: 325.654 | K18: 370.053 | L18: 405.694 | M18: 564.183
B19: Long-term investments | C19: LONG-TERM INVESTMENTS | D19: 95.105 | E19: 90.172 | F19: 49.783 | G19: 58.97 | H19: 10.014 | I19: 82.226 | J19: 70.038 | K19: 35.385 | L19: 134.278 | M19: 80.92
B20: Equipment, building, furniture and fixtures, net | C20: EQUIPMENT BUILDING FURNITURE AND FIXTURES NET | D20: 191.973 | E20: 288.406 | F20: 308.465 | G20: 292.067 | H20: 286.884 | I20: 272.377 | J20: 284.968 | K20: 267.779 | L20: 280.147 | M20: 337.722
B21: Operating lease right-of-use assets | C21: OPERATING LEASE RIGHT-OF-USE ASSETS | D21: - | E21: - | F21: - | G21: - | H21: 0 | I21: 57.026 | J21: 44.285 | K21: 45.108 | L21: 35.14 | M21: 27.417
B22: Goodwill | C22: GOODWILL | D22: 256.434 | E22: 266.974 | F22: 267.458 | G22: 297.968 | H22: 297.937 | I22: 310.847 | J22: 311.645 | K22: 328.322 | L22: 444.765 | M22: 444.707
B23: Other intangible assets, net | C23: OTHER INTANGIBLE ASSETS NET | D23: 202.673 | E23: 146.711 | F23: 100.997 | G23: 148.225 | H23: 112.781 | I23: 96.647 | J23: 65.314 | K23: 69.517 | L23: 205.627 | M23: 165.02
B24: Other long-term assets | C24: OTHER LONG-TERM ASSETS | D24: 84.656 | E24: 68.12 | F24: 1218.697 | G24: 816.691 | H24: 803.928 | I24: 750.635 | J24: 900.071 | K24: 937.625 | L24: 925.759 | M24: 1041.135
