Workbook
Name CS: Model!$F$10
Name current_year: Model!$C$11
Name debt: Model!$F$13
Name live_case: Model!$C$12
Name live_tax: Model!$C$20
Name live_tgr: Model!$C$19
Name live_wacc: Model!$C$18
Name net_cash: Model!$F$12

Sheet WACC
B2: META-US
E4: FY2024
B5: Debt | E5: =Model!F13 -> 28298
B6: % Debt | E6: =Model!F13/Model!F11 -> 0.014603302
B7: Cost of Debt | E7: =Debt!C33*0.01 -> 0.050568872
B8: tax rate | E8: =live_tax -> 0.2
E10: 45837
B11: Equity Value | E11: =Model!F11 -> 1937780.9
B12: % Equity | E12: =1-E6 -> 0.9853967
B13: Cost of Equity | E13: =E14+E15*E16 -> 0.097801
B14: Risk free Rate | E14: 0.04281
B15: Beta | E15: 1.27
B16: Market Risk Premium | E16: 0.0433
B18: WACC | E18: =E6*E7*(1-E8)+E13*E12 -> 0.09696356

Sheet Model
B2: META-US
A5: 1 | B5: Overview
E7: Current | H7: Future
B9: Ticker | C9: Meta | E9: $/Shr | F9: 733.63 | H9: Implied $/Shr | I9: =N110 -> 444.83443
B10: Date | C10: =TODAY() -> 45837 | E10: CS | F10: 2641.36 | H10: % imp. Move | I10: =I9/F9-1 -> -0.3936529
B11: Starting Year | C11: 2024 | E11: MC | F11: =F9*F10 -> 1937780.9 | H11: Fwrd FCE | I11: =F11/J100 -> 67.701668
B12: Live Scenario | C12: 2 | E12: Net Cash | F12: 70301
E13: Debt | F13: =28298 -> 28298
E14: EV | F14: =F11-F12+F13 -> 1895777.9
B16: Live Case | E16: Bear Case | H16: Street Case | K16: Bull Case
B17: # | C17: =live_case -> 2 | E17: # | F17: 1 | H17: # | I17: 2 | K17: # | L17: 3
B18: WACC | C18: =CHOOSE($C$17,F18,I18,L18) -> 0.0969 | E18: WACC | F18: 0.12 | H18: WACC | I18: 0.0969 | K18: WACC | L18: 0.09
B19: TGR | C19: =CHOOSE($C$17,F19,I19,L19) -> 0.04 | E19: TGR | F19: 0.04 | H19: TGR | I19: 0.04 | K19: TGR | L19: 0.05
B20: Tax Rate | C20: =CHOOSE($C$17,F20,I20,L20) -> 0.2 | E20: Tax Rate | F20: 0.3 | H20: Tax Rate | I20: 0.2 | K20: Tax Rate | L20: 0.19
A27: 2 | B27: Income Statement | D27: Units
J28: 1 | K28: 2 | L28: 3 | M28: 4 | N28: 5
B29: Year Ended | E29: =F29-1 -> 2020 | F29: =G29-1 -> 2021 | G29: =H29-1 -> 2022 | H29: =I29-1 -> 2023 | I29: =current_year -> 2024 | J29: =I29+1 -> 2025 | K29: =J29+1 -> 2026 | L29: =K29+1 -> 2027 | M29: =L29+1 -> 2028 | N29: =M29+1 -> 2029
B30: Revenue | E30: ='Income Statement_Static'!H11 -> 85965 | F30: ='Income Statement_Static'!I11 -> 117929 | G30: ='Income Statement_Static'!J11 -> 116609 | H30: ='Income Statement_Static'!K11 -> 134902 | I30: ='Income Statement_Static'!L11 -> 164501
B31: % growth | F31: =F30/E30-1 -> 0.37182574 | G31: =G30/F30-1 -> -0.011193176 | H31: =H30/G30-1 -> 0.15687468 | I31: =I30/H30-1 -> 0.21941113
B33: Cost of Goods Sold | E33: ='Income Statement_Static'!H12 -> 16692 | F33: ='Income Statement_Static'!I12 -> 22649 | G33: ='Income Statement_Static'!J12 -> 23754 | H33: ='Income Statement_Static'!K12 -> 26006 | I33: ='Income Statement_Static'!L12 -> 30130
B34: % of revenue | E34: =E33/E30 -> 0.19417205 | F34: =F33/F30 -> 0.19205624 | G34: =G33/G30 -> 0.2037064 | H34: =H33/H30 -> 0.19277698 | I34: =I33/I30 -> 0.18315998
B36: Gross Profit | E36: =E30-E33 -> 69273 | F36: =F30-F33 -> 95280 | G36: =G30-G33 -> 92855 | H36: =H30-H33 -> 108896 | I36: =I30-I33 -> 134371
B37: % of sales | E37: =E36/E30 -> 0.80582795 | F37: =F36/F30 -> 0.80794376 | G37: =G36/G30 -> 0.7962936 | H37: =H36/H30 -> 0.80722302 | I37: =I36/I30 -> 0.81684002
B39: SG&A | E39: ='Income Statement_Static'!H18 -> 36602 | F39: ='Income Statement_Static'!I18 -> 48527 | G39: ='Income Statement_Static'!J18 -> 59300 | H39: ='Income Statement_Static'!K18 -> 58693 | I39: ='Income Statement_Static'!L18 -> 64602
B40: % of sales | E40: =E39/E30 -> 0.42577793 | F40: =F39/F30 -> 0.41149336 | G40: =G39/G30 -> 0.50853708 | H40: =H39/H30 -> 0.4350788 | I40: =I39/I30 -> 0.39271494
B42: EBIT | E42: =E36-E39 -> 32671 | F42: =F36-F39 -> 46753 | G42: =G36-G39 -> 33555 | H42: =H36-H39 -> 50203 | I42: =I36-I39 -> 69769
B43: % of sales | E43: =E42/E30 -> 0.38005002 | F43: =F42/F30 -> 0.39645041 | G43: =G42/G30 -> 0.28775652 | H43: =H42/H30 -> 0.37214422 | I43: =I42/I30 -> 0.42412508
B45: Taxes | E45: ='Income Statement_Static'!H50 -> 4034 | F45: ='Income Statement_Static'!I50 -> 7914 | G45: ='Income Statement_Static'!J50 -> 5619 | H45: ='Income Statement_Static'!K50 -> 8330 | I45: ='Income Statement_Static'!L50 -> 8303
B46: % of sales | E46: =E45/E30 -> 0.046926075 | F46: =F45/F30 -> 0.067108175 | G46: =G45/G30 -> 0.048186675 | H46: =H45/H30 -> 0.061748529 | I46: =I45/I30 -> 0.050473857
B48: NOPAT | E48: =E42-E45 -> 28637 | F48: =F42-F45 -> 38839 | G48: =G42-G45 -> 27936 | H48: =H42-H45 -> 41873 | I48: =I42-I45 -> 61466
B49: % growth | F49: =F48/E48-1 -> 0.3562524 | G49: =G48/F48-1 -> -0.28072298 | H49: =H48/G48-1 -> 0.49889032 | I49: =I48/H48-1 -> 0.46791489
A51: 2 | B51: Cashflow Items | D51: Units
B53: Year Ended | E53: =F53-1 -> 2020 | F53: =G53-1 -> 2021 | G53: =H53-1 -> 2022 | H53: =I53-1 -> 2023 | I53: =current_year -> 2024 | J53: =I53+1 -> 2025 | K53: =J53+1 -> 2026 | L53: =K53+1 -> 2027 | M53: =L53+1 -> 2028 | N53: =M53+1 -> 2029
B54: NOPAT | E54: =E48 -> 28637 | F54: =F48 -> 38839 | G54: =G48 -> 27936 | H54: =H48 -> 41873 | I54: =I48 -> 61466
B56: D&A | E56: ='Income Statement_Static'!H14 -> 6862 | F56: ='Income Statement_Static'!I14 -> 7967 | G56: ='Income Statement_Static'!J14 -> 8686 | H56: ='Income Statement_Static'!K14 -> 11178 | I56: ='Income Statement_Static'!L14 -> 15498
B57: % of CapEx | E57: =E56/-E65 -> 0.45398611 | F57: =F56/-F65 -> 0.42909463 | G57: =G56/-G65 -> 0.27635137 | H57: =H56/-H65 -> 0.40996112 | I57: =I56/-I65 -> 0.41598669
B59: Deferred Taxes | E59: ='Cash Flow_Static'!H16 -> -1192 | F59: ='Cash Flow_Static'!I16 -> 609 | G59: ='Cash Flow_Static'!J16 -> -3286 | H59: ='Cash Flow_Static'!K16 -> 131 | I59: ='Cash Flow_Static'!L16 -> -4738
B60: % of
B62: Changes in WC | E62: ='Cash Flow_Static'!H22 -> -2723 | F62: ='Cash Flow_Static'!I22 -> 700 | G62: ='Cash Flow_Static'!J22 -> 5683 | H62: ='Cash Flow_Static'!K22 -> 3836 | I62: ='Cash Flow_Static'!L22 -> 1048
B63: % change in sales | E63: =ABS(E62)/E30 -> 0.031675682 | F63: =ABS(F62)/F30 -> 0.0059357749 | G63: =ABS(G62)/G30 -> 0.048735518 | H63: =ABS(H62)/H30 -> 0.028435457 | I63: =ABS(I62)/I30 -> 0.0063707819
...

Sheet Debt
A1: Meta Platforms Inc Class A
A2: META 30303M102 B7TL820 NASDAQ Common stock
A5: Instrument ID | B5: Description | C5: Balance Sheet Amt Out (USD) | D5: Current Amt Out (USD) | E5: Coupon Rate | F5: Coupon Type | G5: Issue Date | H5: Maturity Date | I5: Issue Curr | J5: Seniority | K5: Price | L5: YTW | M5: OAS (LIBOR)
A6: Notes/Bonds | C6: 29000 | D6: 29000 | O6: WA
A7: 30303M8B1 (144A) | B7: Meta Platforms Inc | C7: 91.9 | D7: 91.9 | E7: 0.035 | F7: Fixed | G7: 08/22 | H7: 08/27 | I7: USD | J7: SNR Unsec | K7: 98.96 | L7: 4.01 | M7: 47.01 | N7: _ | O7: =C7/$C$27*L7 -> 0.012782927
A8: 30303M8G0 | B8: Meta Platforms Inc | C8: 2658.1 | D8: 2658.1 | E8: 0.035 | F8: Fixed | G8: 12/22 | H8: 08/27 | I8: USD | J8: SNR Unsec | K8: 98.96 | L8: 4.01 | M8: 47.01 | N8: _ | O8: =C8/$C$27*L8 -> 0.36973121
A9: 30303M8L9 | B9: Meta Platforms Inc | C9: 1500 | D9: 1500 | E9: 0.046 | F9: Fixed | G9: 05/23 | H9: 05/28 | I9: USD | J9: SNR Unsec | K9: 101.72 | L9: 3.94 | M9: 46.6 | N9: _ | O9: =C9/$C$27*L9 -> 0.20500191
A10: 30303M8S4 | B10: Meta Platforms Inc | C10: 1000 | D10: 1000 | E10: 0.043 | F10: Fixed | G10: 08/24 | H10: 08/29 | I10: USD | J10: SNR Unsec | K10: 100.79 | L10: 4.08 | M10: 62.04 | O10: =C10/$C$27*L10 -> 0.14152416
A11: 30303M8M7 | B11: Meta Platforms Inc | C11: 1000 | D11: 1000 | E11: 0.048 | F11: Fixed | G11: 05/23 | H11: 05/30 | I11: USD | J11: SNR Unsec | K11: 102.81 | L11: 4.14 | M11: 65 | O11: =C11/$C$27*L11 -> 0.1436054
A12: 30303M8T2 | B12: Meta Platforms Inc | C12: 1000 | D12: 1000 | E12: 0.0455 | F12: Fixed | G12: 08/24 | H12: 08/31 | I12: USD | J12: SNR Unsec | K12: 101.11 | L12: 4.34 | M12: 78.22 | O12: =C12/$C$27*L12 -> 0.15054286
A13: 30303M8D7 (144A) | B13: Meta Platforms Inc | C13: 21.2 | D13: 21.2 | E13: 0.0385 | F13: Fixed | G13: 08/22 | H13: 08/32 | I13: USD | J13: SNR Unsec | K13: 95.76 | L13: 4.55 | M13: 93.8 | N13: _ | O13: =C13/$C$27*L13 -> 0.0033459364
A14: 30303M8H8 | B14: Meta Platforms Inc | C14: 2978.8 | D14: 2978.8 | E14: 0.0385 | F14: Fixed | G14: 12/22 | H14: 08/32 | I14: USD | J14: SNR Unsec | K14: 95.76 | L14: 4.55 | M14: 93.8 | N14: _ | O14: =C14/$C$27*L14 -> 0.47013563
A15: 30303M8N5 | B15: Meta Platforms Inc | C15: 1750 | D15: 1750 | E15: 0.0495 | F15: Fixed | G15: 05/23 | H15: 05/33 | I15: USD | J15: SNR Unsec | K15: 101.99 | L15: 4.64 | M15: 98.51 | N15: _ | O15: =C15/$C$27*L15 -> 0.28166083
A16: 30303M8U9 | B16: Meta Platforms Inc | C16: 2500 | D16: 2500 | E16: 0.0475 | F16: Fixed | G16: 08/24 | H16: 08/34 | I16: USD | J16: SNR Unsec | K16: 99.88 | L16: 4.77 | M16: 104.75 | O16: =C16/$C$27*L16 -> 0.41364598
A17: 30303M8E5 (144A) | B17: Meta Platforms Inc | C17: 1.2 | D17: 1.2 | E17: 0.0445 | F17: Fixed | G17: 08/22 | H17: 08/52 | I17: USD | J17: SNR Unsec | K17: 83.55 | L17: 5.64 | M17: 164.58 | N17: _ | O17: =C17/$C$27*L17 -> 0.00023476361
A18: 30303M8J4 | B18: Meta Platforms Inc | C18: 2748.8 | D18: 2748.8 | E18: 0.0445 | F18: Fixed | G18: 12/22 | H18: 08/52 | I18: USD | J18: SNR Unsec | K18: 83.55 | L18: 5.64 | M18: 164.58 | O18: =C18/$C$27*L18 -> 0.53776517
A19: 30303M8Q8 | B19: Meta Platforms Inc | C19: 2500 | D19: 2500 | E19: 0.056 | F19: Fixed | G19: 05/23 | H19: 05/53 | I19: USD | J19: SNR Unsec | K19: 99.05 | L19: 5.67 | M19: 168.19 | O19: =C19/$C$27*L19 -> 0.49169239
A20: 30303M8V7 | B20: Meta Platforms Inc | C20: 3250 | D20: 3250 | E20: 0.054 | F20: Fixed | G20: 08/24 | H20: 08/54 | I20: USD | J20: SNR Unsec | K20: 96.31 | L20: 5.66 | M20: 168.22 | N20: _ | O20: =C20/$C$27*L20 -> 0.63807277
A21: 30303M8F2 (144A) | B21: Meta Platforms Inc | C21: 6 | D21: 6 | E21: 0.0465 | F21: Fixed | G21: 08/22 | H21: 08/62 | I21: USD | J21: SNR Unsec | K21: 83.28 | L21: 5.74 | M21: 185.05 | N21: _ | O21: =C21/$C$27*L21 -> 0.0011946304
A22: 30303M8K1 | B22: Meta Platforms Inc | C22: 1494 | D22: 1494 | E22: 0.0465 | F22: Fixed | G22: 12/22 | H22: 08/62 | I22: USD | J22: SNR Unsec | K22: 83.28 | L22: 5.74 | M22: 185.05 | N22: _ | O22: =C22/$C$27*L22 -> 0.29746297
A23: 30303M8R6 | B23: Meta Platforms Inc | C23: 1750 | D23: 1750 | E23: 0.0575 | F23: Fixed | G23: 05/23 | H23: 05/63 | I23: USD | J23: SNR Unsec | K23: 99.93 | L23: 5.75 | M23: 186.08 | O23: =C23/$C$27*L23 -> 0.3490409
A24: 30303M8W5 | B24: Meta Platforms Inc | C24: 2750 | D24: 2750 | E24: 0.0555 | F24: Fixed | G24: 08/24 | H24: 08/64 | I24: USD | J24: SNR Unsec | K24: 96.76 | L24: 5.76 | M24: 187.83 | N24: _ | O24: =C24/$C$27*L24 -> 0.54944674
A25: Other | C25: -171 | D25: -171
A26: - | B26: Unamortized Discount & Issuance Costs - Unsecured Bonds | C26: -171 | D26: -171 | E26: - | F26: - | G26: - | H26: - | I26: USD | J26: Other | K26: - | L26: - | M26: -
B27: LT Debt Total | C27: 28829
B28: Current Portion of LTD | C28: 0
B29: Net LT Debt Total | C29: 28829
B30: ST Debt Total | C30: 0
B31: Total Debt | C31: 28829 | D31: 28829
A32: Data as of 27 Jun '25 | B32: Amount Outstanding in millions of USD
A33: Source: FactSet DCS and FactSet Fixed Income | B33: WA COST OF DEBT | C33: =SUM(O7:O24) -> 5.0568872
A34: * The current total debt outstanding value is not considered a reconciled amount. Activity is determined on a transactional basis and there can be events that may affect amounts that are not disclosed until the next filing date.

Sheet Income Statement_Static
K2: Identifier | L2: META-US
K3: Start Date | L3: -9
K4: End Date | L4: 0
K5: Report Basis | L5: ANN_R
K6: Currency | L6: LOC | M6: USD
B7: Meta Platforms Inc Class A
B9: Income Statement | C9: 42369 | D9: 42734 | E9: 43098 | F9: 43465 | G9: 43830 | H9: 44196 | I9: 44561 | J9: 44925 | K9: 45289 | L9: 45657
C10: Final/ | D10: Final/ | E10: Final/ | F10: Final/ | G10: Final/ | H10: Final/ | I10: Final/ | J10: Final/ | K10: Final/Restate | L10: Final/
B11: Sales | C11: 17928 | D11: 27638 | E11: 40653 | F11: 55838 | G11: 70697 | H11: 85965 | I11: 117929 | J11: 116609 | K11: 134902 | L11: 164501
B12: Cost of Goods Sold (COGS) incl. D&A | C12: 2867 | D12: 3789 | E12: 5454 | F12: 9355 | G12: 12770 | H12: 16692 | I12: 22649 | J12: 23754 | K12: 26006 | L12: 30130
B13: COGS excluding D&A | C13: 922 | D13: 1447 | E13: 2429 | F13: 5040 | G13: 7029 | H13: 9830 | I13: 14682 | J13: 15068 | K13: 14828 | L13: 14632
B14: Depreciation & Amortization Expense | C14: 1945 | D14: 2342 | E14: 3025 | F14: 4315 | G14: 5741 | H14: 6862 | I14: 7967 | J14: 8686 | K14: 11178 | L14: 15498
B15: Depreciation | C15: 1215 | D15: 1591 | E15: 2333 | F15: 3675 | G15: 5179 | H15: 6389 | I15: 7560 | J15: 8501 | K15: 11017 | L15: 15287
B16: Amortization of Intangibles | C16: 730 | D16: 751 | E16: 692 | F16: 640 | G16: 562 | H16: 473 | I16: 407 | J16: 185 | K16: 161 | L16: 211
B17: Gross Income | C17: 15061 | D17: 23849 | E17: 35199 | F17: 46483 | G17: 57927 | H17: 69273 | I17: 95280 | J17: 92855 | K17: 108896 | L17: 134371
B18: SG&A Expense | C18: 8767 | D18: 11422 | E18: 14996 | F18: 21570 | G18: 28941 | H18: 36602 | I18: 48527 | J18: 59300 | K18: 58693 | L18: 64602
B19: Research & Development | C19: 4747 | D19: 5919 | E19: 7754 | F19: 10273 | G19: 13600 | H19: 18447 | I19: 24655 | J19: 33619 | K19: 36489 | L19: 43619
B20: Other SG&A | C20: 4020 | D20: 5503 | E20: 7242 | F20: 11297 | G20: 15341 | H20: 18155 | I20: 23872 | J20: 25681 | K20: 22204 | L20: 20983
B21: EBIT (Operating Income) | C21: 6294 | D21: 12427 | E21: 20203 | F21: 24913 | G21: 28986 | H21: 32671 | I21: 46753 | J21: 33555 | K21: 50203 | L21: 69769
B22: Nonoperating Income - Net | C22: -8 | D22: 91 | E22: 391 | F22: 448 | G22: 846 | H22: 509 | I22: 531 | J22: 35 | K22: 1123 | L22: 1998
B23: Nonoperating Interest Income | C23: 52 | D23: 176 | E23: 398 | F23: 661 | G23: 924 | H23: 672 | I23: 461 | J23: 436 | K23: 1639 | L23: 2517
B24: Equity in Earnings of Affiliates | C24: 0 | D24: 0 | E24: 0 | F24: 0 | G24: 0 | H24: 0 | I24: 0 | J24: 0 | K24: 0 | L24: -
B25: Other Income (Expense) | C25: -60 | D25: -85 | E25: -7 | F25: -213 | G25: -78 | H25: -163 | I25: 70 | J25: -401 | K25: -516 | L25: -519
B26: Interest Expense | C26: 23 | D26: 0 | E26: - | F26: - | G26: 20 | H26: - | I26: - | J26: 160 | K26: 446 | L26: 715
B27: Gross Interest Expense | C27: 23 | D27: 0 | E27: - | F27: - | G27: 20 | H27: - | I27: - | J27: 160 | K27: 446 | L27: 715
B28: Interest Capitalized | C28: 0 | D28: 0 | E28: 0 | F28: 0 | G28: 0 | H28: 0 | I28: 0 | J28: 0 | K28: 0 | L28: 0
B29: Unusual Expense - Net | C29: 69 | D29: - | E29: - | F29: - | G29: 5000 | H29: 0 | I29: 0 | J29: 4611 | K29: 3452 | L29: 389
B30: Impairments | C30: - | D30: - | E30: - | F30: - | G30: - | H30: - | I30: - | J30: - | K30: - | L30: -
B31: Goodwill | C31: 0 | D31: 0 | E31: 0 | F31: 0 | G31: 0 | H31: 0 | I31: 0 | J31: 0 | K31: 0 | L31: 0
B32: Property,Plant & Equipment | C32: - | D32: - | E32: - | F32: - | G32: - | H32: - | I32: - | J32: - | K32: - | L32: -
B33: Financial Fixed Assets | C33: - | D33: - | E33: - | F33: - | G33: - | H33: - | I33: - | J33: - | K33: - | L33: -
B34: Restructuring Expense | C34: 0 | D34: 0 | E34: 0 | F34: 0 | G34: 0 | H34: 0 | I34: 0 | J34: 4611 | K34: 3452 | L34: 389
B35: Legal Claim Expense | C35: - | D35: - | E35: - | F35: - | G35: 5000 | H35: 0 | I35: 0 | J35: - | K35: - | L35: -
B36: Unrealized Valuation Gain/Loss | C36: - | D36: - | E36: - | F36: - | G36: - | H36: - | I36: - | J36: - | K36: - | L36: -
B37: Investments | C37: - | D37: - | E37: - | F37: - | G37: - | H37: - | I37: - | J37: - | K37: - | L37: -
B38: Investment Property | C38: - | D38: - | E38: - | F38: - | G38: - | H38: - | I38: - | J38: - | K38: - | L38: -
B39: Biological Assets | C39: - | D39: - | E39: - | F39: - | G39: - | H39: - | I39: - | J39: - | K39: - | L39: -
B40: Hedges/Derivatives | C40: - | D40: - | E40: - | F40: - | G40: - | H40: - | I40: - | J40: - | K40: - | L40: -
B41: Other Intangibles | C41: - | D41: - | E41: - | F41: - | G41: - | H41: - | I41: - | J41: - | K41: - | L41: -
B42: Excpl Chrgs - Others | C42: - | D42: - | E42: - | F42: - | G42: - | H42: - | I42: - | J42: - | K42: - | L42: -
...

Sheet Balance Sheet_Static
K2: Identifier | L2: META-US
K3: Start Date | L3: -9
K4: End Date | L4: 0
C5: ='Balance Sheet_Static'!L71+'Balance Sheet_Static'!L62-'Balance Sheet_Static'!L13 -> 5527 | K5: Report Basis | L5: ANN_R
K6: Currency | L6: LOC | M6: USD
B7: Meta Platforms Inc Class A
B9: Balance Sheet | C9: 42369 | D9: 42734 | E9: 43098 | F9: 43465 | G9: 43830 | H9: 44196 | I9: 44561 | J9: 44925 | K9: 45289 | L9: 45657
C10: Final/ | D10: Final/ | E10: Final/ | F10: Final/ | G10: Final/ | H10: Final/ | I10: Final/ | J10: Final/ | K10: Final/Restate | L10: Final/
B11: Assets
B12: Cash & Short-Term Investments | C12: 18434 | D12: 29449 | E12: 41711 | F12: 41124 | G12: 54863 | H12: 62195 | I12: 48147 | J12: 41032 | K12: 65502 | L12: 78168
B13: Cash Only | C13: 4907 | D13: 8903 | E13: 8079 | F13: 10029 | G13: 19087 | H13: 17817 | I13: 16750 | J13: 14975 | K13: 41961 | L13: 44242
B14: Total Short Term Investments | C14: 13527 | D14: 20546 | E14: 33632 | F14: 31095 | G14: 35776 | H14: 44378 | I14: 31397 | J14: 26057 | K14: 23541 | L14: 33926
B15: Short-Term Receivables | C15: 2559 | D15: 3993 | E15: 5832 | F15: 7587 | G15: 9518 | H15: 11335 | I15: 14039 | J15: 13466 | K15: 16169 | L15: 16994
B16: Accounts Receivables, Net | C16: 2559 | D16: 3993 | E16: 5832 | F16: 7587 | G16: 9518 | H16: 11335 | I16: 14039 | J16: 13466 | K16: 16169 | L16: 16994
B17: Accounts Receivables, Gross | C17: 2627 | D17: 4087 | E17: 6021 | F17: 7816 | G17: 9724 | H17: 11449 | I17: 14039 | J17: 13466 | K17: 16169 | L17: 16994
B18: Bad Debt/Doubtful Accounts | C18: -68 | D18: -94 | E18: -189 | F18: -229 | G18: -206 | H18: -114 | I18: - | J18: - | K18: - | L18: -
B19: Other Receivables | C19: 0 | D19: 0 | E19: 0 | F19: 0 | G19: 0 | H19: 0 | I19: 0 | J19: 0 | K19: 0 | L19: 0
B20: Inventories | C20: 0 | D20: 0 | E20: 0 | F20: 0 | G20: 0 | H20: 0 | I20: 0 | J20: 0 | K20: 0 | L20: 0
B21: Finished Goods | C21: 0 | D21: 0 | E21: 0 | F21: 0 | G21: 0 | H21: 0 | I21: 0 | J21: 0 | K21: 0 | L21: 0
B22: Other Current Assets | C22: 659 | D22: 959 | E22: 1020 | F22: 1769 | G22: 1844 | H22: 2140 | I22: 4480 | J22: 5051 | K22: 3694 | L22: 4883
B23: Prepaid Expenses | C23: - | D23: - | E23: - | F23: - | G23: - | H23: - | I23: - | J23: - | K23: - | L23: -
B24: Miscellaneous Current Assets | C24: 659 | D24: 959 | E24: 1020 | F24: 1769 | G24: 1844 | H24: 2140 | I24: 4480 | J24: 5051 | K24: 3694 | L24: 4883
B25: Total Current Assets | C25: 21652 | D25: 34401 | E25: 48563 | F25: 50480 | G25: 66225 | H25: 75670 | I25: 66666 | J25: 59549 | K25: 85365 | L25: 100045
B26: Net Property, Plant & Equipment | C26: 5687 | D26: 8591 | E26: 13721 | F26: 24683 | G26: 44783 | H26: 54981 | I26: 69964 | J26: 92191 | K26: 109881 | L26: 136268
B27: Property, Plant & Equipment - Gross | C27: 7819 | D27: 11803 | E27: 18337 | F27: 31573 | G27: 55446 | H27: 70399 | I27: 90044 | J27: 117166 | K27: 143015 | L27: 179585
B28: Buildings | C28: 2273 | D28: 3109 | E28: 4909 | F28: 7401 | G28: 11226 | H28: 17360 | I28: 22531 | J28: 27720 | K28: 37961 | L28: 47076
B29: Land & Improvements | C29: 596 | D29: 696 | E29: 798 | F29: 899 | G29: 1097 | H29: 1326 | I29: 1688 | J29: 1874 | K29: 2080 | L29: 2561
B30: Machinery & Equipment | C30: 3633 | D30: 5179 | E30: 7998 | F30: 13017 | G30: 17004 | H30: 22003 | I30: 25584 | J30: 39972 | K30: 46838 | L30: 68397
B31: Construction in Progress | C31: 622 | D31: 1890 | E31: 2992 | F31: 7228 | G31: 10099 | H31: 11288 | I31: 14687 | J31: 25052 | K31: 24269 | L31: 26802
B32: Leases | C32: - | D32: - | E32: - | F32: - | G32: 1635 | H32: 2295 | I32: 2840 | J32: 3353 | K32: 4185 | L32: 5384
B33: Computer Software and Equipment | C33: - | D33: - | E33: - | F33: - | G33: - | H33: - | I33: - | J33: - | K33: - | L33: -
B34: Leased Property | C34: - | D34: - | E34: - | F34: - | G34: - | H34: - | I34: - | J34: - | K34: - | L34: -
B35: Transportation Equipment | C35: - | D35: - | E35: - | F35: - | G35: - | H35: - | I35: - | J35: - | K35: - | L35: -
B36: Other Property, Plant & Equipment | C36: 695 | D36: 929 | E36: 1640 | F36: 3028 | G36: 4925 | H36: 6779 | I36: 10559 | J36: 6522 | K36: 14388 | L36: 14443
B37: Operating Lease Right-of-Use Assets | C37: - | D37: - | E37: - | F37: - | G37: 9460 | H37: 9348 | I37: 12155 | J37: 12673 | K37: 13294 | L37: 14922
B38: Accumulated Depreciation | C38: 2132 | D38: 3212 | E38: 4616 | F38: 6890 | G38: 10663 | H38: 15418 | I38: 20080 | J38: 24975 | K38: 33134 | L38: 43317
B39: Buildings | C39: - | D39: - | E39: - | F39: - | G39: - | H39: - | I39: - | J39: - | K39: - | L39: -
B40: Land & Improvements | C40: - | D40: - | E40: - | F40: - | G40: - | H40: - | I40: - | J40: - | K40: - | L40: -
B41: Machinery & Equipment | C41: - | D41: - | E41: - | F41: - | G41: - | H41: - | I41: - | J41: - | K41: - | L41: -
B42: Construction in Progress | C42: - | D42: - | E42: - | F42: - | G42: - | H42: - | I42: - | J42: - | K42: - | L42: -
...

Sheet Cash Flow_Static
K2: Identifier | L2: META-US
K3: Start Date | L3: -9
K4: End Date | L4: 0
K5: Report Basis | L5: ANN_R
K6: Currency | L6: LOC | M6: USD
B7: Meta Platforms Inc Class A
B9: Cash Flow | C9: 42369 | D9: 42734 | E9: 43098 | F9: 43465 | G9: 43830 | H9: 44196 | I9: 44561 | J9: 44925 | K9: 45289 | L9: 45657
C10: Final/ | D10: Final/ | E10: Final/ | F10: Final/ | G10: Final/ | H10: Final/ | I10: Final/ | J10: Final/ | K10: Final/Restate | L10: Final/
B11: Operating Activities
B12: Net Income / Starting Line | C12: 3688 | D12: 10217 | E12: 15934 | F12: 22112 | G12: 18485 | H12: 29146 | I12: 39370 | J12: 23200 | K12: 39098 | L12: 62360
B13: Depreciation, Depletion & Amortization | C13: 1945 | D13: 2342 | E13: 3025 | F13: 4315 | G13: 5741 | H13: 6862 | I13: 7967 | J13: 8686 | K13: 11178 | L13: 15498
B14: Depreciation and Depletion | C14: 1215 | D14: 1591 | E14: 2333 | F14: 3675 | G14: 5179 | H14: 6389 | I14: 7560 | J14: 8501 | K14: 11017 | L14: 15287
B15: Amortization of Intangible Assets | C15: 730 | D15: 751 | E15: 692 | F15: 640 | G15: 562 | H15: 473 | I15: 407 | J15: 185 | K15: 161 | L15: 211
B16: Deferred Taxes & Investment Tax Credit | C16: -795 | D16: -457 | E16: -377 | F16: 286 | G16: -37 | H16: -1192 | I16: 609 | J16: -3286 | K16: 131 | L16: -4738
B17: Deferred Taxes | C17: -795 | D17: -457 | E17: -377 | F17: 286 | G17: -37 | H17: -1192 | I17: 609 | J17: -3286 | K17: 131 | L17: -4738
B18: Investment Tax Credit | C18: - | D18: - | E18: - | F18: - | G18: - | H18: - | I18: - | J18: - | K18: - | L18: -
B19: Interest paid on Lease Liabilities - Operating | C19: - | D19: - | E19: - | F19: - | G19: - | H19: - | I19: - | J19: - | K19: - | L19: -
B20: Other Funds | C20: 2977 | D20: 3248 | E20: 3747 | F20: 4088 | G20: 4875 | H20: 6654 | I20: 9037 | J20: 16192 | K20: 16870 | L20: 17160
B21: Funds from Operations | C21: 7815 | D21: 15350 | E21: 22329 | F21: 30801 | G21: 29064 | H21: 41470 | I21: 56983 | J21: 44792 | K21: 67277 | L21: 90280
B22: Changes in Working Capital | C22: 784 | D22: 758 | E22: 1887 | F22: -1527 | G22: 7250 | H22: -2723 | I22: 700 | J22: 5683 | K22: 3836 | L22: 1048
B23: Receivables | C23: -973 | D23: -1489 | E23: -1609 | F23: -1892 | G23: -1961 | H23: -1512 | I23: -3110 | J23: 231 | K23: -2399 | L23: -1485
B24: Inventories | C24: - | D24: - | E24: - | F24: - | G24: - | H24: - | I24: - | J24: - | K24: - | L24: -
B25: Accounts Payable | C25: 35 | D25: 81 | E25: 138 | F25: 378 | G25: 461 | H25: 161 | I25: 1424 | J25: 300 | K25: -220 | L25: 373
B26: Income Taxes Payable | C26: - | D26: - | E26: - | F26: - | G26: - | H26: - | I26: - | J26: - | K26: - | L26: -
B27: Other Accruals | C27: 513 | D27: 1014 | E27: 309 | F27: 1417 | G27: 7300 | H27: -1054 | I27: 3357 | J27: 4210 | K27: 5352 | L27: 323
B28: Other Assets/Liabilities | C28: 1209 | D28: 1152 | E28: 3049 | F28: -1430 | G28: 1450 | H28: -318 | I28: -971 | J28: 942 | K28: 1103 | L28: 1837
B29: Net Operating Cash Flow | C29: 8599 | D29: 16108 | E29: 24216 | F29: 29274 | G29: 36314 | H29: 38747 | I29: 57683 | J29: 50475 | K29: 71113 | L29: 91328
B30: Investing Activities
B31: Capital Expenditures | C31: -2523 | D31: -4491 | E31: -6733 | F31: -13915 | G31: -15102 | H31: -15115 | I31: -18567 | J31: -31431 | K31: -27266 | L31: -37256
B32: Capital Expenditures (Fixed Assets) | C32: -2523 | D32: -4491 | E32: -6733 | F32: -13915 | G32: -15102 | H32: -15115 | I32: -18567 | J32: -31431 | K32: -27266 | L32: -37256
B33: Capital Expenditures (Other Assets) | C33: 0 | D33: 0 | E33: 0 | F33: - | G33: 0 | H33: 0 | I33: 0 | J33: 0 | K33: 0 | L33: 0
B34: Net Assets from Acquisitions | C34: -313 | D34: -123 | E34: -122 | F34: -137 | G34: -508 | H34: -388 | I34: -851 | J34: -1312 | K34: -629 | L34: -270
B35: Sale of Fixed Assets & Businesses | C35: - | D35: - | E35: - | F35: - | G35: 0 | H35: 0 | I35: 0 | J35: 245 | K35: 221 | L35: 0
B36: Purchase/Sale of Investments | C36: -6700 | D36: -7186 | E36: -13250 | F36: 2474 | G36: -4193 | H36: -14520 | I36: 12132 | J36: 3527 | K36: 3202 | L36: -9753
B37: Sale/Maturity of Investments | C37: 9238 | D37: 15155 | E37: 12432 | F37: 17130 | G37: 19717 | H37: 25771 | I37: 42586 | J37: 13158 | K37: 6184 | L37: 15789
B38: Other Funds | C38: 102 | D38: 61 | E38: 67 | F38: -25 | G38: -61 | H38: -36 | I38: -284 | J38: 1 | K38: -23 | L38: 129
B39: Other Uses | C39: 0 | D39: 0 | E39: 0 | F39: -25 | G39: -61 | H39: -36 | I39: -284 | J39: 0 | K39: -23 | L39: 0
B40: Other Sources | C40: 102 | D40: 61 | E40: 67 | F40: 0 | G40: 0 | H40: 0 | I40: 0 | J40: 1 | K40: 0 | L40: 129
B41: Net Investing Cash Flow | C41: -9434 | D41: -11739 | E41: -20038 | F41: -11603 | G41: -19864 | H41: -30059 | I41: -7570 | J41: -28970 | K41: -24495 | L41: -47150
B42: Financing Activities
...

Sheet Ratio Analysis_Static
K2: Identifier | L2: META-US
K3: Start Date | L3: -9
K4: End Date | L4: 0
K5: Report Basis | L5: ANN_R
K6: Currency | L6: LOC
B7: Meta Platforms Inc Class A
B9: Ratio Analysis | C9: 42369 | D9: 42734 | E9: 43098 | F9: 43465 | G9: 43830 | H9: 44196 | I9: 44561 | J9: 44925 | K9: 45289 | L9: 45657
C10: Final/ | D10: Final/ | E10: Final/ | F10: Final/ | G10: Final/ | H10: Final/ | I10: Final/ | J10: Final/ | K10: Final/Restate | L10: Final/
B11: Profitability
B12: Gross Margin | C12: 84.008255 | D12: 86.290614 | E12: 86.584016 | F12: 83.246176 | G12: 81.936999 | H12: 80.582795 | I12: 80.794376 | J12: 79.62936 | K12: 80.722302 | L12: 81.684002
B13: SG&A to Sales | C13: 48.90116 | D13: 41.327158 | E13: 36.887807 | F13: 38.629607 | G13: 40.936673 | H13: 42.577793 | I13: 41.149336 | J13: 50.853708 | K13: 43.50788 | L13: 39.271494
B14: Operating Margin | C14: 35.107095 | D14: 44.963456 | E14: 49.696209 | F14: 44.616569 | G14: 41.000325 | H14: 38.005002 | I14: 39.645041 | J14: 28.775652 | K14: 37.214422 | L14: 42.412508
B15: Pretax Margin | C15: 34.549308 | D15: 45.292713 | E15: 50.658008 | F15: 45.41889 | G15: 35.096256 | H15: 38.597103 | I15: 40.095312 | J15: 24.714216 | K15: 35.157374 | L15: 42.95597
B16: Net Margin | C16: 20.465194 | D16: 36.862291 | E16: 39.160702 | F16: 39.598481 | G16: 26.146795 | H16: 33.904496 | I16: 33.384494 | J16: 19.895548 | K16: 28.982521 | L16: 37.908584
B17: Free Cash Flow Margin | C17: 33.89112 | D17: 42.032709 | E17: 43.005436 | F17: 27.506358 | G17: 30.004102 | H17: 27.490258 | I17: 33.16911 | J17: 16.331501 | K17: 32.502854 | L17: 32.870317
B18: Return on Assets | C18: 8.1905549 | D18: 17.816172 | E18: 21.299796 | F18: 24.316775 | G18: 16.024446 | H18: 19.915816 | I18: 24.205126 | J18: 13.192537 | K18: 18.826532 | L18: 24.663965
B19: Return on Equity | C19: 9.1366387 | D19: 19.703709 | E19: 23.842865 | F19: 27.904893 | G19: 19.964251 | H19: 25.416841 | I19: 31.101754 | J19: 18.516154 | K19: 28.0392 | L19: 37.140602
B20: Return on Common Equity | C20: 9.1366387 | D20: 19.703709 | E20: 23.842865 | F20: 27.904893 | G20: 19.964251 | H20: 25.416841 | I20: 31.101754 | J20: 18.516154 | K20: 28.0392 | L20: 37.140602
B21: Return on Total Capital | C21: 15.567263 | D21: 23.960974 | E21: 30.241069 | F21: 31.328043 | G21: 29.464054 | H21: 25.971104 | I21: 33.538737 | J21: 22.957403 | K21: 29.18075 | L21: 32.948916
B22: Return on Invested Capital | C22: 9.1110007 | D22: 19.683343 | E22: 23.830017 | F22: 27.892221 | G22: 18.948383 | H22: 23.376832 | I22: 28.47822 | J22: 16.022431 | K22: 22.940999 | L22: 29.711721
B23: Cash Flow Return on Invested Capital | C23: 21.353365 | D23: 31.120857 | E23: 36.24797 | F23: 36.928084 | G23: 37.224321 | H23: 31.077407 | I23: 41.724896 | J23: 34.859148 | K23: 41.726002 | L23: 43.513664
B24: Valuation
B25: Price/Sales | C25: 16.655231 | D25: 12.176035 | E25: 12.830929 | F25: 6.8575861 | G25: 8.3497037 | H25: 9.1768287 | I25: 8.1542678 | J25: 2.7884527 | K25: 6.8980507 | L25: 9.3040355
B26: Price/Earnings | C26: 81.131783 | D26: 32.937303 | E26: 32.735975 | F26: 17.317041 | G26: 31.934094 | H26: 27.066716 | I26: 24.425225 | J26: 14.015513 | K26: 23.80075 | L26: 24.543305
B27: Price/Book Value | C27: 6.7338551 | D27: 5.6209171 | E27: 6.8972903 | F27: 4.4472157 | G27: 5.792675 | H27: 6.0661997 | I27: 7.3826291 | J27: 2.5022769 | K27: 5.9182827 | L27: 8.1236674
B28: Price/Tangible Book Value | C28: 12.976453 | D28: 8.6338999 | E28: 9.4537952 | F28: 5.7976021 | G28: 7.1873412 | H28: 7.1649267 | I28: 8.7763246 | J28: 3.0099393 | K28: 6.8816449 | L28: 9.2115277
B29: Price/Cash Flow | C29: 34.724384 | D29: 20.89156 | E29: 21.540129 | F29: 13.080341 | G29: 16.255411 | H29: 20.359927 | I29: 16.67085 | J29: 6.4419748 | K29: 13.085664 | L29: 16.758531
B30: Price/Free Cash Flow | C30: 49.143348 | D30: 28.967999 | E30: 29.835598 | F30: 24.930913 | G30: 27.82854 | H30: 33.382112 | I30: 24.583921 | J30: 17.074075 | K30: 21.222908 | L30: 28.305281
B31: Dividend Yield (%) | C31: 0 | D31: 0 | E31: 0 | F31: 0 | G31: 0 | H31: 0 | I31: 0 | J31: 0 | K31: 0 | L31: 0.34158255
B32: Enterprise Value/EBIT | C32: 270.432 | D32: 140.87606 | E32: 86.043127 | F32: 69.628138 | G32: 58.676154 | H32: 53.307499 | I32: 37.988976 | J32: 52.666297 | K32: 36.076392 | L32: 26.138741
B33: Enterprise Value/EBITDA | C33: 206.59048 | D33: 118.53658 | E33: 74.837666 | F33: 59.348768 | G33: 48.975927 | H33: 44.05457 | I33: 32.457942 | J33: 41.836547 | K33: 29.506575 | L33: 21.387803
B34: Enterprise Value/Sales | C34: 94.940819 | D34: 63.342745 | E34: 42.760173 | F34: 31.065686 | G34: 24.057414 | H34: 20.259516 | I34: 15.060745 | J34: 15.15507 | K34: 13.425621 | L34: 11.086096
B35: Total Debt/Enterprise Value | C35: 0.00018506562 | D35: 0 | E35: 4.141908e-05 | F35: 0.00028824328 | G35: 0.0065111034 | H35: 0.0064176277 | I35: 0.0081380617 | J35: 0.015435564 | K35: 0.020939262 | L35: 0.027290517
B36: Per Share
B37: Sales per Share | C37: 6.2839117 | D37: 9.4488889 | E37: 13.752706 | F37: 19.116056 | G37: 24.581711 | H37: 29.766274 | I37: 41.248339 | J37: 43.156551 | K37: 51.313047 | L37: 62.930757
B38: EBIT (Operating Income) per Share | C38: 2.2060988 | D38: 4.248547 | E38: 6.8345737 | F38: 8.5289284 | G38: 10.078581 | H38: 11.312673 | I38: 16.352921 | J38: 12.418579 | K38: 19.095854 | L38: 26.690513
B39: EPS (recurring) | C39: 1.3096039 | D39: 3.4929915 | E39: 5.3903924 | F39: 7.5700103 | G39: 7.6442976 | H39: 10.092105 | I39: 13.770549 | J39: 9.780792 | K39: 15.790947 | L39: 23.960329
B40: EPS (basic) | C40: 1.31 | D40: 3.5585 | E40: 5.4878 | F40: 7.6509 | G40: 6.4769 | H40: 10.2231 | I40: 13.9858 | J40: 8.6342 | K40: 15.1896 | L40: 24.6093
B41: EPS (diluted) | C41: 1.29 | D41: 3.493 | E41: 5.3904 | F41: 7.57 | G41: 6.4273 | H41: 10.0921 | I41: 13.7706 | J41: 8.5862 | K41: 14.8718 | L41: 23.8562
B42: Headline EPS | C42: - | D42: - | E42: - | F42: - | G42: - | H42: - | I42: - | J42: - | K42: - | L42: -
...
